Workbook

Sheet RESUMEN SEPTIEMBRE
B2: RESUMEN DE COMPRAS · SEPTIEMBRE 2026
B3: LA MINA DE CHAMARTÍN
B4: Todo se calcula desde la hoja TOTAL SEPTIEMBRE. La columna de agosto es el importe fijo del Excel de agosto.
B6: BASE IMPONIBLE | D6: CUOTA IVA | F6: TOTAL CON IVA
B7: =SUM('TOTAL SEPTIEMBRE'!D4:D2000) | D7: =SUM('TOTAL SEPTIEMBRE'!F4:F2000)-SUM('TOTAL SEPTIEMBRE'!D4:D2000) | F7: =SUM('TOTAL SEPTIEMBRE'!F4:F2000)
B9: Nº ALBARANES | D9: Nº PROVEEDORES | F9: CUADRES A REVISAR
B10: =SUMPRODUCT(('TOTAL SEPTIEMBRE'!B4:B1000<>"")/COUNTIFS('TOTAL SEPTIEMBRE'!B4:B1000,'TOTAL SEPTIEMBRE'!B4:B1000&"",'TOTAL SEPTIEMBRE'!C4:C1000,'TOTAL SEPTIEMBRE'!C4:C1000&"")) | D10: =SUMPRODUCT(('TOTAL SEPTIEMBRE'!B4:B2000<>"")/COUNTIF('TOTAL SEPTIEMBRE'!B4:B2000,'TOTAL SEPTIEMBRE'!B4:B2000&"")) | F10: =COUNTIF('CUADRE ALBARANES'!H:H,"REVISAR")
B12: BASE AL 4% DE IVA | D12: BASE AL 10% DE IVA | F12: BASE AL 21% DE IVA | H12: SIN IVA EN EL TICKET
B13: =SUMIF('TOTAL SEPTIEMBRE'!$E$4:$E$2000,0.04,'TOTAL SEPTIEMBRE'!$D$4:$D$2000) | D13: =SUMIF('TOTAL SEPTIEMBRE'!$E$4:$E$2000,0.1,'TOTAL SEPTIEMBRE'!$D$4:$D$2000) | F13: =SUMIF('TOTAL SEPTIEMBRE'!$E$4:$E$2000,0.21,'TOTAL SEPTIEMBRE'!$D$4:$D$2000) | H13: =SUMIF('TOTAL SEPTIEMBRE'!$E$4:$E$2000,0,'TOTAL SEPTIEMBRE'!$D$4:$D$2000)
B16: COMPRAS POR PROVEEDOR
B17: PROVEEDOR | C17: Nº ALB. | D17: BASE SEPTIEMBRE | E17: % DEL MES | F17: BASE AGOSTO | G17: DIF. € | H17: DIF. %
B18: PESCARUM | C18: =SUMPRODUCT(('TOTAL SEPTIEMBRE'!$B$4:$B$1000=B18)/COUNTIFS('TOTAL SEPTIEMBRE'!$B$4:$B$1000,'TOTAL SEPTIEMBRE'!$B$4:$B$1000&"",'TOTAL SEPTIEMBRE'!$C$4:$C$1000,'TOTAL SEPTIEMBRE'!$C$4:$C$1000&"")) | D18: =SUMIF('TOTAL SEPTIEMBRE'!$B$4:$B$2000,B18,'TOTAL SEPTIEMBRE'!$D$4:$D$2000) | E18: =IF($D$61=0,0,D18/$D$61) | F18: 5112.89 | G18: =IF(F18="","",D18-F18) | H18: =IF(OR(F18="",N(F18)=0),"",D18/F18-1)
B19: MAHOU | C19: =SUMPRODUCT(('TOTAL SEPTIEMBRE'!$B$4:$B$1000=B19)/COUNTIFS('TOTAL SEPTIEMBRE'!$B$4:$B$1000,'TOTAL SEPTIEMBRE'!$B$4:$B$1000&"",'TOTAL SEPTIEMBRE'!$C$4:$C$1000,'TOTAL SEPTIEMBRE'!$C$4:$C$1000&"")) | D19: =SUMIF('TOTAL SEPTIEMBRE'!$B$4:$B$2000,B19,'TOTAL SEPTIEMBRE'!$D$4:$D$2000) | E19: =IF($D$61=0,0,D19/$D$61) | G19: =IF(F19="","",D19-F19) | H19: =IF(OR(F19="",N(F19)=0),"",D19/F19-1)
B20: VOLDIS | C20: =SUMPRODUCT(('TOTAL SEPTIEMBRE'!$B$4:$B$1000=B20)/COUNTIFS('TOTAL SEPTIEMBRE'!$B$4:$B$1000,'TOTAL SEPTIEMBRE'!$B$4:$B$1000&"",'TOTAL SEPTIEMBRE'!$C$4:$C$1000,'TOTAL SEPTIEMBRE'!$C$4:$C$1000&"")) | D20: =SUMIF('TOTAL SEPTIEMBRE'!$B$4:$B$2000,B20,'TOTAL SEPTIEMBRE'!$D$4:$D$2000) | E20: =IF($D$61=0,0,D20/$D$61) | F20: 780.87 | G20: =IF(F20="","",D20-F20) | H20: =IF(OR(F20="",N(F20)=0),"",D20/F20-1)
B21: AGROFOOD | C21: =SUMPRODUCT(('TOTAL SEPTIEMBRE'!$B$4:$B$1000=B21)/COUNTIFS('TOTAL SEPTIEMBRE'!$B$4:$B$1000,'TOTAL SEPTIEMBRE'!$B$4:$B$1000&"",'TOTAL SEPTIEMBRE'!$C$4:$C$1000,'TOTAL SEPTIEMBRE'!$C$4:$C$1000&"")) | D21: =SUMIF('TOTAL SEPTIEMBRE'!$B$4:$B$2000,B21,'TOTAL SEPTIEMBRE'!$D$4:$D$2000) | E21: =IF($D$61=0,0,D21/$D$61) | F21: 1199.46 | G21: =IF(F21="","",D21-F21) | H21: =IF(OR(F21="",N(F21)=0),"",D21/F21-1)
B22: MAKRO | C22: =SUMPRODUCT(('TOTAL SEPTIEMBRE'!$B$4:$B$1000=B22)/COUNTIFS('TOTAL SEPTIEMBRE'!$B$4:$B$1000,'TOTAL SEPTIEMBRE'!$B$4:$B$1000&"",'TOTAL SEPTIEMBRE'!$C$4:$C$1000,'TOTAL SEPTIEMBRE'!$C$4:$C$1000&"")) | D22: =SUMIF('TOTAL SEPTIEMBRE'!$B$4:$B$2000,B22,'TOTAL SEPTIEMBRE'!$D$4:$D$2000) | E22: =IF($D$61=0,0,D22/$D$61) | G22: =IF(F22="","",D22-F22) | H22: =IF(OR(F22="",N(F22)=0),"",D22/F22-1)
B23: MARTIN CANEDA | C23: =SUMPRODUCT(('TOTAL SEPTIEMBRE'!$B$4:$B$1000=B23)/COUNTIFS('TOTAL SEPTIEMBRE'!$B$4:$B$1000,'TOTAL SEPTIEMBRE'!$B$4:$B$1000&"",'TOTAL SEPTIEMBRE'!$C$4:$C$1000,'TOTAL SEPTIEMBRE'!$C$4:$C$1000&"")) | D23: =SUMIF('TOTAL SEPTIEMBRE'!$B$4:$B$2000,B23,'TOTAL SEPTIEMBRE'!$D$4:$D$2000) | E23: =IF($D$61=0,0,D23/$D$61) | F23: 1617.8 | G23: =IF(F23="","",D23-F23) | H23: =IF(OR(F23="",N(F23)=0),"",D23/F23-1)
B24: MUNDELA | C24: =SUMPRODUCT(('TOTAL SEPTIEMBRE'!$B$4:$B$1000=B24)/COUNTIFS('TOTAL SEPTIEMBRE'!$B$4:$B$1000,'TOTAL SEPTIEMBRE'!$B$4:$B$1000&"",'TOTAL SEPTIEMBRE'!$C$4:$C$1000,'TOTAL SEPTIEMBRE'!$C$4:$C$1000&"")) | D24: =SUMIF('TOTAL SEPTIEMBRE'!$B$4:$B$2000,B24,'TOTAL SEPTIEMBRE'!$D$4:$D$2000) | E24: =IF($D$61=0,0,D24/$D$61) | F24: 1920.54 | G24: =IF(F24="","",D24-F24) | H24: =IF(OR(F24="",N(F24)=0),"",D24/F24-1)
B25: DIST. TENA MTNEZ | C25: =SUMPRODUCT(('TOTAL SEPTIEMBRE'!$B$4:$B$1000=B25)/COUNTIFS('TOTAL SEPTIEMBRE'!$B$4:$B$1000,'TOTAL SEPTIEMBRE'!$B$4:$B$1000&"",'TOTAL SEPTIEMBRE'!$C$4:$C$1000,'TOTAL SEPTIEMBRE'!$C$4:$C$1000&"")) | D25: =SUMIF('TOTAL SEPTIEMBRE'!$B$4:$B$2000,B25,'TOTAL SEPTIEMBRE'!$D$4:$D$2000) | E25: =IF($D$61=0,0,D25/$D$61) | F25: 1320.36 | G25: =IF(F25="","",D25-F25) | H25: =IF(OR(F25="",N(F25)=0),"",D25/F25-1)
B26: ACEITE Y SAL | C26: =SUMPRODUCT(('TOTAL SEPTIEMBRE'!$B$4:$B$1000=B26)/COUNTIFS('TOTAL SEPTIEMBRE'!$B$4:$B$1000,'TOTAL SEPTIEMBRE'!$B$4:$B$1000&"",'TOTAL SEPTIEMBRE'!$C$4:$C$1000,'TOTAL SEPTIEMBRE'!$C$4:$C$1000&"")) | D26: =SUMIF('TOTAL SEPTIEMBRE'!$B$4:$B$2000,B26,'TOTAL SEPTIEMBRE'!$D$4:$D$2000) | E26: =IF($D$61=0,0,D26/$D$61) | G26: =IF(F26="","",D26-F26) | H26: =IF(OR(F26="",N(F26)=0),"",D26/F26-1)
B27: CONS. Y SAL. JIMENEZ | C27: =SUMPRODUCT(('TOTAL SEPTIEMBRE'!$B$4:$B$1000=B27)/COUNTIFS('TOTAL SEPTIEMBRE'!$B$4:$B$1000,'TOTAL SEPTIEMBRE'!$B$4:$B$1000&"",'TOTAL SEPTIEMBRE'!$C$4:$C$1000,'TOTAL SEPTIEMBRE'!$C$4:$C$1000&"")) | D27: =SUMIF('TOTAL SEPTIEMBRE'!$B$4:$B$2000,B27,'TOTAL SEPTIEMBRE'!$D$4:$D$2000) | E27: =IF($D$61=0,0,D27/$D$61) | F27: 1061.59 | G27: =IF(F27="","",D27-F27) | H27: =IF(OR(F27="",N(F27)=0),"",D27/F27-1)
B28: CRUSTAPESCA | C28: =SUMPRODUCT(('TOTAL SEPTIEMBRE'!$B$4:$B$1000=B28)/COUNTIFS('TOTAL SEPTIEMBRE'!$B$4:$B$1000,'TOTAL SEPTIEMBRE'!$B$4:$B$1000&"",'TOTAL SEPTIEMBRE'!$C$4:$C$1000,'TOTAL SEPTIEMBRE'!$C$4:$C$1000&"")) | D28: =SUMIF('TOTAL SEPTIEMBRE'!$B$4:$B$2000,B28,'TOTAL SEPTIEMBRE'!$D$4:$D$2000) | E28: =IF($D$61=0,0,D28/$D$61) | F28: 772 | G28: =IF(F28="","",D28-F28) | H28: =IF(OR(F28="",N(F28)=0),"",D28/F28-1)
B29: PEÑALASTALLAS | C29: =SUMPRODUCT(('TOTAL SEPTIEMBRE'!$B$4:$B$1000=B29)/COUNTIFS('TOTAL SEPTIEMBRE'!$B$4:$B$1000,'TOTAL SEPTIEMBRE'!$B$4:$B$1000&"",'TOTAL SEPTIEMBRE'!$C$4:$C$1000,'TOTAL SEPTIEMBRE'!$C$4:$C$1000&"")) | D29: =SUMIF('TOTAL SEPTIEMBRE'!$B$4:$B$2000,B29,'TOTAL SEPTIEMBRE'!$D$4:$D$2000) | E29: =IF($D$61=0,0,D29/$D$61) | F29: 519.69 | G29: =IF(F29="","",D29-F29) | H29: =IF(OR(F29="",N(F29)=0),"",D29/F29-1)
B30: MANUEL AMBRES | C30: =SUMPRODUCT(('TOTAL SEPTIEMBRE'!$B$4:$B$1000=B30)/COUNTIFS('TOTAL SEPTIEMBRE'!$B$4:$B$1000,'TOTAL SEPTIEMBRE'!$B$4:$B$1000&"",'TOTAL SEPTIEMBRE'!$C$4:$C$1000,'TOTAL SEPTIEMBRE'!$C$4:$C$1000&"")) | D30: =SUMIF('TOTAL SEPTIEMBRE'!$B$4:$B$2000,B30,'TOTAL SEPTIEMBRE'!$D$4:$D$2000) | E30: =IF($D$61=0,0,D30/$D$61) | F30: 425 | G30: =IF(F30="","",D30-F30) | H30: =IF(OR(F30="",N(F30)=0),"",D30/F30-1)
B31: AGMASFOOD | C31: =SUMPRODUCT(('TOTAL SEPTIEMBRE'!$B$4:$B$1000=B31)/COUNTIFS('TOTAL SEPTIEMBRE'!$B$4:$B$1000,'TOTAL SEPTIEMBRE'!$B$4:$B$1000&"",'TOTAL SEPTIEMBRE'!$C$4:$C$1000,'TOTAL SEPTIEMBRE'!$C$4:$C$1000&"")) | D31: =SUMIF('TOTAL SEPTIEMBRE'!$B$4:$B$2000,B31,'TOTAL SEPTIEMBRE'!$D$4:$D$2000) | E31: =IF($D$61=0,0,D31/$D$61) | F31: 1125.19 | G31: =IF(F31="","",D31-F31) | H31: =IF(OR(F31="",N(F31)=0),"",D31/F31-1)
B32: SUBMARINER | C32: =SUMPRODUCT(('TOTAL SEPTIEMBRE'!$B$4:$B$1000=B32)/COUNTIFS('TOTAL SEPTIEMBRE'!$B$4:$B$1000,'TOTAL SEPTIEMBRE'!$B$4:$B$1000&"",'TOTAL SEPTIEMBRE'!$C$4:$C$1000,'TOTAL SEPTIEMBRE'!$C$4:$C$1000&"")) | D32: =SUMIF('TOTAL SEPTIEMBRE'!$B$4:$B$2000,B32,'TOTAL SEPTIEMBRE'!$D$4:$D$2000) | E32: =IF($D$61=0,0,D32/$D$61) | F32: 712.94 | G32: =IF(F32="","",D32-F32) | H32: =IF(OR(F32="",N(F32)=0),"",D32/F32-1)
B33: CARNICAS MEAT | C33: =SUMPRODUCT(('TOTAL SEPTIEMBRE'!$B$4:$B$1000=B33)/COUNTIFS('TOTAL SEPTIEMBRE'!$B$4:$B$1000,'TOTAL SEPTIEMBRE'!$B$4:$B$1000&"",'TOTAL SEPTIEMBRE'!$C$4:$C$1000,'TOTAL SEPTIEMBRE'!$C$4:$C$1000&"")) | D33: =SUMIF('TOTAL SEPTIEMBRE'!$B$4:$B$2000,B33,'TOTAL SEPTIEMBRE'!$D$4:$D$2000) | E33: =IF($D$61=0,0,D33/$D$61) | F33: 640.26 | G33: =IF(F33="","",D33-F33) | H33: =IF(OR(F33="",N(F33)=0),"",D33/F33-1)
B34: ENRIQUE CAMPS | C34: =SUMPRODUCT(('TOTAL SEPTIEMBRE'!$B$4:$B$1000=B34)/COUNTIFS('TOTAL SEPTIEMBRE'!$B$4:$B$1000,'TOTAL SEPTIEMBRE'!$B$4:$B$1000&"",'TOTAL SEPTIEMBRE'!$C$4:$C$1000,'TOTAL SEPTIEMBRE'!$C$4:$C$1000&"")) | D34: =SUMIF('TOTAL SEPTIEMBRE'!$B$4:$B$2000,B34,'TOTAL SEPTIEMBRE'!$D$4:$D$2000) | E34: =IF($D$61=0,0,D34/$D$61) | F34: 432 | G34: =IF(F34="","",D34-F34) | H34: =IF(OR(F34="",N(F34)=0),"",D34/F34-1)
B35: CONS. SELEC. SANTO | C35: =SUMPRODUCT(('TOTAL SEPTIEMBRE'!$B$4:$B$1000=B35)/COUNTIFS('TOTAL SEPTIEMBRE'!$B$4:$B$1000,'TOTAL SEPTIEMBRE'!$B$4:$B$1000&"",'TOTAL SEPTIEMBRE'!$C$4:$C$1000,'TOTAL SEPTIEMBRE'!$C$4:$C$1000&"")) | D35: =SUMIF('TOTAL SEPTIEMBRE'!$B$4:$B$2000,B35,'TOTAL SEPTIEMBRE'!$D$4:$D$2000) | E35: =IF($D$61=0,0,D35/$D$61) | F35: 382.59 | G35: =IF(F35="","",D35-F35) | H35: =IF(OR(F35="",N(F35)=0),"",D35/F35-1)
B36: PESCADERIA PALACIO | C36: =SUMPRODUCT(('TOTAL SEPTIEMBRE'!$B$4:$B$1000=B36)/COUNTIFS('TOTAL SEPTIEMBRE'!$B$4:$B$1000,'TOTAL SEPTIEMBRE'!$B$4:$B$1000&"",'TOTAL SEPTIEMBRE'!$C$4:$C$1000,'TOTAL SEPTIEMBRE'!$C$4:$C$1000&"")) | D36: =SUMIF('TOTAL SEPTIEMBRE'!$B$4:$B$2000,B36,'TOTAL SEPTIEMBRE'!$D$4:$D$2000) | E36: =IF($D$61=0,0,D36/$D$61) | F36: 369.6 | G36: =IF(F36="","",D36-F36) | H36: =IF(OR(F36="",N(F36)=0),"",D36/F36-1)
B37: MAGOASE | C37: =SUMPRODUCT(('TOTAL SEPTIEMBRE'!$B$4:$B$1000=B37)/COUNTIFS('TOTAL SEPTIEMBRE'!$B$4:$B$1000,'TOTAL SEPTIEMBRE'!$B$4:$B$1000&"",'TOTAL SEPTIEMBRE'!$C$4:$C$1000,'TOTAL SEPTIEMBRE'!$C$4:$C$1000&"")) | D37: =SUMIF('TOTAL SEPTIEMBRE'!$B$4:$B$2000,B37,'TOTAL SEPTIEMBRE'!$D$4:$D$2000) | E37: =IF($D$61=0,0,D37/$D$61) | F37: 930.8 | G37: =IF(F37="","",D37-F37) | H37: =IF(OR(F37="",N(F37)=0),"",D37/F37-1)
B38: DISOLTRIGO | C38: =SUMPRODUCT(('TOTAL SEPTIEMBRE'!$B$4:$B$1000=B38)/COUNTIFS('TOTAL SEPTIEMBRE'!$B$4:$B$1000,'TOTAL SEPTIEMBRE'!$B$4:$B$1000&"",'TOTAL SEPTIEMBRE'!$C$4:$C$1000,'TOTAL SEPTIEMBRE'!$C$4:$C$1000&"")) | D38: =SUMIF('TOTAL SEPTIEMBRE'!$B$4:$B$2000,B38,'TOTAL SEPTIEMBRE'!$D$4:$D$2000) | E38: =IF($D$61=0,0,D38/$D$61) | F38: 318 | G38: =IF(F38="","",D38-F38) | H38: =IF(OR(F38="",N(F38)=0),"",D38/F38-1)
... B43: COCACOLA | C43: =SUMPRODUCT(('TOTAL SEPTIEMBRE'!$B$4:$B$1000=B43)/COUNTIFS('TOTAL SEPTIEMBRE'!$B$4:$B$1000,'TOTAL SEPTIEMBRE'!$B$4:$B$1000&"",'TOTAL SEPTIEMBRE'!$C$4:$C$1000,'TOTAL SEPTIEMBRE'!$C$4:$C$1000&"")) | D43: =SUMIF('TOTAL SEPTIEMBRE'!$B$4:$B$2000,B43,'TOTAL SEPTIEMBRE'!$D$4:$D$2000) | E43: =IF($D$61=0,0,D43/$D$61) | F43: 457.72 | G43: =IF(F43="","",D43-F43) | H43: =IF(OR(F43="",N(F43)=0),"",D43/F43-1)
B44: HIELOS ANGEL ICE | C44: =SUMPRODUCT(('TOTAL SEPTIEMBRE'!$B$4:$B$1000=B44)/COUNTIFS('TOTAL SEPTIEMBRE'!$B$4:$B$1000,'TOTAL SEPTIEMBRE'!$B$4:$B$1000&"",'TOTAL SEPTIEMBRE'!$C$4:$C$1000,'TOTAL SEPTIEMBRE'!$C$4:$C$1000&"")) | D44: =SUMIF('TOTAL SEPTIEMBRE'!$B$4:$B$2000,B44,'TOTAL SEPTIEMBRE'!$D$4:$D$2000) | E44: =IF($D$61=0,0,D44/$D$61) | G44: =IF(F44="","",D44-F44) | H44: =IF(OR(F44="",N(F44)=0),"",D44/F44-1)
B45: TOMATERIA DE CEA | C45: =SUMPRODUCT(('TOTAL SEPTIEMBRE'!$B$4:$B$1000=B45)/COUNTIFS('TOTAL SEPTIEMBRE'!$B$4:$B$1000,'TOTAL SEPTIEMBRE'!$B$4:$B$1000&"",'TOTAL SEPTIEMBRE'!$C$4:$C$1000,'TOTAL SEPTIEMBRE'!$C$4:$C$1000&"")) | D45: =SUMIF('TOTAL SEPTIEMBRE'!$B$4:$B$2000,B45,'TOTAL SEPTIEMBRE'!$D$4:$D$2000) | E45: =IF($D$61=0,0,D45/$D$61) | F45: 320 | G45: =IF(F45="","",D45-F45) | H45: =IF(OR(F45="",N(F45)=0),"",D45/F45-1)
B46: REGERE AOVE | C46: =SUMPRODUCT(('TOTAL SEPTIEMBRE'!$B$4:$B$1000=B46)/COUNTIFS('TOTAL SEPTIEMBRE'!$B$4:$B$1000,'TOTAL SEPTIEMBRE'!$B$4:$B$1000&"",'TOTAL SEPTIEMBRE'!$C$4:$C$1000,'TOTAL SEPTIEMBRE'!$C$4:$C$1000&"")) | D46: =SUMIF('TOTAL SEPTIEMBRE'!$B$4:$B$2000,B46,'TOTAL SEPTIEMBRE'!$D$4:$D$2000) | E46: =IF($D$61=0,0,D46/$D$61) | G46: =IF(F46="","",D46-F46) | H46: =IF(OR(F46="",N(F46)=0),"",D46/F46-1)
B47: PATATAS YAGO | C47: =SUMPRODUCT(('TOTAL SEPTIEMBRE'!$B$4:$B$1000=B47)/COUNTIFS('TOTAL SEPTIEMBRE'!$B$4:$B$1000,'TOTAL SEPTIEMBRE'!$B$4:$B$1000&"",'TOTAL SEPTIEMBRE'!$C$4:$C$1000,'TOTAL SEPTIEMBRE'!$C$4:$C$1000&"")) | D47: =SUMIF('TOTAL SEPTIEMBRE'!$B$4:$B$2000,B47,'TOTAL SEPTIEMBRE'!$D$4:$D$2000) | E47: =IF($D$61=0,0,D47/$D$61) | F47: 358.9 | G47: =IF(F47="","",D47-F47) | H47: =IF(OR(F47="",N(F47)=0),"",D47/F47-1)
B48: ESCRIBANO SANZ | C48: =SUMPRODUCT(('TOTAL SEPTIEMBRE'!$B$4:$B$1000=B48)/COUNTIFS('TOTAL SEPTIEMBRE'!$B$4:$B$1000,'TOTAL SEPTIEMBRE'!$B$4:$B$1000&"",'TOTAL SEPTIEMBRE'!$C$4:$C$1000,'TOTAL SEPTIEMBRE'!$C$4:$C$1000&"")) | D48: =SUMIF('TOTAL SEPTIEMBRE'!$B$4:$B$2000,B48,'TOTAL SEPTIEMBRE'!$D$4:$D$2000) | E48: =IF($D$61=0,0,D48/$D$61) | F48: 84.48 | G48: =IF(F48="","",D48-F48) | H48: =IF(OR(F48="",N(F48)=0),"",D48/F48-1)
B49: VINS DES DIEUX | C49: =SUMPRODUCT(('TOTAL SEPTIEMBRE'!$B$4:$B$1000=B49)/COUNTIFS('TOTAL SEPTIEMBRE'!$B$4:$B$1000,'TOTAL SEPTIEMBRE'!$B$4:$B$1000&"",'TOTAL SEPTIEMBRE'!$C$4:$C$1000,'TOTAL SEPTIEMBRE'!$C$4:$C$1000&"")) | D49: =SUMIF('TOTAL SEPTIEMBRE'!$B$4:$B$2000,B49,'TOTAL SEPTIEMBRE'!$D$4:$D$2000) | E49: =IF($D$61=0,0,D49/$D$61) | G49: =IF(F49="","",D49-F49) | H49: =IF(OR(F49="",N(F49)=0),"",D49/F49-1)
B50: INESCU SERVICES | C50: =SUMPRODUCT(('TOTAL SEPTIEMBRE'!$B$4:$B$1000=B50)/COUNTIFS('TOTAL SEPTIEMBRE'!$B$4:$B$1000,'TOTAL SEPTIEMBRE'!$B$4:$B$1000&"",'TOTAL SEPTIEMBRE'!$C$4:$C$1000,'TOTAL SEPTIEMBRE'!$C$4:$C$1000&"")) | D50: =SUMIF('TOTAL SEPTIEMBRE'!$B$4:$B$2000,B50,'TOTAL SEPTIEMBRE'!$D$4:$D$2000) | E50: =IF($D$61=0,0,D50/$D$61) | G50: =IF(F50="","",D50-F50) | H50: =IF(OR(F50="",N(F50)=0),"",D50/F50-1)
...

Sheet TOTAL SEPTIEMBRE
B1: ALBARANES SEPTIEMBRE 2026 · LA MINA DE CHAMARTÍN
B2: PROVEEDOR | C2: ALBARAN | D2: BASE | E2: IVA | F2: TOTAL | H2: PROVEEDOR | I2: BASE | J2: CUOTA IVA | K2: TOTAL FRA | M2: TOTAL FACTURADO
B4: ACEITE Y SAL | C4: 26003920 | D4: 220.88 | E4: 0.1 | F4: =D4+(D4*E4) | H4: ACEITE Y SAL | I4: =SUMIF($B$4:$B$2000,H4,$D$4:$D$2000) | J4: =K4-I4 | K4: =SUMIF($B$4:$B$2000,H4,$F$4:$F$2000) | M4: =K45
B5: ACEITE Y SAL | C5: 26003939 | D5: 113.21 | E5: 0.1 | F5: =D5+(D5*E5) | H5: AGMASFOOD | I5: =SUMIF($B$4:$B$2000,H5,$D$4:$D$2000) | J5: =K5-I5 | K5: =SUMIF($B$4:$B$2000,H5,$F$4:$F$2000)
B6: ACEITE Y SAL | C6: 26003992 | D6: 309.15 | E6: 0.1 | F6: =D6+(D6*E6) | H6: AGROFOOD | I6: =SUMIF($B$4:$B$2000,H6,$D$4:$D$2000) | J6: =K6-I6 | K6: =SUMIF($B$4:$B$2000,H6,$F$4:$F$2000)
B7: ACEITE Y SAL | C7: 26004025 | D7: 330.41 | E7: 0.1 | F7: =D7+(D7*E7) | H7: CARNICAS MEAT | I7: =SUMIF($B$4:$B$2000,H7,$D$4:$D$2000) | J7: =K7-I7 | K7: =SUMIF($B$4:$B$2000,H7,$F$4:$F$2000)
B8: ACEITE Y SAL | C8: 26004078 | D8: 180.49 | E8: 0.1 | F8: =D8+(D8*E8) | H8: CASA MISU | I8: =SUMIF($B$4:$B$2000,H8,$D$4:$D$2000) | J8: =K8-I8 | K8: =SUMIF($B$4:$B$2000,H8,$F$4:$F$2000)
B9: ACEITE Y SAL | C9: 26004093 | D9: 284.89 | E9: 0.1 | F9: =D9+(D9*E9) | H9: COCACOLA | I9: =SUMIF($B$4:$B$2000,H9,$D$4:$D$2000) | J9: =K9-I9 | K9: =SUMIF($B$4:$B$2000,H9,$F$4:$F$2000)
B10: ACEITE Y SAL | C10: 26004113 | D10: 201.1 | E10: 0.1 | F10: =D10+(D10*E10) | H10: CONS. SELEC. SANTO | I10: =SUMIF($B$4:$B$2000,H10,$D$4:$D$2000) | J10: =K10-I10 | K10: =SUMIF($B$4:$B$2000,H10,$F$4:$F$2000)
B11: ACEITE Y SAL | C11: 26000075 | D11: 9.64 | E11: 0.1 | F11: =D11+(D11*E11) | H11: CONS. Y SAL. JIMENEZ | I11: =SUMIF($B$4:$B$2000,H11,$D$4:$D$2000) | J11: =K11-I11 | K11: =SUMIF($B$4:$B$2000,H11,$F$4:$F$2000)
B12: ACEITE Y SAL | C12: 26004189 | D12: 450.21 | E12: 0.1 | F12: =D12+(D12*E12) | H12: CRNAS SERVAN | I12: =SUMIF($B$4:$B$2000,H12,$D$4:$D$2000) | J12: =K12-I12 | K12: =SUMIF($B$4:$B$2000,H12,$F$4:$F$2000)
B13: ACEITE Y SAL | C13: 26004218 | D13: 258.91 | E13: 0.1 | F13: =D13+(D13*E13) | H13: CRUSTAPESCA | I13: =SUMIF($B$4:$B$2000,H13,$D$4:$D$2000) | J13: =K13-I13 | K13: =SUMIF($B$4:$B$2000,H13,$F$4:$F$2000)
B14: AGMASFOOD | C14: 26 7364 | D14: 128.7 | E14: 0.1 | F14: =D14+(D14*E14) | H14: DELIPAN | I14: =SUMIF($B$4:$B$2000,H14,$D$4:$D$2000) | J14: =K14-I14 | K14: =SUMIF($B$4:$B$2000,H14,$F$4:$F$2000)
B15: AGMASFOOD | C15: 26 7432 | D15: 343 | E15: 0.1 | F15: =D15+(D15*E15) | H15: DISOLTRIGO | I15: =SUMIF($B$4:$B$2000,H15,$D$4:$D$2000) | J15: =K15-I15 | K15: =SUMIF($B$4:$B$2000,H15,$F$4:$F$2000)
B16: AGMASFOOD | C16: 26 7607 | D16: 289.47 | E16: 0.1 | F16: =D16+(D16*E16) | H16: DIST. TENA MTNEZ | I16: =SUMIF($B$4:$B$2000,H16,$D$4:$D$2000) | J16: =K16-I16 | K16: =SUMIF($B$4:$B$2000,H16,$F$4:$F$2000)
... B44: COCACOLA | C44: 4536891120 | D44: 435.64 | E44: 0.21 | F44: =D44+(D44*E44) | H44: VOLDIS | I44: =SUMIF($B$4:$B$2000,H44,$D$4:$D$2000) | J44: =K44-I44 | K44: =SUMIF($B$4:$B$2000,H44,$F$4:$F$2000)
B45: COCACOLA | C45: 4537342018 | D45: 189.26 | E45: 0.21 | F45: =D45+(D45*E45) | H45: TOTAL | I45: =SUM(I4:I44) | J45: =SUM(J4:J44) | K45: =SUM(K4:K44)
B46: COCACOLA | C46: 4537429705 | D46: 304.19 | E46: 0.21 | F46: =D46+(D46*E46)
B47: CONS. SELEC. SANTO | C47: 5869 | D47: 385.56 | E47: 0.1 | F47: =D47+(D47*E47)
B48: CONS. SELEC. SANTO | C48: 6193 | D48: 368.01 | E48: 0.1 | F48: =D48+(D48*E48)
B49: CONS. SELEC. SANTO | C49: 6369 | D49: 365.85 | E49: 0.1 | F49: =D49+(D49*E49)
B50: CONS. SELEC. SANTO | C50: 6562 | D50: 185.49 | E50: 0.1 | F50: =D50+(D50*E50)
B51: CONS. Y SAL. JIMENEZ | C51: 26A01087 | D51: 587.22 | E51: 0.1 | F51: =D51+(D51*E51)
B52: CONS. Y SAL. JIMENEZ | C52: 26A01109 | D52: 264.99 | E52: 0.1 | F52: =D52+(D52*E52)
B53: CONS. Y SAL. JIMENEZ | C53: 26A01144 | D53: 374.14 | E53: 0.1 | F53: =D53+(D53*E53)
B54: CONS. Y SAL. JIMENEZ | C54: 26A01162 | D54: 670.95 | E54: 0.1 | F54: =D54+(D54*E54)
B55: CONS. Y SAL. JIMENEZ | C55: 26A01199 | D55: 301.02 | E55: 0.1 | F55: =D55+(D55*E55)
B56: CRNAS SERVAN | C56: A2609-0052 | D56: 71.82 | E56: 0.1 | F56: =D56+(D56*E56)
B57: CRNAS SERVAN | C57: A2609-0097 | D57: 113.22 | E57: 0.1 | F57: =D57+(D57*E57)
... B347: VOLDIS | C347: AP26-032600 | D347: 864.27 | E347: 0.21 | F347: =D347+(D347*E347)

Sheet CUADRE ALBARANES
A2: CUADRE POR PROVEEDOR Y MES
A3: Compara, en cada hoja de proveedor, la suma de las líneas de producto con la suma de albaranes, y ésta con la hoja TOTAL del mes (JULIO y AGOSTO: importe fijo de los Excel de esos meses; SEPTIEMBRE: fórmula sobre TOTAL SEPTIEMBRE). Tolerancia ±0,05 €.
A5: PROVEEDOR | B5: MES | C5: TOTAL LÍNEAS PRODUCTO | D5: TOTAL ALBARANES (hoja proveedor) | E5: TOTAL EN HOJA TOTAL DEL MES | F5: DIF. LÍNEAS − ALBARANES | G5: DIF. ALBARANES − HOJA TOTAL | H5: ¿CUADRA? | I5: NOTA
A6: ACEITE Y SAL | B6: SEPTIEMBRE | C6: =SUM('_____ACEITE Y SAL'!F6:F300) | D6: =SUM('_____ACEITE Y SAL'!I9:I300) | E6: =SUMIF('TOTAL SEPTIEMBRE'!$B$4:$B$2000,"ACEITE Y SAL",'TOTAL SEPTIEMBRE'!$D$4:$D$2000) | F6: =IF(D6="","",ROUND(C6-D6,2)) | G6: =IF(D6="",ROUND(C6-E6,2),ROUND(D6-E6,2)) | H6: =IF(AND(ABS(N(F6))<=0.05,ABS(G6)<=0.05),"OK","REVISAR")
A7: AGMASFOOD | B7: JULIO | C7: =SUM(_____AGMASFOOD!F6:F300) | D7: =SUM(_____AGMASFOOD!I9:I300) | E7: 1122.99 | F7: =IF(D7="","",ROUND(C7-D7,2)) | G7: =IF(D7="",ROUND(C7-E7,2),ROUND(D7-E7,2)) | H7: =IF(AND(ABS(N(F7))<=0.05,ABS(G7)<=0.05),"OK","REVISAR")
A8: AGMASFOOD | B8: AGOSTO | C8: =SUM(_____AGMASFOOD!P6:P300) | D8: =SUM(_____AGMASFOOD!S9:S300) | E8: 1125.19 | F8: =IF(D8="","",ROUND(C8-D8,2)) | G8: =IF(D8="",ROUND(C8-E8,2),ROUND(D8-E8,2)) | H8: =IF(AND(ABS(N(F8))<=0.05,ABS(G8)<=0.05),"OK","REVISAR")
A9: AGMASFOOD | B9: SEPTIEMBRE | C9: =SUM(_____AGMASFOOD!Z6:Z300) | D9: =SUM(_____AGMASFOOD!AC9:AC300) | E9: =SUMIF('TOTAL SEPTIEMBRE'!$B$4:$B$2000,"AGMASFOOD",'TOTAL SEPTIEMBRE'!$D$4:$D$2000) | F9: =IF(D9="","",ROUND(C9-D9,2)) | G9: =IF(D9="",ROUND(C9-E9,2),ROUND(D9-E9,2)) | H9: =IF(AND(ABS(N(F9))<=0.05,ABS(G9)<=0.05),"OK","REVISAR")
A10: AGROFOOD | B10: JULIO | C10: =SUM(_____AGROFOOD!F6:F300) | D10: =SUM(_____AGROFOOD!I9:I300) | E10: 4059.72 | F10: =IF(D10="","",ROUND(C10-D10,2)) | G10: =IF(D10="",ROUND(C10-E10,2),ROUND(D10-E10,2)) | H10: =IF(AND(ABS(N(F10))<=0.05,ABS(G10)<=0.05),"OK","REVISAR")
A11: AGROFOOD | B11: AGOSTO | C11: =SUM(_____AGROFOOD!P6:P300) | D11: =SUM(_____AGROFOOD!S9:S300) | E11: 1199.46 | F11: =IF(D11="","",ROUND(C11-D11,2)) | G11: =IF(D11="",ROUND(C11-E11,2),ROUND(D11-E11,2)) | H11: =IF(AND(ABS(N(F11))<=0.05,ABS(G11)<=0.05),"OK","REVISAR")
A12: AGROFOOD | B12: SEPTIEMBRE | C12: =SUM(_____AGROFOOD!Z6:Z300) | D12: =SUM(_____AGROFOOD!AC9:AC300) | E12: =SUMIF('TOTAL SEPTIEMBRE'!$B$4:$B$2000,"AGROFOOD",'TOTAL SEPTIEMBRE'!$D$4:$D$2000) | F12: =IF(D12="","",ROUND(C12-D12,2)) | G12: =IF(D12="",ROUND(C12-E12,2),ROUND(D12-E12,2)) | H12: =IF(AND(ABS(N(F12))<=0.05,ABS(G12)<=0.05),"OK","REVISAR")
A13: ANTONIO DE MIGUEL | B13: JULIO | C13: =SUM('_____ANTONIO DE MIGUEL'!F6:F300) | D13: =SUM('_____ANTONIO DE MIGUEL'!I9:I300) | E13: 280.3 | F13: =IF(D13="","",ROUND(C13-D13,2)) | G13: =IF(D13="",ROUND(C13-E13,2),ROUND(D13-E13,2)) | H13: =IF(AND(ABS(N(F13))<=0.05,ABS(G13)<=0.05),"OK","REVISAR")
A14: CALIDOSCOPI | B14: JULIO | C14: =SUM(_____CALIDOSCOPI!F6:F300) | D14: =SUM(_____CALIDOSCOPI!I9:I300) | E14: 339 | F14: =IF(D14="","",ROUND(C14-D14,2)) | G14: =IF(D14="",ROUND(C14-E14,2),ROUND(D14-E14,2)) | H14: =IF(AND(ABS(N(F14))<=0.05,ABS(G14)<=0.05),"OK","REVISAR")
A15: CARNICAS MEAT | B15: JULIO | C15: =SUM('_____CARNICAS MEAT'!F6:F300) | D15: =SUM('_____CARNICAS MEAT'!I9:I300) | E15: 1412.35 | F15: =IF(D15="","",ROUND(C15-D15,2)) | G15: =IF(D15="",ROUND(C15-E15,2),ROUND(D15-E15,2)) | H15: =IF(AND(ABS(N(F15))<=0.05,ABS(G15)<=0.05),"OK","REVISAR") | I15: Diferencia de redondeo en las líneas (A1/209: 6,48 kg x 34,55 = 223,88 € y el albarán pone 223,85 €).
A16: CARNICAS MEAT | B16: AGOSTO | C16: =SUM('_____CARNICAS MEAT'!P6:P300) | D16: =SUM('_____CARNICAS MEAT'!S9:S300) | E16: 640.26 | F16: =IF(D16="","",ROUND(C16-D16,2)) | G16: =IF(D16="",ROUND(C16-E16,2),ROUND(D16-E16,2)) | H16: =IF(AND(ABS(N(F16))<=0.05,ABS(G16)<=0.05),"OK","REVISAR")
A17: CARNICAS MEAT | B17: SEPTIEMBRE | C17: =SUM('_____CARNICAS MEAT'!Z6:Z300) | D17: =SUM('_____CARNICAS MEAT'!AC9:AC300) | E17: =SUMIF('TOTAL SEPTIEMBRE'!$B$4:$B$2000,"CARNICAS MEAT",'TOTAL SEPTIEMBRE'!$D$4:$D$2000) | F17: =IF(D17="","",ROUND(C17-D17,2)) | G17: =IF(D17="",ROUND(C17-E17,2),ROUND(D17-E17,2)) | H17: =IF(AND(ABS(N(F17))<=0.05,ABS(G17)<=0.05),"OK","REVISAR")
A18: CARNICAS OPC | B18: JULIO | C18: =SUM('_____CARNICAS OPC'!F6:F300) | D18: =SUM('_____CARNICAS OPC'!I9:I300) | E18: 240.66 | F18: =IF(D18="","",ROUND(C18-D18,2)) | G18: =IF(D18="",ROUND(C18-E18,2),ROUND(D18-E18,2)) | H18: =IF(AND(ABS(N(F18))<=0.05,ABS(G18)<=0.05),"OK","REVISAR")
A19: CASA MISU | B19: SEPTIEMBRE | C19: =SUM('_____CASA MISU'!F6:F300) | D19: =SUM('_____CASA MISU'!I9:I300) | E19: =SUMIF('TOTAL SEPTIEMBRE'!$B$4:$B$2000,"CASA MISU",'TOTAL SEPTIEMBRE'!$D$4:$D$2000) | F19: =IF(D19="","",ROUND(C19-D19,2)) | G19: =IF(D19="",ROUND(C19-E19,2),ROUND(D19-E19,2)) | H19: =IF(AND(ABS(N(F19))<=0.05,ABS(G19)<=0.05),"OK","REVISAR")
A20: COCACOLA | B20: JULIO | C20: =SUM('_____COCA-COLA'!F6:F300) | D20: =SUM('_____COCA-COLA'!I9:I300) | E20: 2124.02 | F20: =IF(D20="","",ROUND(C20-D20,2)) | G20: =IF(D20="",ROUND(C20-E20,2),ROUND(D20-E20,2)) | H20: =IF(AND(ABS(N(F20))<=0.05,ABS(G20)<=0.05),"OK","REVISAR")
A21: COCACOLA | B21: AGOSTO | C21: =SUM('_____COCA-COLA'!P6:P300) | D21: =SUM('_____COCA-COLA'!S9:S300) | E21: 457.72 | F21: =IF(D21="","",ROUND(C21-D21,2)) | G21: =IF(D21="",ROUND(C21-E21,2),ROUND(D21-E21,2)) | H21: =IF(AND(ABS(N(F21))<=0.05,ABS(G21)<=0.05),"OK","REVISAR")
A22: COCACOLA | B22: SEPTIEMBRE | C22: =SUM('_____COCA-COLA'!Z6:Z300) | D22: =SUM('_____COCA-COLA'!AC9:AC300) | E22: =SUMIF('TOTAL SEPTIEMBRE'!$B$4:$B$2000,"COCACOLA",'TOTAL SEPTIEMBRE'!$D$4:$D$2000) | F22: =IF(D22="","",ROUND(C22-D22,2)) | G22: =IF(D22="",ROUND(C22-E22,2),ROUND(D22-E22,2)) | H22: =IF(AND(ABS(N(F22))<=0.05,ABS(G22)<=0.05),"OK","REVISAR")
A23: CONS. SELEC. SANTO | B23: JULIO | C23: =SUM('_____CONS. SELEC. SANT'!F6:F300) | D23: =SUM('_____CONS. SELEC. SANT'!I9:I300) | E23: 705.24 | F23: =IF(D23="","",ROUND(C23-D23,2)) | G23: =IF(D23="",ROUND(C23-E23,2),ROUND(D23-E23,2)) | H23: =IF(AND(ABS(N(F23))<=0.05,ABS(G23)<=0.05),"OK","REVISAR")
A24: CONS. SELEC. SANTO | B24: AGOSTO | C24: =SUM('_____CONS. SELEC. SANT'!P6:P300) | D24: =SUM('_____CONS. SELEC. SANT'!S9:S300) | E24: 382.59 | F24: =IF(D24="","",ROUND(C24-D24,2)) | G24: =IF(D24="",ROUND(C24-E24,2),ROUND(D24-E24,2)) | H24: =IF(AND(ABS(N(F24))<=0.05,ABS(G24)<=0.05),"OK","REVISAR")
A25: CONS. SELEC. SANTO | B25: SEPTIEMBRE | C25: =SUM('_____CONS. SELEC. SANT'!Z6:Z300) | D25: =SUM('_____CONS. SELEC. SANT'!AC9:AC300) | E25: =SUMIF('TOTAL SEPTIEMBRE'!$B$4:$B$2000,"CONS. SELEC. SANTO",'TOTAL SEPTIEMBRE'!$D$4:$D$2000) | F25: =IF(D25="","",ROUND(C25-D25,2)) | G25: =IF(D25="",ROUND(C25-E25,2),ROUND(D25-E25,2)) | H25: =IF(AND(ABS(N(F25))<=0.05,ABS(G25)<=0.05),"OK","REVISAR")
A26: CONS. Y SAL. JIMENEZ | B26: JULIO | C26: =SUM('_____CONS. Y SALAZONES'!F6:F300) | D26: =SUM('_____CONS. Y SALAZONES'!I9:I300) | E26: 3739.92 | F26: =IF(D26="","",ROUND(C26-D26,2)) | G26: =IF(D26="",ROUND(C26-E26,2),ROUND(D26-E26,2)) | H26: =IF(AND(ABS(N(F26))<=0.05,ABS(G26)<=0.05),"OK","REVISAR")
A27: CONS. Y SAL. JIMENEZ | B27: AGOSTO | C27: =SUM('_____CONS. Y SALAZONES'!P6:P300) | D27: =SUM('_____CONS. Y SALAZONES'!S9:S300) | E27: 1061.59 | F27: =IF(D27="","",ROUND(C27-D27,2)) | G27: =IF(D27="",ROUND(C27-E27,2),ROUND(D27-E27,2)) | H27: =IF(AND(ABS(N(F27))<=0.05,ABS(G27)<=0.05),"OK","REVISAR")
A28: CONS. Y SAL. JIMENEZ | B28: SEPTIEMBRE | C28: =SUM('_____CONS. Y SALAZONES'!Z6:Z300) | D28: =SUM('_____CONS. Y SALAZONES'!AC9:AC300) | E28: =SUMIF('TOTAL SEPTIEMBRE'!$B$4:$B$2000,"CONS. Y SAL. JIMENEZ",'TOTAL SEPTIEMBRE'!$D$4:$D$2000) | F28: =IF(D28="","",ROUND(C28-D28,2)) | G28: =IF(D28="",ROUND(C28-E28,2),ROUND(D28-E28,2)) | H28: =IF(AND(ABS(N(F28))<=0.05,ABS(G28)<=0.05),"OK","REVISAR")
A29: CRNAS SERVAN | B29: JULIO | C29: =SUM('_____CRNAS SERVAN'!F6:F300) | D29: =SUM('_____CRNAS SERVAN'!I9:I300) | E29: 1086.03 | F29: =IF(D29="","",ROUND(C29-D29,2)) | G29: =IF(D29="",ROUND(C29-E29,2),ROUND(D29-E29,2)) | H29: =IF(AND(ABS(N(F29))<=0.05,ABS(G29)<=0.05),"OK","REVISAR")
A30: CRNAS SERVAN | B30: AGOSTO | C30: =SUM('_____CRNAS SERVAN'!P6:P300) | D30: =SUM('_____CRNAS SERVAN'!S9:S300) | E30: 890.28 | F30: =IF(D30="","",ROUND(C30-D30,2)) | G30: =IF(D30="",ROUND(C30-E30,2),ROUND(D30-E30,2)) | H30: =IF(AND(ABS(N(F30))<=0.05,ABS(G30)<=0.05),"OK","REVISAR")
A31: CRNAS SERVAN | B31: SEPTIEMBRE | C31: =SUM('_____CRNAS SERVAN'!Z6:Z300) | D31: =SUM('_____CRNAS SERVAN'!AC9:AC300) | E31: =SUMIF('TOTAL SEPTIEMBRE'!$B$4:$B$2000,"CRNAS SERVAN",'TOTAL SEPTIEMBRE'!$D$4:$D$2000) | F31: =IF(D31="","",ROUND(C31-D31,2)) | G31: =IF(D31="",ROUND(C31-E31,2),ROUND(D31-E31,2)) | H31: =IF(AND(ABS(N(F31))<=0.05,ABS(G31)<=0.05),"OK","REVISAR")
A32: CRUSTAPESCA | B32: JULIO | C32: =SUM(_____CRUSTAPESCA!F6:F300) | D32: =SUM(_____CRUSTAPESCA!I9:I300) | E32: 1970.46 | F32: =IF(D32="","",ROUND(C32-D32,2)) | G32: =IF(D32="",ROUND(C32-E32,2),ROUND(D32-E32,2)) | H32: =IF(AND(ABS(N(F32))<=0.05,ABS(G32)<=0.05),"OK","REVISAR")
A33: CRUSTAPESCA | B33: AGOSTO | C33: =SUM(_____CRUSTAPESCA!P6:P300) | D33: =SUM(_____CRUSTAPESCA!S9:S300) | E33: 772 | F33: =IF(D33="","",ROUND(C33-D33,2)) | G33: =IF(D33="",ROUND(C33-E33,2),ROUND(D33-E33,2)) | H33: =IF(AND(ABS(N(F33))<=0.05,ABS(G33)<=0.05),"OK","REVISAR")
A34: CRUSTAPESCA | B34: SEPTIEMBRE | C34: =SUM(_____CRUSTAPESCA!Z6:Z300) | D34: =SUM(_____CRUSTAPESCA!AC9:AC300) | E34: =SUMIF('TOTAL SEPTIEMBRE'!$B$4:$B$2000,"CRUSTAPESCA",'TOTAL SEPTIEMBRE'!$D$4:$D$2000) | F34: =IF(D34="","",ROUND(C34-D34,2)) | G34: =IF(D34="",ROUND(C34-E34,2),ROUND(D34-E34,2)) | H34: =IF(AND(ABS(N(F34))<=0.05,ABS(G34)<=0.05),"OK","REVISAR")
A35: DELIPAN | B35: JULIO | C35: =SUM(_____DELIPAN!F6:F300) | D35: =SUM(_____DELIPAN!I9:I300) | E35: 1032.66 | F35: =IF(D35="","",ROUND(C35-D35,2)) | G35: =IF(D35="",ROUND(C35-E35,2),ROUND(D35-E35,2)) | H35: =IF(AND(ABS(N(F35))<=0.05,ABS(G35)<=0.05),"OK","REVISAR")
A36: DELIPAN | B36: AGOSTO | C36: =SUM(_____DELIPAN!P6:P300) | D36: =SUM(_____DELIPAN!S9:S300) | E36: 381.21 | F36: =IF(D36="","",ROUND(C36-D36,2)) | G36: =IF(D36="",ROUND(C36-E36,2),ROUND(D36-E36,2)) | H36: =IF(AND(ABS(N(F36))<=0.05,ABS(G36)<=0.05),"OK","REVISAR")
A37: DELIPAN | B37: SEPTIEMBRE | C37: =SUM(_____DELIPAN!Z6:Z300) | D37: =SUM(_____DELIPAN!AC9:AC300) | E37: =SUMIF('TOTAL SEPTIEMBRE'!$B$4:$B$2000,"DELIPAN",'TOTAL SEPTIEMBRE'!$D$4:$D$2000) | F37: =IF(D37="","",ROUND(C37-D37,2)) | G37: =IF(D37="",ROUND(C37-E37,2),ROUND(D37-E37,2)) | H37: =IF(AND(ABS(N(F37))<=0.05,ABS(G37)<=0.05),"OK","REVISAR")
A38: DISOLTRIGO | B38: JULIO | C38: =SUM(_____DISOLTRIGO!F6:F300) | D38: =SUM(_____DISOLTRIGO!I9:I300) | E38: 1295.5 | F38: =IF(D38="","",ROUND(C38-D38,2)) | G38: =IF(D38="",ROUND(C38-E38,2),ROUND(D38-E38,2)) | H38: =IF(AND(ABS(N(F38))<=0.05,ABS(G38)<=0.05),"OK","REVISAR")
A39: DISOLTRIGO | B39: AGOSTO | C39: =SUM(_____DISOLTRIGO!P6:P300) | D39: =SUM(_____DISOLTRIGO!S9:S300) | E39: 318 | F39: =IF(D39="","",ROUND(C39-D39,2)) | G39: =IF(D39="",ROUND(C39-E39,2),ROUND(D39-E39,2)) | H39: =IF(AND(ABS(N(F39))<=0.05,ABS(G39)<=0.05),"OK","REVISAR")
A40: DISOLTRIGO | B40: SEPTIEMBRE | C40: =SUM(_____DISOLTRIGO!Z6:Z300) | D40: =SUM(_____DISOLTRIGO!AC9:AC300) | E40: =SUMIF('TOTAL SEPTIEMBRE'!$B$4:$B$2000,"DISOLTRIGO",'TOTAL SEPTIEMBRE'!$D$4:$D$2000) | F40: =IF(D40="","",ROUND(C40-D40,2)) | G40: =IF(D40="",ROUND(C40-E40,2),ROUND(D40-E40,2)) | H40: =IF(AND(ABS(N(F40))<=0.05,ABS(G40)<=0.05),"OK","REVISAR")
A41: DIST. TENA MTNEZ | B41: JULIO | C41: =SUM('_____DIST. TENA'!F6:F300) | D41: =SUM('_____DIST. TENA'!I9:I300) | E41: 3131.64 | F41: =IF(D41="","",ROUND(C41-D41,2)) | G41: =IF(D41="",ROUND(C41-E41,2),ROUND(D41-E41,2)) | H41: =IF(AND(ABS(N(F41))<=0.05,ABS(G41)<=0.05),"OK","REVISAR")
A42: DIST. TENA MTNEZ | B42: AGOSTO | C42: =SUM('_____DIST. TENA'!P6:P300) | D42: =SUM('_____DIST. TENA'!S9:S300) | E42: 1320.36 | F42: =IF(D42="","",ROUND(C42-D42,2)) | G42: =IF(D42="",ROUND(C42-E42,2),ROUND(D42-E42,2)) | H42: =IF(AND(ABS(N(F42))<=0.05,ABS(G42)<=0.05),"OK","REVISAR")
...

Sheet _____ACEITE Y SAL
B2: 46266
H4: TOTAL | I4: =SUM(F6:F300)
B5: PRODUCTO | C5: UNIDADES | D5: PRECIO | E5: DTO | F5: TOTAL | H5: ALBARANES | I5: =SUM(I9:I300)
B6: PATATAS SAL CARTUCHO (2bx500g) | C6: =25+20+15+10+10+15+25+10 | D6: 4.5 | E6: 0.02 | F6: =(C6*D6)-((C6*D6)*E6) | H6: DIFERENCIA | I6: =I5-I4
B7: BANDERILLAS DULCES cortada (1cux1,7kg) | C7: =6+3+9+10+10+8+1+14+6 | D7: 9.84 | E7: 0.02 | F7: =(C7*D7)-((C7*D7)*E7)
B8: MINI MIX PICA (1bx1kg) | C8: =7+7+6+5+6 | D8: 5.25 | E8: 0.02 | F8: =(C8*D8)-((C8*D8)*E8) | H8: Nº ALBARÁN | I8: BASE | J8: % IVA
B9: ACEITUNA MANZANILLA (200) (1cux4,3kg) | C9: =1+1+1+1+1+1 | D9: 17.1 | E9: 0.02 | F9: =(C9*D9)-((C9*D9)*E9) | H9: 26003920 | I9: 220.88 | J9: 0.1
B10: MEJILLON MEDIA CONCHA (1cux1,5kg) | C10: =4+2+4+2+4+4 | D10: 21.5 | E10: 0.02 | F10: =(C10*D10)-((C10*D10)*E10) | H10: 26003939 | I10: 113.21 | J10: 0.1
B11: ALMENDRA COMUNA REP. FRITA (1bx1kg) | C11: =1+1 | D11: 12.7 | E11: 0.02 | F11: =(C11*D11)-((C11*D11)*E11) | H11: 26003992 | I11: 309.15 | J11: 0.1
B12: ACEITUNA RELL. ANCHOA 160/180 (1botex2k) | C12: =2+2+2+1+3+3 | D12: 15.7 | E12: 0.02 | F12: =(C12*D12)-((C12*D12)*E12) | H12: 26004025 | I12: 330.41 | J12: 0.1
B13: PIPARRA VASCA (tarro 1800g) | C13: =3+4+3+3+3 | D13: 10.9 | E13: 0.02 | F13: =(C13*D13)-((C13*D13)*E13) | H13: 26004078 | I13: 180.49 | J13: 0.1
B14: MEZCLA DE FRUTOS SECOS N01 (1bx2kg) | C14: 2 | D14: 10.585 | E14: 0.02 | F14: =(C14*D14)-((C14*D14)*E14) | H14: 26004093 | I14: 284.89 | J14: 0.1
B15: MEZCLA DE FRUTOS SECOS N01 (1bx2kg) | C15: =1+3 | D15: 10.5825 | E15: 0.02 | F15: =(C15*D15)-((C15*D15)*E15) | H15: 26004113 | I15: 201.1 | J15: 0.1
H16: 26000075 | I16: 9.64 | J16: 0.1
H17: 26004189 | I17: 450.21 | J17: 0.1
H18: 26004218 | I18: 258.91 | J18: 0.1

Sheet _____AGMASFOOD
B2: 46204 | L2: 46235 | V2: 46266
H4: TOTAL | I4: =SUM(F6:F300) | R4: TOTAL | S4: =SUM(P6:P300) | AB4: TOTAL | AC4: =SUM(Z6:Z300)
B5: PRODUCTO | C5: UNIDADES | D5: PRECIO | E5: DTO | F5: TOTAL | H5: ALBARANES | I5: =SUM(I9:I300) | L5: PRODUCTO | M5: UNIDADES | N5: PRECIO | O5: DTO | P5: TOTAL | R5: ALBARANES | S5: =SUM(S9:S300) | V5: PRODUCTO | W5: UNIDADES | X5: PRECIO | Y5: DTO | Z5: TOTAL | AB5: ALBARANES | AC5: =SUM(AC9:AC300)
B6: LOMO NEGRO SIN COLA LIMPIO | C6: =4.9+5+5.2 | D6: 39.05 | E6: 0 | F6: =(C6*D6)-((C6*D6)*E6) | H6: DIFERENCIA | I6: =I5-I4 | L6: LOMO NEGRO SIN COLA LIMPIO | M6: =4.9+5.05+4.75 | N6: 39.05 | O6: 0 | P6: =(M6*N6)-((M6*N6)*O6) | R6: DIFERENCIA | S6: =S5-S4 | V6: GAMBA ROJA ALISTADA 15-20P | W6: =1.2+1.3+1.3+1 | X6: 89 | Y6: 0 | Z6: =(W6*X6)-((W6*X6)*Y6) | AB6: DIFERENCIA | AC6: =AC5-AC4
B7: GAMBA ROJA ALISTADA 15-20P | C7: =1.3+1.2 | D7: 79 | E7: 0 | F7: =(C7*D7)-((C7*D7)*E7) | L7: GAMBA ROJA ALISTADA 15-20P | M7: =1.3+1+1.2 | N7: 84 | O7: 0 | P7: =(M7*N7)-((M7*N7)*O7) | V7: BOQUERON GORDO | W7: =3+3 | X7: 7.3 | Y7: 0 | Z7: =(W7*X7)-((W7*X7)*Y7)
B8: BOQUERON GORDO | C8: =3.5 | D8: 11.95 | E8: 0 | F8: =(C8*D8)-((C8*D8)*E8) | H8: Nº ALBARÁN | I8: BASE | J8: % IVA | L8: BOQUERON GORDO | M8: 3 | N8: 11.95 | O8: 0 | P8: =(M8*N8)-((M8*N8)*O8) | R8: Nº ALBARÁN | S8: BASE | T8: % IVA | V8: LOMO NEGRO SIN COLA LIMPIO | W8: =5.26+4.45+4.8+5.36+5.26 | X8: 39.05 | Y8: 0 | Z8: =(W8*X8)-((W8*X8)*Y8) | AB8: Nº ALBARÁN | AC8: BASE | AD8: % IVA
B9: GAMBA ROJA ALISTADA 15-20P | C9: =1.5+1+1 | D9: 84 | E9: 0 | F9: =(C9*D9)-((C9*D9)*E9) | H9: 26 6093 | I9: 191.35 | J9: 0.1 | L9: BOQUERON GORDO | M9: =3+3.5+3+4 | N9: 9.8 | O9: 0 | P9: =(M9*N9)-((M9*N9)*O9) | R9: 26 6717 | S9: 300.55 | T9: 0.1 | V9: GAMBA ROJA ALISTADA 15-20P | W9: =1+1+1.3 | X9: 95 | Y9: 0 | Z9: =(W9*X9)-((W9*X9)*Y9) | AB9: 26 7364 | AC9: 128.7 | AD9: 0.1
H10: 26 6075 | I10: 102.7 | J10: 0.1 | L10: GAMBA ROJA ALISTADA 15-20P | M10: 1 | N10: 89 | O10: 0 | P10: =(M10*N10)-((M10*N10)*O10) | R10: 26 6980 | S10: 35.85 | T10: 0.1 | AB10: 26 7432 | AC10: 343 | AD10: 0.1
H11: 26 6029 | I11: 41.83 | J11: 0.1 | R11: 26 7006 | S11: 84 | T11: 0.1 | AB11: 26 7607 | AC11: 289.47 | AD11: 0.1
H12: 26 5876 | I12: 195.25 | J12: 0.1 | R12: 26 7016 | S12: 226.6 | T12: 0.1 | AB12: 26 7678 | AC12: 276.44 | AD12: 0.1
H13: 26 5951 | I13: 94.8 | J13: 0.1 | R13: 26 7048 | S13: 100.8 | T13: 0.1 | AB13: 26 7923 | AC13: 304.31 | AD13: 0.1
H14: 26 6564 | I14: 203.06 | J14: 0.1 | R14: 26 7103 | S14: 34.3 | T14: 0.1 | AB14: 26 8103 | AC14: 95 | AD14: 0.1
H15: 26 6530 | I15: 126 | J15: 0.1 | R15: 26 7151 | S15: 0 | T15: 0.1 | AB15: 26 8111 | AC15: 328.9 | AD15: 0.1
H16: 26 6503 | I16: 84 | J16: 0.1 | R16: 26 7202 | S16: 29.4 | T16: 0.1
H17: 26 6629 | I17: 84 | J17: 0.1 | R17: 26 7226 | S17: 185.49 | T17: 0.1
R18: 26 7264 | S18: 128.2 | T18: 0.1

Sheet _____AGROFOOD
B2: 46204 | L2: 46235 | V2: 46266
H4: TOTAL | I4: =SUM(F6:F300) | R4: TOTAL | S4: =SUM(P6:P300) | AB4: TOTAL | AC4: =SUM(Z6:Z300)
B5: PRODUCTO | C5: UNIDADES | D5: PRECIO | E5: DTO | F5: TOTAL | H5: ALBARANES | I5: =SUM(I9:I300) | L5: PRODUCTO | M5: UNIDADES | N5: PRECIO | O5: DTO | P5: TOTAL | R5: ALBARANES | S5: =SUM(S9:S300) | V5: PRODUCTO | W5: UNIDADES | X5: PRECIO | Y5: DTO | Z5: TOTAL | AB5: ALBARANES | AC5: =SUM(AC9:AC300)
B6: ENTRECOT T. MORUCHA | C6: =6.95+3.4+7.12+3.42+15.16+10.41+3.21+8.21+13.51+3.29+7.16+3.57+13.04+10.45 | D6: 27.5 | E6: 0 | F6: =(C6*D6)-((C6*D6)*E6) | H6: DIFERENCIA | I6: =I5-I4 | L6: MEDALLON P. SOLOMILLO VACUNO (precio+MER 0,07) | M6: =6.17+4.19+4 | N6: 36.97 | O6: 0 | P6: =(M6*N6)-((M6*N6)*O6) | R6: DIFERENCIA | S6: =S5-S4 | V6: ENTRECOT T. MORUCHA (precio+MER 0,07) | W6: =6.48+6.83+13.87+17.78+13.13+3.54+7.21+6.73+13.63+3.45+13.26+13.82 | X6: 27.57 | Y6: 0 | Z6: =(W6*X6)-((W6*X6)*Y6) | AB6: DIFERENCIA | AC6: =AC5-AC4
B7: MEDALLON P. SOLOMILLO VACUNO | C7: =2.09+2.12+2.08+2+2.05+2.04+4.19+2.03+2.01+1.94+3.95+2.1 | D7: 36.9 | E7: 0 | F7: =(C7*D7)-((C7*D7)*E7) | L7: ENTRECOT T. MORUCHA (precio+MER 0,07) | M7: =13.34+10.91 | N7: 27.57 | O7: 0 | P7: =(M7*N7)-((M7*N7)*O7) | V7: MEDALLON P. SOLOMILLO VACUNO (precio+MER 0,07) | W7: =2.09+4.09+4.03+4.04+4.25+4.25+4.16+2.06+2.01+5.97+2.21 | X7: 36.97 | Y7: 0 | Z7: =(W7*X7)-((W7*X7)*Y7)
B8: TASA DE ELIMINACION DE RESIDUOS | C8: 1 | D8: 1.02 | E8: 0 | F8: =(C8*D8)-((C8*D8)*E8) | H8: Nº ALBARÁN | I8: BASE | J8: % IVA | R8: Nº ALBARÁN | S8: BASE | T8: % IVA | AB8: Nº ALBARÁN | AC8: BASE | AD8: % IVA
B9: TASA DE ELIMINACION DE RESIDUOS | C9: 1 | D9: 0.74 | E9: 0 | F9: =(C9*D9)-((C9*D9)*E9) | H9: M26/810 | I9: 441 | J9: 0.1 | R9: M26/935 | S9: 228.11 | T9: 0.1 | AB9: M26/963 | AC9: 178.65 | AD9: 0.1
B10: TASA DE ELIMINACION DE RESIDUOS | C10: 1 | D10: 1.21 | E10: 0 | F10: =(C10*D10)-((C10*D10)*E10) | H10: M26/787 | I10: 290.59 | J10: 0.1 | R10: M26/952 | S10: 522.68 | T10: 0.1 | AB10: M26/967 | AC10: 188.3 | AD10: 0.1
B11: TASA DE ELIMINACION DE RESIDUOS | C11: 1 | D11: 1.15 | E11: 0 | F11: =(C11*D11)-((C11*D11)*E11) | H11: M26/776 | I11: 494.86 | J11: 0.1 | R11: M26/928 | S11: 448.67 | T11: 0.1 | AB11: M26/985 | AC11: 610.88 | AD11: 0.1
B12: TASA DE ELIMINACION DE RESIDUOS | C12: 1 | D12: 0.22 | E12: 0 | F12: =(C12*D12)-((C12*D12)*E12) | H12: M26/865 | I12: 512.15 | J12: 0.1 | AB12: M26/999 | AC12: 788.54 | AD12: 0.1
B13: TASA DE ELIMINACION DE RESIDUOS | C13: 1 | D13: 0.57 | E13: 0 | F13: =(C13*D13)-((C13*D13)*E13) | H13: M26/849 | I13: 88.5 | J13: 0.1 | AB13: M26/1032 | AC13: 361.99 | AD13: 0.1
B14: TASA DE ELIMINACION DE RESIDUOS | C14: 1 | D14: 1.47 | E14: 0 | F14: =(C14*D14)-((C14*D14)*E14) | H14: M26/844 | I14: 226.35 | J14: 0.1 | AB14: M26/1036 | AC14: 157.12 | AD14: 0.1
B15: TASA DE ELIMINACION DE RESIDUOS | C15: 1 | D15: 1.03 | E15: 0 | F15: =(C15*D15)-((C15*D15)*E15) | H15: M26/839 | I15: 618.08 | J15: 0.1 | AB15: M26/1043 | AC15: 408.52 | AD15: 0.1
B16: TASA DE ELIMINACION DE RESIDUOS | C16: 1 | D16: 1.33 | E16: 0 | F16: =(C16*D16)-((C16*D16)*E16) | H16: M26/817 | I16: 445.18 | J16: 0.1 | AB16: M26/1067 | AC16: 349.25 | AD16: 0.1
B17: TASA DE ELIMINACION DE RESIDUOS | C17: 1 | D17: 0.88 | E17: 0 | F17: =(C17*D17)-((C17*D17)*E17) | H17: M26/890 | I17: 577.26 | J17: 0.1 | AB17: M26/1075 | AC17: 185.55 | AD17: 0.1
H18: M26/872 | I18: 365.75 | J18: 0.1 | AB18: M26/1081 | AC18: 375.78 | AD18: 0.1
AB19: M26/1102 | AC19: 681.41 | AD19: 0.1
AB20: M26/1117 | AC20: 462.72 | AD20: 0.1

Sheet _____ANTONIO DE MIGUEL
B2: 46204
H4: TOTAL | I4: =SUM(F6:F300)
B5: PRODUCTO | C5: UNIDADES | D5: PRECIO | E5: DTO | F5: TOTAL | H5: ALBARANES | I5: =SUM(I9:I300)
B6: PATO CEBADO-FOIE RESTAURACION (400-900) | C6: 10 | D6: 28.03 | E6: 0 | F6: =(C6*D6)-((C6*D6)*E6) | H6: DIFERENCIA | I6: =I5-I4
H8: Nº ALBARÁN | I8: BASE | J8: % IVA
H9: A/2066113 | I9: 280.3 | J9: 0.1

Sheet _____CALIDOSCOPI
B2: 46204
H4: TOTAL | I4: =SUM(F6:F300)
B5: PRODUCTO | C5: UNIDADES | D5: PRECIO | E5: DTO | F5: TOTAL | H5: ALBARANES | I5: =SUM(I9:I300)
B6: PAGO DE CARRAOVEJAS 2023 | C6: 12 | D6: 28.25 | E6: 0 | F6: =(C6*D6)-((C6*D6)*E6) | H6: DIFERENCIA | I6: =I5-I4
H8: Nº ALBARÁN | I8: BASE | J8: % IVA
H9: AV-CV26-004508 | I9: 339 | J9: 0.21

Sheet _____CARNICAS MEAT
B2: 46204 | L2: 46235 | V2: 46266
H4: TOTAL | I4: =SUM(F6:F300) | R4: TOTAL | S4: =SUM(P6:P300) | AB4: TOTAL | AC4: =SUM(Z6:Z300)
B5: PRODUCTO | C5: UNIDADES | D5: PRECIO | E5: DTO | F5: TOTAL | H5: ALBARANES | I5: =SUM(I9:I300) | L5: PRODUCTO | M5: UNIDADES | N5: PRECIO | O5: DTO | P5: TOTAL | R5: ALBARANES | S5: =SUM(S9:S300) | V5: PRODUCTO | W5: UNIDADES | X5: PRECIO | Y5: DTO | Z5: TOTAL | AB5: ALBARANES | AC5: =SUM(AC9:AC300)
B6: CHULETA CORDERO LECHAL | C6: =8.86+6.715+4.685 | D6: 25 | E6: 0 | F6: =(C6*D6)-((C6*D6)*E6) | H6: DIFERENCIA | I6: =I5-I4 | L6: SOLOMILLO VACA | M6: =6.65+4.375 | N6: 35 | O6: 0 | P6: =(M6*N6)-((M6*N6)*O6) | R6: DIFERENCIA | S6: =S5-S4 | V6: SOLOMILLO VACA | W6: =5.32+7.1+3.785 | X6: 35 | Y6: 0 | Z6: =(W6*X6)-((W6*X6)*Y6) | AB6: DIFERENCIA | AC6: =AC5-AC4
B7: TERNERA MIXTA | C7: =5.11 | D7: 10.9 | E7: 0 | F7: =(C7*D7)-((C7*D7)*E7) | L7: CHULETA CORDERO LECHAL | M7: =5.925+4.25 | N7: 25 | O7: 0 | P7: =(M7*N7)-((M7*N7)*O7) | V7: CHULETA CORDERO LECHAL | W7: =2.85+7.65+9.2+8.6 | X7: 25 | Y7: 0 | Z7: =(W7*X7)-((W7*X7)*Y7)
B8: SOLOMILLO VACA | C8: =5.445+6.48 | D8: 34.55 | E8: 0 | F8: =(C8*D8)-((C8*D8)*E8) | H8: Nº ALBARÁN | I8: BASE | J8: % IVA | R8: Nº ALBARÁN | S8: BASE | T8: % IVA | V8: SOLOMILLO VACA | W8: 5.095 | X8: 34.5456 | Y8: 0 | Z8: =(W8*X8)-((W8*X8)*Y8) | AB8: Nº ALBARÁN | AC8: BASE | AD8: % IVA
B9: SOLOMILLO VACA | C9: =5.795+6.725 | D9: 35 | E9: 0 | F9: =(C9*D9)-((C9*D9)*E9) | H9: A1/195 | I9: 221.5 | J9: 0.1 | R9: A1/221 | S9: 380.88 | T9: 0.1 | AB9: A1/234 | AC9: 186.2 | AD9: 0.1
H10: A1/191 | I10: 243.8 | J10: 0.1 | R10: A1/227 | S10: 259.38 | T10: 0.1 | AB10: A1/247 | AC10: 452.23 | AD10: 0.1
H11: A1/188 | I11: 370.7 | J11: 0.1 | AB11: A1/250 | AC11: 191.25 | AD11: 0.1
H12: A1/209 | I12: 340.98 | J12: 0.1 | AB12: A1/258 | AC12: 230 | AD12: 0.1
H13: A1/202 | I13: 235.37 | J13: 0.1 | AB13: A1/261 | AC13: 391.01 | AD13: 0.1

Sheet _____CARNICAS OPC
B2: 46204
H4: TOTAL | I4: =SUM(F6:F300)
B5: PRODUCTO | C5: UNIDADES | D5: PRECIO | E5: DTO | F5: TOTAL | H5: ALBARANES | I5: =SUM(I9:I300)
B6: MEDIA CAJA HUEVO | C6: 1 | D6: 45 | E6: 0 | F6: =(C6*D6)-((C6*D6)*E6) | H6: DIFERENCIA | I6: =I5-I4
B7: PANCETA ADOBADA | C7: =4.2+4+3 | D7: 8.8 | E7: 0 | F7: =(C7*D7)-((C7*D7)*E7)
B8: CAJA HUEVOS CORRAL | C8: 1 | D8: 52.5 | E8: 0 | F8: =(C8*D8)-((C8*D8)*E8) | H8: Nº ALBARÁN | I8: BASE | J8: % IVA
B9: POLLO TROCEADO | C9: =5.2 | D9: 3.5 | E9: 0 | F9: =(C9*D9)-((C9*D9)*E9) | H9: A2607-0221 | I9: 81.96 | J9: 0.1
B10: OREJA DE CERDO | C10: =4.4 | D10: 6 | E10: 0 | F10: =(C10*D10)-((C10*D10)*E10) | H10: A2607-0169 | I10: 105.9 | J10: 0.21
H11: A2607-0092 | I11: 52.8 | J11: 0.1

Sheet _____CASA MISU
B2: 46266
H4: TOTAL | I4: =SUM(F6:F300)
B5: PRODUCTO | C5: UNIDADES | D5: PRECIO | E5: DTO | F5: TOTAL | H5: ALBARANES | I5: =SUM(I9:I300)
B6: BANDEJA TIRAMISU PISTACCHIO | C6: =1+1+1+1+1+1 | D6: 70 | E6: 0 | F6: =(C6*D6)-((C6*D6)*E6) | H6: DIFERENCIA | I6: =I5-I4
H8: Nº ALBARÁN | I8: BASE | J8: % IVA
H9: FRA 2026-118 | I9: 70 | J9: 0.1
H10: FRA 2026-122 | I10: 70 | J10: 0.1
H11: FRA 2026-126 | I11: 70 | J11: 0.1
H12: FRA 2026-127 | I12: 70 | J12: 0.1
H13: FRA 2026-132 | I13: 70 | J13: 0.1
H14: FRA 2026-134 | I14: 70 | J14: 0.1

Sheet _____COCA-COLA
B2: 46204 | L2: 46235 | V2: 46266
H4: TOTAL | I4: =SUM(F6:F300) | R4: TOTAL | S4: =SUM(P6:P300) | AB4: TOTAL | AC4: =SUM(Z6:Z300)
B5: PRODUCTO | C5: UNIDADES | D5: PRECIO | E5: DTO | F5: TOTAL | H5: ALBARANES | I5: =SUM(I9:I300) | L5: PRODUCTO | M5: UNIDADES | N5: PRECIO | O5: DTO | P5: TOTAL | R5: ALBARANES | S5: =SUM(S9:S300) | V5: PRODUCTO | W5: UNIDADES | X5: PRECIO | Y5: DTO | Z5: TOTAL | AB5: ALBARANES | AC5: =SUM(AC9:AC300)
B6: CAJA+BOTELLAS VR237 | C6: 20 | D6: 4.8 | E6: 0 | F6: =(C6*D6)-((C6*D6)*E6) | H6: DIFERENCIA | I6: =I5-I4 | L6: COCACOLA VR237 C24 (neto caja) | M6: 3 | N6: 20.28 | O6: 0 | P6: =(M6*N6)-((M6*N6)*O6) | R6: DIFERENCIA | S6: =S5-S4 | V6: COCACOLA VR237 C24 (neto caja) | W6: =5+6+3 | X6: 20.2793 | Y6: 0 | Z6: =(W6*X6)-((W6*X6)*Y6) | AB6: DIFERENCIA | AC6: =AC5-AC4
B7: COCACOLA PET2L C6 | C7: 36 | D7: 2.504 | E7: 0 | F7: =(C7*D7)-((C7*D7)*E7) | L7: COCACOLA ZERO VR237 C24 (neto caja) | M7: 6 | N7: 20.2783 | O7: 0 | P7: =(M7*N7)-((M7*N7)*O7) | V7: COCACOLA ZERO VR237 C24 (neto caja) | W7: =14+12 | X7: 20.2792 | Y7: 0 | Z7: =(W7*X7)-((W7*X7)*Y7)
B8: COCACOLA VR237 C24 | C8: =48+48+96+96+96+144 | D8: 0.845 | E8: 0 | F8: =(C8*D8)-((C8*D8)*E8) | H8: Nº ALBARÁN | I8: BASE | J8: % IVA | L8: COCACOLA ZERO ZERO VR237 C24 (neto caja) | M8: =2+1 | N8: 20.28 | O8: 0 | P8: =(M8*N8)-((M8*N8)*O8) | R8: Nº ALBARÁN | S8: BASE | T8: % IVA | V8: COCACOLA ZERO ZERO VR237 C24 (neto caja) | W8: =1+2 | X8: 20.28 | Y8: 0 | Z8: =(W8*X8)-((W8*X8)*Y8) | AB8: Nº ALBARÁN | AC8: BASE | AD8: % IVA
B9: COCACOLA VR237 C24 | C9: 21 | D9: 4.8 | E9: 0 | F9: =(C9*D9)-((C9*D9)*E9) | H9: 521604 | I9: 200.66 | J9: 0.21 | L9: COCACOLA PET 2L C6 (neto caja) | M9: 1 | N9: 15.02 | O9: 0 | P9: =(M9*N9)-((M9*N9)*O9) | R9: 4536210096 | S9: 238.09 | T9: 0.21 | V9: COCACOLA PET 2L C6 (neto caja) | W9: 2 | X9: 15.025 | Y9: 0 | Z9: =(W9*X9)-((W9*X9)*Y9) | AB9: 4536891120 | AC9: 435.64 | AD9: 0.21
B10: COCACOLA ZER VR237 C24 | C10: =144+120+168+216+144+360+288 | D10: 0.845 | E10: 0 | F10: =(C10*D10)-((C10*D10)*E10) | H10: 629349 | I10: 141.96 | J10: 0.21 | L10: COCACOLA VR237 C24 (neto caja) | M10: 6 | N10: 20.2783 | O10: 0 | P10: =(M10*N10)-((M10*N10)*O10) | R10: 4536386996 | S10: 223.07 | T10: 0.21 | V10: COCACOLA VNR20 P4 C6 (neto caja) | W10: 1 | X10: 27.03 | Y10: 0 | Z10: =(W10*X10)-((W10*X10)*Y10) | AB10: 4537342018 | AC10: 189.26 | AD10: 0.21
B11: COCACOLA ZER ZER VR237 C24 | C11: =48+24+72 | D11: 0.845 | E11: 0 | F11: =(C11*D11)-((C11*D11)*E11) | H11: 658014 | I11: 34.96 | J11: 0.1 | L11: COCACOLA ZERO VR237 C24 (neto caja) | M11: 4 | N11: 20.28 | O11: 0 | P11: =(M11*N11)-((M11*N11)*O11) | R11: 4536386996 | S11: 34.96 | T11: 0.1 | AB11: 4537429705 | AC11: 304.19 | AD11: 0.21
B12: MINUTE MAID TOM VNR20 C24 | C12: =48+24 | D12: 0.728 | E12: 0 | F12: =(C12*D12)-((C12*D12)*E12) | H12: 658014 | I12: 293.69 | J12: 0.21 | L12: MINUTE MAID TOMATE VNR20 C24 (neto caja) | M12: 2 | N12: 17.48 | O12: 0 | P12: =(M12*N12)-((M12*N12)*O12) | R12: 4536386995 | S12: -38.4 | T12: 0.21
H13: 657975 | I13: 48 | J13: 0.21 | L13: DEVOLUCION CAJA+BOTELLAS VR237 | M13: -8 | N13: 4.8 | O13: 0 | P13: =(M13*N13)-((M13*N13)*O13)
H14: 874907 | I14: 17.48 | J14: 0.1
H15: 874907 | I15: 287.64 | J15: 0.21
H16: 970813 | I16: 232.84 | J16: 0.21
H17: 122492 | I17: 484.55 | J17: 0.21
H18: 366393 | I18: 334.24 | J18: 0.1
H19: 366398 | I19: 48 | J19: 0.21

Sheet _____CONS. SELEC. SANT
B2: 46204 | L2: 46235 | V2: 46266
H4: TOTAL | I4: =SUM(F6:F300) | R4: TOTAL | S4: =SUM(P6:P300) | AB4: TOTAL | AC4: =SUM(Z6:Z300)
B5: PRODUCTO | C5: UNIDADES | D5: PRECIO | E5: DTO | F5: TOTAL | H5: ALBARANES | I5: =SUM(I9:I300) | L5: PRODUCTO | M5: UNIDADES | N5: PRECIO | O5: DTO | P5: TOTAL | R5: ALBARANES | S5: =SUM(S9:S300) | V5: PRODUCTO | W5: UNIDADES | X5: PRECIO | Y5: DTO | Z5: TOTAL | AB5: ALBARANES | AC5: =SUM(AC9:AC300)
B6: DON BOCARTE MEDIO PULPO 360-400 gr | C6: =12.88+13.24 | D6: 27 | E6: 0 | F6: =(C6*D6)-((C6*D6)*E6) | H6: DIFERENCIA | I6: =I5-I4 | L6: DON BOCARTE MEDIO PULPO 360-400 gr | M6: 14.17 | N6: 27 | O6: 0 | P6: =(M6*N6)-((M6*N6)*O6) | R6: DIFERENCIA | S6: =S5-S4 | V6: DON BOCARTE MEDIO PULPO 360-400 gr | W6: =14.28+13.63+6.69+6.86+6.87 | X6: 27 | Y6: 0 | Z6: =(W6*X6)-((W6*X6)*Y6) | AB6: DIFERENCIA | AC6: =AC5-AC4
H8: Nº ALBARÁN | I8: BASE | J8: % IVA | R8: Nº ALBARÁN | S8: BASE | T8: % IVA | AB8: Nº ALBARÁN | AC8: BASE | AD8: % IVA
H9: 4604 | I9: 347.76 | J9: 0.1 | R9: 5653 | S9: 382.59 | T9: 0.1 | AB9: 5869 | AC9: 385.56 | AD9: 0.1
H10: 5016 | I10: 357.48 | J10: 0.1 | AB10: 6193 | AC10: 368.01 | AD10: 0.1
AB11: 6369 | AC11: 365.85 | AD11: 0.1
AB12: 6562 | AC12: 185.49 | AD12: 0.1

Sheet _____CONS. Y SALAZONES
B2: 46204 | L2: 46235 | V2: 46266
H4: TOTAL | I4: =SUM(F6:F300) | R4: TOTAL | S4: =SUM(P6:P300) | AB4: TOTAL | AC4: =SUM(Z6:Z300)
B5: PRODUCTO | C5: UNIDADES | D5: PRECIO | E5: DTO | F5: TOTAL | H5: ALBARANES | I5: =SUM(I9:I300) | L5: PRODUCTO | M5: UNIDADES | N5: PRECIO | O5: DTO | P5: TOTAL | R5: ALBARANES | S5: =SUM(S9:S300) | V5: PRODUCTO | W5: UNIDADES | X5: PRECIO | Y5: DTO | Z5: TOTAL | AB5: ALBARANES | AC5: =SUM(AC9:AC300)
B6: ANCHOAS CANTABRICO COSTERA | C6: =8+8+8+8+8+8 | D6: 16.9 | E6: 0.02 | F6: =(C6*D6)-((C6*D6)*E6) | H6: DIFERENCIA | I6: =I5-I4 | L6: ANCHOAS CANTABRICO COSTERA | M6: =8+8 | N6: 16.9 | O6: 0.02 | P6: =(M6*N6)-((M6*N6)*O6) | R6: DIFERENCIA | S6: =S5-S4 | V6: VENTRESCA DE BONITO EXTRA | W6: =24+24 | X6: 5.86 | Y6: 0.02 | Z6: =(W6*X6)-((W6*X6)*Y6) | AB6: DIFERENCIA | AC6: =AC5-AC4
B7: ANCHOAS DEL CANTABRICO GRAN RESERVA | C7: =16+16+16+16 | D7: 28.66 | E7: 0.02 | F7: =(C7*D7)-((C7*D7)*E7) | L7: VENTRESCA DE BONITO EXTRA | M7: 24 | N7: 5.86 | O7: 0.02 | P7: =(M7*N7)-((M7*N7)*O7) | V7: ANCHOAS DEL CANTABRICO GRAN RESERVA | W7: =16+8+8+6 | X7: 28.66 | Y7: 0.02 | Z7: =(W7*X7)-((W7*X7)*Y7)
B8: VENTRESCA DE BONITO EXTRA | C8: =24+24 | D8: 5.86 | E8: 0.02 | F8: =(C8*D8)-((C8*D8)*E8) | H8: Nº ALBARÁN | I8: BASE | J8: % IVA | L8: ANCHOAS DEL CANTABRICO GRAN RESERVA | M8: 16 | N8: 28.66 | O8: 0.02 | P8: =(M8*N8)-((M8*N8)*O8) | R8: Nº ALBARÁN | S8: BASE | T8: % IVA | V8: ANCHOAS CANTABRICO COSTERA | W8: =16+8+8 | X8: 16.9 | Y8: 0.02 | Z8: =(W8*X8)-((W8*X8)*Y8) | AB8: Nº ALBARÁN | AC8: BASE | AD8: % IVA
B9: MEJILLONES ESCABECHE RIAS GALLEGAS RR-125 | C9: 25 | D9: 5.86 | E9: 0.02 | F9: =(C9*D9)-((C9*D9)*E9) | H9: 26A00878 | I9: 719.71 | J9: 0.1 | L9: MEJILLONES ESCABECHE RIAS GALLEGAS OL-120 6/8 | M9: 24 | N9: 5.96 | O9: 0.02 | P9: =(M9*N9)-((M9*N9)*O9) | R9: 26A01042 | S9: 859.89 | T9: 0.1 | V9: MEJILLONES ESCABECHE RIAS GALLEGAS RR-125 | W9: 25 | X9: 6.1 | Y9: 0.02 | Z9: =(W9*X9)-((W9*X9)*Y9) | AB9: 26A01087 | AC9: 587.22 | AD9: 0.1
B10: BERBERECHOS RIAS GALLEGAS RO-120 30/40 | C10: 24 | D10: 11.4 | E10: 0.02 | F10: =(C10*D10)-((C10*D10)*E10) | H10: 26A00831 | I10: 993.58 | J10: 0.1 | L10: MOJAMA EXTRA SUPERIOR LA CHANCA | M10: 1.94 | N10: 36.4 | O10: 0.02 | P10: =(M10*N10)-((M10*N10)*O10) | R10: 26A01059 | S10: 201.7 | T10: 0.1 | V10: MUESTRA: MEJILLONES ESCABECHE PICANTES RIAS GALLEGAS RO-120 8/12 MARISCADORA SELECTA | W10: 1 | X10: 4.4 | Y10: 1 | Z10: =(W10*X10)-((W10*X10)*Y10) | AB10: 26A01109 | AC10: 264.99 | AD10: 0.1
B11: ANCHOAS CANTABRICO RO-550 ETIQUETA ROJA | C11: 18 | D11: 20.6 | E11: 0.02 | F11: =(C11*D11)-((C11*D11)*E11) | H11: 26A00946 | I11: 270.32 | J11: 0.1 | V11: MEJILLONES EN ESCABECHE PICANTES OL-120 20/25 RAMON FRANCO | W11: 50 | X11: 2.16 | Y11: 0.02 | Z11: =(W11*X11)-((W11*X11)*Y11) | AB11: 26A01144 | AC11: 374.14 | AD11: 0.1
B12: MOJAMA EXTRA SUPERIOR LA CHANCA | C12: 2.71 | D12: 36.4 | E12: 0.02 | F12: =(C12*D12)-((C12*D12)*E12) | H12: 26A00922 | I12: 132.5 | J12: 0.1 | V12: MEJILLONES ESCABECHE RIAS GALLEGAS OL-120 6/8 | W12: 12 | X12: 5.96 | Y12: 0.02 | Z12: =(W12*X12)-((W12*X12)*Y12) | AB12: 26A01162 | AC12: 670.95 | AD12: 0.1
H13: 26A00916 | I13: 812.77 | J13: 0.1 | AB13: 26A01199 | AC13: 301.02 | AD13: 0.1
H14: 26A00903 | I14: 229.16 | J14: 0.1
H15: 26A00978 | I15: 581.88 | J15: 0.1

Sheet _____CRNAS SERVAN
B2: 46204 | L2: 46235 | V2: 46266
H4: TOTAL | I4: =SUM(F6:F300) | R4: TOTAL | S4: =SUM(P6:P300) | AB4: TOTAL | AC4: =SUM(Z6:Z300)
B5: PRODUCTO | C5: UNIDADES | D5: PRECIO | E5: DTO | F5: TOTAL | H5: ALBARANES | I5: =SUM(I9:I300) | L5: PRODUCTO | M5: UNIDADES | N5: PRECIO | O5: DTO | P5: TOTAL | R5: ALBARANES | S5: =SUM(S9:S300) | V5: PRODUCTO | W5: UNIDADES | X5: PRECIO | Y5: DTO | Z5: TOTAL | AB5: ALBARANES | AC5: =SUM(AC9:AC300)
B6: MEDIA CAJA DE HUERVO | C6: =2+1 | D6: 45 | E6: 0 | F6: =(C6*D6)-((C6*D6)*E6) | H6: DIFERENCIA | I6: =I5-I4 | L6: MEDIA CAJA DE HUERVO | M6: =1+1+1+1 | N6: 45 | O6: 0 | P6: =(M6*N6)-((M6*N6)*O6) | R6: DIFERENCIA | S6: =S5-S4 | V6: PANCETA ADOBADA | W6: =3.9+6.9+9.3+8+7.3+8+3.5+3.9+5.8+7.2+7.3 | X6: 8.8 | Y6: 0 | Z6: =(W6*X6)-((W6*X6)*Y6) | AB6: DIFERENCIA | AC6: =AC5-AC4
B7: PANCETA ADOBADA | C7: =4.5+8.5+4.3+8.8+3.8+9.8+7.8 | D7: 8.8 | E7: 0 | F7: =(C7*D7)-((C7*D7)*E7) | L7: PANCETA ADOBADA | M7: =3.9+4.1+3.1+3.9+6.8+6.9+7.4 | N7: 8.8 | O7: 0 | P7: =(M7*N7)-((M7*N7)*O7) | V7: PICADA MIXTA | W7: 5 | X7: 7.5 | Y7: 0 | Z7: =(W7*X7)-((W7*X7)*Y7)
B8: CAJA HUEVOS DE CORRAL | C8: =1+1+1 | D8: 52.5 | E8: 0 | F8: =(C8*D8)-((C8*D8)*E8) | H8: Nº ALBARÁN | I8: BASE | J8: % IVA | L8: HUESO FRESCO | M8: 6 | N8: 2 | O8: 0 | P8: =(M8*N8)-((M8*N8)*O8) | R8: Nº ALBARÁN | S8: BASE | T8: % IVA | V8: CAJA HUEVOS DE CORRAL | W8: =1+1+1+1 | X8: 52.5 | Y8: 0 | Z8: =(W8*X8)-((W8*X8)*Y8) | AB8: Nº ALBARÁN | AC8: BASE | AD8: % IVA
B9: POLLO TROCEADO | C9: =5.5+5.5+6.5 | D9: 3.5 | E9: 0 | F9: =(C9*D9)-((C9*D9)*E9) | H9: A2607-0444 | I9: 84.6 | J9: 0.1 | L9: HUESO DE TUETANO | M9: 6 | N9: 3 | O9: 0 | P9: =(M9*N9)-((M9*N9)*O9) | R9: A2608-0010 | S9: 45 | T9: 0.1 | V9: OREJA DE CERDO | W9: 5.1 | X9: 6 | Y9: 0 | Z9: =(W9*X9)-((W9*X9)*Y9) | AB9: A2609-0052 | AC9: 71.82 | AD9: 0.1
B10: PALETILLA IBERICA | C10: 3.8 | D10: 36 | E10: 0 | F10: =(C10*D10)-((C10*D10)*E10) | H10: A2607-0048 | I10: 172.3 | J10: 0.1 | L10: MORCILLA ASTURIANA | M10: 8.6 | N10: 9 | O10: 0 | P10: =(M10*N10)-((M10*N10)*O10) | R10: A2608-0213 | S10: 285.02 | T10: 0.1 | V10: MEDIA CAJA DE HUEVO | W10: =1+1 | X10: 45 | Y10: 0 | Z10: =(W10*X10)-((W10*X10)*Y10) | AB10: A2609-0097 | AC10: 113.22 | AD10: 0.1
B11: OREJA DE CERDO | C11: =4.4+5.1 | D11: 6 | E11: 0 | F11: =(C11*D11)-((C11*D11)*E11) | H11: A2607-0010 | I11: 57.09 | J11: 0.1 | L11: MORRO DE TERNERA | M11: 4 | N11: 8.5 | O11: 0 | P11: =(M11*N11)-((M11*N11)*O11) | R11: A2608-0233 | S11: 111.68 | T11: 0.1 | AB11: A2609-0112 | AC11: 30.6 | AD11: 0.1
B12: POLLO ENTERO | C12: 5.9 | D12: 3.5 | E12: 0 | F12: =(C12*D12)-((C12*D12)*E12) | H12: A2607-0507 | I12: 208.55 | J12: 0.1 | L12: FALDA DE TERNERA | M12: 6.4 | N12: 11.5 | O12: 0 | P12: =(M12*N12)-((M12*N12)*O12) | R12: A2608-0257 | S12: 27.28 | T12: 0.1 | AB12: A2609-0146 | AC12: 81.84 | AD12: 0.1
B13: GALLINAS | C13: 4.9 | D13: 3.75 | E13: 0 | F13: =(C13*D13)-((C13*D13)*E13) | H13: A2607-0519 | I13: 77.44 | J13: 0.1 | L13: PATAS DE TERNERA | M13: 4.2 | N13: 8.5 | O13: 0 | P13: =(M13*N13)-((M13*N13)*O13) | R13: A2608-0274 | S13: 67.32 | T13: 0.1 | AB13: A2609-0177 | AC13: 115.4 | AD13: 0.1
B14: MORCILLO DE TERNERA | C14: 3 | D14: 12.5 | E14: 0 | F14: =(C14*D14)-((C14*D14)*E14) | H14: A2607-0476 | I14: 71.4 | J14: 0.1 | L14: OREJA DE CERDO | M14: =5.1+5.5+4.3 | N14: 6 | O14: 0 | P14: =(M14*N14)-((M14*N14)*O14) | R14: A2608-0327 | S14: 45 | T14: 0.1 | AB14: A2609-0245 | AC14: 52.5 | AD14: 0.1
B15: PATAS DE TERNERA | C15: 2 | D15: 8.5 | E15: 0 | F15: =(C15*D15)-((C15*D15)*E15) | H15: A2607-0335 | I15: 64.04 | J15: 0.1 | L15: CAJA HUEVOS DE CORRAL | M15: 1 | N15: 52.5 | O15: 0 | P15: =(M15*N15)-((M15*N15)*O15) | R15: A2608-0351 | S15: 104.84 | T15: 0.1 | AB15: A2609-0271 | AC15: 64.24 | AD15: 0.1
B16: MANOS DE CERDO | C16: 2.1 | D16: 4.5 | E16: 0 | F16: =(C16*D16)-((C16*D16)*E16) | H16: A2607-0309 | I16: 161.49 | J16: 0.1 | R16: A2608-0356 | S16: 60.72 | T16: 0.1 | AB16: A2609-0298 | AC16: 70.4 | AD16: 0.1
B17: MORRO DE TERNERA | C17: 1 | D17: 8.5 | E17: 0 | F17: =(C17*D17)-((C17*D17)*E17) | H17: A2607-0239 | I17: 189.12 | J17: 0.1 | R17: A2608-0379 | S17: 143.42 | T17: 0.1 | AB17: A2609-0338 | AC17: 83.3 | AD17: 0.1
B18: CHORIZO ASTURIANO | C18: 1 | D18: 9 | E18: 0 | F18: =(C18*D18)-((C18*D18)*E18) | AB18: A2609-0384 | AC18: 79.32 | AD18: 0.1
AB19: A2609-0440 | AC19: 103.54 | AD19: 0.1
AB20: A2609-0484 | AC20: 63.36 | AD20: 0.1
AB21: A2609-0505 | AC21: 64.24 | AD21: 0.1

Sheet _____CRUSTAPESCA
B2: 46204 | L2: 46235 | V2: 46266
H4: TOTAL | I4: =SUM(F6:F300) | R4: TOTAL | S4: =SUM(P6:P300) | AB4: TOTAL | AC4: =SUM(Z6:Z300)
B5: PRODUCTO | C5: UNIDADES | D5: PRECIO | E5: DTO | F5: TOTAL | H5: ALBARANES | I5: =SUM(I9:I300) | L5: PRODUCTO | M5: UNIDADES | N5: PRECIO | O5: DTO | P5: TOTAL | R5: ALBARANES | S5: =SUM(S9:S300) | V5: PRODUCTO | W5: UNIDADES | X5: PRECIO | Y5: DTO | Z5: TOTAL | AB5: ALBARANES | AC5: =SUM(AC9:AC300)
B6: GAMBA FR M | C6: =18+3+3+3+6+3+6+3+4+3 | D6: 26 | E6: 0 | F6: =(C6*D6)-((C6*D6)*E6) | H6: DIFERENCIA | I6: =I5-I4 | L6: COLA GAMBON (abono) | M6: -5 | N6: 22 | O6: 0 | P6: =(M6*N6)-((M6*N6)*O6) | R6: DIFERENCIA | S6: =S5-S4 | V6: GAMBA FR M | W6: =3+6+3+3+6+3+3+6+3+3 | X6: 26 | Y6: 0 | Z6: =(W6*X6)-((W6*X6)*Y6) | AB6: DIFERENCIA | AC6: =AC5-AC4
B7: VENTRESCA | C7: 4.84 | D7: 59.6 | E7: 0 | F7: =(C7*D7)-((C7*D7)*E7) | L7: VENTRESCA (abono) | M7: -2 | N7: 59.8 | O7: 0 | P7: =(M7*N7)-((M7*N7)*O7) | V7: PRODUCTO NO VISIBLE (alb. 03/09, importe 93,60) | W7: 1 | X7: 93.6 | Y7: 0 | Z7: =(W7*X7)-((W7*X7)*Y7)
B8: COLA G | C8: =4.5+6+6 | D8: 20 | E8: 0 | F8: =(C8*D8)-((C8*D8)*E8) | H8: Nº ALBARÁN | I8: BASE | J8: % IVA | L8: VENTRESCA | M8: 2 | N8: 59.8 | O8: 0 | P8: =(M8*N8)-((M8*N8)*O8) | R8: Nº ALBARÁN | S8: BASE | T8: % IVA | V8: PRODUCTO NO VISIBLE (alb. 03/09, importe 60,00) | W8: 1 | X8: 60 | Y8: 0 | Z8: =(W8*X8)-((W8*X8)*Y8) | AB8: Nº ALBARÁN | AC8: BASE | AD8: % IVA
H9: 10073 | I9: 78 | J9: 0.1 | L9: GAMBA FR M | M9: =3+3+3+3+3+3+3+6 | N9: 26 | O9: 0 | P9: =(M9*N9)-((M9*N9)*O9) | R9: 20081 (ABONO) | S9: -229.6 | T9: 0.1 | V9: GAMBA M | W9: 3 | X9: 26 | Y9: 0 | Z9: =(W9*X9)-((W9*X9)*Y9) | AB9: 1094 | AC9: 78 | AD9: 0.1
H10: 9071 | I10: 156 | J10: 0.1 | L10: COLA G | M10: =4.5+4.5 | N10: 20 | O10: 0 | P10: =(M10*N10)-((M10*N10)*O10) | R10: 25081 | S10: 119.6 | T10: 0.1 | V10: VENTRESCA | W10: =2.2+4.3 | X10: 52 | Y10: 0 | Z10: =(W10*X10)-((W10*X10)*Y10) | AB10: s/n (03/09) | AC10: 153.6 | AD10: 0.1
H11: 8074 | I11: 288.46 | J11: 0.1 | R11: 27084 | S11: 78 | T11: 0.1 | V11: COLA G | W11: 6 | X11: 20 | Y11: 0 | Z11: =(W11*X11)-((W11*X11)*Y11) | AB11: 3091 | AC11: 192.4 | AD11: 0.1
H12: 2074 | I12: 156 | J12: 0.1 | R12: 5081 | S12: 78 | T12: 0.1 | V12: VENTRESCA | W12: 4.7 | X12: 62 | Y12: 0 | Z12: =(W12*X12)-((W12*X12)*Y12) | AB12: 5091 | AC12: 156 | AD12: 0.1
H13: 1074 | I13: 78 | J13: 0.1 | R13: 6083 | S13: 78 | T13: 0.1 | V13: COLA G | W13: 4.5 | X13: 22 | Y13: 0 | Z13: =(W13*X13)-((W13*X13)*Y13) | AB13: 7069 | AC13: 78 | AD13: 0.1
H14: 31074 | I14: 90 | J14: 0.1 | R14: 18086 | S14: 78 | T14: 0.1 | AB14: 110911 | AC14: 78 | AD14: 0.1
H15: 30076 | I15: 78 | J15: 0.1 | R15: 19083 | S15: 78 | T15: 0.1 | AB15: 12091 | AC15: 156 | AD15: 0.1
H16: 29074 | I16: 78 | J16: 0.1 | R16: S/N 22-08 | S16: 168 | T16: 0.1 | AB16: 15091 | AC16: 301.6 | AD16: 0.1
H17: 28071 | I17: 198 | J17: 0.1 | R17: 25085 | S17: 78 | T17: 0.1 | AB17: 17091 | AC17: 198 | AD17: 0.1
H18: 18071 | I18: 156 | J18: 0.1 | R18: 29082 | S18: 246 | T18: 0.1 | AB18: 19091 | AC18: 156 | AD18: 0.1
H19: S/N 16-07 | I19: 78 | J19: 0.1 | AB19: 24092 | AC19: 468.4 | AD19: 0.1
H20: 150710 | I20: 120 | J20: 0.1 | AB20: 25093 | AC20: 78 | AD20: 0.1
H21: 14071 | I21: 156 | J21: 0.1
H22: 23077 | I22: 78 | J22: 0.1
H23: S/N 21-07 | I23: 104 | J23: 0.1
H24: S/N 24-07 | I24: 78 | J24: 0.1

Sheet _____DELIPAN
B2: 46204 | L2: 46235 | V2: 46266
H4: TOTAL | I4: =SUM(F6:F300) | R4: TOTAL | S4: =SUM(P6:P300) | AB4: TOTAL | AC4: =SUM(Z6:Z300)
B5: PRODUCTO | C5: UNIDADES | D5: PRECIO | E5: DTO | F5: TOTAL | H5: ALBARANES | I5: =SUM(I9:I300) | L5: PRODUCTO | M5: UNIDADES | N5: PRECIO | O5: DTO | P5: TOTAL | R5: ALBARANES | S5: =SUM(S9:S300) | V5: PRODUCTO | W5: UNIDADES | X5: PRECIO | Y5: DTO | Z5: TOTAL | AB5: ALBARANES | AC5: =SUM(AC9:AC300)
B6: DELIPAN | C6: 4 | D6: 17.73 | E6: 0 | F6: =(C6*D6)-((C6*D6)*E6) | H6: DIFERENCIA | I6: =I5-I4 | L6: PICOS ARTESANOS 500gr | M6: =2+2+3 | N6: 11.48 | O6: 0 | P6: =(M6*N6)-((M6*N6)*O6) | R6: DIFERENCIA | S6: =S5-S4 | V6: DELIFLAUTA 17 PERRITO 90 uds | W6: =3+4+2+1+1 | X6: 17.73 | Y6: 0 | Z6: =(W6*X6)-((W6*X6)*Y6) | AB6: DIFERENCIA | AC6: =AC5-AC4
B7: PICOS ARTESANOS 500gr | C7: =5+2+1+2+2+2 | D7: 11.48 | E7: 0 | F7: =(C7*D7)-((C7*D7)*E7) | L7: DELIFLAUTA 17 PERRITO 90 uds | M7: =1+2+3+3+3 | N7: 17.73 | O7: 0 | P7: =(M7*N7)-((M7*N7)*O7) | V7: PAN MOLDE BRIOCHE (7 ud) | W7: =1+1+1+1+1+1 | X7: 88.09 | Y7: 0 | Z7: =(W7*X7)-((W7*X7)*Y7)
B8: DELIFLAUTA 17 PERRITO 90 uds | C8: =3+4+3+2+4+4+5+4 | D8: 17.73 | E8: 0 | F8: =(C8*D8)-((C8*D8)*E8) | H8: Nº ALBARÁN | I8: BASE | J8: % IVA | L8: PAN MOLDE BRIOCHE (7 ud) | M8: 1 | N8: 88.09 | O8: 0 | P8: =(M8*N8)-((M8*N8)*O8) | R8: Nº ALBARÁN | S8: BASE | T8: % IVA | V8: PICOS ARTESANOS 500gr | W8: =3+3+2+2+4+2+4 | X8: 11.48 | Y8: 0 | Z8: =(W8*X8)-((W8*X8)*Y8) | AB8: Nº ALBARÁN | AC8: BASE | AD8: % IVA
B9: PAN MOLDE BRIOCHE (7 ud) | C9: =1+1+1 | D9: 88.09 | E9: 0 | F9: =(C9*D9)-((C9*D9)*E9) | H9: A2/8520 | I9: 105.36 | J9: 0.04 | R9: A2/9526 | S9: 88.09 | T9: 0.1 | V9: PICOS SIN GLUTEN 20gr (25 uds) | W9: =2+1 | X9: 11.29 | Y9: 0 | Z9: =(W9*X9)-((W9*X9)*Y9) | AB9: A2/10.367 | AC9: 110.21 | AD9: 0.04
B10: PICOS SIN GLUTEN 20gr (25 uds) | C10: =1+1 | D10: 11.29 | E10: 0 | F10: =(C10*D10)-((C10*D10)*E10) | H10: A2/8358 | I10: 88.09 | J10: 0.1 | R10: A2/9526 | S10: 40.69 | T10: 0.04 | AB10: A2/10.367 | AC10: 88.09 | AD10: 0.1
H11: A2/8358 | I11: 76.15 | J11: 0.04 | R11: A2/9861 | S11: 35.46 | T11: 0.04 | AB11: A2/10.551 | AC11: 105.36 | AD11: 0.04
