Workbook

Sheet RESUMEN SUBIDAS
A2: COMPARATIVO DE PRECIOS 2026 · LA MINA DE CHAMARTÍN 2 · PRODUCTOS CON SUBIDAS
A5: CATEGORÍA | B5: PROVEEDOR | C5: PRODUCTO (ver hoja) | D5: ENERO | E5: FEBRERO | F5: MARZO | G5: ABRIL | H5: MAYO | I5: JUNIO | J5: JULIO | K5: AGOSTO | L5: PRECIO INICIAL | M5: PRECIO ACTUAL | N5: VARIACIÓN TOTAL % | O5: Nº SUBIDAS | P5: CAMBIOS DE PRECIO (mes a mes) | Q5: ESTADO
A6: CARNE | B6: CARNICAS OPC / CRNAS SERVAN | C6: MORCILLA ASTURIANA | E6: =IFERROR(INDEX('MORCILLA ASTURIANA'!$D$7:$D$9,MATCH("FEBRERO",'MORCILLA ASTURIANA'!$A$7:$A$9,0)),"") -> 8 | G6: =IFERROR(INDEX('MORCILLA ASTURIANA'!$D$7:$D$9,MATCH("ABRIL",'MORCILLA ASTURIANA'!$A$7:$A$9,0)),"") -> 8 | K6: =IFERROR(INDEX('MORCILLA ASTURIANA'!$D$7:$D$9,MATCH("AGOSTO",'MORCILLA ASTURIANA'!$A$7:$A$9,0)),"") -> 9 | L6: ='MORCILLA ASTURIANA'!D7 -> 8 | M6: ='MORCILLA ASTURIANA'!D9 -> 9 | N6: =IFERROR(M6/L6-1,0) -> 0.125 | O6: 1 | P6: ABR 8,00 → AGO 9,00 (+12,5%) | Q6: SUBE
A7: ENVASADO / BEBIDA / OTROS | B7: VINS DES DIEUX | C7: CANTALAPIEDRA CHIVIRITERO 2023 | E7: =IFERROR(INDEX('CANTALAPIEDRA CHIVIRITERO 20'!$D$7:$D$11,MATCH("FEBRERO",'CANTALAPIEDRA CHIVIRITERO 20'!$A$7:$A$11,0)),"") -> 15.5 | F7: =IFERROR(INDEX('CANTALAPIEDRA CHIVIRITERO 20'!$D$7:$D$11,MATCH("MARZO",'CANTALAPIEDRA CHIVIRITERO 20'!$A$7:$A$11,0)),"") -> 15.5 | G7: =IFERROR(INDEX('CANTALAPIEDRA CHIVIRITERO 20'!$D$7:$D$11,MATCH("ABRIL",'CANTALAPIEDRA CHIVIRITERO 20'!$A$7:$A$11,0)),"") -> 15.5 | H7: =IFERROR(INDEX('CANTALAPIEDRA CHIVIRITERO 20'!$D$7:$D$11,MATCH("MAYO",'CANTALAPIEDRA CHIVIRITERO 20'!$A$7:$A$11,0)),"") -> 16.9 | J7: =IFERROR(INDEX('CANTALAPIEDRA CHIVIRITERO 20'!$D$7:$D$11,MATCH("JULIO",'CANTALAPIEDRA CHIVIRITERO 20'!$A$7:$A$11,0)),"") -> 16.9 | L7: ='CANTALAPIEDRA CHIVIRITERO 20'!D7 -> 15.5 | M7: ='CANTALAPIEDRA CHIVIRITERO 20'!D11 -> 16.9 | N7: =IFERROR(M7/L7-1,0) -> 0.090322581 | O7: 1 | P7: ABR 15,50 → MAY 16,90 (+9,0%) | Q7: SUBE
A8: ENVASADO / BEBIDA / OTROS | B8: CONSERVAS Y SALAZONES JIMENEZ | C8: ANCHOAS CANTABRICO RO 550 ETIQUETA ROJA | E8: =IFERROR(INDEX('ANCHOAS CANTABRICO RO 550 ET'!$D$7:$D$10,MATCH("FEBRERO",'ANCHOAS CANTABRICO RO 550 ET'!$A$7:$A$10,0)),"") -> 18.96 | G8: =IFERROR(INDEX('ANCHOAS CANTABRICO RO 550 ET'!$D$7:$D$10,MATCH("ABRIL",'ANCHOAS CANTABRICO RO 550 ET'!$A$7:$A$10,0)),"") -> 18.96 | H8: =IFERROR(INDEX('ANCHOAS CANTABRICO RO 550 ET'!$D$7:$D$10,MATCH("MAYO",'ANCHOAS CANTABRICO RO 550 ET'!$A$7:$A$10,0)),"") -> 20.6 | J8: =IFERROR(INDEX('ANCHOAS CANTABRICO RO 550 ET'!$D$7:$D$10,MATCH("JULIO",'ANCHOAS CANTABRICO RO 550 ET'!$A$7:$A$10,0)),"") -> 20.6 | L8: ='ANCHOAS CANTABRICO RO 550 ET'!D7 -> 18.96 | M8: ='ANCHOAS CANTABRICO RO 550 ET'!D10 -> 20.6 | N8: =IFERROR(M8/L8-1,0) -> 0.08649789 | O8: 1 | P8: ABR 18,96 → MAY 20,60 (+8,6%) | Q8: SUBE
A9: ENVASADO / BEBIDA / OTROS | B9: SUBMARINER | C9: ZACAPA X O | D9: =IFERROR(INDEX('ZACAPA X O'!$D$7:$D$8,MATCH("ENERO",'ZACAPA X O'!$A$7:$A$8,0)),"") -> 122.71 | H9: =IFERROR(INDEX('ZACAPA X O'!$D$7:$D$8,MATCH("MAYO",'ZACAPA X O'!$A$7:$A$8,0)),"") -> 132.94 | L9: ='ZACAPA X O'!D7 -> 122.71 | M9: ='ZACAPA X O'!D8 -> 132.94 | N9: =IFERROR(M9/L9-1,0) -> 0.083367289 | O9: 1 | P9: ENE 122,71 → MAY 132,94 (+8,3%) | Q9: SUBE
A10: ENVASADO / BEBIDA / OTROS | B10: CALIDOSCOPI | C10: OREMUS 3 | D10: =IFERROR(INDEX('OREMUS 3'!$D$7:$D$8,MATCH("ENERO",'OREMUS 3'!$A$7:$A$8,0)),"") -> 27.4 | H10: =IFERROR(INDEX('OREMUS 3'!$D$7:$D$8,MATCH("MAYO",'OREMUS 3'!$A$7:$A$8,0)),"") -> 29.25 | L10: ='OREMUS 3'!D7 -> 27.4 | M10: ='OREMUS 3'!D8 -> 29.25 | N10: =IFERROR(M10/L10-1,0) -> 0.067518248 | O10: 1 | P10: ENE 27,40 → MAY 29,25 (+6,8%) | Q10: SUBE
A11: ENVASADO / BEBIDA / OTROS | B11: DITEMA (DIST. TENA) | C11: GINEBRA MARTIN MILLER 3/4 | D11: =IFERROR(INDEX('GINEBRA MARTIN MILLER 3 4'!$D$7:$D$9,MATCH("ENERO",'GINEBRA MARTIN MILLER 3 4'!$A$7:$A$9,0)),"") -> 15.1 | H11: =IFERROR(INDEX('GINEBRA MARTIN MILLER 3 4'!$D$7:$D$9,MATCH("MAYO",'GINEBRA MARTIN MILLER 3 4'!$A$7:$A$9,0)),"") -> 16.1 | J11: =IFERROR(INDEX('GINEBRA MARTIN MILLER 3 4'!$D$7:$D$9,MATCH("JULIO",'GINEBRA MARTIN MILLER 3 4'!$A$7:$A$9,0)),"") -> 16.1 | L11: ='GINEBRA MARTIN MILLER 3 4'!D7 -> 15.1 | M11: ='GINEBRA MARTIN MILLER 3 4'!D9 -> 16.1 | N11: =IFERROR(M11/L11-1,0) -> 0.066225166 | O11: 1 | P11: ENE 15,10 → MAY 16,10 (+6,6%) | Q11: SUBE
A12: ENVASADO / BEBIDA / OTROS | B12: VOLDIS | C12: AQUARADE ZERO NARANJA VIDRIO 35CL | D12: =IFERROR(INDEX('AQUARADE ZERO NARANJA VIDRIO'!$D$7:$D$10,MATCH("ENERO",'AQUARADE ZERO NARANJA VIDRIO'!$A$7:$A$10,0)),"") -> 31.92 | E12: =IFERROR(INDEX('AQUARADE ZERO NARANJA VIDRIO'!$D$7:$D$10,MATCH("FEBRERO",'AQUARADE ZERO NARANJA VIDRIO'!$A$7:$A$10,0)),"") -> 33.84 | H12: =IFERROR(INDEX('AQUARADE ZERO NARANJA VIDRIO'!$D$7:$D$10,MATCH("MAYO",'AQUARADE ZERO NARANJA VIDRIO'!$A$7:$A$10,0)),"") -> 33.84 | J12: =IFERROR(INDEX('AQUARADE ZERO NARANJA VIDRIO'!$D$7:$D$10,MATCH("JULIO",'AQUARADE ZERO NARANJA VIDRIO'!$A$7:$A$10,0)),"") -> 33.84 | L12: ='AQUARADE ZERO NARANJA VIDRIO'!D7 -> 31.92 | M12: ='AQUARADE ZERO NARANJA VIDRIO'!D10 -> 33.84 | N12: =IFERROR(M12/L12-1,0) -> 0.060150376 | O12: 1 | P12: ENE 31,92 → FEB 33,84 (+6,0%) | Q12: SUBE
A13: ENVASADO / BEBIDA / OTROS | B13: CONSERVAS Y SALAZONES JIMENEZ | C13: VENTRESCA BONITO EXTRA | D13: =IFERROR(INDEX('VENTRESCA BONITO EXTRA'!$D$7:$D$12,MATCH("ENERO",'VENTRESCA BONITO EXTRA'!$A$7:$A$12,0)),"") -> 5.56 | E13: =IFERROR(INDEX('VENTRESCA BONITO EXTRA'!$D$7:$D$12,MATCH("FEBRERO",'VENTRESCA BONITO EXTRA'!$A$7:$A$12,0)),"") -> 5.56 | G13: =IFERROR(INDEX('VENTRESCA BONITO EXTRA'!$D$7:$D$12,MATCH("ABRIL",'VENTRESCA BONITO EXTRA'!$A$7:$A$12,0)),"") -> 5.56 | H13: =IFERROR(INDEX('VENTRESCA BONITO EXTRA'!$D$7:$D$12,MATCH("MAYO",'VENTRESCA BONITO EXTRA'!$A$7:$A$12,0)),"") -> 5.56 | J13: =IFERROR(INDEX('VENTRESCA BONITO EXTRA'!$D$7:$D$12,MATCH("JULIO",'VENTRESCA BONITO EXTRA'!$A$7:$A$12,0)),"") -> 5.86 | K13: =IFERROR(INDEX('VENTRESCA BONITO EXTRA'!$D$7:$D$12,MATCH("AGOSTO",'VENTRESCA BONITO EXTRA'!$A$7:$A$12,0)),"") -> 5.86 | L13: ='VENTRESCA BONITO EXTRA'!D7 -> 5.56 | M13: ='VENTRESCA BONITO EXTRA'!D12 -> 5.86 | N13: =IFERROR(M13/L13-1,0) -> 0.053956835 | O13: 1 | P13: MAY 5,56 → JUL 5,86 (+5,4%) | Q13: SUBE
A14: ENVASADO / BEBIDA / OTROS | B14: EIF DISTRIBUCIONES | C14: SOLAN CABRAS CON GAS | D14: =IFERROR(INDEX('SOLAN CABRAS CON GAS'!$D$7:$D$9,MATCH("ENERO",'SOLAN CABRAS CON GAS'!$A$7:$A$9,0)),"") -> 25.44 | J14: =IFERROR(INDEX('SOLAN CABRAS CON GAS'!$D$7:$D$9,MATCH("JULIO",'SOLAN CABRAS CON GAS'!$A$7:$A$9,0)),"") -> 26.8 | K14: =IFERROR(INDEX('SOLAN CABRAS CON GAS'!$D$7:$D$9,MATCH("AGOSTO",'SOLAN CABRAS CON GAS'!$A$7:$A$9,0)),"") -> 26.8 | L14: ='SOLAN CABRAS CON GAS'!D7 -> 25.44 | M14: ='SOLAN CABRAS CON GAS'!D9 -> 26.8 | N14: =IFERROR(M14/L14-1,0) -> 0.053459119 | O14: 1 | P14: ENE 25,44 → JUL 26,80 (+5,3%) | Q14: SUBE
A15: ENVASADO / BEBIDA / OTROS | B15: VOLDIS | C15: AGUA SOLAN CABRAS VIDRIO 50CL | D15: =IFERROR(INDEX('AGUA SOLAN CABRAS VIDRIO 50C'!$D$7:$D$10,MATCH("ENERO",'AGUA SOLAN CABRAS VIDRIO 50C'!$A$7:$A$10,0)),"") -> 11.68 | E15: =IFERROR(INDEX('AGUA SOLAN CABRAS VIDRIO 50C'!$D$7:$D$10,MATCH("FEBRERO",'AGUA SOLAN CABRAS VIDRIO 50C'!$A$7:$A$10,0)),"") -> 11.68 | H15: =IFERROR(INDEX('AGUA SOLAN CABRAS VIDRIO 50C'!$D$7:$D$10,MATCH("MAYO",'AGUA SOLAN CABRAS VIDRIO 50C'!$A$7:$A$10,0)),"") -> 11.68 | J15: =IFERROR(INDEX('AGUA SOLAN CABRAS VIDRIO 50C'!$D$7:$D$10,MATCH("JULIO",'AGUA SOLAN CABRAS VIDRIO 50C'!$A$7:$A$10,0)),"") -> 12.3 | L15: ='AGUA SOLAN CABRAS VIDRIO 50C'!D7 -> 11.68 | M15: ='AGUA SOLAN CABRAS VIDRIO 50C'!D10 -> 12.3 | N15: =IFERROR(M15/L15-1,0) -> 0.053082192 | O15: 1 | P15: MAY 11,68 → JUL 12,30 (+5,3%) | Q15: SUBE
A16: ENVASADO / BEBIDA / OTROS | B16: VOLDIS | C16: AGUA CON GAS SOLAN CABRAS VIDRIO 33CL | D16: =IFERROR(INDEX('AGUA CON GAS SOLAN CABRAS VI'!$D$7:$D$10,MATCH("ENERO",'AGUA CON GAS SOLAN CABRAS VI'!$A$7:$A$10,0)),"") -> 25.464 | E16: =IFERROR(INDEX('AGUA CON GAS SOLAN CABRAS VI'!$D$7:$D$10,MATCH("FEBRERO",'AGUA CON GAS SOLAN CABRAS VI'!$A$7:$A$10,0)),"") -> 25.464 | H16: =IFERROR(INDEX('AGUA CON GAS SOLAN CABRAS VI'!$D$7:$D$10,MATCH("MAYO",'AGUA CON GAS SOLAN CABRAS VI'!$A$7:$A$10,0)),"") -> 25.464 | J16: =IFERROR(INDEX('AGUA CON GAS SOLAN CABRAS VI'!$D$7:$D$10,MATCH("JULIO",'AGUA CON GAS SOLAN CABRAS VI'!$A$7:$A$10,0)),"") -> 26.81 | L16: ='AGUA CON GAS SOLAN CABRAS VI'!D7 -> 25.464 | M16: ='AGUA CON GAS SOLAN CABRAS VI'!D10 -> 26.81 | N16: =IFERROR(M16/L16-1,0) -> 0.052858938 | O16: 1 | P16: MAY 25,46 → JUL 26,81 (+5,3%) | Q16: SUBE
A17: ENVASADO / BEBIDA / OTROS | B17: CONSERVAS Y SALAZONES JIMENEZ | C17: MOJAMA EXTRA SUPERIOR CHANCA | D17: =IFERROR(INDEX('MOJAMA EXTRA SUPERIOR CHANCA'!$D$7:$D$10,MATCH("ENERO",'MOJAMA EXTRA SUPERIOR CHANCA'!$A$7:$A$10,0)),"") -> 34.6 | H17: =IFERROR(INDEX('MOJAMA EXTRA SUPERIOR CHANCA'!$D$7:$D$10,MATCH("MAYO",'MOJAMA EXTRA SUPERIOR CHANCA'!$A$7:$A$10,0)),"") -> 36.4 | J17: =IFERROR(INDEX('MOJAMA EXTRA SUPERIOR CHANCA'!$D$7:$D$10,MATCH("JULIO",'MOJAMA EXTRA SUPERIOR CHANCA'!$A$7:$A$10,0)),"") -> 36.4 | K17: =IFERROR(INDEX('MOJAMA EXTRA SUPERIOR CHANCA'!$D$7:$D$10,MATCH("AGOSTO",'MOJAMA EXTRA SUPERIOR CHANCA'!$A$7:$A$10,0)),"") -> 36.4 | L17: ='MOJAMA EXTRA SUPERIOR CHANCA'!D7 -> 34.6 | M17: ='MOJAMA EXTRA SUPERIOR CHANCA'!D10 -> 36.4 | N17: =IFERROR(M17/L17-1,0) -> 0.052023121 | O17: 1 | P17: ENE 34,60 → MAY 36,40 (+5,2%) | Q17: SUBE
A18: ENVASADO / BEBIDA / OTROS | B18: VOLDIS | C18: BITTER KAS VIDRIO 20CL | D18: =IFERROR(INDEX('BITTER KAS VIDRIO 20CL'!$D$7:$D$8,MATCH("ENERO",'BITTER KAS VIDRIO 20CL'!$A$7:$A$8,0)),"") -> 37.68 | H18: =IFERROR(INDEX('BITTER KAS VIDRIO 20CL'!$D$7:$D$8,MATCH("MAYO",'BITTER KAS VIDRIO 20CL'!$A$7:$A$8,0)),"") -> 39.6 | L18: ='BITTER KAS VIDRIO 20CL'!D7 -> 37.68 | M18: ='BITTER KAS VIDRIO 20CL'!D8 -> 39.6 | N18: =IFERROR(M18/L18-1,0) -> 0.050955414 | O18: 1 | P18: ENE 37,68 → MAY 39,60 (+5,1%) | Q18: SUBE
A19: ENVASADO / BEBIDA / OTROS | B19: VOLDIS | C19: AQUARADE ZERO LIMON VIDRIO 35CL | D19: =IFERROR(INDEX('AQUARADE ZERO LIMON VIDRIO 3'!$D$7:$D$10,MATCH("ENERO",'AQUARADE ZERO LIMON VIDRIO 3'!$A$7:$A$10,0)),"") -> 31.92 | E19: =IFERROR(INDEX('AQUARADE ZERO LIMON VIDRIO 3'!$D$7:$D$10,MATCH("FEBRERO",'AQUARADE ZERO LIMON VIDRIO 3'!$A$7:$A$10,0)),"") -> 33.84 | H19: =IFERROR(INDEX('AQUARADE ZERO LIMON VIDRIO 3'!$D$7:$D$10,MATCH("MAYO",'AQUARADE ZERO LIMON VIDRIO 3'!$A$7:$A$10,0)),"") -> 33.84 | J19: =IFERROR(INDEX('AQUARADE ZERO LIMON VIDRIO 3'!$D$7:$D$10,MATCH("JULIO",'AQUARADE ZERO LIMON VIDRIO 3'!$A$7:$A$10,0)),"") -> 33.54 | L19: ='AQUARADE ZERO LIMON VIDRIO 3'!D7 -> 31.92 | M19: ='AQUARADE ZERO LIMON VIDRIO 3'!D10 -> 33.54 | N19: =IFERROR(M19/L19-1,0) -> 0.05075188 | O19: 1 | P19: ENE 31,92 → FEB 33,84 (+6,0%) · MAY 33,84 → JUL 33,54 (-0,9%) | Q19: SUBE
A20: ENVASADO / BEBIDA / OTROS | B20: EL ESCRIBANO | C20: LOMO BELLOTA 100 SM | E20: =IFERROR(INDEX('LOMO BELLOTA 100 SM'!$D$7:$D$11,MATCH("FEBRERO",'LOMO BELLOTA 100 SM'!$A$7:$A$11,0)),"") -> 48.6 | G20: =IFERROR(INDEX('LOMO BELLOTA 100 SM'!$D$7:$D$11,MATCH("ABRIL",'LOMO BELLOTA 100 SM'!$A$7:$A$11,0)),"") -> 48.6 | H20: =IFERROR(INDEX('LOMO BELLOTA 100 SM'!$D$7:$D$11,MATCH("MAYO",'LOMO BELLOTA 100 SM'!$A$7:$A$11,0)),"") -> 48.6 | J20: =IFERROR(INDEX('LOMO BELLOTA 100 SM'!$D$7:$D$11,MATCH("JULIO",'LOMO BELLOTA 100 SM'!$A$7:$A$11,0)),"") -> 49.8 | K20: =IFERROR(INDEX('LOMO BELLOTA 100 SM'!$D$7:$D$11,MATCH("AGOSTO",'LOMO BELLOTA 100 SM'!$A$7:$A$11,0)),"") -> 51 | L20: ='LOMO BELLOTA 100 SM'!D7 -> 48.6 | M20: ='LOMO BELLOTA 100 SM'!D11 -> 51 | N20: =IFERROR(M20/L20-1,0) -> 0.049382716 | O20: 2 | P20: MAY 48,60 → JUL 49,80 (+2,5%) · JUL 49,80 → AGO 51,00 (+2,4%) | Q20: SUBE
A21: ENVASADO / BEBIDA / OTROS | B21: EIF DISTRIBUCIONES | C21: COCA COLA ZERO NAC | D21: =IFERROR(INDEX('COCA COLA ZERO NAC'!$D$7:$D$8,MATCH("ENERO",'COCA COLA ZERO NAC'!$A$7:$A$8,0)),"") -> 20.78 | K21: =IFERROR(INDEX('COCA COLA ZERO NAC'!$D$7:$D$8,MATCH("AGOSTO",'COCA COLA ZERO NAC'!$A$7:$A$8,0)),"") -> 21.78 | L21: ='COCA COLA ZERO NAC'!D7 -> 20.78 | M21: ='COCA COLA ZERO NAC'!D8 -> 21.78 | N21: =IFERROR(M21/L21-1,0) -> 0.048123195 | O21: 1 | P21: ENE 20,78 → AGO 21,78 (+4,8%) | Q21: SUBE
A22: ENVASADO / BEBIDA / OTROS | B22: MUNDELA | C22: MANZANILLA SOLEAR 3/8 | D22: =IFERROR(INDEX('MANZANILLA SOLEAR 3 8'!$D$7:$D$10,MATCH("ENERO",'MANZANILLA SOLEAR 3 8'!$A$7:$A$10,0)),"") -> 4.22 | E22: =IFERROR(INDEX('MANZANILLA SOLEAR 3 8'!$D$7:$D$10,MATCH("FEBRERO",'MANZANILLA SOLEAR 3 8'!$A$7:$A$10,0)),"") -> 4.42 | H22: =IFERROR(INDEX('MANZANILLA SOLEAR 3 8'!$D$7:$D$10,MATCH("MAYO",'MANZANILLA SOLEAR 3 8'!$A$7:$A$10,0)),"") -> 4.42 | K22: =IFERROR(INDEX('MANZANILLA SOLEAR 3 8'!$D$7:$D$10,MATCH("AGOSTO",'MANZANILLA SOLEAR 3 8'!$A$7:$A$10,0)),"") -> 4.42 | L22: ='MANZANILLA SOLEAR 3 8'!D7 -> 4.22 | M22: ='MANZANILLA SOLEAR 3 8'!D10 -> 4.42 | N22: =IFERROR(M22/L22-1,0) -> 0.047393365 | O22: 1 | P22: ENE 4,22 → FEB 4,42 (+4,7%) | Q22: SUBE
A23: ENVASADO / BEBIDA / OTROS | B23: DELIPAN | C23: PICOS ARTESANOS 500 GR | D23: =IFERROR(INDEX('PICOS ARTESANOS 500 GR'!$D$7:$D$10,MATCH("ENERO",'PICOS ARTESANOS 500 GR'!$A$7:$A$10,0)),"") -> 10.97 | E23: =IFERROR(INDEX('PICOS ARTESANOS 500 GR'!$D$7:$D$10,MATCH("FEBRERO",'PICOS ARTESANOS 500 GR'!$A$7:$A$10,0)),"") -> 10.97 | G23: =IFERROR(INDEX('PICOS ARTESANOS 500 GR'!$D$7:$D$10,MATCH("ABRIL",'PICOS ARTESANOS 500 GR'!$A$7:$A$10,0)),"") -> 11.48 | H23: =IFERROR(INDEX('PICOS ARTESANOS 500 GR'!$D$7:$D$10,MATCH("MAYO",'PICOS ARTESANOS 500 GR'!$A$7:$A$10,0)),"") -> 11.48 | L23: ='PICOS ARTESANOS 500 GR'!D7 -> 10.97 | M23: ='PICOS ARTESANOS 500 GR'!D10 -> 11.48 | N23: =IFERROR(M23/L23-1,0) -> 0.046490428 | O23: 1 | P23: FEB 10,97 → ABR 11,48 (+4,6%) | Q23: SUBE
A24: ENVASADO / BEBIDA / OTROS | B24: CONSERVAS Y SALAZONES JIMENEZ | C24: ANCHOAS CANTABRICO GRAN RESERVA | D24: =IFERROR(INDEX('ANCHOAS CANTABRICO GRAN RESE'!$D$7:$D$12,MATCH("ENERO",'ANCHOAS CANTABRICO GRAN RESE'!$A$7:$A$12,0)),"") -> 27.46 | E24: =IFERROR(INDEX('ANCHOAS CANTABRICO GRAN RESE'!$D$7:$D$12,MATCH("FEBRERO",'ANCHOAS CANTABRICO GRAN RESE'!$A$7:$A$12,0)),"") -> 27.46 | G24: =IFERROR(INDEX('ANCHOAS CANTABRICO GRAN RESE'!$D$7:$D$12,MATCH("ABRIL",'ANCHOAS CANTABRICO GRAN RESE'!$A$7:$A$12,0)),"") -> 28.66 | H24: =IFERROR(INDEX('ANCHOAS CANTABRICO GRAN RESE'!$D$7:$D$12,MATCH("MAYO",'ANCHOAS CANTABRICO GRAN RESE'!$A$7:$A$12,0)),"") -> 28.66 | J24: =IFERROR(INDEX('ANCHOAS CANTABRICO GRAN RESE'!$D$7:$D$12,MATCH("JULIO",'ANCHOAS CANTABRICO GRAN RESE'!$A$7:$A$12,0)),"") -> 28.66 | K24: =IFERROR(INDEX('ANCHOAS CANTABRICO GRAN RESE'!$D$7:$D$12,MATCH("AGOSTO",'ANCHOAS CANTABRICO GRAN RESE'!$A$7:$A$12,0)),"") -> 28.66 | L24: ='ANCHOAS CANTABRICO GRAN RESE'!D7 -> 27.46 | M24: ='ANCHOAS CANTABRICO GRAN RESE'!D12 -> 28.66 | N24: =IFERROR(M24/L24-1,0) -> 0.043699927 | O24: 1 | P24: FEB 27,46 → ABR 28,66 (+4,4%) | Q24: SUBE
A25: ENVASADO / BEBIDA / OTROS | B25: DITEMA (DIST. TENA) | C25: PEPE YLLERA 3/4 | D25: =IFERROR(INDEX('PEPE YLLERA 3 4'!$D$7:$D$9,MATCH("ENERO",'PEPE YLLERA 3 4'!$A$7:$A$9,0)),"") -> 7.15 | E25: =IFERROR(INDEX('PEPE YLLERA 3 4'!$D$7:$D$9,MATCH("FEBRERO",'PEPE YLLERA 3 4'!$A$7:$A$9,0)),"") -> 7.46 | H25: =IFERROR(INDEX('PEPE YLLERA 3 4'!$D$7:$D$9,MATCH("MAYO",'PEPE YLLERA 3 4'!$A$7:$A$9,0)),"") -> 7.46 | L25: ='PEPE YLLERA 3 4'!D7 -> 7.15 | M25: ='PEPE YLLERA 3 4'!D9 -> 7.46 | N25: =IFERROR(M25/L25-1,0) -> 0.043356643 | O25: 1 | P25: ENE 7,15 → FEB 7,46 (+4,3%) | Q25: SUBE
A26: ENVASADO / BEBIDA / OTROS | B26: EIF DISTRIBUCIONES | C26: SCHWEPPES TONICA 28 UDS | D26: =IFERROR(INDEX('SCHWEPPES TONICA 28 UDS'!$D$7:$D$8,MATCH("ENERO",'SCHWEPPES TONICA 28 UDS'!$A$7:$A$8,0)),"") -> 23.84 | K26: =IFERROR(INDEX('SCHWEPPES TONICA 28 UDS'!$D$7:$D$8,MATCH("AGOSTO",'SCHWEPPES TONICA 28 UDS'!$A$7:$A$8,0)),"") -> 24.84 | L26: ='SCHWEPPES TONICA 28 UDS'!D7 -> 23.84 | M26: ='SCHWEPPES TONICA 28 UDS'!D8 -> 24.84 | N26: =IFERROR(M26/L26-1,0) -> 0.041946309 | O26: 1 | P26: ENE 23,84 → AGO 24,84 (+4,2%) | Q26: SUBE
A27: ENVASADO / BEBIDA / OTROS | B27: VOLDIS | C27: CASERA LIMON 1L | D27: =IFERROR(INDEX('CASERA LIMON 1L'!$D$7:$D$10,MATCH("ENERO",'CASERA LIMON 1L'!$A$7:$A$10,0)),"") -> 23.64 | E27: =IFERROR(INDEX('CASERA LIMON 1L'!$D$7:$D$10,MATCH("FEBRERO",'CASERA LIMON 1L'!$A$7:$A$10,0)),"") -> 24.61 | H27: =IFERROR(INDEX('CASERA LIMON 1L'!$D$7:$D$10,MATCH("MAYO",'CASERA LIMON 1L'!$A$7:$A$10,0)),"") -> 24.61 | J27: =IFERROR(INDEX('CASERA LIMON 1L'!$D$7:$D$10,MATCH("JULIO",'CASERA LIMON 1L'!$A$7:$A$10,0)),"") -> 24.61 | L27: ='CASERA LIMON 1L'!D7 -> 23.64 | M27: ='CASERA LIMON 1L'!D10 -> 24.61 | N27: =IFERROR(M27/L27-1,0) -> 0.041032149 | O27: 1 | P27: ENE 23,64 → FEB 24,61 (+4,1%) | Q27: SUBE
A28: ENVASADO / BEBIDA / OTROS | B28: VOLDIS | C28: CASERA GASEOSA 1L | D28: =IFERROR(INDEX('CASERA GASEOSA 1L'!$D$7:$D$10,MATCH("ENERO",'CASERA GASEOSA 1L'!$A$7:$A$10,0)),"") -> 20.64 | E28: =IFERROR(INDEX('CASERA GASEOSA 1L'!$D$7:$D$10,MATCH("FEBRERO",'CASERA GASEOSA 1L'!$A$7:$A$10,0)),"") -> 21.48 | H28: =IFERROR(INDEX('CASERA GASEOSA 1L'!$D$7:$D$10,MATCH("MAYO",'CASERA GASEOSA 1L'!$A$7:$A$10,0)),"") -> 21.48 | J28: =IFERROR(INDEX('CASERA GASEOSA 1L'!$D$7:$D$10,MATCH("JULIO",'CASERA GASEOSA 1L'!$A$7:$A$10,0)),"") -> 21.48 | L28: ='CASERA GASEOSA 1L'!D7 -> 20.64 | M28: ='CASERA GASEOSA 1L'!D10 -> 21.48 | N28: =IFERROR(M28/L28-1,0) -> 0.040697674 | O28: 1 | P28: ENE 20,64 → FEB 21,48 (+4,1%) | Q28: SUBE
A29: ENVASADO / BEBIDA / OTROS | B29: DELIPAN | C29: PAN MOLDE BRIOCHE | D29: =IFERROR(INDEX('PAN MOLDE BRIOCHE'!$D$7:$D$12,MATCH("ENERO",'PAN MOLDE BRIOCHE'!$A$7:$A$12,0)),"") -> 84.7 | E29: =IFERROR(INDEX('PAN MOLDE BRIOCHE'!$D$7:$D$12,MATCH("FEBRERO",'PAN MOLDE BRIOCHE'!$A$7:$A$12,0)),"") -> 84.7 | G29: =IFERROR(INDEX('PAN MOLDE BRIOCHE'!$D$7:$D$12,MATCH("ABRIL",'PAN MOLDE BRIOCHE'!$A$7:$A$12,0)),"") -> 88.09 | H29: =IFERROR(INDEX('PAN MOLDE BRIOCHE'!$D$7:$D$12,MATCH("MAYO",'PAN MOLDE BRIOCHE'!$A$7:$A$12,0)),"") -> 88.09 | J29: =IFERROR(INDEX('PAN MOLDE BRIOCHE'!$D$7:$D$12,MATCH("JULIO",'PAN MOLDE BRIOCHE'!$A$7:$A$12,0)),"") -> 88.09 | K29: =IFERROR(INDEX('PAN MOLDE BRIOCHE'!$D$7:$D$12,MATCH("AGOSTO",'PAN MOLDE BRIOCHE'!$A$7:$A$12,0)),"") -> 88.09 | L29: ='PAN MOLDE BRIOCHE'!D7 -> 84.7 | M29: ='PAN MOLDE BRIOCHE'!D12 -> 88.09 | N29: =IFERROR(M29/L29-1,0) -> 0.040023613 | O29: 1 | P29: FEB 84,70 → ABR 88,09 (+4,0%) | Q29: SUBE
A30: ENVASADO / BEBIDA / OTROS | B30: MUNDELA | C30: PACO GARCIA CRIANZA 3/4 | D30: =IFERROR(INDEX('PACO GARCIA CRIANZA 3 4'!$D$7:$D$10,MATCH("ENERO",'PACO GARCIA CRIANZA 3 4'!$A$7:$A$10,0)),"") -> 5.1 | E30: =IFERROR(INDEX('PACO GARCIA CRIANZA 3 4'!$D$7:$D$10,MATCH("FEBRERO",'PACO GARCIA CRIANZA 3 4'!$A$7:$A$10,0)),"") -> 5.1 | H30: =IFERROR(INDEX('PACO GARCIA CRIANZA 3 4'!$D$7:$D$10,MATCH("MAYO",'PACO GARCIA CRIANZA 3 4'!$A$7:$A$10,0)),"") -> 5.3 | K30: =IFERROR(INDEX('PACO GARCIA CRIANZA 3 4'!$D$7:$D$10,MATCH("AGOSTO",'PACO GARCIA CRIANZA 3 4'!$A$7:$A$10,0)),"") -> 5.3 | L30: ='PACO GARCIA CRIANZA 3 4'!D7 -> 5.1 | M30: ='PACO GARCIA CRIANZA 3 4'!D10 -> 5.3 | N30: =IFERROR(M30/L30-1,0) -> 0.039215686 | O30: 1 | P30: FEB 5,10 → MAY 5,30 (+3,9%) | Q30: SUBE
A31: ENVASADO / BEBIDA / OTROS | B31: MUNDELA | C31: RAMON BILBAO BLANCO VERDEJO 3/4 | D31: =IFERROR(INDEX('RAMON BILBAO BLANCO VERDEJO'!$D$7:$D$11,MATCH("ENERO",'RAMON BILBAO BLANCO VERDEJO'!$A$7:$A$11,0)),"") -> 4.5 | E31: =IFERROR(INDEX('RAMON BILBAO BLANCO VERDEJO'!$D$7:$D$11,MATCH("FEBRERO",'RAMON BILBAO BLANCO VERDEJO'!$A$7:$A$11,0)),"") -> 4.5 | H31: =IFERROR(INDEX('RAMON BILBAO BLANCO VERDEJO'!$D$7:$D$11,MATCH("MAYO",'RAMON BILBAO BLANCO VERDEJO'!$A$7:$A$11,0)),"") -> 4.67 | J31: =IFERROR(INDEX('RAMON BILBAO BLANCO VERDEJO'!$D$7:$D$11,MATCH("JULIO",'RAMON BILBAO BLANCO VERDEJO'!$A$7:$A$11,0)),"") -> 4.67 | K31: =IFERROR(INDEX('RAMON BILBAO BLANCO VERDEJO'!$D$7:$D$11,MATCH("AGOSTO",'RAMON BILBAO BLANCO VERDEJO'!$A$7:$A$11,0)),"") -> 4.67 | L31: ='RAMON BILBAO BLANCO VERDEJO'!D7 -> 4.5 | M31: ='RAMON BILBAO BLANCO VERDEJO'!D11 -> 4.67 | N31: =IFERROR(M31/L31-1,0) -> 0.037777778 | O31: 1 | P31: FEB 4,50 → MAY 4,67 (+3,8%) | Q31: SUBE
A32: ENVASADO / BEBIDA / OTROS | B32: DITEMA (DIST. TENA) | C32: GODELLO VINAREDO | D32: =IFERROR(INDEX('GODELLO VINAREDO'!$D$7:$D$11,MATCH("ENERO",'GODELLO VINAREDO'!$A$7:$A$11,0)),"") -> 6.78 | E32: =IFERROR(INDEX('GODELLO VINAREDO'!$D$7:$D$11,MATCH("FEBRERO",'GODELLO VINAREDO'!$A$7:$A$11,0)),"") -> 6.78 | H32: =IFERROR(INDEX('GODELLO VINAREDO'!$D$7:$D$11,MATCH("MAYO",'GODELLO VINAREDO'!$A$7:$A$11,0)),"") -> 7.03 | J32: =IFERROR(INDEX('GODELLO VINAREDO'!$D$7:$D$11,MATCH("JULIO",'GODELLO VINAREDO'!$A$7:$A$11,0)),"") -> 7.03 | K32: =IFERROR(INDEX('GODELLO VINAREDO'!$D$7:$D$11,MATCH("AGOSTO",'GODELLO VINAREDO'!$A$7:$A$11,0)),"") -> 7.03 | L32: ='GODELLO VINAREDO'!D7 -> 6.78 | M32: ='GODELLO VINAREDO'!D11 -> 7.03 | N32: =IFERROR(M32/L32-1,0) -> 0.036873156 | O32: 1 | P32: FEB 6,78 → MAY 7,03 (+3,7%) | Q32: SUBE
A33: ENVASADO / BEBIDA / OTROS | B33: DITEMA (DIST. TENA) | C33: SENORIO FITERO ROBLE | D33: =IFERROR(INDEX('SENORIO FITERO ROBLE'!$D$7:$D$11,MATCH("ENERO",'SENORIO FITERO ROBLE'!$A$7:$A$11,0)),"") -> 2.72 | E33: =IFERROR(INDEX('SENORIO FITERO ROBLE'!$D$7:$D$11,MATCH("FEBRERO",'SENORIO FITERO ROBLE'!$A$7:$A$11,0)),"") -> 2.72 | H33: =IFERROR(INDEX('SENORIO FITERO ROBLE'!$D$7:$D$11,MATCH("MAYO",'SENORIO FITERO ROBLE'!$A$7:$A$11,0)),"") -> 2.82 | J33: =IFERROR(INDEX('SENORIO FITERO ROBLE'!$D$7:$D$11,MATCH("JULIO",'SENORIO FITERO ROBLE'!$A$7:$A$11,0)),"") -> 2.82 | K33: =IFERROR(INDEX('SENORIO FITERO ROBLE'!$D$7:$D$11,MATCH("AGOSTO",'SENORIO FITERO ROBLE'!$A$7:$A$11,0)),"") -> 2.82 | L33: ='SENORIO FITERO ROBLE'!D7 -> 2.72 | M33: ='SENORIO FITERO ROBLE'!D11 -> 2.82 | N33: =IFERROR(M33/L33-1,0) -> 0.036764706 | O33: 1 | P33: FEB 2,72 → MAY 2,82 (+3,7%) | Q33: SUBE
A34: ENVASADO / BEBIDA / OTROS | B34: MUNDELA | C34: CORIMBO | D34: =IFERROR(INDEX(CORIMBO!$D$7:$D$11,MATCH("ENERO",CORIMBO!$A$7:$A$11,0)),"") -> 13.42 | E34: =IFERROR(INDEX(CORIMBO!$D$7:$D$11,MATCH("FEBRERO",CORIMBO!$A$7:$A$11,0)),"") -> 13.42 | H34: =IFERROR(INDEX(CORIMBO!$D$7:$D$11,MATCH("MAYO",CORIMBO!$A$7:$A$11,0)),"") -> 13.91 | J34: =IFERROR(INDEX(CORIMBO!$D$7:$D$11,MATCH("JULIO",CORIMBO!$A$7:$A$11,0)),"") -> 13.91 | K34: =IFERROR(INDEX(CORIMBO!$D$7:$D$11,MATCH("AGOSTO",CORIMBO!$A$7:$A$11,0)),"") -> 13.91 | L34: =CORIMBO!D7 -> 13.42 | M34: =CORIMBO!D11 -> 13.91 | N34: =IFERROR(M34/L34-1,0) -> 0.036512668 | O34: 1 | P34: FEB 13,42 → MAY 13,91 (+3,7%) | Q34: SUBE
A35: ENVASADO / BEBIDA / OTROS | B35: VOLDIS | C35: SCHWEPPES TONICA VIDRIO 20CL | D35: =IFERROR(INDEX('SCHWEPPES TONICA VIDRIO 20CL'!$D$7:$D$10,MATCH("ENERO",'SCHWEPPES TONICA VIDRIO 20CL'!$A$7:$A$10,0)),"") -> 30.8 | E35: =IFERROR(INDEX('SCHWEPPES TONICA VIDRIO 20CL'!$D$7:$D$10,MATCH("FEBRERO",'SCHWEPPES TONICA VIDRIO 20CL'!$A$7:$A$10,0)),"") -> 31.92 | H35: =IFERROR(INDEX('SCHWEPPES TONICA VIDRIO 20CL'!$D$7:$D$10,MATCH("MAYO",'SCHWEPPES TONICA VIDRIO 20CL'!$A$7:$A$10,0)),"") -> 31.92 | J35: =IFERROR(INDEX('SCHWEPPES TONICA VIDRIO 20CL'!$D$7:$D$10,MATCH("JULIO",'SCHWEPPES TONICA VIDRIO 20CL'!$A$7:$A$10,0)),"") -> 31.92 | L35: ='SCHWEPPES TONICA VIDRIO 20CL'!D7 -> 30.8 | M35: ='SCHWEPPES TONICA VIDRIO 20CL'!D10 -> 31.92 | N35: =IFERROR(M35/L35-1,0) -> 0.036363636 | O35: 1 | P35: ENE 30,80 → FEB 31,92 (+3,6%) | Q35: SUBE
A36: ENVASADO / BEBIDA / OTROS | B36: MUNDELA | C36: RODA RESERVA 3/4 | D36: =IFERROR(INDEX('RODA RESERVA 3 4'!$D$7:$D$10,MATCH("ENERO",'RODA RESERVA 3 4'!$A$7:$A$10,0)),"") -> 20.63 | E36: =IFERROR(INDEX('RODA RESERVA 3 4'!$D$7:$D$10,MATCH("FEBRERO",'RODA RESERVA 3 4'!$A$7:$A$10,0)),"") -> 20.63 | H36: =IFERROR(INDEX('RODA RESERVA 3 4'!$D$7:$D$10,MATCH("MAYO",'RODA RESERVA 3 4'!$A$7:$A$10,0)),"") -> 21.38 | J36: =IFERROR(INDEX('RODA RESERVA 3 4'!$D$7:$D$10,MATCH("JULIO",'RODA RESERVA 3 4'!$A$7:$A$10,0)),"") -> 21.38 | L36: ='RODA RESERVA 3 4'!D7 -> 20.63 | M36: ='RODA RESERVA 3 4'!D10 -> 21.38 | N36: =IFERROR(M36/L36-1,0) -> 0.036354823 | O36: 1 | P36: FEB 20,63 → MAY 21,38 (+3,6%) | Q36: SUBE
A37: ENVASADO / BEBIDA / OTROS | B37: DITEMA (DIST. TENA) | C37: ALBARINO MAR FRADES | D37: =IFERROR(INDEX('ALBARINO MAR FRADES'!$D$7:$D$11,MATCH("ENERO",'ALBARINO MAR FRADES'!$A$7:$A$11,0)),"") -> 11.02 | E37: =IFERROR(INDEX('ALBARINO MAR FRADES'!$D$7:$D$11,MATCH("FEBRERO",'ALBARINO MAR FRADES'!$A$7:$A$11,0)),"") -> 11.02 | H37: =IFERROR(INDEX('ALBARINO MAR FRADES'!$D$7:$D$11,MATCH("MAYO",'ALBARINO MAR FRADES'!$A$7:$A$11,0)),"") -> 11.42 | J37: =IFERROR(INDEX('ALBARINO MAR FRADES'!$D$7:$D$11,MATCH("JULIO",'ALBARINO MAR FRADES'!$A$7:$A$11,0)),"") -> 11.42 | K37: =IFERROR(INDEX('ALBARINO MAR FRADES'!$D$7:$D$11,MATCH("AGOSTO",'ALBARINO MAR FRADES'!$A$7:$A$11,0)),"") -> 11.42 | L37: ='ALBARINO MAR FRADES'!D7 -> 11.02 | M37: ='ALBARINO MAR FRADES'!D11 -> 11.42 | N37: =IFERROR(M37/L37-1,0) -> 0.036297641 | O37: 1 | P37: FEB 11,02 → MAY 11,42 (+3,6%) | Q37: SUBE
A38: ENVASADO / BEBIDA / OTROS | B38: MUNDELA | C38: VINA MAYOR VERDEJO | D38: =IFERROR(INDEX('VINA MAYOR VERDEJO'!$D$7:$D$9,MATCH("ENERO",'VINA MAYOR VERDEJO'!$A$7:$A$9,0)),"") -> 5.88 | E38: =IFERROR(INDEX('VINA MAYOR VERDEJO'!$D$7:$D$9,MATCH("FEBRERO",'VINA MAYOR VERDEJO'!$A$7:$A$9,0)),"") -> 5.88 | H38: =IFERROR(INDEX('VINA MAYOR VERDEJO'!$D$7:$D$9,MATCH("MAYO",'VINA MAYOR VERDEJO'!$A$7:$A$9,0)),"") -> 6.08 | L38: ='VINA MAYOR VERDEJO'!D7 -> 5.88 | M38: ='VINA MAYOR VERDEJO'!D9 -> 6.08 | N38: =IFERROR(M38/L38-1,0) -> 0.034013605 | O38: 1 | P38: FEB 5,88 → MAY 6,08 (+3,4%) | Q38: SUBE
A39: ENVASADO / BEBIDA / OTROS | B39: VOLDIS | C39: SEVEN UP FREE VIDRIO 20CL | D39: =IFERROR(INDEX('SEVEN UP FREE VIDRIO 20CL'!$D$7:$D$9,MATCH("ENERO",'SEVEN UP FREE VIDRIO 20CL'!$A$7:$A$9,0)),"") -> 22.56 | E39: =IFERROR(INDEX('SEVEN UP FREE VIDRIO 20CL'!$D$7:$D$9,MATCH("FEBRERO",'SEVEN UP FREE VIDRIO 20CL'!$A$7:$A$9,0)),"") -> 23.28 | H39: =IFERROR(INDEX('SEVEN UP FREE VIDRIO 20CL'!$D$7:$D$9,MATCH("MAYO",'SEVEN UP FREE VIDRIO 20CL'!$A$7:$A$9,0)),"") -> 23.28 | L39: ='SEVEN UP FREE VIDRIO 20CL'!D7 -> 22.56 | M39: ='SEVEN UP FREE VIDRIO 20CL'!D9 -> 23.28 | N39: =IFERROR(M39/L39-1,0) -> 0.031914894 | O39: 1 | P39: ENE 22,56 → FEB 23,28 (+3,2%) | Q39: SUBE
A40: ENVASADO / BEBIDA / OTROS | B40: VOLDIS | C40: LIPTON ZERO LIMON VIDRIO 35CL | D40: =IFERROR(INDEX('LIPTON ZERO LIMON VIDRIO 35C'!$D$7:$D$10,MATCH("ENERO",'LIPTON ZERO LIMON VIDRIO 35C'!$A$7:$A$10,0)),"") -> 31.92 | E40: =IFERROR(INDEX('LIPTON ZERO LIMON VIDRIO 35C'!$D$7:$D$10,MATCH("FEBRERO",'LIPTON ZERO LIMON VIDRIO 35C'!$A$7:$A$10,0)),"") -> 32.88 | H40: =IFERROR(INDEX('LIPTON ZERO LIMON VIDRIO 35C'!$D$7:$D$10,MATCH("MAYO",'LIPTON ZERO LIMON VIDRIO 35C'!$A$7:$A$10,0)),"") -> 32.88 | J40: =IFERROR(INDEX('LIPTON ZERO LIMON VIDRIO 35C'!$D$7:$D$10,MATCH("JULIO",'LIPTON ZERO LIMON VIDRIO 35C'!$A$7:$A$10,0)),"") -> 32.88 | L40: ='LIPTON ZERO LIMON VIDRIO 35C'!D7 -> 31.92 | M40: ='LIPTON ZERO LIMON VIDRIO 35C'!D10 -> 32.88 | N40: =IFERROR(M40/L40-1,0) -> 0.030075188 | O40: 1 | P40: ENE 31,92 → FEB 32,88 (+3,0%) | Q40: SUBE
A41: ENVASADO / BEBIDA / OTROS | B41: MUNDELA | C41: R B EDI LIM EARLY HARVEST ROSADO | D41: =IFERROR(INDEX('R B EDI LIM EARLY HARVEST RO'!$D$7:$D$10,MATCH("ENERO",'R B EDI LIM EARLY HARVEST RO'!$A$7:$A$10,0)),"") -> 7.69 | E41: =IFERROR(INDEX('R B EDI LIM EARLY HARVEST RO'!$D$7:$D$10,MATCH("FEBRERO",'R B EDI LIM EARLY HARVEST RO'!$A$7:$A$10,0)),"") -> 7.69 | H41: =IFERROR(INDEX('R B EDI LIM EARLY HARVEST RO'!$D$7:$D$10,MATCH("MAYO",'R B EDI LIM EARLY HARVEST RO'!$A$7:$A$10,0)),"") -> 7.88 | J41: =IFERROR(INDEX('R B EDI LIM EARLY HARVEST RO'!$D$7:$D$10,MATCH("JULIO",'R B EDI LIM EARLY HARVEST RO'!$A$7:$A$10,0)),"") -> 7.88 | L41: ='R B EDI LIM EARLY HARVEST RO'!D7 -> 7.69 | M41: ='R B EDI LIM EARLY HARVEST RO'!D10 -> 7.88 | N41: =IFERROR(M41/L41-1,0) -> 0.024707412 | O41: 1 | P41: FEB 7,69 → MAY 7,88 (+2,5%) | Q41: SUBE
A42: ENVASADO / BEBIDA / OTROS | B42: DITEMA (DIST. TENA) | C42: POMMERY ROYAL BRUT 3/4 | D42: =IFERROR(INDEX('POMMERY ROYAL BRUT 3 4'!$D$7:$D$9,MATCH("ENERO",'POMMERY ROYAL BRUT 3 4'!$A$7:$A$9,0)),"") -> 35.49 | E42: =IFERROR(INDEX('POMMERY ROYAL BRUT 3 4'!$D$7:$D$9,MATCH("FEBRERO",'POMMERY ROYAL BRUT 3 4'!$A$7:$A$9,0)),"") -> 35.49 | H42: =IFERROR(INDEX('POMMERY ROYAL BRUT 3 4'!$D$7:$D$9,MATCH("MAYO",'POMMERY ROYAL BRUT 3 4'!$A$7:$A$9,0)),"") -> 36.35 | L42: ='POMMERY ROYAL BRUT 3 4'!D7 -> 35.49 | M42: ='POMMERY ROYAL BRUT 3 4'!D9 -> 36.35 | N42: =IFERROR(M42/L42-1,0) -> 0.024232178 | O42: 1 | P42: FEB 35,49 → MAY 36,35 (+2,4%) | Q42: SUBE
A43: ENVASADO / BEBIDA / OTROS | B43: DITEMA (DIST. TENA) | C43: GODELLO MAR FRADES | E43: =IFERROR(INDEX('GODELLO MAR FRADES'!$D$7:$D$8,MATCH("FEBRERO",'GODELLO MAR FRADES'!$A$7:$A$8,0)),"") -> 17.63 | H43: =IFERROR(INDEX('GODELLO MAR FRADES'!$D$7:$D$8,MATCH("MAYO",'GODELLO MAR FRADES'!$A$7:$A$8,0)),"") -> 18.03 | L43: ='GODELLO MAR FRADES'!D7 -> 17.63 | M43: ='GODELLO MAR FRADES'!D8 -> 18.03 | N43: =IFERROR(M43/L43-1,0) -> 0.022688599 | O43: 1 | P43: FEB 17,63 → MAY 18,03 (+2,3%) | Q43: SUBE
...

Sheet TODOS LOS PRODUCTOS
A1: TODOS LOS PRODUCTOS COMPRADOS EN 2 O MÁS MESES · PRECIO MEDIO UNITARIO POR MES
A3: CATEGORÍA | B3: PROVEEDOR | C3: PRODUCTO | D3: ENERO | E3: FEBRERO | F3: MARZO | G3: ABRIL | H3: MAYO | I3: JULIO | J3: AGOSTO | K3: PRIMER PRECIO | L3: ÚLTIMO PRECIO | M3: VARIACIÓN % | N3: ESTADO
A4: CARNE | B4: AGROFOOD | C4: CAJAS CERDO IBERICO | D4: 1 | G4: 1 | H4: 1 | K4: 1 | L4: 1 | M4: =IFERROR(L4/K4-1,0) -> 0 | N4: ESTABLE
A5: CARNE | B5: AGROFOOD | C5: DESMIGADA COLA TORO EN SU JUGO A BA | G5: 28.5 | H5: 28.5 | K5: 28.5 | L5: 28.5 | M5: =IFERROR(L5/K5-1,0) -> 0 | N5: ESTABLE
A6: CARNE | B6: AGROFOOD | C6: ENTRECOT T MORUCHA | D6: 27.5 | E6: 27.5 | G6: 27.5 | H6: 27.5 | I6: 27.5 | J6: 27.57 | K6: 27.5 | L6: 27.57 | M6: =IFERROR(L6/K6-1,0) -> 0.0025454545 | N6: SUBE
A7: CARNE | B7: AGROFOOD | C7: MEDALLON P SOLOMILLO VACUNO | D7: 36.9 | E7: 36.9 | G7: 36.9 | H7: 36.9 | I7: 36.9 | J7: 36.97 | K7: 36.9 | L7: 36.97 | M7: =IFERROR(L7/K7-1,0) -> 0.001897019 | N7: SUBE
A8: CARNE | B8: CARNICAS MEAT | C8: CHULETA CORDERO | H8: 25 | I8: 25 | J8: 25 | K8: 25 | L8: 25 | M8: =IFERROR(L8/K8-1,0) -> 0 | N8: ESTABLE
A9: CARNE | B9: CARNICAS MEAT | C9: SOLOMILLO VACA | H9: 35 | I9: 34.775 | J9: 35 | K9: 35 | L9: 35 | M9: =IFERROR(L9/K9-1,0) -> 0 | N9: SUBIDA INTERMEDIA
A10: CARNE | B10: CARNICAS MEAT | C10: TERNERA MIXTA | H10: 11.81 | I10: 10.9 | K10: 11.81 | L10: 10.9 | M10: =IFERROR(L10/K10-1,0) -> -0.077053345 | N10: BAJA
A11: CARNE | B11: CARNICAS OPC / CRNAS SERVAN | C11: CHORIZO ASTURIANO | E11: 9 | G11: 9 | I11: 9 | K11: 9 | L11: 9 | M11: =IFERROR(L11/K11-1,0) -> 0 | N11: ESTABLE
A12: CARNE | B12: CARNICAS OPC / CRNAS SERVAN | C12: FALDA TERNERA | D12: 11.5 | E12: 11.5 | G12: 11.5 | J12: 11.5 | K12: 11.5 | L12: 11.5 | M12: =IFERROR(L12/K12-1,0) -> 0 | N12: ESTABLE
A13: CARNE | B13: CARNICAS OPC / CRNAS SERVAN | C13: GALLINAS | G13: 3.75 | I13: 3.75 | K13: 3.75 | L13: 3.75 | M13: =IFERROR(L13/K13-1,0) -> 0 | N13: ESTABLE
A14: CARNE | B14: CARNICAS OPC / CRNAS SERVAN | C14: HUESO FRESCO | D14: 2 | E14: 2 | G14: 2 | J14: 2 | K14: 2 | L14: 2 | M14: =IFERROR(L14/K14-1,0) -> 0 | N14: ESTABLE
A15: CARNE | B15: CARNICAS OPC / CRNAS SERVAN | C15: HUESOS JAMON | E15: 4.5 | G15: 4.5 | K15: 4.5 | L15: 4.5 | M15: =IFERROR(L15/K15-1,0) -> 0 | N15: ESTABLE
A16: CARNE | B16: CARNICAS OPC / CRNAS SERVAN | C16: HUEVOS CORRAL | D16: 52.5 | E16: 52.5 | G16: 52.5 | H16: 52.5 | I16: 52.5 | J16: 52.5 | K16: 52.5 | L16: 52.5 | M16: =IFERROR(L16/K16-1,0) -> 0 | N16: ESTABLE
A17: CARNE | B17: CARNICAS OPC / CRNAS SERVAN | C17: MANOS CERDO | D17: 4.5 | E17: 4.5 | G17: 4.5 | I17: 4.5 | K17: 4.5 | L17: 4.5 | M17: =IFERROR(L17/K17-1,0) -> 0 | N17: ESTABLE
A18: CARNE | B18: CARNICAS OPC / CRNAS SERVAN | C18: MEDIA HUERVO | I18: 45 | J18: 45 | K18: 45 | L18: 45 | M18: =IFERROR(L18/K18-1,0) -> 0 | N18: ESTABLE
A19: CARNE | B19: CARNICAS OPC / CRNAS SERVAN | C19: MEDIA HUEVO | D19: 45 | E19: 45 | G19: 45 | H19: 45 | I19: 45 | K19: 45 | L19: 45 | M19: =IFERROR(L19/K19-1,0) -> 0 | N19: ESTABLE
A20: CARNE | B20: CARNICAS OPC / CRNAS SERVAN | C20: MORCILLA ASTURIANA | E20: 8 | G20: 8 | J20: 9 | K20: 8 | L20: 9 | M20: =IFERROR(L20/K20-1,0) -> 0.125 | N20: SUBE
A21: CARNE | B21: CARNICAS OPC / CRNAS SERVAN | C21: MORCILLO TERNERA | D21: 12.5 | E21: 12.5 | G21: 12.5 | I21: 12.5 | K21: 12.5 | L21: 12.5 | M21: =IFERROR(L21/K21-1,0) -> 0 | N21: ESTABLE
A22: CARNE | B22: CARNICAS OPC / CRNAS SERVAN | C22: MORRO TERNERA | D22: 8.5 | E22: 8.5 | G22: 8.5 | I22: 8.5 | J22: 8.5 | K22: 8.5 | L22: 8.5 | M22: =IFERROR(L22/K22-1,0) -> 0 | N22: ESTABLE
A23: CARNE | B23: CARNICAS OPC / CRNAS SERVAN | C23: OREJA CERDO | D23: 6 | E23: 6 | G23: 6 | H23: 6 | I23: 6 | J23: 6 | K23: 6 | L23: 6 | M23: =IFERROR(L23/K23-1,0) -> 0 | N23: ESTABLE
A24: CARNE | B24: CARNICAS OPC / CRNAS SERVAN | C24: PANCETA ADOBADA | D24: 8.8 | E24: 8.8 | G24: 8.8 | H24: 8.8 | I24: 8.8 | J24: 8.8 | K24: 8.8 | L24: 8.8 | M24: =IFERROR(L24/K24-1,0) -> 0 | N24: ESTABLE
A25: CARNE | B25: CARNICAS OPC / CRNAS SERVAN | C25: PANCETA FRESCA | E25: 7 | G25: 7 | K25: 7 | L25: 7 | M25: =IFERROR(L25/K25-1,0) -> 0 | N25: ESTABLE
A26: CARNE | B26: CARNICAS OPC / CRNAS SERVAN | C26: PATA TERNERA 2 | D26: 8.5 | E26: 8.5 | G26: 8.5 | I26: 8.5 | J26: 8.5 | K26: 8.5 | L26: 8.5 | M26: =IFERROR(L26/K26-1,0) -> 0 | N26: ESTABLE
A27: CARNE | B27: CARNICAS OPC / CRNAS SERVAN | C27: PECHUGA POLLO | E27: 6.5 | G27: 6.5 | K27: 6.5 | L27: 6.5 | M27: =IFERROR(L27/K27-1,0) -> 0 | N27: ESTABLE
A28: CARNE | B28: CARNICAS OPC / CRNAS SERVAN | C28: PICADA MIXTA | E28: 7.5 | G28: 7.5 | K28: 7.5 | L28: 7.5 | M28: =IFERROR(L28/K28-1,0) -> 0 | N28: ESTABLE
A29: CARNE | B29: CARNICAS OPC / CRNAS SERVAN | C29: POLLO ENTERO | E29: 3.5 | G29: 3.5 | I29: 3.5 | K29: 3.5 | L29: 3.5 | M29: =IFERROR(L29/K29-1,0) -> 0 | N29: ESTABLE
A30: CARNE | B30: CARNICAS OPC / CRNAS SERVAN | C30: POLLO TROCEADO | D30: 3.5 | E30: 3.5 | G30: 3.5 | H30: 3.5 | I30: 3.5 | K30: 3.5 | L30: 3.5 | M30: =IFERROR(L30/K30-1,0) -> 0 | N30: ESTABLE
A31: CARNE | B31: CARNICAS OPC / CRNAS SERVAN | C31: TOCINO IBERICO | E31: 5 | G31: 5 | K31: 5 | L31: 5 | M31: =IFERROR(L31/K31-1,0) -> 0 | N31: ESTABLE
A32: CARNE | B32: PEÑALASTALLAS | C32: MOLLEJAS CERDO | D32: 27.9 | E32: 27.9 | G32: 27.9 | H32: 27.9 | K32: 27.9 | L32: 27.9 | M32: =IFERROR(L32/K32-1,0) -> 0 | N32: ESTABLE
A33: CARNE | B33: PEÑALASTALLAS | C33: MOLLEJAS CORDERO | E33: 27.9 | G33: 27.9 | H33: 27.9 | I33: 27.9 | J33: 27.9 | K33: 27.9 | L33: 27.9 | M33: =IFERROR(L33/K33-1,0) -> 0 | N33: ESTABLE
A34: CARNE | B34: PEÑALASTALLAS | C34: PINCHO MORUNO POLLO | D34: 8.95 | E34: 8.9 | G34: 8.9 | H34: 8.9 | I34: 8.9 | J34: 8.9 | K34: 8.95 | L34: 8.9 | M34: =IFERROR(L34/K34-1,0) -> -0.0055865922 | N34: BAJA
A35: CARNE | B35: PEÑALASTALLAS | C35: PINCHOS MORUNOS | D35: 8.9 | E35: 8.9 | G35: 8.9 | H35: 8.9 | I35: 8.9 | J35: 8.9 | K35: 8.9 | L35: 8.9 | M35: =IFERROR(L35/K35-1,0) -> 0 | N35: ESTABLE
A36: CARNE | B36: ROMERO ALVAREZ | C36: PRESA 100 IBERICA | G36: 25.2 | I36: 25.2 | J36: 25.2 | K36: 25.2 | L36: 25.2 | M36: =IFERROR(L36/K36-1,0) -> 0 | N36: ESTABLE
A37: CARNE | B37: VENERO CLARO (CHAPTER ONE) | C37: LOMO VACA VENERO CLARO C/H | D37: 26 | E37: 26 | G37: 26 | H37: 26 | I37: 26 | J37: 26 | K37: 26 | L37: 26 | M37: =IFERROR(L37/K37-1,0) -> 0 | N37: ESTABLE
A38: ENVASADO / BEBIDA / OTROS | B38: ANTONIO DE MIGUEL | C38: PATO CEBADO FOIE RESTAURACION | D38: 28.03 | E38: 28.03 | G38: 28.03 | H38: 28.03 | I38: 28.03 | K38: 28.03 | L38: 28.03 | M38: =IFERROR(L38/K38-1,0) -> 0 | N38: ESTABLE
A39: ENVASADO / BEBIDA / OTROS | B39: CALIDOSCOPI | C39: OREMUS 3 | D39: 27.4 | H39: 29.25 | K39: 27.4 | L39: 29.25 | M39: =IFERROR(L39/K39-1,0) -> 0.067518248 | N39: SUBE
A40: ENVASADO / BEBIDA / OTROS | B40: CALIDOSCOPI | C40: PAGO CARRAOVEJAS 2023 | D40: 28.25 | E40: 28.25 | H40: 28.25 | I40: 28.25 | K40: 28.25 | L40: 28.25 | M40: =IFERROR(L40/K40-1,0) -> 0 | N40: ESTABLE
A41: ENVASADO / BEBIDA / OTROS | B41: CALIDOSCOPI | C41: ROMANICO 2023 | E41: 7.85 | H41: 7.85 | K41: 7.85 | L41: 7.85 | M41: =IFERROR(L41/K41-1,0) -> 0 | N41: ESTABLE
...

Sheet NOTAS
A1: NOTAS Y CRITERIOS
A3: Fuentes: ALBARANES ENERO/FEBRERO/ABRIL/MAYO 2026 (raíz 2026, de Adri), ALBARANES JULIO 2026 v3 y ALBARANES AGOSTO 2026 v1 (3t).
A5: Marzo: no hay Excel de marzo; solo aparecen 2 precios sueltos de Vins des Dieux. Junio: el archivo "ALBARANES JUNIO 2026" es una copia de mayo sin datos propios de junio, por eso no se usa.
A7: Precio comparado: precio unitario del albarán (P/U), sin IVA y antes de descuento. Si en un mes hay varios precios se usa la media, y en la hoja del producto se ven mínimo, medio y máximo.
A9: Coca-Cola: en julio el precio está por botella y en agosto por caja; los de agosto se han pasado a precio por botella (caja ÷ 24, PET 2L ÷ 6) para poder compararlos.
A11: Agrofood: desde julio/agosto el precio lleva sumado el "MER" (0,07 €/kg); se compara tal cual porque es lo que se paga.
A13: Se agrupan nombres del mismo producto escritos de forma distinta (p. ej. "ANCHOAS CANTABRICO COSTERA" y "... CESMAR PREMIUM 65/70"). No se mezclan variedades (zero/light, limón/naranja...).
A15: No se incluyen tasas de residuos, envases, portes, servicios logísticos, abonos ni regalos.
A17: Criterio SUBIDA: envasados, bebidas y carne → cualquier subida del precio medio entre el primer y el último mes con compras. Frescos (marisco, pescado, fruta y verdura) → solo si la media del último mes supera en más de un 10 % a la del primero; si varía más de un 15 % pero sin tendencia se marca FLUCTÚA.
A19: Cada mes, al cerrar el Excel de albaranes, se actualizará este comparativo con el nuevo mes.

Sheet MORCILLA ASTURIANA
A1: MORCILLA ASTURIANA | I1: ← Volver al resumen
A2: Proveedor: CARNICAS OPC / CRNAS SERVAN · Categoría: CARNE
A3: Nombres en albaranes: MORCILLA ASTURIANA
A4: Producto envasado / tarifa: cualquier subida de precio unitario entre el primer y el último mes con compras se considera SUBIDA.
A6: MES | B6: Nº PRECIOS | C6: PRECIO MÍN. | D6: PRECIO MEDIO | E6: PRECIO MÁX. | F6: VAR. vs MES ANTERIOR | G6: VAR. vs PRIMER MES
A7: FEBRERO | B7: =COUNTIF($A$14:$A$16,A7) -> 1 | C7: =_xlfn.MINIFS($B$14:$B$16,$A$14:$A$16,A7) -> 8 | D7: =AVERAGEIF($A$14:$A$16,A7,$B$14:$B$16) -> 8 | E7: =_xlfn.MAXIFS($B$14:$B$16,$A$14:$A$16,A7) -> 8
A8: ABRIL | B8: =COUNTIF($A$14:$A$16,A8) -> 1 | C8: =_xlfn.MINIFS($B$14:$B$16,$A$14:$A$16,A8) -> 8 | D8: =AVERAGEIF($A$14:$A$16,A8,$B$14:$B$16) -> 8 | E8: =_xlfn.MAXIFS($B$14:$B$16,$A$14:$A$16,A8) -> 8 | F8: =D8/D7-1 -> 0 | G8: =D8/$D$7-1 -> 0
A9: AGOSTO | B9: =COUNTIF($A$14:$A$16,A9) -> 1 | C9: =_xlfn.MINIFS($B$14:$B$16,$A$14:$A$16,A9) -> 9 | D9: =AVERAGEIF($A$14:$A$16,A9,$B$14:$B$16) -> 9 | E9: =_xlfn.MAXIFS($B$14:$B$16,$A$14:$A$16,A9) -> 9 | F9: =D9/D8-1 -> 0.125 | G9: =D9/$D$7-1 -> 0.125
F10: SUBIDA TOTAL | G10: =D9/D7-1 -> 0.125
A12: DETALLE DE PRECIOS (una línea por precio distinto anotado en el Excel del mes)
A13: MES | B13: PRECIO | C13: CANTIDAD | D13: PRODUCTO (tal cual en el Excel) | E13: ARCHIVO ORIGEN
A14: FEBRERO | B14: 8 | C14: 3 | D14: MORCILLA ASTURIANA | E14: ALBARANES MAYO 2026
A15: ABRIL | B15: 8 | D15: MORCILLA ASTURIANA | E15: ALBARANES MAYO 2026
A16: AGOSTO | B16: 9 | C16: 8.6 | D16: MORCILLA ASTURIANA | E16: ALBARANES AGOSTO 2026 v1

Sheet CANTALAPIEDRA CHIVIRITERO 20
A1: CANTALAPIEDRA CHIVIRITERO 2023 | I1: ← Volver al resumen
A2: Proveedor: VINS DES DIEUX · Categoría: ENVASADO / BEBIDA / OTROS
A3: Nombres en albaranes: CANTALAPIEDRA CHIVIRITERO 2023 | CANTALAPIEDRA CHIVIRITERO 2024
A4: Producto envasado / tarifa: cualquier subida de precio unitario entre el primer y el último mes con compras se considera SUBIDA.
A6: MES | B6: Nº PRECIOS | C6: PRECIO MÍN. | D6: PRECIO MEDIO | E6: PRECIO MÁX. | F6: VAR. vs MES ANTERIOR | G6: VAR. vs PRIMER MES
A7: FEBRERO | B7: =COUNTIF($A$16:$A$20,A7) -> 1 | C7: =_xlfn.MINIFS($B$16:$B$20,$A$16:$A$20,A7) -> 15.5 | D7: =AVERAGEIF($A$16:$A$20,A7,$B$16:$B$20) -> 15.5 | E7: =_xlfn.MAXIFS($B$16:$B$20,$A$16:$A$20,A7) -> 15.5
A8: MARZO | B8: =COUNTIF($A$16:$A$20,A8) -> 1 | C8: =_xlfn.MINIFS($B$16:$B$20,$A$16:$A$20,A8) -> 15.5 | D8: =AVERAGEIF($A$16:$A$20,A8,$B$16:$B$20) -> 15.5 | E8: =_xlfn.MAXIFS($B$16:$B$20,$A$16:$A$20,A8) -> 15.5 | F8: =D8/D7-1 -> 0 | G8: =D8/$D$7-1 -> 0
A9: ABRIL | B9: =COUNTIF($A$16:$A$20,A9) -> 1 | C9: =_xlfn.MINIFS($B$16:$B$20,$A$16:$A$20,A9) -> 15.5 | D9: =AVERAGEIF($A$16:$A$20,A9,$B$16:$B$20) -> 15.5 | E9: =_xlfn.MAXIFS($B$16:$B$20,$A$16:$A$20,A9) -> 15.5 | F9: =D9/D8-1 -> 0 | G9: =D9/$D$7-1 -> 0
A10: MAYO | B10: =COUNTIF($A$16:$A$20,A10) -> 1 | C10: =_xlfn.MINIFS($B$16:$B$20,$A$16:$A$20,A10) -> 16.9 | D10: =AVERAGEIF($A$16:$A$20,A10,$B$16:$B$20) -> 16.9 | E10: =_xlfn.MAXIFS($B$16:$B$20,$A$16:$A$20,A10) -> 16.9 | F10: =D10/D9-1 -> 0.090322581 | G10: =D10/$D$7-1 -> 0.090322581
A11: JULIO | B11: =COUNTIF($A$16:$A$20,A11) -> 1 | C11: =_xlfn.MINIFS($B$16:$B$20,$A$16:$A$20,A11) -> 16.9 | D11: =AVERAGEIF($A$16:$A$20,A11,$B$16:$B$20) -> 16.9 | E11: =_xlfn.MAXIFS($B$16:$B$20,$A$16:$A$20,A11) -> 16.9 | F11: =D11/D10-1 -> 0 | G11: =D11/$D$7-1 -> 0.090322581
F12: SUBIDA TOTAL | G12: =D11/D7-1 -> 0.090322581
A14: DETALLE DE PRECIOS (una línea por precio distinto anotado en el Excel del mes)
A15: MES | B15: PRECIO | C15: CANTIDAD | D15: PRODUCTO (tal cual en el Excel) | E15: ARCHIVO ORIGEN
A16: FEBRERO | B16: 15.5 | C16: 6 | D16: CANTALAPIEDRA CHIVIRITERO 2023 | E16: ALBARANES MAYO 2026
A17: MARZO | B17: 15.5 | D17: CANTALAPIEDRA CHIVIRITERO 2023 | E17: ALBARANES MAYO 2026
A18: ABRIL | B18: 15.5 | D18: CANTALAPIEDRA CHIVIRITERO 2023 | E18: ALBARANES MAYO 2026
A19: MAYO | B19: 16.9 | C19: 12 | D19: CANTALAPIEDRA CHIVIRITERO 2023 | E19: ALBARANES MAYO 2026
A20: JULIO | B20: 16.9 | C20: 12 | D20: CANTALAPIEDRA CHIVIRITERO 2024 | E20: ALBARANES JULIO 2026 v3

Sheet ANCHOAS CANTABRICO RO 550 ET
A1: ANCHOAS CANTABRICO RO 550 ETIQUETA ROJA | I1: ← Volver al resumen
A2: Proveedor: CONSERVAS Y SALAZONES JIMENEZ · Categoría: ENVASADO / BEBIDA / OTROS
A3: Nombres en albaranes: ANCHOAS CANTABRICO RO-550 ETIQUETA ROJA | ANCHOAS CANTABRICO RO-550 ETIQUETA ROJA REZUMAR
A4: Producto envasado / tarifa: cualquier subida de precio unitario entre el primer y el último mes con compras se considera SUBIDA.
A6: MES | B6: Nº PRECIOS | C6: PRECIO MÍN. | D6: PRECIO MEDIO | E6: PRECIO MÁX. | F6: VAR. vs MES ANTERIOR | G6: VAR. vs PRIMER MES
A7: FEBRERO | B7: =COUNTIF($A$15:$A$18,A7) -> 1 | C7: =_xlfn.MINIFS($B$15:$B$18,$A$15:$A$18,A7) -> 18.96 | D7: =AVERAGEIF($A$15:$A$18,A7,$B$15:$B$18) -> 18.96 | E7: =_xlfn.MAXIFS($B$15:$B$18,$A$15:$A$18,A7) -> 18.96
A8: ABRIL | B8: =COUNTIF($A$15:$A$18,A8) -> 1 | C8: =_xlfn.MINIFS($B$15:$B$18,$A$15:$A$18,A8) -> 18.96 | D8: =AVERAGEIF($A$15:$A$18,A8,$B$15:$B$18) -> 18.96 | E8: =_xlfn.MAXIFS($B$15:$B$18,$A$15:$A$18,A8) -> 18.96 | F8: =D8/D7-1 -> 0 | G8: =D8/$D$7-1 -> 0
A9: MAYO | B9: =COUNTIF($A$15:$A$18,A9) -> 1 | C9: =_xlfn.MINIFS($B$15:$B$18,$A$15:$A$18,A9) -> 20.6 | D9: =AVERAGEIF($A$15:$A$18,A9,$B$15:$B$18) -> 20.6 | E9: =_xlfn.MAXIFS($B$15:$B$18,$A$15:$A$18,A9) -> 20.6 | F9: =D9/D8-1 -> 0.08649789 | G9: =D9/$D$7-1 -> 0.08649789
A10: JULIO | B10: =COUNTIF($A$15:$A$18,A10) -> 1 | C10: =_xlfn.MINIFS($B$15:$B$18,$A$15:$A$18,A10) -> 20.6 | D10: =AVERAGEIF($A$15:$A$18,A10,$B$15:$B$18) -> 20.6 | E10: =_xlfn.MAXIFS($B$15:$B$18,$A$15:$A$18,A10) -> 20.6 | F10: =D10/D9-1 -> 0 | G10: =D10/$D$7-1 -> 0.08649789
F11: SUBIDA TOTAL | G11: =D10/D7-1 -> 0.08649789
A13: DETALLE DE PRECIOS (una línea por precio distinto anotado en el Excel del mes)
A14: MES | B14: PRECIO | C14: CANTIDAD | D14: PRODUCTO (tal cual en el Excel) | E14: ARCHIVO ORIGEN
A15: FEBRERO | B15: 18.96 | C15: 12 | D15: ANCHOAS CANTABRICO RO-550 ETIQUETA ROJA REZUMAR | E15: ALBARANES MAYO 2026
A16: ABRIL | B16: 18.96 | D16: ANCHOAS CANTABRICO RO-550 ETIQUETA ROJA REZUMAR | E16: ALBARANES MAYO 2026
A17: MAYO | B17: 20.6 | C17: 12 | D17: ANCHOAS CANTABRICO RO-550 ETIQUETA ROJA REZUMAR | E17: ALBARANES MAYO 2026
A18: JULIO | B18: 20.6 | C18: 18 | D18: ANCHOAS CANTABRICO RO-550 ETIQUETA ROJA | E18: ALBARANES JULIO 2026 v3

Sheet ZACAPA X O
A1: ZACAPA X O | I1: ← Volver al resumen
A2: Proveedor: SUBMARINER · Categoría: ENVASADO / BEBIDA / OTROS
A3: Nombres en albaranes: ACAPA X.O. | ZACAPA X.O.
A4: Producto envasado / tarifa: cualquier subida de precio unitario entre el primer y el último mes con compras se considera SUBIDA.
A6: MES | B6: Nº PRECIOS | C6: PRECIO MÍN. | D6: PRECIO MEDIO | E6: PRECIO MÁX. | F6: VAR. vs MES ANTERIOR | G6: VAR. vs PRIMER MES
A7: ENERO | B7: =COUNTIF($A$13:$A$14,A7) -> 1 | C7: =_xlfn.MINIFS($B$13:$B$14,$A$13:$A$14,A7) -> 122.71 | D7: =AVERAGEIF($A$13:$A$14,A7,$B$13:$B$14) -> 122.71 | E7: =_xlfn.MAXIFS($B$13:$B$14,$A$13:$A$14,A7) -> 122.71
A8: MAYO | B8: =COUNTIF($A$13:$A$14,A8) -> 1 | C8: =_xlfn.MINIFS($B$13:$B$14,$A$13:$A$14,A8) -> 132.94 | D8: =AVERAGEIF($A$13:$A$14,A8,$B$13:$B$14) -> 132.94 | E8: =_xlfn.MAXIFS($B$13:$B$14,$A$13:$A$14,A8) -> 132.94 | F8: =D8/D7-1 -> 0.083367289 | G8: =D8/$D$7-1 -> 0.083367289
F9: SUBIDA TOTAL | G9: =D8/D7-1 -> 0.083367289
A11: DETALLE DE PRECIOS (una línea por precio distinto anotado en el Excel del mes)
A12: MES | B12: PRECIO | C12: CANTIDAD | D12: PRODUCTO (tal cual en el Excel) | E12: ARCHIVO ORIGEN
A13: ENERO | B13: 122.71 | C13: 1 | D13: ZACAPA X.O. | E13: ALBARANES MAYO 2026
A14: MAYO | B14: 132.94 | C14: 2 | D14: ACAPA X.O. | E14: ALBARANES MAYO 2026

Sheet OREMUS 3
A1: OREMUS 3 | I1: ← Volver al resumen
A2: Proveedor: CALIDOSCOPI · Categoría: ENVASADO / BEBIDA / OTROS
A3: Nombres en albaranes: OREMUS 3 | OREMUS 3 PUTTONYOS 2018 (50CL)
A4: Producto envasado / tarifa: cualquier subida de precio unitario entre el primer y el último mes con compras se considera SUBIDA.
A6: MES | B6: Nº PRECIOS | C6: PRECIO MÍN. | D6: PRECIO MEDIO | E6: PRECIO MÁX. | F6: VAR. vs MES ANTERIOR | G6: VAR. vs PRIMER MES
A7: ENERO | B7: =COUNTIF($A$13:$A$14,A7) -> 1 | C7: =_xlfn.MINIFS($B$13:$B$14,$A$13:$A$14,A7) -> 27.4 | D7: =AVERAGEIF($A$13:$A$14,A7,$B$13:$B$14) -> 27.4 | E7: =_xlfn.MAXIFS($B$13:$B$14,$A$13:$A$14,A7) -> 27.4
A8: MAYO | B8: =COUNTIF($A$13:$A$14,A8) -> 1 | C8: =_xlfn.MINIFS($B$13:$B$14,$A$13:$A$14,A8) -> 29.25 | D8: =AVERAGEIF($A$13:$A$14,A8,$B$13:$B$14) -> 29.25 | E8: =_xlfn.MAXIFS($B$13:$B$14,$A$13:$A$14,A8) -> 29.25 | F8: =D8/D7-1 -> 0.067518248 | G8: =D8/$D$7-1 -> 0.067518248
F9: SUBIDA TOTAL | G9: =D8/D7-1 -> 0.067518248
A11: DETALLE DE PRECIOS (una línea por precio distinto anotado en el Excel del mes)
A12: MES | B12: PRECIO | C12: CANTIDAD | D12: PRODUCTO (tal cual en el Excel) | E12: ARCHIVO ORIGEN
A13: ENERO | B13: 27.4 | C13: 6 | D13: OREMUS 3 PUTTONYOS 2018 (50CL) | E13: ALBARANES MAYO 2026
A14: MAYO | B14: 29.25 | C14: 6 | D14: OREMUS 3 | E14: ALBARANES MAYO 2026

Sheet GINEBRA MARTIN MILLER 3 4
A1: GINEBRA MARTIN MILLER 3/4 | I1: ← Volver al resumen
A2: Proveedor: DITEMA (DIST. TENA) · Categoría: ENVASADO / BEBIDA / OTROS
A3: Nombres en albaranes: GINEBRA MARTIN MILLER 3/4
A4: Producto envasado / tarifa: cualquier subida de precio unitario entre el primer y el último mes con compras se considera SUBIDA.
A6: MES | B6: Nº PRECIOS | C6: PRECIO MÍN. | D6: PRECIO MEDIO | E6: PRECIO MÁX. | F6: VAR. vs MES ANTERIOR | G6: VAR. vs PRIMER MES
A7: ENERO | B7: =COUNTIF($A$14:$A$16,A7) -> 1 | C7: =_xlfn.MINIFS($B$14:$B$16,$A$14:$A$16,A7) -> 15.1 | D7: =AVERAGEIF($A$14:$A$16,A7,$B$14:$B$16) -> 15.1 | E7: =_xlfn.MAXIFS($B$14:$B$16,$A$14:$A$16,A7) -> 15.1
A8: MAYO | B8: =COUNTIF($A$14:$A$16,A8) -> 1 | C8: =_xlfn.MINIFS($B$14:$B$16,$A$14:$A$16,A8) -> 16.1 | D8: =AVERAGEIF($A$14:$A$16,A8,$B$14:$B$16) -> 16.1 | E8: =_xlfn.MAXIFS($B$14:$B$16,$A$14:$A$16,A8) -> 16.1 | F8: =D8/D7-1 -> 0.066225166 | G8: =D8/$D$7-1 -> 0.066225166
A9: JULIO | B9: =COUNTIF($A$14:$A$16,A9) -> 1 | C9: =_xlfn.MINIFS($B$14:$B$16,$A$14:$A$16,A9) -> 16.1 | D9: =AVERAGEIF($A$14:$A$16,A9,$B$14:$B$16) -> 16.1 | E9: =_xlfn.MAXIFS($B$14:$B$16,$A$14:$A$16,A9) -> 16.1 | F9: =D9/D8-1 -> 0 | G9: =D9/$D$7-1 -> 0.066225166
F10: SUBIDA TOTAL | G10: =D9/D7-1 -> 0.066225166
A12: DETALLE DE PRECIOS (una línea por precio distinto anotado en el Excel del mes)
A13: MES | B13: PRECIO | C13: CANTIDAD | D13: PRODUCTO (tal cual en el Excel) | E13: ARCHIVO ORIGEN
A14: ENERO | B14: 15.1 | C14: 6 | D14: GINEBRA MARTIN MILLER 3/4 | E14: ALBARANES MAYO 2026
A15: MAYO | B15: 16.1 | C15: 6 | D15: GINEBRA MARTIN MILLER 3/4 | E15: ALBARANES MAYO 2026
A16: JULIO | B16: 16.1 | D16: GINEBRA MARTIN MILLER 3/4 | E16: ALBARANES JULIO 2026 v3

Sheet AQUARADE ZERO NARANJA VIDRIO
A1: AQUARADE ZERO NARANJA VIDRIO 35CL | I1: ← Volver al resumen
A2: Proveedor: VOLDIS · Categoría: ENVASADO / BEBIDA / OTROS
A3: Nombres en albaranes: AQUARADE ZERO NARANJA VIDRIO RET 35CL | AQUARADE ZERO NARANJA VIDRIO RET 35CL CAJA 24U
A4: Producto envasado / tarifa: cualquier subida de precio unitario entre el primer y el último mes con compras se considera SUBIDA.
A6: MES | B6: Nº PRECIOS | C6: PRECIO MÍN. | D6: PRECIO MEDIO | E6: PRECIO MÁX. | F6: VAR. vs MES ANTERIOR | G6: VAR. vs PRIMER MES
A7: ENERO | B7: =COUNTIF($A$15:$A$18,A7) -> 1 | C7: =_xlfn.MINIFS($B$15:$B$18,$A$15:$A$18,A7) -> 31.92 | D7: =AVERAGEIF($A$15:$A$18,A7,$B$15:$B$18) -> 31.92 | E7: =_xlfn.MAXIFS($B$15:$B$18,$A$15:$A$18,A7) -> 31.92
A8: FEBRERO | B8: =COUNTIF($A$15:$A$18,A8) -> 1 | C8: =_xlfn.MINIFS($B$15:$B$18,$A$15:$A$18,A8) -> 33.84 | D8: =AVERAGEIF($A$15:$A$18,A8,$B$15:$B$18) -> 33.84 | E8: =_xlfn.MAXIFS($B$15:$B$18,$A$15:$A$18,A8) -> 33.84 | F8: =D8/D7-1 -> 0.060150376 | G8: =D8/$D$7-1 -> 0.060150376
A9: MAYO | B9: =COUNTIF($A$15:$A$18,A9) -> 1 | C9: =_xlfn.MINIFS($B$15:$B$18,$A$15:$A$18,A9) -> 33.84 | D9: =AVERAGEIF($A$15:$A$18,A9,$B$15:$B$18) -> 33.84 | E9: =_xlfn.MAXIFS($B$15:$B$18,$A$15:$A$18,A9) -> 33.84 | F9: =D9/D8-1 -> 0 | G9: =D9/$D$7-1 -> 0.060150376
A10: JULIO | B10: =COUNTIF($A$15:$A$18,A10) -> 1 | C10: =_xlfn.MINIFS($B$15:$B$18,$A$15:$A$18,A10) -> 33.84 | D10: =AVERAGEIF($A$15:$A$18,A10,$B$15:$B$18) -> 33.84 | E10: =_xlfn.MAXIFS($B$15:$B$18,$A$15:$A$18,A10) -> 33.84 | F10: =D10/D9-1 -> 0 | G10: =D10/$D$7-1 -> 0.060150376
F11: SUBIDA TOTAL | G11: =D10/D7-1 -> 0.060150376
A13: DETALLE DE PRECIOS (una línea por precio distinto anotado en el Excel del mes)
A14: MES | B14: PRECIO | C14: CANTIDAD | D14: PRODUCTO (tal cual en el Excel) | E14: ARCHIVO ORIGEN
A15: ENERO | B15: 31.92 | C15: 4 | D15: AQUARADE ZERO NARANJA VIDRIO RET 35CL CAJA 24U | E15: ALBARANES MAYO 2026
A16: FEBRERO | B16: 33.84 | C16: 2 | D16: AQUARADE ZERO NARANJA VIDRIO RET 35CL CAJA 24U | E16: ALBARANES MAYO 2026
A17: MAYO | B17: 33.84 | C17: 3 | D17: AQUARADE ZERO NARANJA VIDRIO RET 35CL CAJA 24U | E17: ALBARANES MAYO 2026
A18: JULIO | B18: 33.84 | C18: 2 | D18: AQUARADE ZERO NARANJA VIDRIO RET 35CL | E18: ALBARANES JULIO 2026 v3

Sheet VENTRESCA BONITO EXTRA
A1: VENTRESCA BONITO EXTRA | I1: ← Volver al resumen
A2: Proveedor: CONSERVAS Y SALAZONES JIMENEZ · Categoría: ENVASADO / BEBIDA / OTROS
A3: Nombres en albaranes: VENTRESCA DE BONITO EXTRA | VENTRESCA DE BONITO EXTRA EN ACEITE OL-120 ARROYABE
A4: Producto envasado / tarifa: cualquier subida de precio unitario entre el primer y el último mes con compras se considera SUBIDA.
A6: MES | B6: Nº PRECIOS | C6: PRECIO MÍN. | D6: PRECIO MEDIO | E6: PRECIO MÁX. | F6: VAR. vs MES ANTERIOR | G6: VAR. vs PRIMER MES
A7: ENERO | B7: =COUNTIF($A$17:$A$22,A7) -> 1 | C7: =_xlfn.MINIFS($B$17:$B$22,$A$17:$A$22,A7) -> 5.56 | D7: =AVERAGEIF($A$17:$A$22,A7,$B$17:$B$22) -> 5.56 | E7: =_xlfn.MAXIFS($B$17:$B$22,$A$17:$A$22,A7) -> 5.56
A8: FEBRERO | B8: =COUNTIF($A$17:$A$22,A8) -> 1 | C8: =_xlfn.MINIFS($B$17:$B$22,$A$17:$A$22,A8) -> 5.56 | D8: =AVERAGEIF($A$17:$A$22,A8,$B$17:$B$22) -> 5.56 | E8: =_xlfn.MAXIFS($B$17:$B$22,$A$17:$A$22,A8) -> 5.56 | F8: =D8/D7-1 -> 0 | G8: =D8/$D$7-1 -> 0
A9: ABRIL | B9: =COUNTIF($A$17:$A$22,A9) -> 1 | C9: =_xlfn.MINIFS($B$17:$B$22,$A$17:$A$22,A9) -> 5.56 | D9: =AVERAGEIF($A$17:$A$22,A9,$B$17:$B$22) -> 5.56 | E9: =_xlfn.MAXIFS($B$17:$B$22,$A$17:$A$22,A9) -> 5.56 | F9: =D9/D8-1 -> 0 | G9: =D9/$D$7-1 -> 0
A10: MAYO | B10: =COUNTIF($A$17:$A$22,A10) -> 1 | C10: =_xlfn.MINIFS($B$17:$B$22,$A$17:$A$22,A10) -> 5.56 | D10: =AVERAGEIF($A$17:$A$22,A10,$B$17:$B$22) -> 5.56 | E10: =_xlfn.MAXIFS($B$17:$B$22,$A$17:$A$22,A10) -> 5.56 | F10: =D10/D9-1 -> 0 | G10: =D10/$D$7-1 -> 0
A11: JULIO | B11: =COUNTIF($A$17:$A$22,A11) -> 1 | C11: =_xlfn.MINIFS($B$17:$B$22,$A$17:$A$22,A11) -> 5.86 | D11: =AVERAGEIF($A$17:$A$22,A11,$B$17:$B$22) -> 5.86 | E11: =_xlfn.MAXIFS($B$17:$B$22,$A$17:$A$22,A11) -> 5.86 | F11: =D11/D10-1 -> 0.053956835 | G11: =D11/$D$7-1 -> 0.053956835
A12: AGOSTO | B12: =COUNTIF($A$17:$A$22,A12) -> 1 | C12: =_xlfn.MINIFS($B$17:$B$22,$A$17:$A$22,A12) -> 5.86 | D12: =AVERAGEIF($A$17:$A$22,A12,$B$17:$B$22) -> 5.86 | E12: =_xlfn.MAXIFS($B$17:$B$22,$A$17:$A$22,A12) -> 5.86 | F12: =D12/D11-1 -> 0 | G12: =D12/$D$7-1 -> 0.053956835
F13: SUBIDA TOTAL | G13: =D12/D7-1 -> 0.053956835
A15: DETALLE DE PRECIOS (una línea por precio distinto anotado en el Excel del mes)
A16: MES | B16: PRECIO | C16: CANTIDAD | D16: PRODUCTO (tal cual en el Excel) | E16: ARCHIVO ORIGEN
A17: ENERO | B17: 5.56 | C17: 24 | D17: VENTRESCA DE BONITO EXTRA EN ACEITE OL-120 ARROYABE | E17: ALBARANES MAYO 2026
A18: FEBRERO | B18: 5.56 | C18: 48 | D18: VENTRESCA DE BONITO EXTRA EN ACEITE OL-120 ARROYABE | E18: ALBARANES MAYO 2026
A19: ABRIL | B19: 5.56 | C19: 48 | D19: VENTRESCA DE BONITO EXTRA EN ACEITE OL-120 ARROYABE | E19: ALBARANES MAYO 2026
A20: MAYO | B20: 5.56 | C20: 24 | D20: VENTRESCA DE BONITO EXTRA EN ACEITE OL-120 ARROYABE | E20: ALBARANES MAYO 2026
A21: JULIO | B21: 5.86 | D21: VENTRESCA DE BONITO EXTRA | E21: ALBARANES JULIO 2026 v3
A22: AGOSTO | B22: 5.86 | C22: 24 | D22: VENTRESCA DE BONITO EXTRA | E22: ALBARANES AGOSTO 2026 v1

Sheet SOLAN CABRAS CON GAS
A1: SOLAN CABRAS CON GAS | I1: ← Volver al resumen
A2: Proveedor: EIF DISTRIBUCIONES · Categoría: ENVASADO / BEBIDA / OTROS
A3: Nombres en albaranes: SOLAN DE CABRAS CON GAS | SOLAN DE CABRAS CON GAS 0.33
A4: Producto envasado / tarifa: cualquier subida de precio unitario entre el primer y el último mes con compras se considera SUBIDA.
A6: MES | B6: Nº PRECIOS | C6: PRECIO MÍN. | D6: PRECIO MEDIO | E6: PRECIO MÁX. | F6: VAR. vs MES ANTERIOR | G6: VAR. vs PRIMER MES
A7: ENERO | B7: =COUNTIF($A$14:$A$17,A7) -> 2 | C7: =_xlfn.MINIFS($B$14:$B$17,$A$14:$A$17,A7) -> 25.44 | D7: =AVERAGEIF($A$14:$A$17,A7,$B$14:$B$17) -> 25.44 | E7: =_xlfn.MAXIFS($B$14:$B$17,$A$14:$A$17,A7) -> 25.44
A8: JULIO | B8: =COUNTIF($A$14:$A$17,A8) -> 1 | C8: =_xlfn.MINIFS($B$14:$B$17,$A$14:$A$17,A8) -> 26.8 | D8: =AVERAGEIF($A$14:$A$17,A8,$B$14:$B$17) -> 26.8 | E8: =_xlfn.MAXIFS($B$14:$B$17,$A$14:$A$17,A8) -> 26.8 | F8: =D8/D7-1 -> 0.053459119 | G8: =D8/$D$7-1 -> 0.053459119
A9: AGOSTO | B9: =COUNTIF($A$14:$A$17,A9) -> 1 | C9: =_xlfn.MINIFS($B$14:$B$17,$A$14:$A$17,A9) -> 26.8 | D9: =AVERAGEIF($A$14:$A$17,A9,$B$14:$B$17) -> 26.8 | E9: =_xlfn.MAXIFS($B$14:$B$17,$A$14:$A$17,A9) -> 26.8 | F9: =D9/D8-1 -> 0 | G9: =D9/$D$7-1 -> 0.053459119
F10: SUBIDA TOTAL | G10: =D9/D7-1 -> 0.053459119
A12: DETALLE DE PRECIOS (una línea por precio distinto anotado en el Excel del mes)
A13: MES | B13: PRECIO | C13: CANTIDAD | D13: PRODUCTO (tal cual en el Excel) | E13: ARCHIVO ORIGEN
A14: ENERO | B14: 25.44 | C14: 3 | D14: SOLAN DE CABRAS CON GAS 0.33 | E14: ALBARANES MAYO 2026
A15: ENERO | B15: 25.44 | D15: SOLAN DE CABRAS CON GAS 0.33 | E15: ALBARANES MAYO 2026
A16: JULIO | B16: 26.8 | C16: 5 | D16: SOLAN DE CABRAS CON GAS | E16: ALBARANES JULIO 2026 v3
A17: AGOSTO | B17: 26.8 | C17: 2 | D17: SOLAN DE CABRAS CON GAS | E17: ALBARANES AGOSTO 2026 v1

Sheet AGUA SOLAN CABRAS VIDRIO 50C
A1: AGUA SOLAN CABRAS VIDRIO 50CL | I1: ← Volver al resumen
A2: Proveedor: VOLDIS · Categoría: ENVASADO / BEBIDA / OTROS
A3: Nombres en albaranes: AGUA SOLAN DE CABRAS VIDRIO RET 50CL 20U | AGUA SOLAN DE CABRAS VIDRIO RET 50CL CAJA 20UDS
A4: Producto envasado / tarifa: cualquier subida de precio unitario entre el primer y el último mes con compras se considera SUBIDA.
A6: MES | B6: Nº PRECIOS | C6: PRECIO MÍN. | D6: PRECIO MEDIO | E6: PRECIO MÁX. | F6: VAR. vs MES ANTERIOR | G6: VAR. vs PRIMER MES
A7: ENERO | B7: =COUNTIF($A$15:$A$18,A7) -> 1 | C7: =_xlfn.MINIFS($B$15:$B$18,$A$15:$A$18,A7) -> 11.68 | D7: =AVERAGEIF($A$15:$A$18,A7,$B$15:$B$18) -> 11.68 | E7: =_xlfn.MAXIFS($B$15:$B$18,$A$15:$A$18,A7) -> 11.68
A8: FEBRERO | B8: =COUNTIF($A$15:$A$18,A8) -> 1 | C8: =_xlfn.MINIFS($B$15:$B$18,$A$15:$A$18,A8) -> 11.68 | D8: =AVERAGEIF($A$15:$A$18,A8,$B$15:$B$18) -> 11.68 | E8: =_xlfn.MAXIFS($B$15:$B$18,$A$15:$A$18,A8) -> 11.68 | F8: =D8/D7-1 -> 0 | G8: =D8/$D$7-1 -> 0
A9: MAYO | B9: =COUNTIF($A$15:$A$18,A9) -> 1 | C9: =_xlfn.MINIFS($B$15:$B$18,$A$15:$A$18,A9) -> 11.68 | D9: =AVERAGEIF($A$15:$A$18,A9,$B$15:$B$18) -> 11.68 | E9: =_xlfn.MAXIFS($B$15:$B$18,$A$15:$A$18,A9) -> 11.68 | F9: =D9/D8-1 -> 0 | G9: =D9/$D$7-1 -> 0
A10: JULIO | B10: =COUNTIF($A$15:$A$18,A10) -> 1 | C10: =_xlfn.MINIFS($B$15:$B$18,$A$15:$A$18,A10) -> 12.3 | D10: =AVERAGEIF($A$15:$A$18,A10,$B$15:$B$18) -> 12.3 | E10: =_xlfn.MAXIFS($B$15:$B$18,$A$15:$A$18,A10) -> 12.3 | F10: =D10/D9-1 -> 0.053082192 | G10: =D10/$D$7-1 -> 0.053082192
F11: SUBIDA TOTAL | G11: =D10/D7-1 -> 0.053082192
A13: DETALLE DE PRECIOS (una línea por precio distinto anotado en el Excel del mes)
A14: MES | B14: PRECIO | C14: CANTIDAD | D14: PRODUCTO (tal cual en el Excel) | E14: ARCHIVO ORIGEN
A15: ENERO | B15: 11.68 | C15: 44 | D15: AGUA SOLAN DE CABRAS VIDRIO RET 50CL CAJA 20UDS | E15: ALBARANES MAYO 2026
A16: FEBRERO | B16: 11.68 | C16: 40 | D16: AGUA SOLAN DE CABRAS VIDRIO RET 50CL CAJA 20UDS | E16: ALBARANES MAYO 2026
A17: MAYO | B17: 11.68 | C17: 49 | D17: AGUA SOLAN DE CABRAS VIDRIO RET 50CL CAJA 20UDS | E17: ALBARANES MAYO 2026
A18: JULIO | B18: 12.3 | C18: 49 | D18: AGUA SOLAN DE CABRAS VIDRIO RET 50CL 20U | E18: ALBARANES JULIO 2026 v3

Sheet AGUA CON GAS SOLAN CABRAS VI
A1: AGUA CON GAS SOLAN CABRAS VIDRIO 33CL | I1: ← Volver al resumen
A2: Proveedor: VOLDIS · Categoría: ENVASADO / BEBIDA / OTROS
A3: Nombres en albaranes: AGUA CON GAS SOLAN DE CABRAS VIDRIO NR 33CL | AGUA CON GAS SOLAN DE CABRAS VIDRIO RNR 33CL
A4: Producto envasado / tarifa: cualquier subida de precio unitario entre el primer y el último mes con compras se considera SUBIDA.
A6: MES | B6: Nº PRECIOS | C6: PRECIO MÍN. | D6: PRECIO MEDIO | E6: PRECIO MÁX. | F6: VAR. vs MES ANTERIOR | G6: VAR. vs PRIMER MES
A7: ENERO | B7: =COUNTIF($A$15:$A$18,A7) -> 1 | C7: =_xlfn.MINIFS($B$15:$B$18,$A$15:$A$18,A7) -> 25.464 | D7: =AVERAGEIF($A$15:$A$18,A7,$B$15:$B$18) -> 25.464 | E7: =_xlfn.MAXIFS($B$15:$B$18,$A$15:$A$18,A7) -> 25.464
A8: FEBRERO | B8: =COUNTIF($A$15:$A$18,A8) -> 1 | C8: =_xlfn.MINIFS($B$15:$B$18,$A$15:$A$18,A8) -> 25.464 | D8: =AVERAGEIF($A$15:$A$18,A8,$B$15:$B$18) -> 25.464 | E8: =_xlfn.MAXIFS($B$15:$B$18,$A$15:$A$18,A8) -> 25.464 | F8: =D8/D7-1 -> 0 | G8: =D8/$D$7-1 -> 0
A9: MAYO | B9: =COUNTIF($A$15:$A$18,A9) -> 1 | C9: =_xlfn.MINIFS($B$15:$B$18,$A$15:$A$18,A9) -> 25.464 | D9: =AVERAGEIF($A$15:$A$18,A9,$B$15:$B$18) -> 25.464 | E9: =_xlfn.MAXIFS($B$15:$B$18,$A$15:$A$18,A9) -> 25.464 | F9: =D9/D8-1 -> 0 | G9: =D9/$D$7-1 -> 0
A10: JULIO | B10: =COUNTIF($A$15:$A$18,A10) -> 1 | C10: =_xlfn.MINIFS($B$15:$B$18,$A$15:$A$18,A10) -> 26.81 | D10: =AVERAGEIF($A$15:$A$18,A10,$B$15:$B$18) -> 26.81 | E10: =_xlfn.MAXIFS($B$15:$B$18,$A$15:$A$18,A10) -> 26.81 | F10: =D10/D9-1 -> 0.052858938 | G10: =D10/$D$7-1 -> 0.052858938
F11: SUBIDA TOTAL | G11: =D10/D7-1 -> 0.052858938
A13: DETALLE DE PRECIOS (una línea por precio distinto anotado en el Excel del mes)
A14: MES | B14: PRECIO | C14: CANTIDAD | D14: PRODUCTO (tal cual en el Excel) | E14: ARCHIVO ORIGEN
A15: ENERO | B15: 25.464 | C15: 36 | D15: AGUA CON GAS SOLAN DE CABRAS VIDRIO NR 33CL | E15: ALBARANES MAYO 2026
A16: FEBRERO | B16: 25.464 | C16: 35 | D16: AGUA CON GAS SOLAN DE CABRAS VIDRIO NR 33CL | E16: ALBARANES MAYO 2026
A17: MAYO | B17: 25.464 | C17: 47 | D17: AGUA CON GAS SOLAN DE CABRAS VIDRIO NR 33CL | E17: ALBARANES MAYO 2026
A18: JULIO | B18: 26.81 | C18: 41 | D18: AGUA CON GAS SOLAN DE CABRAS VIDRIO RNR 33CL | E18: ALBARANES JULIO 2026 v3

Sheet MOJAMA EXTRA SUPERIOR CHANCA
A1: MOJAMA EXTRA SUPERIOR CHANCA | I1: ← Volver al resumen
A2: Proveedor: CONSERVAS Y SALAZONES JIMENEZ · Categoría: ENVASADO / BEBIDA / OTROS
