Workbook

Sheet RESUMEN JULIO
B2: RESUMEN DE COMPRAS · JULIO 2026
B3: LA MINA DE CHAMARTÍN
B4: Todo se calcula desde la hoja TOTAL JULIO. La columna de mayo es el importe fijo del Excel de mayo. (En junio no hay datos de Chamartín: se compara con mayo.)
B6: BASE IMPONIBLE | D6: CUOTA IVA | F6: TOTAL CON IVA
B7: =SUM('TOTAL JULIO'!D4:D2000) -> 63628.05 | D7: =SUM('TOTAL JULIO'!F4:F2000)-SUM('TOTAL JULIO'!D4:D2000) -> 8355.597 | F7: =SUM('TOTAL JULIO'!F4:F2000) -> 71983.647
B9: Nº ALBARANES | D9: Nº PROVEEDORES | F9: CUADRES A REVISAR
B10: =COUNTIF('TOTAL JULIO'!B4:B2000,"?*") -> 271 | D10: =SUMPRODUCT(('TOTAL JULIO'!B4:B2000<>"")/COUNTIF('TOTAL JULIO'!B4:B2000,'TOTAL JULIO'!B4:B2000&"")) -> 37 | F10: =COUNTIF('CUADRE ALBARANES'!H:H,"REVISAR") -> 2
B12: BASE AL 4% DE IVA | D12: BASE AL 10% DE IVA | F12: BASE AL 21% DE IVA
B13: =SUMIF('TOTAL JULIO'!$E$4:$E$2000,0.04,'TOTAL JULIO'!$D$4:$D$2000) -> 3449.91 | D13: =SUMIF('TOTAL JULIO'!$E$4:$E$2000,0.1,'TOTAL JULIO'!$D$4:$D$2000) -> 40180.08 | F13: =SUMIF('TOTAL JULIO'!$E$4:$E$2000,0.21,'TOTAL JULIO'!$D$4:$D$2000) -> 19998.06
B16: COMPRAS POR PROVEEDOR
B17: PROVEEDOR | C17: Nº ALB. | D17: BASE JULIO | E17: % DEL MES | F17: BASE MAYO | G17: DIF. € | H17: DIF. %
B18: PESCARUM | C18: =COUNTIF('TOTAL JULIO'!$B$4:$B$2000,B18) -> 22 | D18: =SUMIF('TOTAL JULIO'!$B$4:$B$2000,B18,'TOTAL JULIO'!$D$4:$D$2000) -> 10740.83 | E18: =IF($D$57=0,0,D18/$D$57) -> 0.16880652 | F18: 10858.44 | G18: =IF(F18="","",D18-F18) -> -117.61 | H18: =IF(OR(F18="",N(F18)=0),"",D18/F18-1) -> -0.010831206
B19: VOLDIS | C19: =COUNTIF('TOTAL JULIO'!$B$4:$B$2000,B19) -> 15 | D19: =SUMIF('TOTAL JULIO'!$B$4:$B$2000,B19,'TOTAL JULIO'!$D$4:$D$2000) -> 6546.46 | E19: =IF($D$57=0,0,D19/$D$57) -> 0.10288638 | F19: 7460.83 | G19: =IF(F19="","",D19-F19) -> -914.37 | H19: =IF(OR(F19="",N(F19)=0),"",D19/F19-1) -> -0.12255607
B20: MUNDELA | C20: =COUNTIF('TOTAL JULIO'!$B$4:$B$2000,B20) -> 6 | D20: =SUMIF('TOTAL JULIO'!$B$4:$B$2000,B20,'TOTAL JULIO'!$D$4:$D$2000) -> 5092.38 | E20: =IF($D$57=0,0,D20/$D$57) -> 0.08003357 | F20: 5751.42 | G20: =IF(F20="","",D20-F20) -> -659.04 | H20: =IF(OR(F20="",N(F20)=0),"",D20/F20-1) -> -0.11458735
B21: AGROFOOD | C21: =COUNTIF('TOTAL JULIO'!$B$4:$B$2000,B21) -> 10 | D21: =SUMIF('TOTAL JULIO'!$B$4:$B$2000,B21,'TOTAL JULIO'!$D$4:$D$2000) -> 4059.72 | E21: =IF($D$57=0,0,D21/$D$57) -> 0.063803936 | F21: 3732.35 | G21: =IF(F21="","",D21-F21) -> 327.37 | H21: =IF(OR(F21="",N(F21)=0),"",D21/F21-1) -> 0.087711495
B22: CONS. Y SAL. JIMENEZ | C22: =COUNTIF('TOTAL JULIO'!$B$4:$B$2000,B22) -> 7 | D22: =SUMIF('TOTAL JULIO'!$B$4:$B$2000,B22,'TOTAL JULIO'!$D$4:$D$2000) -> 3739.92 | E22: =IF($D$57=0,0,D22/$D$57) -> 0.05877785 | F22: 3037.64 | G22: =IF(F22="","",D22-F22) -> 702.28 | H22: =IF(OR(F22="",N(F22)=0),"",D22/F22-1) -> 0.23119264
B23: MARTIN CANEDA | C23: =COUNTIF('TOTAL JULIO'!$B$4:$B$2000,B23) -> 21 | D23: =SUMIF('TOTAL JULIO'!$B$4:$B$2000,B23,'TOTAL JULIO'!$D$4:$D$2000) -> 3561.4 | E23: =IF($D$57=0,0,D23/$D$57) -> 0.05597217 | F23: 3701.1 | G23: =IF(F23="","",D23-F23) -> -139.7 | H23: =IF(OR(F23="",N(F23)=0),"",D23/F23-1) -> -0.037745535
B24: SUBMARINER | C24: =COUNTIF('TOTAL JULIO'!$B$4:$B$2000,B24) -> 5 | D24: =SUMIF('TOTAL JULIO'!$B$4:$B$2000,B24,'TOTAL JULIO'!$D$4:$D$2000) -> 3291.32 | E24: =IF($D$57=0,0,D24/$D$57) -> 0.051727501 | F24: 6879.55 | G24: =IF(F24="","",D24-F24) -> -3588.23 | H24: =IF(OR(F24="",N(F24)=0),"",D24/F24-1) -> -0.52157917
B25: DIST. TENA MTNEZ | C25: =COUNTIF('TOTAL JULIO'!$B$4:$B$2000,B25) -> 6 | D25: =SUMIF('TOTAL JULIO'!$B$4:$B$2000,B25,'TOTAL JULIO'!$D$4:$D$2000) -> 3131.64 | E25: =IF($D$57=0,0,D25/$D$57) -> 0.049217916 | F25: 6168.3 | G25: =IF(F25="","",D25-F25) -> -3036.66 | H25: =IF(OR(F25="",N(F25)=0),"",D25/F25-1) -> -0.49230096
B26: COCACOLA | C26: =COUNTIF('TOTAL JULIO'!$B$4:$B$2000,B26) -> 11 | D26: =SUMIF('TOTAL JULIO'!$B$4:$B$2000,B26,'TOTAL JULIO'!$D$4:$D$2000) -> 2124.02 | E26: =IF($D$57=0,0,D26/$D$57) -> 0.033381818 | G26: =IF(F26="","",D26-F26) | H26: =IF(OR(F26="",N(F26)=0),"",D26/F26-1)
B27: CRUSTAPESCA | C27: =COUNTIF('TOTAL JULIO'!$B$4:$B$2000,B27) -> 16 | D27: =SUMIF('TOTAL JULIO'!$B$4:$B$2000,B27,'TOTAL JULIO'!$D$4:$D$2000) -> 1970.46 | E27: =IF($D$57=0,0,D27/$D$57) -> 0.030968417 | F27: 1909.06 | G27: =IF(F27="","",D27-F27) -> 61.4 | H27: =IF(OR(F27="",N(F27)=0),"",D27/F27-1) -> 0.032162425
B28: MAGOASE | C28: =COUNTIF('TOTAL JULIO'!$B$4:$B$2000,B28) -> 13 | D28: =SUMIF('TOTAL JULIO'!$B$4:$B$2000,B28,'TOTAL JULIO'!$D$4:$D$2000) -> 1815.6 | E28: =IF($D$57=0,0,D28/$D$57) -> 0.028534585 | F28: 3162 | G28: =IF(F28="","",D28-F28) -> -1346.4 | H28: =IF(OR(F28="",N(F28)=0),"",D28/F28-1) -> -0.42580645
B29: PEÑALASTALLAS | C29: =COUNTIF('TOTAL JULIO'!$B$4:$B$2000,B29) -> 7 | D29: =SUMIF('TOTAL JULIO'!$B$4:$B$2000,B29,'TOTAL JULIO'!$D$4:$D$2000) -> 1568.32 | E29: =IF($D$57=0,0,D29/$D$57) -> 0.024648249 | F29: 1521.34 | G29: =IF(F29="","",D29-F29) -> 46.98 | H29: =IF(OR(F29="",N(F29)=0),"",D29/F29-1) -> 0.030880671
B30: CARNICAS MEAT | C30: =COUNTIF('TOTAL JULIO'!$B$4:$B$2000,B30) -> 5 | D30: =SUMIF('TOTAL JULIO'!$B$4:$B$2000,B30,'TOTAL JULIO'!$D$4:$D$2000) -> 1412.35 | E30: =IF($D$57=0,0,D30/$D$57) -> 0.022196971 | F30: 1525.66 | G30: =IF(F30="","",D30-F30) -> -113.31 | H30: =IF(OR(F30="",N(F30)=0),"",D30/F30-1) -> -0.074269496
B31: PESCADERIA PALACIO | C31: =COUNTIF('TOTAL JULIO'!$B$4:$B$2000,B31) -> 6 | D31: =SUMIF('TOTAL JULIO'!$B$4:$B$2000,B31,'TOTAL JULIO'!$D$4:$D$2000) -> 1400.16 | E31: =IF($D$57=0,0,D31/$D$57) -> 0.022005389 | F31: 1512 | G31: =IF(F31="","",D31-F31) -> -111.84 | H31: =IF(OR(F31="",N(F31)=0),"",D31/F31-1) -> -0.073968254
B32: DISOLTRIGO | C32: =COUNTIF('TOTAL JULIO'!$B$4:$B$2000,B32) -> 6 | D32: =SUMIF('TOTAL JULIO'!$B$4:$B$2000,B32,'TOTAL JULIO'!$D$4:$D$2000) -> 1295.5 | E32: =IF($D$57=0,0,D32/$D$57) -> 0.020360517 | F32: 1516 | G32: =IF(F32="","",D32-F32) -> -220.5 | H32: =IF(OR(F32="",N(F32)=0),"",D32/F32-1) -> -0.14544855
B33: ENRIQUE CAMPS | C33: =COUNTIF('TOTAL JULIO'!$B$4:$B$2000,B33) -> 7 | D33: =SUMIF('TOTAL JULIO'!$B$4:$B$2000,B33,'TOTAL JULIO'!$D$4:$D$2000) -> 1189 | E33: =IF($D$57=0,0,D33/$D$57) -> 0.018686727 | F33: 1403 | G33: =IF(F33="","",D33-F33) -> -214 | H33: =IF(OR(F33="",N(F33)=0),"",D33/F33-1) -> -0.15253029
B34: AGMASFOOD | C34: =COUNTIF('TOTAL JULIO'!$B$4:$B$2000,B34) -> 9 | D34: =SUMIF('TOTAL JULIO'!$B$4:$B$2000,B34,'TOTAL JULIO'!$D$4:$D$2000) -> 1122.99 | E34: =IF($D$57=0,0,D34/$D$57) -> 0.017649291 | F34: 2777.24 | G34: =IF(F34="","",D34-F34) -> -1654.25 | H34: =IF(OR(F34="",N(F34)=0),"",D34/F34-1) -> -0.59564532
B35: CRNAS SERVAN | C35: =COUNTIF('TOTAL JULIO'!$B$4:$B$2000,B35) -> 9 | D35: =SUMIF('TOTAL JULIO'!$B$4:$B$2000,B35,'TOTAL JULIO'!$D$4:$D$2000) -> 1086.03 | E35: =IF($D$57=0,0,D35/$D$57) -> 0.017068416 | G35: =IF(F35="","",D35-F35) | H35: =IF(OR(F35="",N(F35)=0),"",D35/F35-1)
B36: DELIPAN | C36: =COUNTIF('TOTAL JULIO'!$B$4:$B$2000,B36) -> 12 | D36: =SUMIF('TOTAL JULIO'!$B$4:$B$2000,B36,'TOTAL JULIO'!$D$4:$D$2000) -> 1032.66 | E36: =IF($D$57=0,0,D36/$D$57) -> 0.016229635 | F36: 1179.17 | G36: =IF(F36="","",D36-F36) -> -146.51 | H36: =IF(OR(F36="",N(F36)=0),"",D36/F36-1) -> -0.12424841
B37: MANUEL AMBRES | C37: =COUNTIF('TOTAL JULIO'!$B$4:$B$2000,B37) -> 3 | D37: =SUMIF('TOTAL JULIO'!$B$4:$B$2000,B37,'TOTAL JULIO'!$D$4:$D$2000) -> 904.82 | E37: =IF($D$57=0,0,D37/$D$57) -> 0.014220458 | F37: 1726 | G37: =IF(F37="","",D37-F37) -> -821.18 | H37: =IF(OR(F37="",N(F37)=0),"",D37/F37-1) -> -0.47577057
B38: JOSE PEÑA | C38: =COUNTIF('TOTAL JULIO'!$B$4:$B$2000,B38) -> 1 | D38: =SUMIF('TOTAL JULIO'!$B$4:$B$2000,B38,'TOTAL JULIO'!$D$4:$D$2000) -> 748.5 | E38: =IF($D$57=0,0,D38/$D$57) -> 0.01176368 | G38: =IF(F38="","",D38-F38) | H38: =IF(OR(F38="",N(F38)=0),"",D38/F38-1)
B39: CONS. SELEC. SANTO | C39: =COUNTIF('TOTAL JULIO'!$B$4:$B$2000,B39) -> 2 | D39: =SUMIF('TOTAL JULIO'!$B$4:$B$2000,B39,'TOTAL JULIO'!$D$4:$D$2000) -> 705.24 | E39: =IF($D$57=0,0,D39/$D$57) -> 0.011083791 | F39: 1155.06 | G39: =IF(F39="","",D39-F39) -> -449.82 | H39: =IF(OR(F39="",N(F39)=0),"",D39/F39-1) -> -0.38943432
B40: EIF DISTRIBUCIONES | C40: =COUNTIF('TOTAL JULIO'!$B$4:$B$2000,B40) -> 5 | D40: =SUMIF('TOTAL JULIO'!$B$4:$B$2000,B40,'TOTAL JULIO'!$D$4:$D$2000) -> 646.58 | E40: =IF($D$57=0,0,D40/$D$57) -> 0.01016187 | F40: 691.28 | G40: =IF(F40="","",D40-F40) -> -44.7 | H40: =IF(OR(F40="",N(F40)=0),"",D40/F40-1) -> -0.064662655
B41: PATATAS YAGO | C41: =COUNTIF('TOTAL JULIO'!$B$4:$B$2000,B41) -> 18 | D41: =SUMIF('TOTAL JULIO'!$B$4:$B$2000,B41,'TOTAL JULIO'!$D$4:$D$2000) -> 611.4 | E41: =IF($D$57=0,0,D41/$D$57) -> 0.0096089696 | G41: =IF(F41="","",D41-F41) | H41: =IF(OR(F41="",N(F41)=0),"",D41/F41-1)
B42: TOMATERIA DE CEA | C42: =COUNTIF('TOTAL JULIO'!$B$4:$B$2000,B42) -> 14 | D42: =SUMIF('TOTAL JULIO'!$B$4:$B$2000,B42,'TOTAL JULIO'!$D$4:$D$2000) -> 584.97 | E42: =IF($D$57=0,0,D42/$D$57) -> 0.0091935868 | F42: 520.94 | G42: =IF(F42="","",D42-F42) -> 64.03 | H42: =IF(OR(F42="",N(F42)=0),"",D42/F42-1) -> 0.12291243
B43: ROMERO ALVAREZ | C43: =COUNTIF('TOTAL JULIO'!$B$4:$B$2000,B43) -> 2 | D43: =SUMIF('TOTAL JULIO'!$B$4:$B$2000,B43,'TOTAL JULIO'!$D$4:$D$2000) -> 533.74 | E43: =IF($D$57=0,0,D43/$D$57) -> 0.0083884387 | G43: =IF(F43="","",D43-F43) | H43: =IF(OR(F43="",N(F43)=0),"",D43/F43-1)
B44: JOSE ROMERO PLAZA | C44: =COUNTIF('TOTAL JULIO'!$B$4:$B$2000,B44) -> 14 | D44: =SUMIF('TOTAL JULIO'!$B$4:$B$2000,B44,'TOTAL JULIO'!$D$4:$D$2000) -> 444.1 | E44: =IF($D$57=0,0,D44/$D$57) -> 0.0069796261 | F44: 304.9 | G44: =IF(F44="","",D44-F44) -> 139.2 | H44: =IF(OR(F44="",N(F44)=0),"",D44/F44-1) -> 0.45654313
B45: CALIDOSCOPI | C45: =COUNTIF('TOTAL JULIO'!$B$4:$B$2000,B45) -> 1 | D45: =SUMIF('TOTAL JULIO'!$B$4:$B$2000,B45,'TOTAL JULIO'!$D$4:$D$2000) -> 339 | E45: =IF($D$57=0,0,D45/$D$57) -> 0.0053278389 | F45: 608.7 | G45: =IF(F45="","",D45-F45) -> -269.7 | H45: =IF(OR(F45="",N(F45)=0),"",D45/F45-1) -> -0.44307541
B46: ANTONIO DE MIGUEL | C46: =COUNTIF('TOTAL JULIO'!$B$4:$B$2000,B46) -> 1 | D46: =SUMIF('TOTAL JULIO'!$B$4:$B$2000,B46,'TOTAL JULIO'!$D$4:$D$2000) -> 280.3 | E46: =IF($D$57=0,0,D46/$D$57) -> 0.0044052898 | F46: 585.47 | G46: =IF(F46="","",D46-F46) -> -305.17 | H46: =IF(OR(F46="",N(F46)=0),"",D46/F46-1) -> -0.52123935
...

Sheet TOTAL JULIO
B1: ALBARANES JULIO 2026 · LA MINA DE CHAMARTÍN
B2: PROVEEDOR | C2: ALBARAN | D2: BASE | E2: IVA | F2: TOTAL | H2: PROVEEDOR | I2: BASE | J2: CUOTA IVA | K2: TOTAL FRA | M2: TOTAL FACTURADO
B4: AGMASFOOD | C4: 26 6093 | D4: 191.35 | E4: 0.1 | F4: =D4+(D4*E4) -> 210.485 | H4: AGMASFOOD | I4: =SUMIF($B$4:$B$2000,H4,$D$4:$D$2000) -> 1122.99 | J4: =K4-I4 -> 112.299 | K4: =SUMIF($B$4:$B$2000,H4,$F$4:$F$2000) -> 1235.289 | M4: =K41 -> 71983.647
B5: AGMASFOOD | C5: 26 6075 | D5: 102.7 | E5: 0.1 | F5: =D5+(D5*E5) -> 112.97 | H5: AGROFOOD | I5: =SUMIF($B$4:$B$2000,H5,$D$4:$D$2000) -> 4059.72 | J5: =K5-I5 -> 405.972 | K5: =SUMIF($B$4:$B$2000,H5,$F$4:$F$2000) -> 4465.692
B6: AGMASFOOD | C6: 26 6029 | D6: 41.83 | E6: 0.1 | F6: =D6+(D6*E6) -> 46.013 | H6: ANTONIO DE MIGUEL | I6: =SUMIF($B$4:$B$2000,H6,$D$4:$D$2000) -> 280.3 | J6: =K6-I6 -> 28.03 | K6: =SUMIF($B$4:$B$2000,H6,$F$4:$F$2000) -> 308.33
B7: AGMASFOOD | C7: 26 5876 | D7: 195.25 | E7: 0.1 | F7: =D7+(D7*E7) -> 214.775 | H7: CALIDOSCOPI | I7: =SUMIF($B$4:$B$2000,H7,$D$4:$D$2000) -> 339 | J7: =K7-I7 -> 71.19 | K7: =SUMIF($B$4:$B$2000,H7,$F$4:$F$2000) -> 410.19
B8: AGMASFOOD | C8: 26 5951 | D8: 94.8 | E8: 0.1 | F8: =D8+(D8*E8) -> 104.28 | H8: CARNICAS MEAT | I8: =SUMIF($B$4:$B$2000,H8,$D$4:$D$2000) -> 1412.35 | J8: =K8-I8 -> 141.235 | K8: =SUMIF($B$4:$B$2000,H8,$F$4:$F$2000) -> 1553.585
B9: AGMASFOOD | C9: 26 6564 | D9: 203.06 | E9: 0.1 | F9: =D9+(D9*E9) -> 223.366 | H9: CARNICAS OPC | I9: =SUMIF($B$4:$B$2000,H9,$D$4:$D$2000) -> 240.66 | J9: =K9-I9 -> 35.715 | K9: =SUMIF($B$4:$B$2000,H9,$F$4:$F$2000) -> 276.375
B10: AGMASFOOD | C10: 26 6530 | D10: 126 | E10: 0.1 | F10: =D10+(D10*E10) -> 138.6 | H10: COCACOLA | I10: =SUMIF($B$4:$B$2000,H10,$D$4:$D$2000) -> 2124.02 | J10: =K10-I10 -> 403.5094 | K10: =SUMIF($B$4:$B$2000,H10,$F$4:$F$2000) -> 2527.5294
B11: AGMASFOOD | C11: 26 6503 | D11: 84 | E11: 0.1 | F11: =D11+(D11*E11) -> 92.4 | H11: CONS. SELEC. SANTO | I11: =SUMIF($B$4:$B$2000,H11,$D$4:$D$2000) -> 705.24 | J11: =K11-I11 -> 70.524 | K11: =SUMIF($B$4:$B$2000,H11,$F$4:$F$2000) -> 775.764
B12: AGMASFOOD | C12: 26 6629 | D12: 84 | E12: 0.1 | F12: =D12+(D12*E12) -> 92.4 | H12: CONS. Y SAL. JIMENEZ | I12: =SUMIF($B$4:$B$2000,H12,$D$4:$D$2000) -> 3739.92 | J12: =K12-I12 -> 373.992 | K12: =SUMIF($B$4:$B$2000,H12,$F$4:$F$2000) -> 4113.912
B13: AGROFOOD | C13: M26/810 | D13: 441 | E13: 0.1 | F13: =D13+(D13*E13) -> 485.1 | H13: CRNAS SERVAN | I13: =SUMIF($B$4:$B$2000,H13,$D$4:$D$2000) -> 1086.03 | J13: =K13-I13 -> 108.603 | K13: =SUMIF($B$4:$B$2000,H13,$F$4:$F$2000) -> 1194.633
B14: AGROFOOD | C14: M26/787 | D14: 290.59 | E14: 0.1 | F14: =D14+(D14*E14) -> 319.649 | H14: CRUSTAPESCA | I14: =SUMIF($B$4:$B$2000,H14,$D$4:$D$2000) -> 1970.46 | J14: =K14-I14 -> 197.046 | K14: =SUMIF($B$4:$B$2000,H14,$F$4:$F$2000) -> 2167.506
B15: AGROFOOD | C15: M26/776 | D15: 494.86 | E15: 0.1 | F15: =D15+(D15*E15) -> 544.346 | H15: DELIPAN | I15: =SUMIF($B$4:$B$2000,H15,$D$4:$D$2000) -> 1032.66 | J15: =K15-I15 -> 57.1626 | K15: =SUMIF($B$4:$B$2000,H15,$F$4:$F$2000) -> 1089.8226
B16: AGROFOOD | C16: M26/865 | D16: 512.15 | E16: 0.1 | F16: =D16+(D16*E16) -> 563.365 | H16: DISOLTRIGO | I16: =SUMIF($B$4:$B$2000,H16,$D$4:$D$2000) -> 1295.5 | J16: =K16-I16 -> 129.55 | K16: =SUMIF($B$4:$B$2000,H16,$F$4:$F$2000) -> 1425.05
... B40: COCACOLA | C40: 970813 | D40: 232.84 | E40: 0.21 | F40: =D40+(D40*E40) -> 281.7364 | H40: VOLDIS | I40: =SUMIF($B$4:$B$2000,H40,$D$4:$D$2000) -> 6546.46 | J40: =K40-I40 -> 1269.007 | K40: =SUMIF($B$4:$B$2000,H40,$F$4:$F$2000) -> 7815.467
B41: COCACOLA | C41: 122492 | D41: 484.55 | E41: 0.21 | F41: =D41+(D41*E41) -> 586.3055 | H41: TOTAL | I41: =SUM(I4:I40) -> 63628.05 | J41: =SUM(J4:J40) -> 8355.597 | K41: =SUM(K4:K40) -> 71983.647
B42: COCACOLA | C42: 366393 | D42: 334.24 | E42: 0.1 | F42: =D42+(D42*E42) -> 367.664
B43: COCACOLA | C43: 366398 | D43: 48 | E43: 0.21 | F43: =D43+(D43*E43) -> 58.08
B44: CONS. SELEC. SANTO | C44: 4604 | D44: 347.76 | E44: 0.1 | F44: =D44+(D44*E44) -> 382.536
B45: CONS. SELEC. SANTO | C45: 5016 | D45: 357.48 | E45: 0.1 | F45: =D45+(D45*E45) -> 393.228
B46: CONS. Y SAL. JIMENEZ | C46: 26A00878 | D46: 719.71 | E46: 0.1 | F46: =D46+(D46*E46) -> 791.681
B47: CONS. Y SAL. JIMENEZ | C47: 26A00831 | D47: 993.58 | E47: 0.1 | F47: =D47+(D47*E47) -> 1092.938
B48: CONS. Y SAL. JIMENEZ | C48: 26A00946 | D48: 270.32 | E48: 0.1 | F48: =D48+(D48*E48) -> 297.352
B49: CONS. Y SAL. JIMENEZ | C49: 26A00922 | D49: 132.5 | E49: 0.1 | F49: =D49+(D49*E49) -> 145.75
B50: CONS. Y SAL. JIMENEZ | C50: 26A00916 | D50: 812.77 | E50: 0.1 | F50: =D50+(D50*E50) -> 894.047
B51: CONS. Y SAL. JIMENEZ | C51: 26A00903 | D51: 229.16 | E51: 0.1 | F51: =D51+(D51*E51) -> 252.076
B52: CONS. Y SAL. JIMENEZ | C52: 26A00978 | D52: 581.88 | E52: 0.1 | F52: =D52+(D52*E52) -> 640.068
B53: CRNAS SERVAN | C53: A2607-0444 | D53: 84.6 | E53: 0.1 | F53: =D53+(D53*E53) -> 93.06
... B274: VOLDIS | C274: 25801 | D274: 1257.42 | E274: 0.21 | F274: =D274+(D274*E274) -> 1521.4782

Sheet CUADRE ALBARANES
A2: CUADRE POR PROVEEDOR Y MES
A3: Compara, en cada hoja de proveedor, la suma de las líneas de producto con la suma de albaranes, y ésta con la hoja TOTAL del mes (fórmula sobre TOTAL JULIO). Tolerancia ±0,05 €.
A5: PROVEEDOR | B5: MES | C5: TOTAL LÍNEAS PRODUCTO | D5: TOTAL ALBARANES (hoja proveedor) | E5: TOTAL EN HOJA TOTAL DEL MES | F5: DIF. LÍNEAS − ALBARANES | G5: DIF. ALBARANES − HOJA TOTAL | H5: ¿CUADRA? | I5: NOTA
A6: AGMASFOOD | B6: JULIO | C6: =SUM(_____AGMASFOOD!F6:F300) -> 1122.98 | D6: =SUM(_____AGMASFOOD!I9:I300) -> 1122.99 | E6: =SUMIF('TOTAL JULIO'!$B$4:$B$2000,"AGMASFOOD",'TOTAL JULIO'!$D$4:$D$2000) -> 1122.99 | F6: =IF(D6="","",ROUND(C6-D6,2)) -> -0.01 | G6: =IF(D6="",ROUND(C6-E6,2),ROUND(D6-E6,2)) -> 0 | H6: =IF(AND(ABS(N(F6))<=0.05,ABS(G6)<=0.05),"OK","REVISAR") -> OK
A7: AGROFOOD | B7: JULIO | C7: =SUM(_____AGROFOOD!F6:F300) -> 4059.71 | D7: =SUM(_____AGROFOOD!I9:I300) -> 4059.72 | E7: =SUMIF('TOTAL JULIO'!$B$4:$B$2000,"AGROFOOD",'TOTAL JULIO'!$D$4:$D$2000) -> 4059.72 | F7: =IF(D7="","",ROUND(C7-D7,2)) -> -0.01 | G7: =IF(D7="",ROUND(C7-E7,2),ROUND(D7-E7,2)) -> 0 | H7: =IF(AND(ABS(N(F7))<=0.05,ABS(G7)<=0.05),"OK","REVISAR") -> OK
A8: ANTONIO DE MIGUEL | B8: JULIO | C8: =SUM('_____ANTONIO DE MIGUEL'!F6:F300) -> 280.3 | D8: =SUM('_____ANTONIO DE MIGUEL'!I9:I300) -> 280.3 | E8: =SUMIF('TOTAL JULIO'!$B$4:$B$2000,"ANTONIO DE MIGUEL",'TOTAL JULIO'!$D$4:$D$2000) -> 280.3 | F8: =IF(D8="","",ROUND(C8-D8,2)) -> 0 | G8: =IF(D8="",ROUND(C8-E8,2),ROUND(D8-E8,2)) -> 0 | H8: =IF(AND(ABS(N(F8))<=0.05,ABS(G8)<=0.05),"OK","REVISAR") -> OK
A9: CALIDOSCOPI | B9: JULIO | C9: =SUM(_____CALIDOSCOPI!F6:F300) -> 339 | D9: =SUM(_____CALIDOSCOPI!I9:I300) -> 339 | E9: =SUMIF('TOTAL JULIO'!$B$4:$B$2000,"CALIDOSCOPI",'TOTAL JULIO'!$D$4:$D$2000) -> 339 | F9: =IF(D9="","",ROUND(C9-D9,2)) -> 0 | G9: =IF(D9="",ROUND(C9-E9,2),ROUND(D9-E9,2)) -> 0 | H9: =IF(AND(ABS(N(F9))<=0.05,ABS(G9)<=0.05),"OK","REVISAR") -> OK
A10: CARNICAS MEAT | B10: JULIO | C10: =SUM('_____CARNICAS MEAT'!F6:F300) -> 1412.4078 | D10: =SUM('_____CARNICAS MEAT'!I9:I300) -> 1412.35 | E10: =SUMIF('TOTAL JULIO'!$B$4:$B$2000,"CARNICAS MEAT",'TOTAL JULIO'!$D$4:$D$2000) -> 1412.35 | F10: =IF(D10="","",ROUND(C10-D10,2)) -> 0.06 | G10: =IF(D10="",ROUND(C10-E10,2),ROUND(D10-E10,2)) -> 0 | H10: =IF(AND(ABS(N(F10))<=0.05,ABS(G10)<=0.05),"OK","REVISAR") -> REVISAR | I10: Diferencia de redondeo en las líneas (A1/209: 6,48 kg x 34,55 = 223,88 € y el albarán pone 223,85 €).
A11: CARNICAS OPC | B11: JULIO | C11: =SUM('_____CARNICAS OPC'!F6:F300) -> 240.66 | D11: =SUM('_____CARNICAS OPC'!I9:I300) -> 240.66 | E11: =SUMIF('TOTAL JULIO'!$B$4:$B$2000,"CARNICAS OPC",'TOTAL JULIO'!$D$4:$D$2000) -> 240.66 | F11: =IF(D11="","",ROUND(C11-D11,2)) -> 0 | G11: =IF(D11="",ROUND(C11-E11,2),ROUND(D11-E11,2)) -> 0 | H11: =IF(AND(ABS(N(F11))<=0.05,ABS(G11)<=0.05),"OK","REVISAR") -> OK
A12: COCACOLA | B12: JULIO | C12: =SUM('_____COCA-COLA'!F6:F300) -> 2124 | D12: =SUM('_____COCA-COLA'!I9:I300) -> 2124.02 | E12: =SUMIF('TOTAL JULIO'!$B$4:$B$2000,"COCACOLA",'TOTAL JULIO'!$D$4:$D$2000) -> 2124.02 | F12: =IF(D12="","",ROUND(C12-D12,2)) -> -0.02 | G12: =IF(D12="",ROUND(C12-E12,2),ROUND(D12-E12,2)) -> 0 | H12: =IF(AND(ABS(N(F12))<=0.05,ABS(G12)<=0.05),"OK","REVISAR") -> OK
A13: CONS. SELEC. SANTO | B13: JULIO | C13: =SUM('_____CONS. SELEC. SANT'!F6:F300) -> 705.24 | D13: =SUM('_____CONS. SELEC. SANT'!I9:I300) -> 705.24 | E13: =SUMIF('TOTAL JULIO'!$B$4:$B$2000,"CONS. SELEC. SANTO",'TOTAL JULIO'!$D$4:$D$2000) -> 705.24 | F13: =IF(D13="","",ROUND(C13-D13,2)) -> 0 | G13: =IF(D13="",ROUND(C13-E13,2),ROUND(D13-E13,2)) -> 0 | H13: =IF(AND(ABS(N(F13))<=0.05,ABS(G13)<=0.05),"OK","REVISAR") -> OK
A14: CONS. Y SAL. JIMENEZ | B14: JULIO | C14: =SUM('_____CONS. Y SALAZONES'!F6:F300) -> 3739.9387 | D14: =SUM('_____CONS. Y SALAZONES'!I9:I300) -> 3739.92 | E14: =SUMIF('TOTAL JULIO'!$B$4:$B$2000,"CONS. Y SAL. JIMENEZ",'TOTAL JULIO'!$D$4:$D$2000) -> 3739.92 | F14: =IF(D14="","",ROUND(C14-D14,2)) -> 0.02 | G14: =IF(D14="",ROUND(C14-E14,2),ROUND(D14-E14,2)) -> 0 | H14: =IF(AND(ABS(N(F14))<=0.05,ABS(G14)<=0.05),"OK","REVISAR") -> OK
A15: CRNAS SERVAN | B15: JULIO | C15: =SUM('_____CRNAS SERVAN'!F6:F300) -> 1086.025 | D15: =SUM('_____CRNAS SERVAN'!I9:I300) -> 1086.03 | E15: =SUMIF('TOTAL JULIO'!$B$4:$B$2000,"CRNAS SERVAN",'TOTAL JULIO'!$D$4:$D$2000) -> 1086.03 | F15: =IF(D15="","",ROUND(C15-D15,2)) -> 0 | G15: =IF(D15="",ROUND(C15-E15,2),ROUND(D15-E15,2)) -> 0 | H15: =IF(AND(ABS(N(F15))<=0.05,ABS(G15)<=0.05),"OK","REVISAR") -> OK
A16: CRUSTAPESCA | B16: JULIO | C16: =SUM(_____CRUSTAPESCA!F6:F300) -> 1970.464 | D16: =SUM(_____CRUSTAPESCA!I9:I300) -> 1970.46 | E16: =SUMIF('TOTAL JULIO'!$B$4:$B$2000,"CRUSTAPESCA",'TOTAL JULIO'!$D$4:$D$2000) -> 1970.46 | F16: =IF(D16="","",ROUND(C16-D16,2)) -> 0 | G16: =IF(D16="",ROUND(C16-E16,2),ROUND(D16-E16,2)) -> 0 | H16: =IF(AND(ABS(N(F16))<=0.05,ABS(G16)<=0.05),"OK","REVISAR") -> OK
A17: DELIPAN | B17: JULIO | C17: =SUM(_____DELIPAN!F6:F300) -> 1032.66 | D17: =SUM(_____DELIPAN!I9:I300) -> 1032.66 | E17: =SUMIF('TOTAL JULIO'!$B$4:$B$2000,"DELIPAN",'TOTAL JULIO'!$D$4:$D$2000) -> 1032.66 | F17: =IF(D17="","",ROUND(C17-D17,2)) -> 0 | G17: =IF(D17="",ROUND(C17-E17,2),ROUND(D17-E17,2)) -> 0 | H17: =IF(AND(ABS(N(F17))<=0.05,ABS(G17)<=0.05),"OK","REVISAR") -> OK
A18: DISOLTRIGO | B18: JULIO | C18: =SUM(_____DISOLTRIGO!F6:F300) -> 1295.5 | D18: =SUM(_____DISOLTRIGO!I9:I300) -> 1295.5 | E18: =SUMIF('TOTAL JULIO'!$B$4:$B$2000,"DISOLTRIGO",'TOTAL JULIO'!$D$4:$D$2000) -> 1295.5 | F18: =IF(D18="","",ROUND(C18-D18,2)) -> 0 | G18: =IF(D18="",ROUND(C18-E18,2),ROUND(D18-E18,2)) -> 0 | H18: =IF(AND(ABS(N(F18))<=0.05,ABS(G18)<=0.05),"OK","REVISAR") -> OK
A19: DIST. TENA MTNEZ | B19: JULIO | C19: =SUM('_____DIST. TENA'!F6:F300) -> 3131.64 | D19: =SUM('_____DIST. TENA'!I9:I300) -> 3131.64 | E19: =SUMIF('TOTAL JULIO'!$B$4:$B$2000,"DIST. TENA MTNEZ",'TOTAL JULIO'!$D$4:$D$2000) -> 3131.64 | F19: =IF(D19="","",ROUND(C19-D19,2)) -> 0 | G19: =IF(D19="",ROUND(C19-E19,2),ROUND(D19-E19,2)) -> 0 | H19: =IF(AND(ABS(N(F19))<=0.05,ABS(G19)<=0.05),"OK","REVISAR") -> OK
A20: EIF DISTRIBUCIONES | B20: JULIO | C20: =SUM('_____EIF DISTRIBUCIONES'!F6:F300) -> 646.5718 | D20: =SUM('_____EIF DISTRIBUCIONES'!I9:I300) -> 646.58 | E20: =SUMIF('TOTAL JULIO'!$B$4:$B$2000,"EIF DISTRIBUCIONES",'TOTAL JULIO'!$D$4:$D$2000) -> 646.58 | F20: =IF(D20="","",ROUND(C20-D20,2)) -> -0.01 | G20: =IF(D20="",ROUND(C20-E20,2),ROUND(D20-E20,2)) -> 0 | H20: =IF(AND(ABS(N(F20))<=0.05,ABS(G20)<=0.05),"OK","REVISAR") -> OK
A21: ENRIQUE CAMPS | B21: JULIO | C21: =SUM('_____ENRIQUE CAMPS'!F6:F300) -> 1189 | D21: =SUM('_____ENRIQUE CAMPS'!I9:I300) -> 1189 | E21: =SUMIF('TOTAL JULIO'!$B$4:$B$2000,"ENRIQUE CAMPS",'TOTAL JULIO'!$D$4:$D$2000) -> 1189 | F21: =IF(D21="","",ROUND(C21-D21,2)) -> 0 | G21: =IF(D21="",ROUND(C21-E21,2),ROUND(D21-E21,2)) -> 0 | H21: =IF(AND(ABS(N(F21))<=0.05,ABS(G21)<=0.05),"OK","REVISAR") -> OK
A22: ESCRIBANO SANZ | B22: JULIO | C22: =SUM('_____ESCRIBANO SANZ'!F6:F300) -> 193.69 | D22: =SUM('_____ESCRIBANO SANZ'!I9:I300) -> 193.7 | E22: =SUMIF('TOTAL JULIO'!$B$4:$B$2000,"ESCRIBANO SANZ",'TOTAL JULIO'!$D$4:$D$2000) -> 193.7 | F22: =IF(D22="","",ROUND(C22-D22,2)) -> -0.01 | G22: =IF(D22="",ROUND(C22-E22,2),ROUND(D22-E22,2)) -> 0 | H22: =IF(AND(ABS(N(F22))<=0.05,ABS(G22)<=0.05),"OK","REVISAR") -> OK
A23: FCO JAVIER LABRADOR | B23: JULIO | C23: =SUM('_____FCO JAVIER LABRADOR'!F6:F300) -> 183.2 | D23: =SUM('_____FCO JAVIER LABRADOR'!I9:I300) -> 183.2 | E23: =SUMIF('TOTAL JULIO'!$B$4:$B$2000,"FCO JAVIER LABRADOR",'TOTAL JULIO'!$D$4:$D$2000) -> 183.2 | F23: =IF(D23="","",ROUND(C23-D23,2)) -> 0 | G23: =IF(D23="",ROUND(C23-E23,2),ROUND(D23-E23,2)) -> 0 | H23: =IF(AND(ABS(N(F23))<=0.05,ABS(G23)<=0.05),"OK","REVISAR") -> OK
A24: FRUTERIA D'ALISTE | B24: JULIO | C24: =SUM('_____FRUTERIA DALISTE'!F6:F300) -> 158.9995 | D24: =SUM('_____FRUTERIA DALISTE'!I9:I300) -> 158.99 | E24: =SUMIF('TOTAL JULIO'!$B$4:$B$2000,"FRUTERIA D'ALISTE",'TOTAL JULIO'!$D$4:$D$2000) -> 158.99 | F24: =IF(D24="","",ROUND(C24-D24,2)) -> 0.01 | G24: =IF(D24="",ROUND(C24-E24,2),ROUND(D24-E24,2)) -> 0 | H24: =IF(AND(ABS(N(F24))<=0.05,ABS(G24)<=0.05),"OK","REVISAR") -> OK
A25: JOSE PEÑA | B25: JULIO | C25: =SUM('_____JOSE PEÑA'!F6:F300) -> 748.5 | D25: =SUM('_____JOSE PEÑA'!I9:I300) -> 748.5 | E25: =SUMIF('TOTAL JULIO'!$B$4:$B$2000,"JOSE PEÑA",'TOTAL JULIO'!$D$4:$D$2000) -> 748.5 | F25: =IF(D25="","",ROUND(C25-D25,2)) -> 0 | G25: =IF(D25="",ROUND(C25-E25,2),ROUND(D25-E25,2)) -> 0 | H25: =IF(AND(ABS(N(F25))<=0.05,ABS(G25)<=0.05),"OK","REVISAR") -> OK
A26: JOSE ROMERO PLAZA | B26: JULIO | C26: =SUM('_____JOSE ROMERO PLAZA'!F6:F300) -> 444.1 | D26: =SUM('_____JOSE ROMERO PLAZA'!I9:I300) -> 444.1 | E26: =SUMIF('TOTAL JULIO'!$B$4:$B$2000,"JOSE ROMERO PLAZA",'TOTAL JULIO'!$D$4:$D$2000) -> 444.1 | F26: =IF(D26="","",ROUND(C26-D26,2)) -> 0 | G26: =IF(D26="",ROUND(C26-E26,2),ROUND(D26-E26,2)) -> 0 | H26: =IF(AND(ABS(N(F26))<=0.05,ABS(G26)<=0.05),"OK","REVISAR") -> OK
A27: MAGOASE | B27: JULIO | C27: =SUM(_____MAGOASE!F6:F300) -> 1815.6 | D27: =SUM(_____MAGOASE!I9:I300) -> 1815.6 | E27: =SUMIF('TOTAL JULIO'!$B$4:$B$2000,"MAGOASE",'TOTAL JULIO'!$D$4:$D$2000) -> 1815.6 | F27: =IF(D27="","",ROUND(C27-D27,2)) -> 0 | G27: =IF(D27="",ROUND(C27-E27,2),ROUND(D27-E27,2)) -> 0 | H27: =IF(AND(ABS(N(F27))<=0.05,ABS(G27)<=0.05),"OK","REVISAR") -> OK
A28: MAKRO | B28: JULIO | C28: =SUM(_____MAKRO!F6:F300) -> 227.89 | D28: =SUM(_____MAKRO!I9:I300) -> 227.89 | E28: =SUMIF('TOTAL JULIO'!$B$4:$B$2000,"MAKRO",'TOTAL JULIO'!$D$4:$D$2000) -> 227.89 | F28: =IF(D28="","",ROUND(C28-D28,2)) -> 0 | G28: =IF(D28="",ROUND(C28-E28,2),ROUND(D28-E28,2)) -> 0 | H28: =IF(AND(ABS(N(F28))<=0.05,ABS(G28)<=0.05),"OK","REVISAR") -> OK
A29: MANUEL AMBRES | B29: JULIO | C29: =SUM('_____MANU AMBRES'!F6:F300) -> 904.824 | D29: =SUM('_____MANU AMBRES'!I9:I300) -> 904.82 | E29: =SUMIF('TOTAL JULIO'!$B$4:$B$2000,"MANUEL AMBRES",'TOTAL JULIO'!$D$4:$D$2000) -> 904.82 | F29: =IF(D29="","",ROUND(C29-D29,2)) -> 0 | G29: =IF(D29="",ROUND(C29-E29,2),ROUND(D29-E29,2)) -> 0 | H29: =IF(AND(ABS(N(F29))<=0.05,ABS(G29)<=0.05),"OK","REVISAR") -> OK
A30: MARTIN CANEDA | B30: JULIO | C30: =SUM('_____MARTIN CANEDA'!F6:F300) -> 3561.4 | D30: =SUM('_____MARTIN CANEDA'!I9:I300) -> 3561.4 | E30: =SUMIF('TOTAL JULIO'!$B$4:$B$2000,"MARTIN CANEDA",'TOTAL JULIO'!$D$4:$D$2000) -> 3561.4 | F30: =IF(D30="","",ROUND(C30-D30,2)) -> 0 | G30: =IF(D30="",ROUND(C30-E30,2),ROUND(D30-E30,2)) -> 0 | H30: =IF(AND(ABS(N(F30))<=0.05,ABS(G30)<=0.05),"OK","REVISAR") -> OK
A31: MONVA | B31: JULIO | C31: =SUM(_____MONVA!F6:F300) -> 171 | D31: =SUM(_____MONVA!I9:I300) -> 171 | E31: =SUMIF('TOTAL JULIO'!$B$4:$B$2000,"MONVA",'TOTAL JULIO'!$D$4:$D$2000) -> 171 | F31: =IF(D31="","",ROUND(C31-D31,2)) -> 0 | G31: =IF(D31="",ROUND(C31-E31,2),ROUND(D31-E31,2)) -> 0 | H31: =IF(AND(ABS(N(F31))<=0.05,ABS(G31)<=0.05),"OK","REVISAR") -> OK
A32: MUNDELA | B32: JULIO | C32: =SUM(_____MUNDELA!F6:F300) -> 5092.38 | D32: =SUM(_____MUNDELA!I9:I300) -> 5092.38 | E32: =SUMIF('TOTAL JULIO'!$B$4:$B$2000,"MUNDELA",'TOTAL JULIO'!$D$4:$D$2000) -> 5092.38 | F32: =IF(D32="","",ROUND(C32-D32,2)) -> 0 | G32: =IF(D32="",ROUND(C32-E32,2),ROUND(D32-E32,2)) -> 0 | H32: =IF(AND(ABS(N(F32))<=0.05,ABS(G32)<=0.05),"OK","REVISAR") -> OK
A33: PATATAS YAGO | B33: JULIO | C33: =SUM('_____PATATAS YAGO'!F6:F300) -> 611.4 | D33: =SUM('_____PATATAS YAGO'!I9:I300) -> 611.4 | E33: =SUMIF('TOTAL JULIO'!$B$4:$B$2000,"PATATAS YAGO",'TOTAL JULIO'!$D$4:$D$2000) -> 611.4 | F33: =IF(D33="","",ROUND(C33-D33,2)) -> 0 | G33: =IF(D33="",ROUND(C33-E33,2),ROUND(D33-E33,2)) -> 0 | H33: =IF(AND(ABS(N(F33))<=0.05,ABS(G33)<=0.05),"OK","REVISAR") -> OK
A34: PESCADERIA PALACIO | B34: JULIO | C34: =SUM('_____PESCADERIA PALACIO'!F6:F300) -> 1400.16 | D34: =SUM('_____PESCADERIA PALACIO'!I9:I300) -> 1400.16 | E34: =SUMIF('TOTAL JULIO'!$B$4:$B$2000,"PESCADERIA PALACIO",'TOTAL JULIO'!$D$4:$D$2000) -> 1400.16 | F34: =IF(D34="","",ROUND(C34-D34,2)) -> 0 | G34: =IF(D34="",ROUND(C34-E34,2),ROUND(D34-E34,2)) -> 0 | H34: =IF(AND(ABS(N(F34))<=0.05,ABS(G34)<=0.05),"OK","REVISAR") -> OK
A35: PESCARUM | B35: JULIO | C35: =SUM(_____PESCARUM!F6:F300) -> 10740.805 | D35: =SUM(_____PESCARUM!I9:I300) -> 10740.83 | E35: =SUMIF('TOTAL JULIO'!$B$4:$B$2000,"PESCARUM",'TOTAL JULIO'!$D$4:$D$2000) -> 10740.83 | F35: =IF(D35="","",ROUND(C35-D35,2)) -> -0.03 | G35: =IF(D35="",ROUND(C35-E35,2),ROUND(D35-E35,2)) -> 0 | H35: =IF(AND(ABS(N(F35))<=0.05,ABS(G35)<=0.05),"OK","REVISAR") -> OK
A36: PEÑALASTALLAS | B36: JULIO | C36: =SUM(_____PEÑALASTALLAS!F6:F300) -> 1635.591 | D36: =SUM(_____PEÑALASTALLAS!I9:I300) -> 1635.61 | E36: =SUMIF('TOTAL JULIO'!$B$4:$B$2000,"PEÑALASTALLAS",'TOTAL JULIO'!$D$4:$D$2000) -> 1568.32 | F36: =IF(D36="","",ROUND(C36-D36,2)) -> -0.02 | G36: =IF(D36="",ROUND(C36-E36,2),ROUND(D36-E36,2)) -> 67.29 | H36: =IF(AND(ABS(N(F36))<=0.05,ABS(G36)<=0.05),"OK","REVISAR") -> REVISAR | I36: Importe suelto de 67,29 € en la hoja sin nº de albarán ni reflejo en TOTAL JULIO (ver incidencias).
A37: ROMERO ALVAREZ | B37: JULIO | C37: =SUM('_____ROMERO ALVAREZ'!F6:F300) -> 533.736 | D37: =SUM('_____ROMERO ALVAREZ'!I9:I300) -> 533.74 | E37: =SUMIF('TOTAL JULIO'!$B$4:$B$2000,"ROMERO ALVAREZ",'TOTAL JULIO'!$D$4:$D$2000) -> 533.74 | F37: =IF(D37="","",ROUND(C37-D37,2)) -> 0 | G37: =IF(D37="",ROUND(C37-E37,2),ROUND(D37-E37,2)) -> 0 | H37: =IF(AND(ABS(N(F37))<=0.05,ABS(G37)<=0.05),"OK","REVISAR") -> OK
A38: SUBMARINER | B38: JULIO | C38: =SUM(_____SUBMARINER!F6:F300) -> 3291.3008 | D38: =SUM(_____SUBMARINER!I9:I300) -> 3291.32 | E38: =SUMIF('TOTAL JULIO'!$B$4:$B$2000,"SUBMARINER",'TOTAL JULIO'!$D$4:$D$2000) -> 3291.32 | F38: =IF(D38="","",ROUND(C38-D38,2)) -> -0.02 | G38: =IF(D38="",ROUND(C38-E38,2),ROUND(D38-E38,2)) -> 0 | H38: =IF(AND(ABS(N(F38))<=0.05,ABS(G38)<=0.05),"OK","REVISAR") -> OK
A39: TOMATERIA DE CEA | B39: JULIO | C39: =SUM('_____TOMATERIA CEA'!F6:F300) -> 584.97 | D39: =SUM('_____TOMATERIA CEA'!I9:I300) -> 584.97 | E39: =SUMIF('TOTAL JULIO'!$B$4:$B$2000,"TOMATERIA DE CEA",'TOTAL JULIO'!$D$4:$D$2000) -> 584.97 | F39: =IF(D39="","",ROUND(C39-D39,2)) -> 0 | G39: =IF(D39="",ROUND(C39-E39,2),ROUND(D39-E39,2)) -> 0 | H39: =IF(AND(ABS(N(F39))<=0.05,ABS(G39)<=0.05),"OK","REVISAR") -> OK
A40: VENERO CLARO | B40: JULIO | C40: =SUM('_____VENERO CLARO'!F6:F300) -> 270.4 | D40: =SUM('_____VENERO CLARO'!I9:I300) -> 270.4 | E40: =SUMIF('TOTAL JULIO'!$B$4:$B$2000,"VENERO CLARO",'TOTAL JULIO'!$D$4:$D$2000) -> 270.4 | F40: =IF(D40="","",ROUND(C40-D40,2)) -> 0 | G40: =IF(D40="",ROUND(C40-E40,2),ROUND(D40-E40,2)) -> 0 | H40: =IF(AND(ABS(N(F40))<=0.05,ABS(G40)<=0.05),"OK","REVISAR") -> OK
A41: VINS DES DIEUX | B41: JULIO | C41: =SUM('_____VINS DES DIEUX'!F6:F300) -> 202.8 | D41: =SUM('_____VINS DES DIEUX'!I9:I300) -> 202.8 | E41: =SUMIF('TOTAL JULIO'!$B$4:$B$2000,"VINS DES DIEUX",'TOTAL JULIO'!$D$4:$D$2000) -> 202.8 | F41: =IF(D41="","",ROUND(C41-D41,2)) -> 0 | G41: =IF(D41="",ROUND(C41-E41,2),ROUND(D41-E41,2)) -> 0 | H41: =IF(AND(ABS(N(F41))<=0.05,ABS(G41)<=0.05),"OK","REVISAR") -> OK
A42: VOLDIS | B42: JULIO | C42: =SUM(_____VOLDIS!F6:F300) -> 6546.456 | D42: =SUM(_____VOLDIS!I9:I300) -> 6546.46 | E42: =SUMIF('TOTAL JULIO'!$B$4:$B$2000,"VOLDIS",'TOTAL JULIO'!$D$4:$D$2000) -> 6546.46 | F42: =IF(D42="","",ROUND(C42-D42,2)) -> 0 | G42: =IF(D42="",ROUND(C42-E42,2),ROUND(D42-E42,2)) -> 0 | H42: =IF(AND(ABS(N(F42))<=0.05,ABS(G42)<=0.05),"OK","REVISAR") -> OK

Sheet _____AGMASFOOD
B2: 46204
H4: TOTAL | I4: =SUM(F6:F300) -> 1122.98
B5: PRODUCTO | C5: UNIDADES | D5: PRECIO | E5: DTO | F5: TOTAL | H5: ALBARANES | I5: =SUM(I9:I300) -> 1122.99
B6: LOMO NEGRO SIN COLA LIMPIO | C6: =4.9+5+5.2 -> 15.1 | D6: 39.05 | E6: 0 | F6: =(C6*D6)-((C6*D6)*E6) -> 589.655 | H6: DIFERENCIA | I6: =I5-I4 -> 0.01
B7: GAMBA ROJA ALISTADA 15-20P | C7: =1.3+1.2 -> 2.5 | D7: 79 | E7: 0 | F7: =(C7*D7)-((C7*D7)*E7) -> 197.5
B8: BOQUERON GORDO | C8: =3.5 -> 3.5 | D8: 11.95 | E8: 0 | F8: =(C8*D8)-((C8*D8)*E8) -> 41.825 | H8: Nº ALBARÁN | I8: BASE | J8: % IVA
B9: GAMBA ROJA ALISTADA 15-20P | C9: =1.5+1+1 -> 3.5 | D9: 84 | E9: 0 | F9: =(C9*D9)-((C9*D9)*E9) -> 294 | H9: 26 6093 | I9: 191.35 | J9: 0.1
H10: 26 6075 | I10: 102.7 | J10: 0.1
H11: 26 6029 | I11: 41.83 | J11: 0.1
H12: 26 5876 | I12: 195.25 | J12: 0.1
H13: 26 5951 | I13: 94.8 | J13: 0.1
H14: 26 6564 | I14: 203.06 | J14: 0.1
H15: 26 6530 | I15: 126 | J15: 0.1
H16: 26 6503 | I16: 84 | J16: 0.1
H17: 26 6629 | I17: 84 | J17: 0.1

Sheet _____AGROFOOD
B2: 46204
H4: TOTAL | I4: =SUM(F6:F300) -> 4059.71
B5: PRODUCTO | C5: UNIDADES | D5: PRECIO | E5: DTO | F5: TOTAL | H5: ALBARANES | I5: =SUM(I9:I300) -> 4059.72
B6: ENTRECOT T. MORUCHA | C6: =6.95+3.4+7.12+3.42+15.16+10.41+3.21+8.21+13.51+3.29+7.16+3.57+13.04+10.45 -> 108.9 | D6: 27.5 | E6: 0 | F6: =(C6*D6)-((C6*D6)*E6) -> 2994.75 | H6: DIFERENCIA | I6: =I5-I4 -> 0.01
B7: MEDALLON P. SOLOMILLO VACUNO | C7: =2.09+2.12+2.08+2+2.05+2.04+4.19+2.03+2.01+1.94+3.95+2.1 -> 28.6 | D7: 36.9 | E7: 0 | F7: =(C7*D7)-((C7*D7)*E7) -> 1055.34
B8: TASA DE ELIMINACION DE RESIDUOS | C8: 1 | D8: 1.02 | E8: 0 | F8: =(C8*D8)-((C8*D8)*E8) -> 1.02 | H8: Nº ALBARÁN | I8: BASE | J8: % IVA
B9: TASA DE ELIMINACION DE RESIDUOS | C9: 1 | D9: 0.74 | E9: 0 | F9: =(C9*D9)-((C9*D9)*E9) -> 0.74 | H9: M26/810 | I9: 441 | J9: 0.1
B10: TASA DE ELIMINACION DE RESIDUOS | C10: 1 | D10: 1.21 | E10: 0 | F10: =(C10*D10)-((C10*D10)*E10) -> 1.21 | H10: M26/787 | I10: 290.59 | J10: 0.1
B11: TASA DE ELIMINACION DE RESIDUOS | C11: 1 | D11: 1.15 | E11: 0 | F11: =(C11*D11)-((C11*D11)*E11) -> 1.15 | H11: M26/776 | I11: 494.86 | J11: 0.1
B12: TASA DE ELIMINACION DE RESIDUOS | C12: 1 | D12: 0.22 | E12: 0 | F12: =(C12*D12)-((C12*D12)*E12) -> 0.22 | H12: M26/865 | I12: 512.15 | J12: 0.1
B13: TASA DE ELIMINACION DE RESIDUOS | C13: 1 | D13: 0.57 | E13: 0 | F13: =(C13*D13)-((C13*D13)*E13) -> 0.57 | H13: M26/849 | I13: 88.5 | J13: 0.1
B14: TASA DE ELIMINACION DE RESIDUOS | C14: 1 | D14: 1.47 | E14: 0 | F14: =(C14*D14)-((C14*D14)*E14) -> 1.47 | H14: M26/844 | I14: 226.35 | J14: 0.1
B15: TASA DE ELIMINACION DE RESIDUOS | C15: 1 | D15: 1.03 | E15: 0 | F15: =(C15*D15)-((C15*D15)*E15) -> 1.03 | H15: M26/839 | I15: 618.08 | J15: 0.1
B16: TASA DE ELIMINACION DE RESIDUOS | C16: 1 | D16: 1.33 | E16: 0 | F16: =(C16*D16)-((C16*D16)*E16) -> 1.33 | H16: M26/817 | I16: 445.18 | J16: 0.1
B17: TASA DE ELIMINACION DE RESIDUOS | C17: 1 | D17: 0.88 | E17: 0 | F17: =(C17*D17)-((C17*D17)*E17) -> 0.88 | H17: M26/890 | I17: 577.26 | J17: 0.1
H18: M26/872 | I18: 365.75 | J18: 0.1

Sheet _____ANTONIO DE MIGUEL
B2: 46204
H4: TOTAL | I4: =SUM(F6:F300) -> 280.3
B5: PRODUCTO | C5: UNIDADES | D5: PRECIO | E5: DTO | F5: TOTAL | H5: ALBARANES | I5: =SUM(I9:I300) -> 280.3
B6: PATO CEBADO-FOIE RESTAURACION (400-900) | C6: 10 | D6: 28.03 | E6: 0 | F6: =(C6*D6)-((C6*D6)*E6) -> 280.3 | H6: DIFERENCIA | I6: =I5-I4 -> 0
H8: Nº ALBARÁN | I8: BASE | J8: % IVA
H9: A/2066113 | I9: 280.3 | J9: 0.1

Sheet _____CALIDOSCOPI
B2: 46204
H4: TOTAL | I4: =SUM(F6:F300) -> 339
B5: PRODUCTO | C5: UNIDADES | D5: PRECIO | E5: DTO | F5: TOTAL | H5: ALBARANES | I5: =SUM(I9:I300) -> 339
B6: PAGO DE CARRAOVEJAS 2023 | C6: 12 | D6: 28.25 | E6: 0 | F6: =(C6*D6)-((C6*D6)*E6) -> 339 | H6: DIFERENCIA | I6: =I5-I4 -> 0
H8: Nº ALBARÁN | I8: BASE | J8: % IVA
H9: AV-CV26-004508 | I9: 339 | J9: 0.21

Sheet _____CARNICAS MEAT
B2: 46204
H4: TOTAL | I4: =SUM(F6:F300) -> 1412.4078
B5: PRODUCTO | C5: UNIDADES | D5: PRECIO | E5: DTO | F5: TOTAL | H5: ALBARANES | I5: =SUM(I9:I300) -> 1412.35
B6: CHULETA CORDERO LECHAL | C6: =8.86+6.715+4.685 -> 20.26 | D6: 25 | E6: 0 | F6: =(C6*D6)-((C6*D6)*E6) -> 506.5 | H6: DIFERENCIA | I6: =I5-I4 -> -0.05775
B7: TERNERA MIXTA | C7: =5.11 -> 5.11 | D7: 10.9 | E7: 0 | F7: =(C7*D7)-((C7*D7)*E7) -> 55.699
B8: SOLOMILLO VACA | C8: =5.445+6.48 -> 11.925 | D8: 34.55 | E8: 0 | F8: =(C8*D8)-((C8*D8)*E8) -> 412.00875 | H8: Nº ALBARÁN | I8: BASE | J8: % IVA
B9: SOLOMILLO VACA | C9: =5.795+6.725 -> 12.52 | D9: 35 | E9: 0 | F9: =(C9*D9)-((C9*D9)*E9) -> 438.2 | H9: A1/195 | I9: 221.5 | J9: 0.1
H10: A1/191 | I10: 243.8 | J10: 0.1
H11: A1/188 | I11: 370.7 | J11: 0.1
H12: A1/209 | I12: 340.98 | J12: 0.1
H13: A1/202 | I13: 235.37 | J13: 0.1

Sheet _____CARNICAS OPC
B2: 46204
H4: TOTAL | I4: =SUM(F6:F300) -> 240.66
B5: PRODUCTO | C5: UNIDADES | D5: PRECIO | E5: DTO | F5: TOTAL | H5: ALBARANES | I5: =SUM(I9:I300) -> 240.66
B6: MEDIA CAJA HUEVO | C6: 1 | D6: 45 | E6: 0 | F6: =(C6*D6)-((C6*D6)*E6) -> 45 | H6: DIFERENCIA | I6: =I5-I4 -> 0
B7: PANCETA ADOBADA | C7: =4.2+4+3 -> 11.2 | D7: 8.8 | E7: 0 | F7: =(C7*D7)-((C7*D7)*E7) -> 98.56
B8: CAJA HUEVOS CORRAL | C8: 1 | D8: 52.5 | E8: 0 | F8: =(C8*D8)-((C8*D8)*E8) -> 52.5 | H8: Nº ALBARÁN | I8: BASE | J8: % IVA
B9: POLLO TROCEADO | C9: =5.2 -> 5.2 | D9: 3.5 | E9: 0 | F9: =(C9*D9)-((C9*D9)*E9) -> 18.2 | H9: A2607-0221 | I9: 81.96 | J9: 0.1
B10: OREJA DE CERDO | C10: =4.4 -> 4.4 | D10: 6 | E10: 0 | F10: =(C10*D10)-((C10*D10)*E10) -> 26.4 | H10: A2607-0169 | I10: 105.9 | J10: 0.21
H11: A2607-0092 | I11: 52.8 | J11: 0.1

Sheet _____COCA-COLA
B2: 46204
H4: TOTAL | I4: =SUM(F6:F300) -> 2124
B5: PRODUCTO | C5: UNIDADES | D5: PRECIO | E5: DTO | F5: TOTAL | H5: ALBARANES | I5: =SUM(I9:I300) -> 2124.02
B6: CAJA+BOTELLAS VR237 | C6: 20 | D6: 4.8 | E6: 0 | F6: =(C6*D6)-((C6*D6)*E6) -> 96 | H6: DIFERENCIA | I6: =I5-I4 -> 0.02
B7: COCACOLA PET2L C6 | C7: 36 | D7: 2.504 | E7: 0 | F7: =(C7*D7)-((C7*D7)*E7) -> 90.144
B8: COCACOLA VR237 C24 | C8: =48+48+96+96+96+144 -> 528 | D8: 0.845 | E8: 0 | F8: =(C8*D8)-((C8*D8)*E8) -> 446.16 | H8: Nº ALBARÁN | I8: BASE | J8: % IVA
B9: COCACOLA VR237 C24 | C9: 21 | D9: 4.8 | E9: 0 | F9: =(C9*D9)-((C9*D9)*E9) -> 100.8 | H9: 521604 | I9: 200.66 | J9: 0.21
B10: COCACOLA ZER VR237 C24 | C10: =144+120+168+216+144+360+288 -> 1440 | D10: 0.845 | E10: 0 | F10: =(C10*D10)-((C10*D10)*E10) -> 1216.8 | H10: 629349 | I10: 141.96 | J10: 0.21
B11: COCACOLA ZER ZER VR237 C24 | C11: =48+24+72 -> 144 | D11: 0.845 | E11: 0 | F11: =(C11*D11)-((C11*D11)*E11) -> 121.68 | H11: 658014 | I11: 34.96 | J11: 0.1
B12: MINUTE MAID TOM VNR20 C24 | C12: =48+24 -> 72 | D12: 0.728 | E12: 0 | F12: =(C12*D12)-((C12*D12)*E12) -> 52.416 | H12: 658014 | I12: 293.69 | J12: 0.21
H13: 657975 | I13: 48 | J13: 0.21
H14: 874907 | I14: 17.48 | J14: 0.1
H15: 874907 | I15: 287.64 | J15: 0.21
H16: 970813 | I16: 232.84 | J16: 0.21
H17: 122492 | I17: 484.55 | J17: 0.21
H18: 366393 | I18: 334.24 | J18: 0.1
H19: 366398 | I19: 48 | J19: 0.21

Sheet _____CONS. SELEC. SANT
B2: 46204
H4: TOTAL | I4: =SUM(F6:F300) -> 705.24
B5: PRODUCTO | C5: UNIDADES | D5: PRECIO | E5: DTO | F5: TOTAL | H5: ALBARANES | I5: =SUM(I9:I300) -> 705.24
B6: DON BOCARTE MEDIO PULPO 360-400 gr | C6: =12.88+13.24 -> 26.12 | D6: 27 | E6: 0 | F6: =(C6*D6)-((C6*D6)*E6) -> 705.24 | H6: DIFERENCIA | I6: =I5-I4 -> 0
H8: Nº ALBARÁN | I8: BASE | J8: % IVA
H9: 4604 | I9: 347.76 | J9: 0.1
H10: 5016 | I10: 357.48 | J10: 0.1

Sheet _____CONS. Y SALAZONES
B2: 46204
H4: TOTAL | I4: =SUM(F6:F300) -> 3739.9387
B5: PRODUCTO | C5: UNIDADES | D5: PRECIO | E5: DTO | F5: TOTAL | H5: ALBARANES | I5: =SUM(I9:I300) -> 3739.92
B6: ANCHOAS CANTABRICO COSTERA | C6: =8+8+8+8+8+8 -> 48 | D6: 16.9 | E6: 0.02 | F6: =(C6*D6)-((C6*D6)*E6) -> 794.976 | H6: DIFERENCIA | I6: =I5-I4 -> -0.01872
B7: ANCHOAS DEL CANTABRICO GRAN RESERVA | C7: =16+16+16+16 -> 64 | D7: 28.66 | E7: 0.02 | F7: =(C7*D7)-((C7*D7)*E7) -> 1797.5552
B8: VENTRESCA DE BONITO EXTRA | C8: =24+24 -> 48 | D8: 5.86 | E8: 0.02 | F8: =(C8*D8)-((C8*D8)*E8) -> 275.6544 | H8: Nº ALBARÁN | I8: BASE | J8: % IVA
B9: MEJILLONES ESCABECHE RIAS GALLEGAS RR-125 | C9: 25 | D9: 5.86 | E9: 0.02 | F9: =(C9*D9)-((C9*D9)*E9) -> 143.57 | H9: 26A00878 | I9: 719.71 | J9: 0.1
B10: BERBERECHOS RIAS GALLEGAS RO-120 30/40 | C10: 24 | D10: 11.4 | E10: 0.02 | F10: =(C10*D10)-((C10*D10)*E10) -> 268.128 | H10: 26A00831 | I10: 993.58 | J10: 0.1
B11: ANCHOAS CANTABRICO RO-550 ETIQUETA ROJA | C11: 18 | D11: 20.6 | E11: 0.02 | F11: =(C11*D11)-((C11*D11)*E11) -> 363.384 | H11: 26A00946 | I11: 270.32 | J11: 0.1
B12: MOJAMA EXTRA SUPERIOR LA CHANCA | C12: 2.71 | D12: 36.4 | E12: 0.02 | F12: =(C12*D12)-((C12*D12)*E12) -> 96.67112 | H12: 26A00922 | I12: 132.5 | J12: 0.1
H13: 26A00916 | I13: 812.77 | J13: 0.1
H14: 26A00903 | I14: 229.16 | J14: 0.1
H15: 26A00978 | I15: 581.88 | J15: 0.1

Sheet _____CRNAS SERVAN
B2: 46204
H4: TOTAL | I4: =SUM(F6:F300) -> 1086.025
B5: PRODUCTO | C5: UNIDADES | D5: PRECIO | E5: DTO | F5: TOTAL | H5: ALBARANES | I5: =SUM(I9:I300) -> 1086.03
B6: MEDIA CAJA DE HUERVO | C6: =2+1 -> 3 | D6: 45 | E6: 0 | F6: =(C6*D6)-((C6*D6)*E6) -> 135 | H6: DIFERENCIA | I6: =I5-I4 -> 0.005
B7: PANCETA ADOBADA | C7: =4.5+8.5+4.3+8.8+3.8+9.8+7.8 -> 47.5 | D7: 8.8 | E7: 0 | F7: =(C7*D7)-((C7*D7)*E7) -> 418
B8: CAJA HUEVOS DE CORRAL | C8: =1+1+1 -> 3 | D8: 52.5 | E8: 0 | F8: =(C8*D8)-((C8*D8)*E8) -> 157.5 | H8: Nº ALBARÁN | I8: BASE | J8: % IVA
B9: POLLO TROCEADO | C9: =5.5+5.5+6.5 -> 17.5 | D9: 3.5 | E9: 0 | F9: =(C9*D9)-((C9*D9)*E9) -> 61.25 | H9: A2607-0444 | I9: 84.6 | J9: 0.1
B10: PALETILLA IBERICA | C10: 3.8 | D10: 36 | E10: 0 | F10: =(C10*D10)-((C10*D10)*E10) -> 136.8 | H10: A2607-0048 | I10: 172.3 | J10: 0.1
B11: OREJA DE CERDO | C11: =4.4+5.1 -> 9.5 | D11: 6 | E11: 0 | F11: =(C11*D11)-((C11*D11)*E11) -> 57 | H11: A2607-0010 | I11: 57.09 | J11: 0.1
B12: POLLO ENTERO | C12: 5.9 | D12: 3.5 | E12: 0 | F12: =(C12*D12)-((C12*D12)*E12) -> 20.65 | H12: A2607-0507 | I12: 208.55 | J12: 0.1
B13: GALLINAS | C13: 4.9 | D13: 3.75 | E13: 0 | F13: =(C13*D13)-((C13*D13)*E13) -> 18.375 | H13: A2607-0519 | I13: 77.44 | J13: 0.1
B14: MORCILLO DE TERNERA | C14: 3 | D14: 12.5 | E14: 0 | F14: =(C14*D14)-((C14*D14)*E14) -> 37.5 | H14: A2607-0476 | I14: 71.4 | J14: 0.1
B15: PATAS DE TERNERA | C15: 2 | D15: 8.5 | E15: 0 | F15: =(C15*D15)-((C15*D15)*E15) -> 17 | H15: A2607-0335 | I15: 64.04 | J15: 0.1
B16: MANOS DE CERDO | C16: 2.1 | D16: 4.5 | E16: 0 | F16: =(C16*D16)-((C16*D16)*E16) -> 9.45 | H16: A2607-0309 | I16: 161.49 | J16: 0.1
B17: MORRO DE TERNERA | C17: 1 | D17: 8.5 | E17: 0 | F17: =(C17*D17)-((C17*D17)*E17) -> 8.5 | H17: A2607-0239 | I17: 189.12 | J17: 0.1
B18: CHORIZO ASTURIANO | C18: 1 | D18: 9 | E18: 0 | F18: =(C18*D18)-((C18*D18)*E18) -> 9

Sheet _____CRUSTAPESCA
B2: 46204
H4: TOTAL | I4: =SUM(F6:F300) -> 1970.464
B5: PRODUCTO | C5: UNIDADES | D5: PRECIO | E5: DTO | F5: TOTAL | H5: ALBARANES | I5: =SUM(I9:I300) -> 1970.46
B6: GAMBA FR M | C6: =18+3+3+3+6+3+6+3+4+3 -> 52 | D6: 26 | E6: 0 | F6: =(C6*D6)-((C6*D6)*E6) -> 1352 | H6: DIFERENCIA | I6: =I5-I4 -> -0.004
B7: VENTRESCA | C7: 4.84 | D7: 59.6 | E7: 0 | F7: =(C7*D7)-((C7*D7)*E7) -> 288.464
B8: COLA G | C8: =4.5+6+6 -> 16.5 | D8: 20 | E8: 0 | F8: =(C8*D8)-((C8*D8)*E8) -> 330 | H8: Nº ALBARÁN | I8: BASE | J8: % IVA
H9: 10073 | I9: 78 | J9: 0.1
H10: 9071 | I10: 156 | J10: 0.1
H11: 8074 | I11: 288.46 | J11: 0.1
H12: 2074 | I12: 156 | J12: 0.1
H13: 1074 | I13: 78 | J13: 0.1
H14: 31074 | I14: 90 | J14: 0.1
H15: 30076 | I15: 78 | J15: 0.1
H16: 29074 | I16: 78 | J16: 0.1
H17: 28071 | I17: 198 | J17: 0.1
H18: 18071 | I18: 156 | J18: 0.1
H19: S/N 16-07 | I19: 78 | J19: 0.1
H20: 150710 | I20: 120 | J20: 0.1
... H24: S/N 24-07 | I24: 78 | J24: 0.1

Sheet _____DELIPAN
B2: 46204
H4: TOTAL | I4: =SUM(F6:F300) -> 1032.66
B5: PRODUCTO | C5: UNIDADES | D5: PRECIO | E5: DTO | F5: TOTAL | H5: ALBARANES | I5: =SUM(I9:I300) -> 1032.66
B6: DELIPAN | C6: 4 | D6: 17.73 | E6: 0 | F6: =(C6*D6)-((C6*D6)*E6) -> 70.92 | H6: DIFERENCIA | I6: =I5-I4 -> 0
B7: PICOS ARTESANOS 500gr | C7: =5+2+1+2+2+2 -> 14 | D7: 11.48 | E7: 0 | F7: =(C7*D7)-((C7*D7)*E7) -> 160.72
B8: DELIFLAUTA 17 PERRITO 90 uds | C8: =3+4+3+2+4+4+5+4 -> 29 | D8: 17.73 | E8: 0 | F8: =(C8*D8)-((C8*D8)*E8) -> 514.17 | H8: Nº ALBARÁN | I8: BASE | J8: % IVA
B9: PAN MOLDE BRIOCHE (7 ud) | C9: =1+1+1 -> 3 | D9: 88.09 | E9: 0 | F9: =(C9*D9)-((C9*D9)*E9) -> 264.27 | H9: A2/8520 | I9: 105.36 | J9: 0.04
B10: PICOS SIN GLUTEN 20gr (25 uds) | C10: =1+1 -> 2 | D10: 11.29 | E10: 0 | F10: =(C10*D10)-((C10*D10)*E10) -> 22.58 | H10: A2/8358 | I10: 88.09 | J10: 0.1
H11: A2/8358 | I11: 76.15 | J11: 0.04
H12: A2/8248 | I12: 105.17 | J12: 0.04
H13: A2/9083 | I13: 88.09 | J13: 0.1
H14: A2/9083 | I14: 75.96 | J14: 0.04
H15: A2/8944 | I15: 35.46 | J15: 0.04
H16: A2/8841 | I16: 93.88 | J16: 0.04
H17: A2/8675 | I17: 88.09 | J17: 0.1
H18: A2/8675 | I18: 93.88 | J18: 0.04
H19: A2/9337 | I19: 88.65 | J19: 0.04
H20: A2/9201 | I20: 93.88 | J20: 0.04

Sheet _____DISOLTRIGO
B2: 46204
H4: TOTAL | I4: =SUM(F6:F300) -> 1295.5
B5: PRODUCTO | C5: UNIDADES | D5: PRECIO | E5: DTO | F5: TOTAL | H5: ALBARANES | I5: =SUM(I9:I300) -> 1295.5
B6: BOQUERON EN VINAGRE PANDERETA | C6: =8+8+8+8 -> 32 | D6: 19 | E6: 0 | F6: =(C6*D6)-((C6*D6)*E6) -> 608 | H6: DIFERENCIA | I6: =I5-I4 -> 0
B7: 24 PERLE NOIRE N.2 | C7: =2+4+1+3+3 -> 13 | D7: 41.5 | E7: 0 | F7: =(C7*D7)-((C7*D7)*E7) -> 539.5
B8: BOQUERON CASERO EN ACEITE 700g | C8: 8 | D8: 18.5 | E8: 0 | F8: =(C8*D8)-((C8*D8)*E8) -> 148 | H8: Nº ALBARÁN | I8: BASE | J8: % IVA
H9: 134806 | I9: 152 | J9: 0.1
H10: 134789 | I10: 83 | J10: 0.1
H11: 134442 | I11: 314 | J11: 0.1
H12: 135177 | I12: 193.5 | J12: 0.1
H13: 135027 | I13: 276.5 | J13: 0.1
H14: 135362 | I14: 276.5 | J14: 0.1

Sheet _____DIST. TENA
B2: 46204
H4: TOTAL | I4: =SUM(F6:F300) -> 3131.64
B5: PRODUCTO | C5: UNIDADES | D5: PRECIO | E5: DTO | F5: TOTAL | H5: ALBARANES | I5: =SUM(I9:I300) -> 3131.64
B6: ALBARIÑO MAR DE FRADES | C6: =(23)*6 -> 138 | D6: 11.42 | E6: 0 | F6: =(C6*D6)-((C6*D6)*E6) -> 1575.96 | H6: DIFERENCIA | I6: =I5-I4 -> 0
B7: CAVA BRUT NATURE GRAN CLAUSTRO | C7: =(2)*6 -> 12 | D7: 15.12 | E7: 0 | F7: =(C7*D7)-((C7*D7)*E7) -> 181.44
B8: CHARDONAY LIAS ECOLOGICO F.ELEZ | C8: =(6)*6 -> 36 | D8: 9.02 | E8: 0 | F8: =(C8*D8)-((C8*D8)*E8) -> 324.72 | H8: Nº ALBARÁN | I8: BASE | J8: % IVA
B9: GINEBRA MARTIN MILLER 3/4 | C9: =(3)*6 -> 18 | D9: 16.1 | E9: 0 | F9: =(C9*D9)-((C9*D9)*E9) -> 289.8 | H9: FD 2221 | I9: 137.04 | J9: 0.21
B10: GODELLO VIÑAREDO | C10: =(7)*12 -> 84 | D10: 7.03 | E10: 0 | F10: =(C10*D10)-((C10*D10)*E10) -> 590.52 | H10: FD 2267 | I10: 488.88 | J10: 0.21
B11: SEÑORIO DE FITERO ROBLE | C11: =(10)*6 -> 60 | D11: 2.82 | E11: 0 | F11: =(C11*D11)-((C11*D11)*E11) -> 169.2 | H11: FD 2309 | I11: 799.08 | J11: 0.21
H12: FD 2334 | I12: 411.12 | J12: 0.21
H13: FD 2369 | I13: 765.48 | J13: 0.21
H14: FD 2419 | I14: 530.04 | J14: 0.21

Sheet _____EIF DISTRIBUCIONES
B2: 46204
H4: TOTAL | I4: =SUM(F6:F300) -> 646.5718
B5: PRODUCTO | C5: UNIDADES | D5: PRECIO | E5: DTO | F5: TOTAL | H5: ALBARANES | I5: =SUM(I9:I300) -> 646.58
B6: IZAGUIRRE BOX 20L | C6: 2 | D6: 120.15 | E6: 0.03 | F6: =(C6*D6)-((C6*D6)*E6) -> 233.091 | H6: DIFERENCIA | I6: =I5-I4 -> 0.0082
B7: RED BULL | C7: 3 | D7: 20.88 | E7: 0 | F7: =(C7*D7)-((C7*D7)*E7) -> 62.64
B8: ALBARAN | C8: 4 | D8: 1 | E8: 0 | F8: =(C8*D8)-((C8*D8)*E8) -> 4 | H8: Nº ALBARÁN | I8: BASE | J8: % IVA
B9: SOLAN DE CABRAS CON GAS | C9: 5 | D9: 26.8 | E9: 0 | F9: =(C9*D9)-((C9*D9)*E9) -> 134 | H9: 2026/1/18961 | I9: 138.43 | J9: 0.21
B10: BARCELO AÑEJO | C10: 12 | D10: 12.72 | E10: 0.03 | F10: =(C10*D10)-((C10*D10)*E10) -> 148.0608 | H10: 2026/1/19030 | I10: 134 | J10: 0.1
B11: RED BULL SIN AZUCAR | C11: 1 | D11: 20.88 | E11: 0 | F11: =(C11*D11)-((C11*D11)*E11) -> 20.88 | H11: 2026/1/19510 | I11: 149.06 | J11: 0.21
B12: MAHOU SIN GLUTEN | C12: 2 | D12: 21.95 | E12: 0 | F12: =(C12*D12)-((C12*D12)*E12) -> 43.9 | H12: 2026/1/20194 | I12: 180.19 | J12: 0.21
H13: 2026/1/20864 | I13: 44.9 | J13: 0.21

Sheet _____ENRIQUE CAMPS
B2: 46204
H4: TOTAL | I4: =SUM(F6:F300) -> 1189
B5: PRODUCTO | C5: UNIDADES | D5: PRECIO | E5: DTO | F5: TOTAL | H5: ALBARANES | I5: =SUM(I9:I300) -> 1189
B6: TARTA CHOCOLATE | C6: =2+4+2+1+3+3+2 -> 17 | D6: 37 | E6: 0 | F6: =(C6*D6)-((C6*D6)*E6) -> 629 | H6: DIFERENCIA | I6: =I5-I4 -> 0
B7: TARTA QUESO | C7: =1+4+2+1+3+3+2 -> 16 | D7: 35 | E7: 0 | F7: =(C7*D7)-((C7*D7)*E7) -> 560
H8: Nº ALBARÁN | I8: BASE | J8: % IVA
H9: A26/1816 | I9: 109 | J9: 0.1
H10: A26/1739 | I10: 288 | J10: 0.1
H11: A26/1957 | I11: 144 | J11: 0.1
H12: A26/2026 | I12: 72 | J12: 0.1
H13: A26/1984 | I13: 216 | J13: 0.1
H14: A26/1892 | I14: 216 | J14: 0.1
H15: A26/1840 | I15: 144 | J15: 0.1

Sheet _____ESCRIBANO SANZ
B2: 46204
H4: TOTAL | I4: =SUM(F6:F300) -> 193.69
B5: PRODUCTO | C5: UNIDADES | D5: PRECIO | E5: DTO | F5: TOTAL | H5: ALBARANES | I5: =SUM(I9:I300) -> 193.7
B6: LOMO BELLOTA 100% | C6: =1.15 -> 1.15 | D6: 48.6 | E6: 0 | F6: =(C6*D6)-((C6*D6)*E6) -> 55.89 | H6: DIFERENCIA | I6: =I5-I4 -> 0.01
B7: PAPADA IBERICA | C7: =10+15 -> 25 | D7: 2.3 | E7: 0 | F7: =(C7*D7)-((C7*D7)*E7) -> 57.5
B8: SALCHICHON IBERICO | C8: 1.1 | D8: 22 | E8: 0 | F8: =(C8*D8)-((C8*D8)*E8) -> 24.2 | H8: Nº ALBARÁN | I8: BASE | J8: % IVA
B9: LOMO BELLOTA 100% | C9: 1.1 | D9: 51 | E9: 0 | F9: =(C9*D9)-((C9*D9)*E9) -> 56.1 | H9: 371 | I9: 78.9 | J9: 0.1
H10: 0465 | I10: 80.3 | J10: 0.1
H11: 0524 | I11: 34.5 | J11: 0.1

Sheet _____FCO JAVIER LABRADOR
B2: 46204
H4: TOTAL | I4: =SUM(F6:F300) -> 183.2
B5: PRODUCTO | C5: UNIDADES | D5: PRECIO | E5: DTO | F5: TOTAL | H5: ALBARANES | I5: =SUM(I9:I300) -> 183.2
B6: FLOR DE ALCACHOFA CONFITADA A. ORUJO (20 uds) | C6: =4+4 -> 8 | D6: 22.9 | E6: 0 | F6: =(C6*D6)-((C6*D6)*E6) -> 183.2 | H6: DIFERENCIA | I6: =I5-I4 -> 0
H8: Nº ALBARÁN | I8: BASE | J8: % IVA
H9: 01-07/26 | I9: 91.6 | J9: 0.1
H10: 02-07/26 | I10: 91.6 | J10: 0.1

Sheet _____FRUTERIA DALISTE
B2: 46204
H4: TOTAL | I4: =SUM(F6:F300) -> 158.9995
B5: PRODUCTO | C5: UNIDADES | D5: PRECIO | E5: DTO | F5: TOTAL | H5: ALBARANES | I5: =SUM(I9:I300) -> 158.99
B6: LIMON | C6: =9.18 -> 9.18 | D6: 3.6 | E6: 0 | F6: =(C6*D6)-((C6*D6)*E6) -> 33.048 | H6: DIFERENCIA | I6: =I5-I4 -> -0.0095
B7: PIMIENTO ROJO | C7: =3.115 -> 3.115 | D7: 4.3 | E7: 0 | F7: =(C7*D7)-((C7*D7)*E7) -> 13.3945
B8: CEBOLLETA CHINA | C8: 2 | D8: 2.2 | E8: 0 | F8: =(C8*D8)-((C8*D8)*E8) -> 4.4 | H8: Nº ALBARÁN | I8: BASE | J8: % IVA
B9: PEREJIL | C9: 1 | D9: 1.6 | E9: 0 | F9: =(C9*D9)-((C9*D9)*E9) -> 1.6 | H9: 08/07/2026 | I9: 91.2 | J9: 0.04
B10: TOMATE IBERICO | C10: =5.96+5.205 -> 11.165 | D10: 5.8 | E10: 0 | F10: =(C10*D10)-((C10*D10)*E10) -> 64.757 | H10: 03/07/2026 | I10: 67.79 | J10: 0.04
B11: LECHUGA BATAVIA | C11: 2 | D11: 2.1 | E11: 0 | F11: =(C11*D11)-((C11*D11)*E11) -> 4.2
B12: CEBOLLETAS | C12: 6 | D12: 2.1 | E12: 0 | F12: =(C12*D12)-((C12*D12)*E12) -> 12.6
B13: PATATAS CREMA (saco 25 kg) | C13: 1 | D13: 25 | E13: 0 | F13: =(C13*D13)-((C13*D13)*E13) -> 25

Sheet _____JOSE PEÑA
B2: 46204
H4: TOTAL | I4: =SUM(F6:F300) -> 748.5
B5: PRODUCTO | C5: UNIDADES | D5: PRECIO | E5: DTO | F5: TOTAL | H5: ALBARANES | I5: =SUM(I9:I300) -> 748.5
B6: VENTRESCA ATUN CLARO OLIVA RO1030 (latas) | C6: 30 | D6: 24.95 | E6: 0 | F6: =(C6*D6)-((C6*D6)*E6) -> 748.5 | H6: DIFERENCIA | I6: =I5-I4 -> 0
H8: Nº ALBARÁN | I8: BASE | J8: % IVA
H9: 2026-260494 | I9: 748.5 | J9: 0.1

Sheet _____JOSE ROMERO PLAZA
B2: 46204
H4: TOTAL | I4: =SUM(F6:F300) -> 444.1
B5: PRODUCTO | C5: UNIDADES | D5: PRECIO | E5: DTO | F5: TOTAL | H5: ALBARANES | I5: =SUM(I9:I300) -> 444.1
B6: BOQUERON GORDO | C6: 5 | D6: 12 | E6: 0 | F6: =(C6*D6)-((C6*D6)*E6) -> 60 | H6: DIFERENCIA | I6: =I5-I4 -> 0
B7: BOQUERON GORDO | C7: =3+2+3+3+3+3 -> 17 | D7: 11 | E7: 0 | F7: =(C7*D7)-((C7*D7)*E7) -> 187
B8: PARROCHAS | C8: =2+1+1+1+1+1 -> 7 | D8: 7 | E8: 0 | F8: =(C8*D8)-((C8*D8)*E8) -> 49 | H8: Nº ALBARÁN | I8: BASE | J8: % IVA
B9: BOQUERON GORDO | C9: =2+3 -> 5 | D9: 10 | E9: 0 | F9: =(C9*D9)-((C9*D9)*E9) -> 50 | H9: 130 | I9: 24 | J9: 0.1
B10: PARROCHAS | C10: =1+1+1 -> 3 | D10: 7.8 | E10: 0 | F10: =(C10*D10)-((C10*D10)*E10) -> 23.4 | H10: 128 | I10: 33 | J10: 0.1
B11: BOQUERON GORDO | C11: 3 | D11: 9.5 | E11: 0 | F11: =(C11*D11)-((C11*D11)*E11) -> 28.5 | H11: 126 | I11: 43 | J11: 0.1
B12: BOQUERON GORDO (alb. 149 - ¿precio erróneo?) | C12: 1 | D12: 46.2 | E12: 0 | F12: =(C12*D12)-((C12*D12)*E12) -> 46.2 | H12: 121 | I12: 7 | J12: 0.1
H13: 113 | I13: 7 | J13: 0.1
H14: 114 | I14: 20 | J14: 0.1
H15: 119 | I15: 29 | J15: 0.1
H16: 145 | I16: 40.8 | J16: 0.1
H17: 141 | I17: 40 | J17: 0.1
H18: 136 | I18: 37 | J18: 0.1
H19: 133 | I19: 35.5 | J19: 0.1
H20: 150 | I20: 40.8 | J20: 0.1
H21: 149 | I21: 79.2 | J21: 0.1
H22: 146 | I22: 7.8 | J22: 0.1

Sheet _____MAGOASE
B2: 46204
H4: TOTAL | I4: =SUM(F6:F300) -> 1815.6
B5: PRODUCTO | C5: UNIDADES | D5: PRECIO | E5: DTO | F5: TOTAL | H5: ALBARANES | I5: =SUM(I9:I300) -> 1815.6
B6: BID. PET CUAD. A.O. SUAVE GUADALIMAR 5L | C6: =(13)*3 -> 39 | D6: 23.95 | E6: 0 | F6: =(C6*D6)-((C6*D6)*E6) -> 934.05 | H6: DIFERENCIA | I6: =I5-I4 -> 0
B7: LATA A.O.V.E. AU LINGOTE TEMPRANO | C7: =(4)*15 -> 60 | D7: 7.95 | E7: 0 | F7: =(C7*D7)-((C7*D7)*E7) -> 477
B8: BID. PET A.GIRASOL ALTO OLEICO | C8: =(9)*1 -> 9 | D8: 44.95 | E8: 0 | F8: =(C8*D8)-((C8*D8)*E8) -> 404.55 | H8: Nº ALBARÁN | I8: BASE | J8: % IVA
H9: 17635 | I9: 262.95 | J9: 0.1
H10: 17367 | I10: 89.9 | J10: 0.1
H11: 17367 | I11: 262.95 | J11: 0.04
H12: 16850 | I12: 44.95 | J12: 0.1
H13: 16850 | I13: 71.85 | J13: 0.04
H14: 18972 | I14: 143.7 | J14: 0.04
H15: 18750 | I15: 89.9 | J15: 0.1
H16: 18750 | I16: 143.7 | J16: 0.04
H17: 18418 | I17: 262.95 | J17: 0.04
H18: 18035 | I18: 89.9 | J18: 0.1
H19: 18035 | I19: 143.7 | J19: 0.04
H20: 19317 | I20: 89.9 | J20: 0.1
H21: 19317 | I21: 119.25 | J21: 0.04

Sheet _____MAKRO
B2: 46204
H4: TOTAL | I4: =SUM(F6:F300) -> 227.89
B5: PRODUCTO | C5: UNIDADES | D5: PRECIO | E5: DTO | F5: TOTAL | H5: ALBARANES | I5: =SUM(I9:I300) -> 227.89
B6: MANTEQUILLA PRESIDENT BQ 1KG | C6: 2 | D6: 16.19 | E6: 0 | F6: =(C6*D6)-((C6*D6)*E6) -> 32.38 | H6: DIFERENCIA | I6: =I5-I4 -> 0
B7: LIMON 2A C-2/6 CJ 9KG | C7: 1 | D7: 17.92 | E7: 0 | F7: =(C7*D7)-((C7*D7)*E7) -> 17.92
B8: NARANJA ZUMO MC C-6/7 SC 5KG | C8: 2 | D8: 7.65 | E8: 0 | F8: =(C8*D8)-((C8*D8)*E8) -> 15.3 | H8: Nº ALBARÁN | I8: BASE | J8: % IVA
B9: ZANAHORIA MC C-35/45 MM 5KG | C9: 1 | D9: 6.11 | E9: 0 | F9: =(C9*D9)-((C9*D9)*E9) -> 6.11 | H9: 9-193072459 | I9: 85.32 | J9: 0.1
B10: CEBOLLINO MC MJ 125G | C10: 4 | D10: 2.81 | E10: 0 | F10: =(C10*D10)-((C10*D10)*E10) -> 11.24 | H10: 9-193072459 | I10: 142.57 | J10: 0.04
B11: CEBOLLA GUISOS MC C-60/80 SC 5KG | C11: 1 | D11: 4.68 | E11: 0 | F11: =(C11*D11)-((C11*D11)*E11) -> 4.68
B12: PATATA LAV AGRIA MC C60/80 12KG | C12: 5 | D12: 11.5 | E12: 0 | F12: =(C12*D12)-((C12*D12)*E12) -> 57.5
B13: CEBOLLETA CHINA MJ | C13: 4 | D13: 1.49 | E13: 0 | F13: =(C13*D13)-((C13*D13)*E13) -> 5.96
B14: PIMIENTO LAMYO VDE ARO 2ACJ5 K | C14: 1 | D14: 10.62 | E14: 0 | F14: =(C14*D14)-((C14*D14)*E14) -> 10.62
B15: CEBOLLETA BCA MJ | C15: 12 | D15: 2.04 | E15: 0 | F15: =(C15*D15)-((C15*D15)*E15) -> 24.48
B16: SAL MALDON 1.4 KG | C16: 1 | D16: 23.64 | E16: 0 | F16: =(C16*D16)-((C16*D16)*E16) -> 23.64
B17: SSA SOJA KIKKOMAN 1L | C17: 2 | D17: 9.03 | E17: 0 | F17: =(C17*D17)-((C17*D17)*E17) -> 18.06

Sheet _____MANU AMBRES
B2: 46204
H4: TOTAL | I4: =SUM(F6:F300) -> 904.824
B5: PRODUCTO | C5: UNIDADES | D5: PRECIO | E5: DTO | F5: TOTAL | H5: ALBARANES | I5: =SUM(I9:I300) -> 904.82
B6: RACION CECINA PREMIUM 100gr | C6: =20+15 -> 35 | D6: 7.35 | E6: 0 | F6: =(C6*D6)-((C6*D6)*E6) -> 257.25 | H6: DIFERENCIA | I6: =I5-I4 -> -0.004
B7: CECINA PREMIUM EMBUCHADA | C7: =-1.34 -> -1.34 | D7: 58.9 | E7: 0 | F7: =(C7*D7)-((C7*D7)*E7) -> -78.926
B8: RACION J. BELLOTA 100% 100gr | C8: =15+20 -> 35 | D8: 13.9 | E8: 0 | F8: =(C8*D8)-((C8*D8)*E8) -> 486.5 | H8: Nº ALBARÁN | I8: BASE | J8: % IVA
B9: RACION CECINA BLACK ANGUS WAGYU 100gr | C9: 15 | D9: 16 | E9: 0 | F9: =(C9*D9)-((C9*D9)*E9) -> 240 | H9: 26/10457 | I9: 68.07 | J9: 0.1
H10: 26/11141 | I10: 558.75 | J10: 0.1
H11: 26/10768 | I11: 278 | J11: 0.1

Sheet _____MARTIN CANEDA
B2: 46204
H4: TOTAL | I4: =SUM(F6:F300) -> 3561.4
B5: PRODUCTO | C5: UNIDADES | D5: PRECIO | E5: DTO | F5: TOTAL | H5: ALBARANES | I5: =SUM(I9:I300) -> 3561.4
B6: BERBERECHO | C6: =6+2+2+2+2+2+2+2 -> 20 | D6: 25 | E6: 0 | F6: =(C6*D6)-((C6*D6)*E6) -> 500 | H6: DIFERENCIA | I6: =I5-I4 -> 0
B7: MEJILLONES | C7: =15+5+5+5+5+5+5 -> 45 | D7: 2.7 | E7: 0 | F7: =(C7*D7)-((C7*D7)*E7) -> 121.5
B8: CAMARON | C8: =1+0.3+0.5+0.5+0.5 -> 2.8 | D8: 98 | E8: 0 | F8: =(C8*D8)-((C8*D8)*E8) -> 274.4 | H8: Nº ALBARÁN | I8: BASE | J8: % IVA
B9: CHOCHAS GDA | C9: =10+4+2+2+4+2+2+4+4+4+2 -> 40 | D9: 50 | E9: 0 | F9: =(C9*D9)-((C9*D9)*E9) -> 2000 | H9: 35519 | I9: 63.5 | J9: 0.1
B10: PERCEBES GDO | C10: =1+0.5+0.65+0.5+0.75+0.5 -> 3.9 | D10: 95 | E10: 0 | F10: =(C10*D10)-((C10*D10)*E10) -> 370.5 | H10: 35508 | I10: 309 | J10: 0.1
B11: CHOCHAS GDA (alb. 035186 sin precio) | C11: 2 | D11: 0 | E11: 0 | F11: =(C11*D11)-((C11*D11)*E11) -> 0 | H11: 27694 | I11: 250 | J11: 0.1
B12: BERBERECHO | C12: =2+1+2 -> 5 | D12: 24 | E12: 0 | F12: =(C12*D12)-((C12*D12)*E12) -> 120 | H12: 27677 | I12: 261 | J12: 0.1
B13: CHOCHAS TDA | C13: =1.5+2 -> 3.5 | D13: 50 | E13: 0 | F13: =(C13*D13)-((C13*D13)*E13) -> 175 | H13: 35535 | I13: 263.5 | J13: 0.1
H14: 35548 | I14: 42.9 | J14: 0.1
H15: 27557 | I15: 197.5 | J15: 0.1
H16: 27565 | I16: 100 | J16: 0.1
H17: 27579 | I17: 249 | J17: 0.1
H18: 27523 | I18: 50 | J18: 0.1
H19: 27534 | I19: 100 | J19: 0.1
H20: 27547 | I20: 149 | J20: 0.1
H21: 27662 | I21: 250 | J21: 0.1
H22: 27591 | I22: 125.25 | J22: 0.1
H23: 35164 | I23: 297.5 | J23: 0.1
H24: 35186 | I24: 84.75 | J24: 0.1
H25: 35175 | I25: 63.5 | J25: 0.1
... H29: 35558 | I29: 148 | J29: 0.1

Sheet _____MONVA
B2: 46204
H4: TOTAL | I4: =SUM(F6:F300) -> 171
B5: PRODUCTO | C5: UNIDADES | D5: PRECIO | E5: DTO | F5: TOTAL | H5: ALBARANES | I5: =SUM(I9:I300) -> 171
B6: GARRAFA AOVE MONTABES 10 L | C6: =1+1+1 -> 3 | D6: 57 | E6: 0 | F6: =(C6*D6)-((C6*D6)*E6) -> 171 | H6: DIFERENCIA | I6: =I5-I4 -> 0
H8: Nº ALBARÁN | I8: BASE | J8: % IVA
H9: AL/5260619 | I9: 57 | J9: 0.04
H10: AL/5260649 | I10: 57 | J10: 0.04
H11: AL/5260627 | I11: 57 | J11: 0.04

Sheet _____MUNDELA
B2: 46204
H4: TOTAL | I4: =SUM(F6:F300) -> 5092.38
B5: PRODUCTO | C5: UNIDADES | D5: PRECIO | E5: DTO | F5: TOTAL | H5: ALBARANES | I5: =SUM(I9:I300) -> 5092.38
B6: BARBADILLO VI MOSCATO FRIZZANTE | C6: =(3)*6 -> 18 | D6: 5.63 | E6: 0 | F6: =(C6*D6)-((C6*D6)*E6) -> 101.34 | H6: DIFERENCIA | I6: =I5-I4 -> 0
B7: CEPAS VELLAS GODEVAL | C7: =(36)*6 -> 216 | D7: 11.77 | E7: 0 | F7: =(C7*D7)-((C7*D7)*E7) -> 2542.32
B8: RAMON BILBAO BLANCO VERDEJO 3/4 | C8: =(27)*6 -> 162 | D8: 4.67 | E8: 0 | F8: =(C8*D8)-((C8*D8)*E8) -> 756.54 | H8: Nº ALBARÁN | I8: BASE | J8: % IVA
B9: RAMON BILBAO VIÑEDOS DE ALTURA 3/4 | C9: =(8)*6 -> 48 | D9: 8.78 | E9: 0 | F9: =(C9*D9)-((C9*D9)*E9) -> 421.44 | H9: FM 2547 | I9: 528.12 | J9: 0.21
B10: R.B. EDI.LIM. EARLY HARVEST ROSADO | C10: =(5)*6 -> 30 | D10: 7.88 | E10: 0 | F10: =(C10*D10)-((C10*D10)*E10) -> 236.4 | H10: FM 2592 | I10: 746.52 | J10: 0.21
B11: CORIMBO | C11: =(7)*6 -> 42 | D11: 13.91 | E11: 0 | F11: =(C11*D11)-((C11*D11)*E11) -> 584.22 | H11: FM 2659 | I11: 848.58 | J11: 0.21
B12: RODA RESERVA 3/4 | C12: =(3)*6 -> 18 | D12: 21.38 | E12: 0 | F12: =(C12*D12)-((C12*D12)*E12) -> 384.84 | H12: FM 2638 | I12: 1280.7 | J12: 0.21
B13: VINAGRE DE JEREZ RESERVA AL MOSCATEL | C13: =(2)*6 -> 12 | D13: 5.44 | E13: 0 | F13: =(C13*D13)-((C13*D13)*E13) -> 65.28 | H13: FM 2692 | I13: 1038.9 | J13: 0.21
H14: FM 2737 | I14: 649.56 | J14: 0.21

Sheet _____PATATAS YAGO
B2: 46204
H4: TOTAL | I4: =SUM(F6:F300) -> 611.4
B5: PRODUCTO | C5: UNIDADES | D5: PRECIO | E5: DTO | F5: TOTAL | H5: ALBARANES | I5: =SUM(I9:I300) -> 611.4
B6: SACO AGRIA NUEVA ALICANTE | C6: =(4+2+1+1)*25 -> 200 | D6: 0.89 | E6: 0 | F6: =(C6*D6)-((C6*D6)*E6) -> 178 | H6: DIFERENCIA | I6: =I5-I4 -> 0
B7: SACO MONALISA | C7: =(1+1+1+1)*25 -> 100 | D7: 0.93 | E7: 0 | F7: =(C7*D7)-((C7*D7)*E7) -> 93
B8: SACO AGRIA NUEVA ALICANTE | C8: =(4)*25 -> 100 | D8: 0.95 | E8: 0 | F8: =(C8*D8)-((C8*D8)*E8) -> 95 | H8: Nº ALBARÁN | I8: BASE | J8: % IVA
B9: SACO MONALISA | C9: =(1)*25 -> 25 | D9: 0.9 | E9: 0 | F9: =(C9*D9)-((C9*D9)*E9) -> 22.5 | H9: 476 | I9: 44.5 | J9: 0.04
B10: SACO AGRIA NUEVA ALICANTE | C10: =(1+1+2+1+1+1+1+1)*25 -> 225 | D10: 0.88 | E10: 0 | F10: =(C10*D10)-((C10*D10)*E10) -> 198 | H10: 468 | I10: 23.25 | J10: 0.04
B11: SACO MONALISA (alb. 499: 30 kg = 1,2 sacos) | C11: =(1.2)*25 -> 30 | D11: 0.83 | E11: 0 | F11: =(C11*D11)-((C11*D11)*E11) -> 24.9 | H11: 463 | I11: 44.5 | J11: 0.04
H12: 445 | I12: 46.25 | J12: 0.04
H13: 435 | I13: 47.5 | J13: 0.04
H14: 404 | I14: 23.75 | J14: 0.04
H15: 601 | I15: 22 | J15: 0.04
H16: 592 | I16: 22 | J16: 0.04
H17: 584 | I17: 67.25 | J17: 0.04
H18: 555 | I18: 23.25 | J18: 0.04
H19: 548 | I19: 22 | J19: 0.04
H20: 541 | I20: 22 | J20: 0.04
H21: 529 | I21: 44.5 | J21: 0.04
H22: 518 | I22: 22.25 | J22: 0.04
H23: 499 | I23: 47.15 | J23: 0.04
... H26: 608 | I26: 22 | J26: 0.04

Sheet _____PESCADERIA PALACIO
B2: 46204
H4: TOTAL | I4: =SUM(F6:F300) -> 1400.16
B5: PRODUCTO | C5: UNIDADES | D5: PRECIO | E5: DTO | F5: TOTAL | H5: ALBARANES | I5: =SUM(I9:I300) -> 1400.16
