Workbook

Sheet RESUMEN AGOSTO
B2: RESUMEN DE COMPRAS · AGOSTO 2026
B3: LA MINA DE CHAMARTÍN
B4: Todo se calcula desde la hoja TOTAL AGOSTO. La columna de julio es el importe fijo del Excel de julio.
B6: BASE IMPONIBLE | D6: CUOTA IVA | F6: TOTAL CON IVA
B7: =SUM('TOTAL AGOSTO'!D4:D2000) -> 24271.19 | D7: =SUM('TOTAL AGOSTO'!F4:F2000)-SUM('TOTAL AGOSTO'!D4:D2000) -> 2945.2262 | F7: =SUM('TOTAL AGOSTO'!F4:F2000) -> 27216.416
B9: Nº ALBARANES | D9: Nº PROVEEDORES | F9: CUADRES A REVISAR
B10: =COUNTIF('TOTAL AGOSTO'!B4:B2000,"?*") -> 131 | D10: =SUMPRODUCT(('TOTAL AGOSTO'!B4:B2000<>"")/COUNTIF('TOTAL AGOSTO'!B4:B2000,'TOTAL AGOSTO'!B4:B2000&"")) -> 29 | F10: =COUNTIF('CUADRE ALBARANES'!H:H,"REVISAR") -> 3
B12: BASE AL 4% DE IVA | D12: BASE AL 10% DE IVA | F12: BASE AL 21% DE IVA
B13: =SUMIF('TOTAL AGOSTO'!$E$4:$E$2000,0.04,'TOTAL AGOSTO'!$D$4:$D$2000) -> 1675.07 | D13: =SUMIF('TOTAL AGOSTO'!$E$4:$E$2000,0.1,'TOTAL AGOSTO'!$D$4:$D$2000) -> 16972.38 | F13: =SUMIF('TOTAL AGOSTO'!$E$4:$E$2000,0.21,'TOTAL AGOSTO'!$D$4:$D$2000) -> 5623.74
B16: COMPRAS POR PROVEEDOR
B17: PROVEEDOR | C17: Nº ALB. | D17: BASE AGOSTO | E17: % DEL MES | F17: BASE JULIO | G17: DIF. € | H17: DIF. %
B18: PESCARUM | C18: =COUNTIF('TOTAL AGOSTO'!$B$4:$B$2000,B18) -> 13 | D18: =SUMIF('TOTAL AGOSTO'!$B$4:$B$2000,B18,'TOTAL AGOSTO'!$D$4:$D$2000) -> 5112.89 | E18: =IF($D$56=0,0,D18/$D$56) -> 0.21065675 | F18: 10740.83 | G18: =IF(F18="","",D18-F18) -> -5627.94 | H18: =IF(OR(F18="",N(F18)=0),"",D18/F18-1) -> -0.52397627
B19: MUNDELA | C19: =COUNTIF('TOTAL AGOSTO'!$B$4:$B$2000,B19) -> 4 | D19: =SUMIF('TOTAL AGOSTO'!$B$4:$B$2000,B19,'TOTAL AGOSTO'!$D$4:$D$2000) -> 1920.54 | E19: =IF($D$56=0,0,D19/$D$56) -> 0.079128382 | F19: 5092.38 | G19: =IF(F19="","",D19-F19) -> -3171.84 | H19: =IF(OR(F19="",N(F19)=0),"",D19/F19-1) -> -0.62286004
B20: MARTIN CANEDA | C20: =COUNTIF('TOTAL AGOSTO'!$B$4:$B$2000,B20) -> 12 | D20: =SUMIF('TOTAL AGOSTO'!$B$4:$B$2000,B20,'TOTAL AGOSTO'!$D$4:$D$2000) -> 1617.8 | E20: =IF($D$56=0,0,D20/$D$56) -> 0.066655158 | F20: 3561.4 | G20: =IF(F20="","",D20-F20) -> -1943.6 | H20: =IF(OR(F20="",N(F20)=0),"",D20/F20-1) -> -0.54574044
B21: DIST. TENA MTNEZ | C21: =COUNTIF('TOTAL AGOSTO'!$B$4:$B$2000,B21) -> 3 | D21: =SUMIF('TOTAL AGOSTO'!$B$4:$B$2000,B21,'TOTAL AGOSTO'!$D$4:$D$2000) -> 1320.36 | E21: =IF($D$56=0,0,D21/$D$56) -> 0.054400299 | F21: 3131.64 | G21: =IF(F21="","",D21-F21) -> -1811.28 | H21: =IF(OR(F21="",N(F21)=0),"",D21/F21-1) -> -0.57838066
B22: AGROFOOD | C22: =COUNTIF('TOTAL AGOSTO'!$B$4:$B$2000,B22) -> 3 | D22: =SUMIF('TOTAL AGOSTO'!$B$4:$B$2000,B22,'TOTAL AGOSTO'!$D$4:$D$2000) -> 1199.46 | E22: =IF($D$56=0,0,D22/$D$56) -> 0.049419085 | F22: 4059.72 | G22: =IF(F22="","",D22-F22) -> -2860.26 | H22: =IF(OR(F22="",N(F22)=0),"",D22/F22-1) -> -0.70454613
B23: AGMASFOOD | C23: =COUNTIF('TOTAL AGOSTO'!$B$4:$B$2000,B23) -> 10 | D23: =SUMIF('TOTAL AGOSTO'!$B$4:$B$2000,B23,'TOTAL AGOSTO'!$D$4:$D$2000) -> 1125.19 | E23: =IF($D$56=0,0,D23/$D$56) -> 0.046359078 | F23: 1122.99 | G23: =IF(F23="","",D23-F23) -> 2.2 | H23: =IF(OR(F23="",N(F23)=0),"",D23/F23-1) -> 0.0019590557
B24: CONS. Y SAL. JIMENEZ | C24: =COUNTIF('TOTAL AGOSTO'!$B$4:$B$2000,B24) -> 2 | D24: =SUMIF('TOTAL AGOSTO'!$B$4:$B$2000,B24,'TOTAL AGOSTO'!$D$4:$D$2000) -> 1061.59 | E24: =IF($D$56=0,0,D24/$D$56) -> 0.043738688 | F24: 3739.92 | G24: =IF(F24="","",D24-F24) -> -2678.33 | H24: =IF(OR(F24="",N(F24)=0),"",D24/F24-1) -> -0.71614633
B25: MAGOASE | C25: =COUNTIF('TOTAL AGOSTO'!$B$4:$B$2000,B25) -> 8 | D25: =SUMIF('TOTAL AGOSTO'!$B$4:$B$2000,B25,'TOTAL AGOSTO'!$D$4:$D$2000) -> 930.8 | E25: =IF($D$56=0,0,D25/$D$56) -> 0.038349994 | F25: 1815.6 | G25: =IF(F25="","",D25-F25) -> -884.8 | H25: =IF(OR(F25="",N(F25)=0),"",D25/F25-1) -> -0.48733201
B26: CRNAS SERVAN | C26: =COUNTIF('TOTAL AGOSTO'!$B$4:$B$2000,B26) -> 9 | D26: =SUMIF('TOTAL AGOSTO'!$B$4:$B$2000,B26,'TOTAL AGOSTO'!$D$4:$D$2000) -> 890.28 | E26: =IF($D$56=0,0,D26/$D$56) -> 0.036680525 | F26: 1086.03 | G26: =IF(F26="","",D26-F26) -> -195.75 | H26: =IF(OR(F26="",N(F26)=0),"",D26/F26-1) -> -0.18024364
B27: VOLDIS | C27: =COUNTIF('TOTAL AGOSTO'!$B$4:$B$2000,B27) -> 4 | D27: =SUMIF('TOTAL AGOSTO'!$B$4:$B$2000,B27,'TOTAL AGOSTO'!$D$4:$D$2000) -> 780.87 | E27: =IF($D$56=0,0,D27/$D$56) -> 0.032172712 | F27: 6546.46 | G27: =IF(F27="","",D27-F27) -> -5765.59 | H27: =IF(OR(F27="",N(F27)=0),"",D27/F27-1) -> -0.88071874
B28: CRUSTAPESCA | C28: =COUNTIF('TOTAL AGOSTO'!$B$4:$B$2000,B28) -> 10 | D28: =SUMIF('TOTAL AGOSTO'!$B$4:$B$2000,B28,'TOTAL AGOSTO'!$D$4:$D$2000) -> 772 | E28: =IF($D$56=0,0,D28/$D$56) -> 0.031807258 | F28: 1970.46 | G28: =IF(F28="","",D28-F28) -> -1198.46 | H28: =IF(OR(F28="",N(F28)=0),"",D28/F28-1) -> -0.60821331
B29: SUBMARINER | C29: =COUNTIF('TOTAL AGOSTO'!$B$4:$B$2000,B29) -> 2 | D29: =SUMIF('TOTAL AGOSTO'!$B$4:$B$2000,B29,'TOTAL AGOSTO'!$D$4:$D$2000) -> 712.94 | E29: =IF($D$56=0,0,D29/$D$56) -> 0.02937392 | F29: 3291.32 | G29: =IF(F29="","",D29-F29) -> -2578.38 | H29: =IF(OR(F29="",N(F29)=0),"",D29/F29-1) -> -0.78338782
... B33: PEÑALASTALLAS | C33: =COUNTIF('TOTAL AGOSTO'!$B$4:$B$2000,B33) -> 4 | D33: =SUMIF('TOTAL AGOSTO'!$B$4:$B$2000,B33,'TOTAL AGOSTO'!$D$4:$D$2000) -> 519.69 | E33: =IF($D$56=0,0,D33/$D$56) -> 0.021411806 | F33: 1568.32 | G33: =IF(F33="","",D33-F33) -> -1048.63 | H33: =IF(OR(F33="",N(F33)=0),"",D33/F33-1) -> -0.66863268
B34: JC MACKINTOSH | C34: =COUNTIF('TOTAL AGOSTO'!$B$4:$B$2000,B34) -> 2 | D34: =SUMIF('TOTAL AGOSTO'!$B$4:$B$2000,B34,'TOTAL AGOSTO'!$D$4:$D$2000) -> 516 | E34: =IF($D$56=0,0,D34/$D$56) -> 0.021259773 | G34: =IF(F34="","",D34-F34) | H34: =IF(OR(F34="",N(F34)=0),"",D34/F34-1)
B35: COCACOLA | C35: =COUNTIF('TOTAL AGOSTO'!$B$4:$B$2000,B35) -> 4 | D35: =SUMIF('TOTAL AGOSTO'!$B$4:$B$2000,B35,'TOTAL AGOSTO'!$D$4:$D$2000) -> 457.72 | E35: =IF($D$56=0,0,D35/$D$56) -> 0.018858573 | F35: 2124.02 | G35: =IF(F35="","",D35-F35) -> -1666.3 | H35: =IF(OR(F35="",N(F35)=0),"",D35/F35-1) -> -0.78450297
B36: ENRIQUE CAMPS | C36: =COUNTIF('TOTAL AGOSTO'!$B$4:$B$2000,B36) -> 2 | D36: =SUMIF('TOTAL AGOSTO'!$B$4:$B$2000,B36,'TOTAL AGOSTO'!$D$4:$D$2000) -> 432 | E36: =IF($D$56=0,0,D36/$D$56) -> 0.01779888 | F36: 1189 | G36: =IF(F36="","",D36-F36) -> -757 | H36: =IF(OR(F36="",N(F36)=0),"",D36/F36-1) -> -0.63666947
B37: MANUEL AMBRES | C37: =COUNTIF('TOTAL AGOSTO'!$B$4:$B$2000,B37) -> 1 | D37: =SUMIF('TOTAL AGOSTO'!$B$4:$B$2000,B37,'TOTAL AGOSTO'!$D$4:$D$2000) -> 425 | E37: =IF($D$56=0,0,D37/$D$56) -> 0.017510472 | F37: 904.82 | G37: =IF(F37="","",D37-F37) -> -479.82 | H37: =IF(OR(F37="",N(F37)=0),"",D37/F37-1) -> -0.53029332
B38: CONS. SELEC. SANTO | C38: =COUNTIF('TOTAL AGOSTO'!$B$4:$B$2000,B38) -> 1 | D38: =SUMIF('TOTAL AGOSTO'!$B$4:$B$2000,B38,'TOTAL AGOSTO'!$D$4:$D$2000) -> 382.59 | E38: =IF($D$56=0,0,D38/$D$56) -> 0.015763133 | F38: 705.24 | G38: =IF(F38="","",D38-F38) -> -322.65 | H38: =IF(OR(F38="",N(F38)=0),"",D38/F38-1) -> -0.45750383
B39: DELIPAN | C39: =COUNTIF('TOTAL AGOSTO'!$B$4:$B$2000,B39) -> 6 | D39: =SUMIF('TOTAL AGOSTO'!$B$4:$B$2000,B39,'TOTAL AGOSTO'!$D$4:$D$2000) -> 381.21 | E39: =IF($D$56=0,0,D39/$D$56) -> 0.015706276 | F39: 1032.66 | G39: =IF(F39="","",D39-F39) -> -651.45 | H39: =IF(OR(F39="",N(F39)=0),"",D39/F39-1) -> -0.63084655
B40: PESCADERIA PALACIO | C40: =COUNTIF('TOTAL AGOSTO'!$B$4:$B$2000,B40) -> 2 | D40: =SUMIF('TOTAL AGOSTO'!$B$4:$B$2000,B40,'TOTAL AGOSTO'!$D$4:$D$2000) -> 369.6 | E40: =IF($D$56=0,0,D40/$D$56) -> 0.015227931 | F40: 1400.16 | G40: =IF(F40="","",D40-F40) -> -1030.56 | H40: =IF(OR(F40="",N(F40)=0),"",D40/F40-1) -> -0.73603017
B41: PATATAS YAGO | C41: =COUNTIF('TOTAL AGOSTO'!$B$4:$B$2000,B41) -> 8 | D41: =SUMIF('TOTAL AGOSTO'!$B$4:$B$2000,B41,'TOTAL AGOSTO'!$D$4:$D$2000) -> 358.9 | E41: =IF($D$56=0,0,D41/$D$56) -> 0.014787079 | F41: 611.4 | G41: =IF(F41="","",D41-F41) -> -252.5 | H41: =IF(OR(F41="",N(F41)=0),"",D41/F41-1) -> -0.41298659
B42: TOMATERIA DE CEA | C42: =COUNTIF('TOTAL AGOSTO'!$B$4:$B$2000,B42) -> 7 | D42: =SUMIF('TOTAL AGOSTO'!$B$4:$B$2000,B42,'TOTAL AGOSTO'!$D$4:$D$2000) -> 320 | E42: =IF($D$56=0,0,D42/$D$56) -> 0.013184356 | F42: 584.97 | G42: =IF(F42="","",D42-F42) -> -264.97 | H42: =IF(OR(F42="",N(F42)=0),"",D42/F42-1) -> -0.4529634
B43: DISOLTRIGO | C43: =COUNTIF('TOTAL AGOSTO'!$B$4:$B$2000,B43) -> 2 | D43: =SUMIF('TOTAL AGOSTO'!$B$4:$B$2000,B43,'TOTAL AGOSTO'!$D$4:$D$2000) -> 318 | E43: =IF($D$56=0,0,D43/$D$56) -> 0.013101953 | F43: 1295.5 | G43: =IF(F43="","",D43-F43) -> -977.5 | H43: =IF(OR(F43="",N(F43)=0),"",D43/F43-1) -> -0.75453493
B44: VENERO CLARO | C44: =COUNTIF('TOTAL AGOSTO'!$B$4:$B$2000,B44) -> 1 | D44: =SUMIF('TOTAL AGOSTO'!$B$4:$B$2000,B44,'TOTAL AGOSTO'!$D$4:$D$2000) -> 271.18 | E44: =IF($D$56=0,0,D44/$D$56) -> 0.011172917 | F44: 270.4 | G44: =IF(F44="","",D44-F44) -> 0.78 | H44: =IF(OR(F44="",N(F44)=0),"",D44/F44-1) -> 0.0028846154
B45: FCO JAVIER LABRADOR | C45: =COUNTIF('TOTAL AGOSTO'!$B$4:$B$2000,B45) -> 1 | D45: =SUMIF('TOTAL AGOSTO'!$B$4:$B$2000,B45,'TOTAL AGOSTO'!$D$4:$D$2000) -> 91.6 | E45: =IF($D$56=0,0,D45/$D$56) -> 0.0037740218 | F45: 183.2 | G45: =IF(F45="","",D45-F45) -> -91.6 | H45: =IF(OR(F45="",N(F45)=0),"",D45/F45-1) -> -0.5
B46: ESCRIBANO SANZ | C46: =COUNTIF('TOTAL AGOSTO'!$B$4:$B$2000,B46) -> 1 | D46: =SUMIF('TOTAL AGOSTO'!$B$4:$B$2000,B46,'TOTAL AGOSTO'!$D$4:$D$2000) -> 84.48 | E46: =IF($D$56=0,0,D46/$D$56) -> 0.0034806699 | F46: 193.7 | G46: =IF(F46="","",D46-F46) -> -109.22 | H46: =IF(OR(F46="",N(F46)=0),"",D46/F46-1) -> -0.56386164
... B55: FRUTERIA D'ALISTE | C55: =COUNTIF('TOTAL AGOSTO'!$B$4:$B$2000,B55) -> 0 | D55: =SUMIF('TOTAL AGOSTO'!$B$4:$B$2000,B55,'TOTAL AGOSTO'!$D$4:$D$2000) -> 0 | E55: =IF($D$56=0,0,D55/$D$56) -> 0 | F55: 158.99 | G55: =IF(F55="","",D55-F55) -> -158.99 | H55: =IF(OR(F55="",N(F55)=0),"",D55/F55-1) -> -1
B56: TOTAL | C56: =SUM(C18:C55) -> 131 | D56: =SUM(D18:D55) -> 24271.19 | E56: =SUM(E18:E55) -> 1 | F56: =SUM(F18:F55) -> 63628.05 | G56: =D56-F56 -> -39356.86 | H56: =IF(F56=0,"",D56/F56-1) -> -0.61854575
B57: Filas en gris: proveedores con compras en julio y sin albaranes en agosto. DIF. en rojo = sube respecto a julio; en verde = baja.

Sheet TOTAL AGOSTO
B1: ALBARANES AGOSTO 2026 · LA MINA DE CHAMARTÍN
B2: PROVEEDOR | C2: ALBARAN | D2: BASE | E2: IVA | F2: TOTAL | H2: PROVEEDOR | I2: BASE | J2: CUOTA IVA | K2: TOTAL FRA | M2: TOTAL FACTURADO
B4: AGMASFOOD | C4: 26 6717 | D4: 300.55 | E4: 0.1 | F4: =D4+(D4*E4) -> 330.605 | H4: AGMASFOOD | I4: =SUMIF($B$4:$B$2000,H4,$D$4:$D$2000) -> 1125.19 | J4: =K4-I4 -> 112.519 | K4: =SUMIF($B$4:$B$2000,H4,$F$4:$F$2000) -> 1237.709 | M4: =K33 -> 27216.416
B5: AGMASFOOD | C5: 26 6980 | D5: 35.85 | E5: 0.1 | F5: =D5+(D5*E5) -> 39.435 | H5: AGROFOOD | I5: =SUMIF($B$4:$B$2000,H5,$D$4:$D$2000) -> 1199.46 | J5: =K5-I5 -> 119.946 | K5: =SUMIF($B$4:$B$2000,H5,$F$4:$F$2000) -> 1319.406
B6: AGMASFOOD | C6: 26 7006 | D6: 84 | E6: 0.1 | F6: =D6+(D6*E6) -> 92.4 | H6: CARNICAS MEAT | I6: =SUMIF($B$4:$B$2000,H6,$D$4:$D$2000) -> 640.26 | J6: =K6-I6 -> 64.026 | K6: =SUMIF($B$4:$B$2000,H6,$F$4:$F$2000) -> 704.286
B7: AGMASFOOD | C7: 26 7016 | D7: 226.6 | E7: 0.1 | F7: =D7+(D7*E7) -> 249.26 | H7: COCACOLA | I7: =SUMIF($B$4:$B$2000,H7,$D$4:$D$2000) -> 457.72 | J7: =K7-I7 -> 92.2756 | K7: =SUMIF($B$4:$B$2000,H7,$F$4:$F$2000) -> 549.9956
B8: AGMASFOOD | C8: 26 7048 | D8: 100.8 | E8: 0.1 | F8: =D8+(D8*E8) -> 110.88 | H8: CONS. SELEC. SANTO | I8: =SUMIF($B$4:$B$2000,H8,$D$4:$D$2000) -> 382.59 | J8: =K8-I8 -> 38.259 | K8: =SUMIF($B$4:$B$2000,H8,$F$4:$F$2000) -> 420.849
B9: AGMASFOOD | C9: 26 7103 | D9: 34.3 | E9: 0.1 | F9: =D9+(D9*E9) -> 37.73 | H9: CONS. Y SAL. JIMENEZ | I9: =SUMIF($B$4:$B$2000,H9,$D$4:$D$2000) -> 1061.59 | J9: =K9-I9 -> 106.159 | K9: =SUMIF($B$4:$B$2000,H9,$F$4:$F$2000) -> 1167.749
B10: AGMASFOOD | C10: 26 7151 | D10: 0 | E10: 0.1 | F10: =D10+(D10*E10) -> 0 | H10: CRNAS SERVAN | I10: =SUMIF($B$4:$B$2000,H10,$D$4:$D$2000) -> 890.28 | J10: =K10-I10 -> 89.028 | K10: =SUMIF($B$4:$B$2000,H10,$F$4:$F$2000) -> 979.308
B11: AGMASFOOD | C11: 26 7202 | D11: 29.4 | E11: 0.1 | F11: =D11+(D11*E11) -> 32.34 | H11: CRUSTAPESCA | I11: =SUMIF($B$4:$B$2000,H11,$D$4:$D$2000) -> 772 | J11: =K11-I11 -> 77.2 | K11: =SUMIF($B$4:$B$2000,H11,$F$4:$F$2000) -> 849.2
B12: AGMASFOOD | C12: 26 7226 | D12: 185.49 | E12: 0.1 | F12: =D12+(D12*E12) -> 204.039 | H12: DELIPAN | I12: =SUMIF($B$4:$B$2000,H12,$D$4:$D$2000) -> 381.21 | J12: =K12-I12 -> 20.5338 | K12: =SUMIF($B$4:$B$2000,H12,$F$4:$F$2000) -> 401.7438
B13: AGMASFOOD | C13: 26 7264 | D13: 128.2 | E13: 0.1 | F13: =D13+(D13*E13) -> 141.02 | H13: DISOLTRIGO | I13: =SUMIF($B$4:$B$2000,H13,$D$4:$D$2000) -> 318 | J13: =K13-I13 -> 31.8 | K13: =SUMIF($B$4:$B$2000,H13,$F$4:$F$2000) -> 349.8
B14: AGROFOOD | C14: M26/935 | D14: 228.11 | E14: 0.1 | F14: =D14+(D14*E14) -> 250.921 | H14: DIST. TENA MTNEZ | I14: =SUMIF($B$4:$B$2000,H14,$D$4:$D$2000) -> 1320.36 | J14: =K14-I14 -> 277.2756 | K14: =SUMIF($B$4:$B$2000,H14,$F$4:$F$2000) -> 1597.6356
B15: AGROFOOD | C15: M26/952 | D15: 522.68 | E15: 0.1 | F15: =D15+(D15*E15) -> 574.948 | H15: EIF DISTRIBUCIONES | I15: =SUMIF($B$4:$B$2000,H15,$D$4:$D$2000) -> 604.05 | J15: =K15-I15 -> 120.9545 | K15: =SUMIF($B$4:$B$2000,H15,$F$4:$F$2000) -> 725.0045
B16: AGROFOOD | C16: M26/928 | D16: 448.67 | E16: 0.1 | F16: =D16+(D16*E16) -> 493.537 | H16: ENRIQUE CAMPS | I16: =SUMIF($B$4:$B$2000,H16,$D$4:$D$2000) -> 432 | J16: =K16-I16 -> 43.2 | K16: =SUMIF($B$4:$B$2000,H16,$F$4:$F$2000) -> 475.2
... B32: CRNAS SERVAN | C32: A2608-0351 | D32: 104.84 | E32: 0.1 | F32: =D32+(D32*E32) -> 115.324 | H32: VOLDIS | I32: =SUMIF($B$4:$B$2000,H32,$D$4:$D$2000) -> 780.87 | J32: =K32-I32 -> 160.2537 | K32: =SUMIF($B$4:$B$2000,H32,$F$4:$F$2000) -> 941.1237
B33: CRNAS SERVAN | C33: A2608-0356 | D33: 60.72 | E33: 0.1 | F33: =D33+(D33*E33) -> 66.792 | H33: TOTAL | I33: =SUM(I4:I32) -> 24271.19 | J33: =SUM(J4:J32) -> 2945.2262 | K33: =SUM(K4:K32) -> 27216.416
B34: CRNAS SERVAN | C34: A2608-0379 | D34: 143.42 | E34: 0.1 | F34: =D34+(D34*E34) -> 157.762
B35: CRUSTAPESCA | C35: 20081 (ABONO) | D35: -229.6 | E35: 0.1 | F35: =D35+(D35*E35) -> -252.56
B36: CRUSTAPESCA | C36: 25081 | D36: 119.6 | E36: 0.1 | F36: =D36+(D36*E36) -> 131.56
B37: CRUSTAPESCA | C37: 27084 | D37: 78 | E37: 0.1 | F37: =D37+(D37*E37) -> 85.8
B38: CRUSTAPESCA | C38: 5081 | D38: 78 | E38: 0.1 | F38: =D38+(D38*E38) -> 85.8
B39: CRUSTAPESCA | C39: 6083 | D39: 78 | E39: 0.1 | F39: =D39+(D39*E39) -> 85.8
B40: CRUSTAPESCA | C40: 18086 | D40: 78 | E40: 0.1 | F40: =D40+(D40*E40) -> 85.8
B41: CRUSTAPESCA | C41: 19083 | D41: 78 | E41: 0.1 | F41: =D41+(D41*E41) -> 85.8
B42: CRUSTAPESCA | C42: S/N 22-08 | D42: 168 | E42: 0.1 | F42: =D42+(D42*E42) -> 184.8
B43: CRUSTAPESCA | C43: 25085 | D43: 78 | E43: 0.1 | F43: =D43+(D43*E43) -> 85.8
B44: CRUSTAPESCA | C44: 29082 | D44: 246 | E44: 0.1 | F44: =D44+(D44*E44) -> 270.6
B45: DELIPAN | C45: A2/9526 | D45: 88.09 | E45: 0.1 | F45: =D45+(D45*E45) -> 96.899
... B134: VOLDIS | C134: AP26-? (19/08) | D134: 262.5 | E134: 0.21 | F134: =D134+(D134*E134) -> 317.625

Sheet CUADRE ALBARANES
A2: CUADRE POR PROVEEDOR Y MES
A3: Compara, en cada hoja de proveedor, la suma de las líneas de producto con la suma de albaranes, y ésta con la hoja TOTAL del mes (JULIO: importe fijo del Excel de julio; AGOSTO: fórmula sobre TOTAL AGOSTO). Tolerancia ±0,05 €.
A5: PROVEEDOR | B5: MES | C5: TOTAL LÍNEAS PRODUCTO | D5: TOTAL ALBARANES (hoja proveedor) | E5: TOTAL EN HOJA TOTAL DEL MES | F5: DIF. LÍNEAS − ALBARANES | G5: DIF. ALBARANES − HOJA TOTAL | H5: ¿CUADRA? | I5: NOTA
A6: AGMASFOOD | B6: JULIO | C6: =SUM(_____AGMASFOOD!F6:F300) -> 1122.98 | D6: =SUM(_____AGMASFOOD!I9:I300) -> 1122.99 | E6: 1122.99 | F6: =IF(D6="","",ROUND(C6-D6,2)) -> -0.01 | G6: =IF(D6="",ROUND(C6-E6,2),ROUND(D6-E6,2)) -> 0 | H6: =IF(AND(ABS(N(F6))<=0.05,ABS(G6)<=0.05),"OK","REVISAR") -> OK
A7: AGMASFOOD | B7: AGOSTO | C7: =SUM(_____AGMASFOOD!P6:P300) -> 1125.185 | D7: =SUM(_____AGMASFOOD!S9:S300) -> 1125.19 | E7: =SUMIF('TOTAL AGOSTO'!$B$4:$B$2000,"AGMASFOOD",'TOTAL AGOSTO'!$D$4:$D$2000) -> 1125.19 | F7: =IF(D7="","",ROUND(C7-D7,2)) -> -0.01 | G7: =IF(D7="",ROUND(C7-E7,2),ROUND(D7-E7,2)) -> 0 | H7: =IF(AND(ABS(N(F7))<=0.05,ABS(G7)<=0.05),"OK","REVISAR") -> OK
A8: AGROFOOD | B8: JULIO | C8: =SUM(_____AGROFOOD!F6:F300) -> 4059.71 | D8: =SUM(_____AGROFOOD!I9:I300) -> 4059.72 | E8: 4059.72 | F8: =IF(D8="","",ROUND(C8-D8,2)) -> -0.01 | G8: =IF(D8="",ROUND(C8-E8,2),ROUND(D8-E8,2)) -> 0 | H8: =IF(AND(ABS(N(F8))<=0.05,ABS(G8)<=0.05),"OK","REVISAR") -> OK
A9: AGROFOOD | B9: AGOSTO | C9: =SUM(_____AGROFOOD!P6:P300) -> 1199.4617 | D9: =SUM(_____AGROFOOD!S9:S300) -> 1199.46 | E9: =SUMIF('TOTAL AGOSTO'!$B$4:$B$2000,"AGROFOOD",'TOTAL AGOSTO'!$D$4:$D$2000) -> 1199.46 | F9: =IF(D9="","",ROUND(C9-D9,2)) -> 0 | G9: =IF(D9="",ROUND(C9-E9,2),ROUND(D9-E9,2)) -> 0 | H9: =IF(AND(ABS(N(F9))<=0.05,ABS(G9)<=0.05),"OK","REVISAR") -> OK
A10: ANTONIO DE MIGUEL | B10: JULIO | C10: =SUM('_____ANTONIO DE MIGUEL'!F6:F300) -> 280.3 | D10: =SUM('_____ANTONIO DE MIGUEL'!I9:I300) -> 280.3 | E10: 280.3 | F10: =IF(D10="","",ROUND(C10-D10,2)) -> 0 | G10: =IF(D10="",ROUND(C10-E10,2),ROUND(D10-E10,2)) -> 0 | H10: =IF(AND(ABS(N(F10))<=0.05,ABS(G10)<=0.05),"OK","REVISAR") -> OK
A11: CALIDOSCOPI | B11: JULIO | C11: =SUM(_____CALIDOSCOPI!F6:F300) -> 339 | D11: =SUM(_____CALIDOSCOPI!I9:I300) -> 339 | E11: 339 | F11: =IF(D11="","",ROUND(C11-D11,2)) -> 0 | G11: =IF(D11="",ROUND(C11-E11,2),ROUND(D11-E11,2)) -> 0 | H11: =IF(AND(ABS(N(F11))<=0.05,ABS(G11)<=0.05),"OK","REVISAR") -> OK
A12: CARNICAS MEAT | B12: JULIO | C12: =SUM('_____CARNICAS MEAT'!F6:F300) -> 1412.4078 | D12: =SUM('_____CARNICAS MEAT'!I9:I300) -> 1412.35 | E12: 1412.35 | F12: =IF(D12="","",ROUND(C12-D12,2)) -> 0.06 | G12: =IF(D12="",ROUND(C12-E12,2),ROUND(D12-E12,2)) -> 0 | H12: =IF(AND(ABS(N(F12))<=0.05,ABS(G12)<=0.05),"OK","REVISAR") -> REVISAR | I12: Diferencia de redondeo en las líneas (A1/209: 6,48 kg x 34,55 = 223,88 € y el albarán pone 223,85 €).
A13: CARNICAS MEAT | B13: AGOSTO | C13: =SUM('_____CARNICAS MEAT'!P6:P300) -> 640.25 | D13: =SUM('_____CARNICAS MEAT'!S9:S300) -> 640.26 | E13: =SUMIF('TOTAL AGOSTO'!$B$4:$B$2000,"CARNICAS MEAT",'TOTAL AGOSTO'!$D$4:$D$2000) -> 640.26 | F13: =IF(D13="","",ROUND(C13-D13,2)) -> -0.01 | G13: =IF(D13="",ROUND(C13-E13,2),ROUND(D13-E13,2)) -> 0 | H13: =IF(AND(ABS(N(F13))<=0.05,ABS(G13)<=0.05),"OK","REVISAR") -> OK
A14: CARNICAS OPC | B14: JULIO | C14: =SUM('_____CARNICAS OPC'!F6:F300) -> 240.66 | D14: =SUM('_____CARNICAS OPC'!I9:I300) -> 240.66 | E14: 240.66 | F14: =IF(D14="","",ROUND(C14-D14,2)) -> 0 | G14: =IF(D14="",ROUND(C14-E14,2),ROUND(D14-E14,2)) -> 0 | H14: =IF(AND(ABS(N(F14))<=0.05,ABS(G14)<=0.05),"OK","REVISAR") -> OK
A15: COCACOLA | B15: JULIO | C15: =SUM('_____COCA-COLA'!F6:F300) -> 2124 | D15: =SUM('_____COCA-COLA'!I9:I300) -> 2124.02 | E15: 2124.02 | F15: =IF(D15="","",ROUND(C15-D15,2)) -> -0.02 | G15: =IF(D15="",ROUND(C15-E15,2),ROUND(D15-E15,2)) -> 0 | H15: =IF(AND(ABS(N(F15))<=0.05,ABS(G15)<=0.05),"OK","REVISAR") -> OK
A16: COCACOLA | B16: AGOSTO | C16: =SUM('_____COCA-COLA'!P6:P300) -> 457.7196 | D16: =SUM('_____COCA-COLA'!S9:S300) -> 457.72 | E16: =SUMIF('TOTAL AGOSTO'!$B$4:$B$2000,"COCACOLA",'TOTAL AGOSTO'!$D$4:$D$2000) -> 457.72 | F16: =IF(D16="","",ROUND(C16-D16,2)) -> 0 | G16: =IF(D16="",ROUND(C16-E16,2),ROUND(D16-E16,2)) -> 0 | H16: =IF(AND(ABS(N(F16))<=0.05,ABS(G16)<=0.05),"OK","REVISAR") -> OK
A17: CONS. SELEC. SANTO | B17: JULIO | C17: =SUM('_____CONS. SELEC. SANT'!F6:F300) -> 705.24 | D17: =SUM('_____CONS. SELEC. SANT'!I9:I300) -> 705.24 | E17: 705.24 | F17: =IF(D17="","",ROUND(C17-D17,2)) -> 0 | G17: =IF(D17="",ROUND(C17-E17,2),ROUND(D17-E17,2)) -> 0 | H17: =IF(AND(ABS(N(F17))<=0.05,ABS(G17)<=0.05),"OK","REVISAR") -> OK
A18: CONS. SELEC. SANTO | B18: AGOSTO | C18: =SUM('_____CONS. SELEC. SANT'!P6:P300) -> 382.59 | D18: =SUM('_____CONS. SELEC. SANT'!S9:S300) -> 382.59 | E18: =SUMIF('TOTAL AGOSTO'!$B$4:$B$2000,"CONS. SELEC. SANTO",'TOTAL AGOSTO'!$D$4:$D$2000) -> 382.59 | F18: =IF(D18="","",ROUND(C18-D18,2)) -> 0 | G18: =IF(D18="",ROUND(C18-E18,2),ROUND(D18-E18,2)) -> 0 | H18: =IF(AND(ABS(N(F18))<=0.05,ABS(G18)<=0.05),"OK","REVISAR") -> OK
A19: CONS. Y SAL. JIMENEZ | B19: JULIO | C19: =SUM('_____CONS. Y SALAZONES'!F6:F300) -> 3739.9387 | D19: =SUM('_____CONS. Y SALAZONES'!I9:I300) -> 3739.92 | E19: 3739.92 | F19: =IF(D19="","",ROUND(C19-D19,2)) -> 0.02 | G19: =IF(D19="",ROUND(C19-E19,2),ROUND(D19-E19,2)) -> 0 | H19: =IF(AND(ABS(N(F19))<=0.05,ABS(G19)<=0.05),"OK","REVISAR") -> OK
A20: CONS. Y SAL. JIMENEZ | B20: AGOSTO | C20: =SUM('_____CONS. Y SALAZONES'!P6:P300) -> 1061.5909 | D20: =SUM('_____CONS. Y SALAZONES'!S9:S300) -> 1061.59 | E20: =SUMIF('TOTAL AGOSTO'!$B$4:$B$2000,"CONS. Y SAL. JIMENEZ",'TOTAL AGOSTO'!$D$4:$D$2000) -> 1061.59 | F20: =IF(D20="","",ROUND(C20-D20,2)) -> 0 | G20: =IF(D20="",ROUND(C20-E20,2),ROUND(D20-E20,2)) -> 0 | H20: =IF(AND(ABS(N(F20))<=0.05,ABS(G20)<=0.05),"OK","REVISAR") -> OK
A21: CRNAS SERVAN | B21: JULIO | C21: =SUM('_____CRNAS SERVAN'!F6:F300) -> 1086.025 | D21: =SUM('_____CRNAS SERVAN'!I9:I300) -> 1086.03 | E21: 1086.03 | F21: =IF(D21="","",ROUND(C21-D21,2)) -> 0 | G21: =IF(D21="",ROUND(C21-E21,2),ROUND(D21-E21,2)) -> 0 | H21: =IF(AND(ABS(N(F21))<=0.05,ABS(G21)<=0.05),"OK","REVISAR") -> OK
A22: CRNAS SERVAN | B22: AGOSTO | C22: =SUM('_____CRNAS SERVAN'!P6:P300) -> 890.28 | D22: =SUM('_____CRNAS SERVAN'!S9:S300) -> 890.28 | E22: =SUMIF('TOTAL AGOSTO'!$B$4:$B$2000,"CRNAS SERVAN",'TOTAL AGOSTO'!$D$4:$D$2000) -> 890.28 | F22: =IF(D22="","",ROUND(C22-D22,2)) -> 0 | G22: =IF(D22="",ROUND(C22-E22,2),ROUND(D22-E22,2)) -> 0 | H22: =IF(AND(ABS(N(F22))<=0.05,ABS(G22)<=0.05),"OK","REVISAR") -> OK
A23: CRUSTAPESCA | B23: JULIO | C23: =SUM(_____CRUSTAPESCA!F6:F300) -> 1970.464 | D23: =SUM(_____CRUSTAPESCA!I9:I300) -> 1970.46 | E23: 1970.46 | F23: =IF(D23="","",ROUND(C23-D23,2)) -> 0 | G23: =IF(D23="",ROUND(C23-E23,2),ROUND(D23-E23,2)) -> 0 | H23: =IF(AND(ABS(N(F23))<=0.05,ABS(G23)<=0.05),"OK","REVISAR") -> OK
A24: CRUSTAPESCA | B24: AGOSTO | C24: =SUM(_____CRUSTAPESCA!P6:P300) -> 772 | D24: =SUM(_____CRUSTAPESCA!S9:S300) -> 772 | E24: =SUMIF('TOTAL AGOSTO'!$B$4:$B$2000,"CRUSTAPESCA",'TOTAL AGOSTO'!$D$4:$D$2000) -> 772 | F24: =IF(D24="","",ROUND(C24-D24,2)) -> 0 | G24: =IF(D24="",ROUND(C24-E24,2),ROUND(D24-E24,2)) -> 0 | H24: =IF(AND(ABS(N(F24))<=0.05,ABS(G24)<=0.05),"OK","REVISAR") -> OK
A25: DELIPAN | B25: JULIO | C25: =SUM(_____DELIPAN!F6:F300) -> 1032.66 | D25: =SUM(_____DELIPAN!I9:I300) -> 1032.66 | E25: 1032.66 | F25: =IF(D25="","",ROUND(C25-D25,2)) -> 0 | G25: =IF(D25="",ROUND(C25-E25,2),ROUND(D25-E25,2)) -> 0 | H25: =IF(AND(ABS(N(F25))<=0.05,ABS(G25)<=0.05),"OK","REVISAR") -> OK
A26: DELIPAN | B26: AGOSTO | C26: =SUM(_____DELIPAN!P6:P300) -> 381.21 | D26: =SUM(_____DELIPAN!S9:S300) -> 381.21 | E26: =SUMIF('TOTAL AGOSTO'!$B$4:$B$2000,"DELIPAN",'TOTAL AGOSTO'!$D$4:$D$2000) -> 381.21 | F26: =IF(D26="","",ROUND(C26-D26,2)) -> 0 | G26: =IF(D26="",ROUND(C26-E26,2),ROUND(D26-E26,2)) -> 0 | H26: =IF(AND(ABS(N(F26))<=0.05,ABS(G26)<=0.05),"OK","REVISAR") -> OK
A27: DISOLTRIGO | B27: JULIO | C27: =SUM(_____DISOLTRIGO!F6:F300) -> 1295.5 | D27: =SUM(_____DISOLTRIGO!I9:I300) -> 1295.5 | E27: 1295.5 | F27: =IF(D27="","",ROUND(C27-D27,2)) -> 0 | G27: =IF(D27="",ROUND(C27-E27,2),ROUND(D27-E27,2)) -> 0 | H27: =IF(AND(ABS(N(F27))<=0.05,ABS(G27)<=0.05),"OK","REVISAR") -> OK
A28: DISOLTRIGO | B28: AGOSTO | C28: =SUM(_____DISOLTRIGO!P6:P300) -> 318 | D28: =SUM(_____DISOLTRIGO!S9:S300) -> 318 | E28: =SUMIF('TOTAL AGOSTO'!$B$4:$B$2000,"DISOLTRIGO",'TOTAL AGOSTO'!$D$4:$D$2000) -> 318 | F28: =IF(D28="","",ROUND(C28-D28,2)) -> 0 | G28: =IF(D28="",ROUND(C28-E28,2),ROUND(D28-E28,2)) -> 0 | H28: =IF(AND(ABS(N(F28))<=0.05,ABS(G28)<=0.05),"OK","REVISAR") -> OK
A29: DIST. TENA MTNEZ | B29: JULIO | C29: =SUM('_____DIST. TENA'!F6:F300) -> 3131.64 | D29: =SUM('_____DIST. TENA'!I9:I300) -> 3131.64 | E29: 3131.64 | F29: =IF(D29="","",ROUND(C29-D29,2)) -> 0 | G29: =IF(D29="",ROUND(C29-E29,2),ROUND(D29-E29,2)) -> 0 | H29: =IF(AND(ABS(N(F29))<=0.05,ABS(G29)<=0.05),"OK","REVISAR") -> OK
A30: DIST. TENA MTNEZ | B30: AGOSTO | C30: =SUM('_____DIST. TENA'!P6:P300) -> 1320.36 | D30: =SUM('_____DIST. TENA'!S9:S300) -> 1320.36 | E30: =SUMIF('TOTAL AGOSTO'!$B$4:$B$2000,"DIST. TENA MTNEZ",'TOTAL AGOSTO'!$D$4:$D$2000) -> 1320.36 | F30: =IF(D30="","",ROUND(C30-D30,2)) -> 0 | G30: =IF(D30="",ROUND(C30-E30,2),ROUND(D30-E30,2)) -> 0 | H30: =IF(AND(ABS(N(F30))<=0.05,ABS(G30)<=0.05),"OK","REVISAR") -> OK
A31: EIF DISTRIBUCIONES | B31: JULIO | C31: =SUM('_____EIF DISTRIBUCIONES'!F6:F300) -> 646.5718 | D31: =SUM('_____EIF DISTRIBUCIONES'!I9:I300) -> 646.58 | E31: 646.58 | F31: =IF(D31="","",ROUND(C31-D31,2)) -> -0.01 | G31: =IF(D31="",ROUND(C31-E31,2),ROUND(D31-E31,2)) -> 0 | H31: =IF(AND(ABS(N(F31))<=0.05,ABS(G31)<=0.05),"OK","REVISAR") -> OK
A32: EIF DISTRIBUCIONES | B32: AGOSTO | C32: =SUM('_____EIF DISTRIBUCIONES'!P6:P300) -> 604.0463 | D32: =SUM('_____EIF DISTRIBUCIONES'!S9:S300) -> 604.05 | E32: =SUMIF('TOTAL AGOSTO'!$B$4:$B$2000,"EIF DISTRIBUCIONES",'TOTAL AGOSTO'!$D$4:$D$2000) -> 604.05 | F32: =IF(D32="","",ROUND(C32-D32,2)) -> 0 | G32: =IF(D32="",ROUND(C32-E32,2),ROUND(D32-E32,2)) -> 0 | H32: =IF(AND(ABS(N(F32))<=0.05,ABS(G32)<=0.05),"OK","REVISAR") -> OK
A33: ENRIQUE CAMPS | B33: JULIO | C33: =SUM('_____ENRIQUE CAMPS'!F6:F300) -> 1189 | D33: =SUM('_____ENRIQUE CAMPS'!I9:I300) -> 1189 | E33: 1189 | F33: =IF(D33="","",ROUND(C33-D33,2)) -> 0 | G33: =IF(D33="",ROUND(C33-E33,2),ROUND(D33-E33,2)) -> 0 | H33: =IF(AND(ABS(N(F33))<=0.05,ABS(G33)<=0.05),"OK","REVISAR") -> OK
A34: ENRIQUE CAMPS | B34: AGOSTO | C34: =SUM('_____ENRIQUE CAMPS'!P6:P300) -> 432 | D34: =SUM('_____ENRIQUE CAMPS'!S9:S300) -> 432 | E34: =SUMIF('TOTAL AGOSTO'!$B$4:$B$2000,"ENRIQUE CAMPS",'TOTAL AGOSTO'!$D$4:$D$2000) -> 432 | F34: =IF(D34="","",ROUND(C34-D34,2)) -> 0 | G34: =IF(D34="",ROUND(C34-E34,2),ROUND(D34-E34,2)) -> 0 | H34: =IF(AND(ABS(N(F34))<=0.05,ABS(G34)<=0.05),"OK","REVISAR") -> OK
A35: ESCRIBANO SANZ | B35: JULIO | C35: =SUM('_____ESCRIBANO SANZ'!F6:F300) -> 193.69 | D35: =SUM('_____ESCRIBANO SANZ'!I9:I300) -> 193.7 | E35: 193.7 | F35: =IF(D35="","",ROUND(C35-D35,2)) -> -0.01 | G35: =IF(D35="",ROUND(C35-E35,2),ROUND(D35-E35,2)) -> 0 | H35: =IF(AND(ABS(N(F35))<=0.05,ABS(G35)<=0.05),"OK","REVISAR") -> OK
A36: ESCRIBANO SANZ | B36: AGOSTO | C36: =SUM('_____ESCRIBANO SANZ'!P6:P300) -> 84.48 | D36: =SUM('_____ESCRIBANO SANZ'!S9:S300) -> 84.48 | E36: =SUMIF('TOTAL AGOSTO'!$B$4:$B$2000,"ESCRIBANO SANZ",'TOTAL AGOSTO'!$D$4:$D$2000) -> 84.48 | F36: =IF(D36="","",ROUND(C36-D36,2)) -> 0 | G36: =IF(D36="",ROUND(C36-E36,2),ROUND(D36-E36,2)) -> 0 | H36: =IF(AND(ABS(N(F36))<=0.05,ABS(G36)<=0.05),"OK","REVISAR") -> OK
A37: FCO JAVIER LABRADOR | B37: JULIO | C37: =SUM('_____FCO JAVIER LABRADOR'!F6:F300) -> 183.2 | D37: =SUM('_____FCO JAVIER LABRADOR'!I9:I300) -> 183.2 | E37: 183.2 | F37: =IF(D37="","",ROUND(C37-D37,2)) -> 0 | G37: =IF(D37="",ROUND(C37-E37,2),ROUND(D37-E37,2)) -> 0 | H37: =IF(AND(ABS(N(F37))<=0.05,ABS(G37)<=0.05),"OK","REVISAR") -> OK
A38: FCO JAVIER LABRADOR | B38: AGOSTO | C38: =SUM('_____FCO JAVIER LABRADOR'!P6:P300) -> 91.6 | D38: =SUM('_____FCO JAVIER LABRADOR'!S9:S300) -> 91.6 | E38: =SUMIF('TOTAL AGOSTO'!$B$4:$B$2000,"FCO JAVIER LABRADOR",'TOTAL AGOSTO'!$D$4:$D$2000) -> 91.6 | F38: =IF(D38="","",ROUND(C38-D38,2)) -> 0 | G38: =IF(D38="",ROUND(C38-E38,2),ROUND(D38-E38,2)) -> 0 | H38: =IF(AND(ABS(N(F38))<=0.05,ABS(G38)<=0.05),"OK","REVISAR") -> OK
A39: FRUTERIA D'ALISTE | B39: JULIO | C39: =SUM('_____FRUTERIA DALISTE'!F6:F300) -> 158.9995 | D39: =SUM('_____FRUTERIA DALISTE'!I9:I300) -> 158.99 | E39: 158.99 | F39: =IF(D39="","",ROUND(C39-D39,2)) -> 0.01 | G39: =IF(D39="",ROUND(C39-E39,2),ROUND(D39-E39,2)) -> 0 | H39: =IF(AND(ABS(N(F39))<=0.05,ABS(G39)<=0.05),"OK","REVISAR") -> OK
A40: JC MACKINTOSH | B40: AGOSTO | C40: =SUM('_____JC MACKINTOSH'!F6:F300) -> 516 | D40: =SUM('_____JC MACKINTOSH'!I9:I300) -> 516 | E40: =SUMIF('TOTAL AGOSTO'!$B$4:$B$2000,"JC MACKINTOSH",'TOTAL AGOSTO'!$D$4:$D$2000) -> 516 | F40: =IF(D40="","",ROUND(C40-D40,2)) -> 0 | G40: =IF(D40="",ROUND(C40-E40,2),ROUND(D40-E40,2)) -> 0 | H40: =IF(AND(ABS(N(F40))<=0.05,ABS(G40)<=0.05),"OK","REVISAR") -> OK
A41: JOSE PEÑA | B41: JULIO | C41: =SUM('_____JOSE PEÑA'!F6:F300) -> 748.5 | D41: =SUM('_____JOSE PEÑA'!I9:I300) -> 748.5 | E41: 748.5 | F41: =IF(D41="","",ROUND(C41-D41,2)) -> 0 | G41: =IF(D41="",ROUND(C41-E41,2),ROUND(D41-E41,2)) -> 0 | H41: =IF(AND(ABS(N(F41))<=0.05,ABS(G41)<=0.05),"OK","REVISAR") -> OK
A42: JOSE ROMERO PLAZA | B42: JULIO | C42: =SUM('_____JOSE ROMERO PLAZA'!F6:F300) -> 444.1 | D42: =SUM('_____JOSE ROMERO PLAZA'!I9:I300) -> 444.1 | E42: 444.1 | F42: =IF(D42="","",ROUND(C42-D42,2)) -> 0 | G42: =IF(D42="",ROUND(C42-E42,2),ROUND(D42-E42,2)) -> 0 | H42: =IF(AND(ABS(N(F42))<=0.05,ABS(G42)<=0.05),"OK","REVISAR") -> OK
...

Sheet _____AGMASFOOD
B2: 46204 | L2: 46235
H4: TOTAL | I4: =SUM(F6:F300) -> 1122.98 | R4: TOTAL | S4: =SUM(P6:P300) -> 1125.185
B5: PRODUCTO | C5: UNIDADES | D5: PRECIO | E5: DTO | F5: TOTAL | H5: ALBARANES | I5: =SUM(I9:I300) -> 1122.99 | L5: PRODUCTO | M5: UNIDADES | N5: PRECIO | O5: DTO | P5: TOTAL | R5: ALBARANES | S5: =SUM(S9:S300) -> 1125.19
B6: LOMO NEGRO SIN COLA LIMPIO | C6: =4.9+5+5.2 -> 15.1 | D6: 39.05 | E6: 0 | F6: =(C6*D6)-((C6*D6)*E6) -> 589.655 | H6: DIFERENCIA | I6: =I5-I4 -> 0.01 | L6: LOMO NEGRO SIN COLA LIMPIO | M6: =4.9+5.05+4.75 -> 14.7 | N6: 39.05 | O6: 0 | P6: =(M6*N6)-((M6*N6)*O6) -> 574.035 | R6: DIFERENCIA | S6: =S5-S4 -> 0.005
B7: GAMBA ROJA ALISTADA 15-20P | C7: =1.3+1.2 -> 2.5 | D7: 79 | E7: 0 | F7: =(C7*D7)-((C7*D7)*E7) -> 197.5 | L7: GAMBA ROJA ALISTADA 15-20P | M7: =1.3+1+1.2 -> 3.5 | N7: 84 | O7: 0 | P7: =(M7*N7)-((M7*N7)*O7) -> 294
B8: BOQUERON GORDO | C8: =3.5 -> 3.5 | D8: 11.95 | E8: 0 | F8: =(C8*D8)-((C8*D8)*E8) -> 41.825 | H8: Nº ALBARÁN | I8: BASE | J8: % IVA | L8: BOQUERON GORDO | M8: 3 | N8: 11.95 | O8: 0 | P8: =(M8*N8)-((M8*N8)*O8) -> 35.85 | R8: Nº ALBARÁN | S8: BASE | T8: % IVA
B9: GAMBA ROJA ALISTADA 15-20P | C9: =1.5+1+1 -> 3.5 | D9: 84 | E9: 0 | F9: =(C9*D9)-((C9*D9)*E9) -> 294 | H9: 26 6093 | I9: 191.35 | J9: 0.1 | L9: BOQUERON GORDO | M9: =3+3.5+3+4 -> 13.5 | N9: 9.8 | O9: 0 | P9: =(M9*N9)-((M9*N9)*O9) -> 132.3 | R9: 26 6717 | S9: 300.55 | T9: 0.1
H10: 26 6075 | I10: 102.7 | J10: 0.1 | L10: GAMBA ROJA ALISTADA 15-20P | M10: 1 | N10: 89 | O10: 0 | P10: =(M10*N10)-((M10*N10)*O10) -> 89 | R10: 26 6980 | S10: 35.85 | T10: 0.1
H11: 26 6029 | I11: 41.83 | J11: 0.1 | R11: 26 7006 | S11: 84 | T11: 0.1
H12: 26 5876 | I12: 195.25 | J12: 0.1 | R12: 26 7016 | S12: 226.6 | T12: 0.1
H13: 26 5951 | I13: 94.8 | J13: 0.1 | R13: 26 7048 | S13: 100.8 | T13: 0.1
H14: 26 6564 | I14: 203.06 | J14: 0.1 | R14: 26 7103 | S14: 34.3 | T14: 0.1
H15: 26 6530 | I15: 126 | J15: 0.1 | R15: 26 7151 | S15: 0 | T15: 0.1
H16: 26 6503 | I16: 84 | J16: 0.1 | R16: 26 7202 | S16: 29.4 | T16: 0.1
H17: 26 6629 | I17: 84 | J17: 0.1 | R17: 26 7226 | S17: 185.49 | T17: 0.1
R18: 26 7264 | S18: 128.2 | T18: 0.1

Sheet _____AGROFOOD
B2: 46204 | L2: 46235
H4: TOTAL | I4: =SUM(F6:F300) -> 4059.71 | R4: TOTAL | S4: =SUM(P6:P300) -> 1199.4617
B5: PRODUCTO | C5: UNIDADES | D5: PRECIO | E5: DTO | F5: TOTAL | H5: ALBARANES | I5: =SUM(I9:I300) -> 4059.72 | L5: PRODUCTO | M5: UNIDADES | N5: PRECIO | O5: DTO | P5: TOTAL | R5: ALBARANES | S5: =SUM(S9:S300) -> 1199.46
B6: ENTRECOT T. MORUCHA | C6: =6.95+3.4+7.12+3.42+15.16+10.41+3.21+8.21+13.51+3.29+7.16+3.57+13.04+10.45 -> 108.9 | D6: 27.5 | E6: 0 | F6: =(C6*D6)-((C6*D6)*E6) -> 2994.75 | H6: DIFERENCIA | I6: =I5-I4 -> 0.01 | L6: MEDALLON P. SOLOMILLO VACUNO (precio+MER 0,07) | M6: =6.17+4.19+4 -> 14.36 | N6: 36.97 | O6: 0 | P6: =(M6*N6)-((M6*N6)*O6) -> 530.8892 | R6: DIFERENCIA | S6: =S5-S4 -> -0.0017
B7: MEDALLON P. SOLOMILLO VACUNO | C7: =2.09+2.12+2.08+2+2.05+2.04+4.19+2.03+2.01+1.94+3.95+2.1 -> 28.6 | D7: 36.9 | E7: 0 | F7: =(C7*D7)-((C7*D7)*E7) -> 1055.34 | L7: ENTRECOT T. MORUCHA (precio+MER 0,07) | M7: =13.34+10.91 -> 24.25 | N7: 27.57 | O7: 0 | P7: =(M7*N7)-((M7*N7)*O7) -> 668.5725
B8: TASA DE ELIMINACION DE RESIDUOS | C8: 1 | D8: 1.02 | E8: 0 | F8: =(C8*D8)-((C8*D8)*E8) -> 1.02 | H8: Nº ALBARÁN | I8: BASE | J8: % IVA | R8: Nº ALBARÁN | S8: BASE | T8: % IVA
B9: TASA DE ELIMINACION DE RESIDUOS | C9: 1 | D9: 0.74 | E9: 0 | F9: =(C9*D9)-((C9*D9)*E9) -> 0.74 | H9: M26/810 | I9: 441 | J9: 0.1 | R9: M26/935 | S9: 228.11 | T9: 0.1
B10: TASA DE ELIMINACION DE RESIDUOS | C10: 1 | D10: 1.21 | E10: 0 | F10: =(C10*D10)-((C10*D10)*E10) -> 1.21 | H10: M26/787 | I10: 290.59 | J10: 0.1 | R10: M26/952 | S10: 522.68 | T10: 0.1
B11: TASA DE ELIMINACION DE RESIDUOS | C11: 1 | D11: 1.15 | E11: 0 | F11: =(C11*D11)-((C11*D11)*E11) -> 1.15 | H11: M26/776 | I11: 494.86 | J11: 0.1 | R11: M26/928 | S11: 448.67 | T11: 0.1
B12: TASA DE ELIMINACION DE RESIDUOS | C12: 1 | D12: 0.22 | E12: 0 | F12: =(C12*D12)-((C12*D12)*E12) -> 0.22 | H12: M26/865 | I12: 512.15 | J12: 0.1
B13: TASA DE ELIMINACION DE RESIDUOS | C13: 1 | D13: 0.57 | E13: 0 | F13: =(C13*D13)-((C13*D13)*E13) -> 0.57 | H13: M26/849 | I13: 88.5 | J13: 0.1
B14: TASA DE ELIMINACION DE RESIDUOS | C14: 1 | D14: 1.47 | E14: 0 | F14: =(C14*D14)-((C14*D14)*E14) -> 1.47 | H14: M26/844 | I14: 226.35 | J14: 0.1
B15: TASA DE ELIMINACION DE RESIDUOS | C15: 1 | D15: 1.03 | E15: 0 | F15: =(C15*D15)-((C15*D15)*E15) -> 1.03 | H15: M26/839 | I15: 618.08 | J15: 0.1
B16: TASA DE ELIMINACION DE RESIDUOS | C16: 1 | D16: 1.33 | E16: 0 | F16: =(C16*D16)-((C16*D16)*E16) -> 1.33 | H16: M26/817 | I16: 445.18 | J16: 0.1
B17: TASA DE ELIMINACION DE RESIDUOS | C17: 1 | D17: 0.88 | E17: 0 | F17: =(C17*D17)-((C17*D17)*E17) -> 0.88 | H17: M26/890 | I17: 577.26 | J17: 0.1
H18: M26/872 | I18: 365.75 | J18: 0.1

Sheet _____ANTONIO DE MIGUEL
B2: 46204
H4: TOTAL | I4: =SUM(F6:F300) -> 280.3
B5: PRODUCTO | C5: UNIDADES | D5: PRECIO | E5: DTO | F5: TOTAL | H5: ALBARANES | I5: =SUM(I9:I300) -> 280.3
B6: PATO CEBADO-FOIE RESTAURACION (400-900) | C6: 10 | D6: 28.03 | E6: 0 | F6: =(C6*D6)-((C6*D6)*E6) -> 280.3 | H6: DIFERENCIA | I6: =I5-I4 -> 0
H8: Nº ALBARÁN | I8: BASE | J8: % IVA
H9: A/2066113 | I9: 280.3 | J9: 0.1

Sheet _____CALIDOSCOPI
B2: 46204
H4: TOTAL | I4: =SUM(F6:F300) -> 339
B5: PRODUCTO | C5: UNIDADES | D5: PRECIO | E5: DTO | F5: TOTAL | H5: ALBARANES | I5: =SUM(I9:I300) -> 339
B6: PAGO DE CARRAOVEJAS 2023 | C6: 12 | D6: 28.25 | E6: 0 | F6: =(C6*D6)-((C6*D6)*E6) -> 339 | H6: DIFERENCIA | I6: =I5-I4 -> 0
H8: Nº ALBARÁN | I8: BASE | J8: % IVA
H9: AV-CV26-004508 | I9: 339 | J9: 0.21

Sheet _____CARNICAS MEAT
B2: 46204 | L2: 46235
H4: TOTAL | I4: =SUM(F6:F300) -> 1412.4078 | R4: TOTAL | S4: =SUM(P6:P300) -> 640.25
B5: PRODUCTO | C5: UNIDADES | D5: PRECIO | E5: DTO | F5: TOTAL | H5: ALBARANES | I5: =SUM(I9:I300) -> 1412.35 | L5: PRODUCTO | M5: UNIDADES | N5: PRECIO | O5: DTO | P5: TOTAL | R5: ALBARANES | S5: =SUM(S9:S300) -> 640.26
B6: CHULETA CORDERO LECHAL | C6: =8.86+6.715+4.685 -> 20.26 | D6: 25 | E6: 0 | F6: =(C6*D6)-((C6*D6)*E6) -> 506.5 | H6: DIFERENCIA | I6: =I5-I4 -> -0.05775 | L6: SOLOMILLO VACA | M6: =6.65+4.375 -> 11.025 | N6: 35 | O6: 0 | P6: =(M6*N6)-((M6*N6)*O6) -> 385.875 | R6: DIFERENCIA | S6: =S5-S4 -> 0.01
B7: TERNERA MIXTA | C7: =5.11 -> 5.11 | D7: 10.9 | E7: 0 | F7: =(C7*D7)-((C7*D7)*E7) -> 55.699 | L7: CHULETA CORDERO LECHAL | M7: =5.925+4.25 -> 10.175 | N7: 25 | O7: 0 | P7: =(M7*N7)-((M7*N7)*O7) -> 254.375
B8: SOLOMILLO VACA | C8: =5.445+6.48 -> 11.925 | D8: 34.55 | E8: 0 | F8: =(C8*D8)-((C8*D8)*E8) -> 412.00875 | H8: Nº ALBARÁN | I8: BASE | J8: % IVA | R8: Nº ALBARÁN | S8: BASE | T8: % IVA
B9: SOLOMILLO VACA | C9: =5.795+6.725 -> 12.52 | D9: 35 | E9: 0 | F9: =(C9*D9)-((C9*D9)*E9) -> 438.2 | H9: A1/195 | I9: 221.5 | J9: 0.1 | R9: A1/221 | S9: 380.88 | T9: 0.1
H10: A1/191 | I10: 243.8 | J10: 0.1 | R10: A1/227 | S10: 259.38 | T10: 0.1
H11: A1/188 | I11: 370.7 | J11: 0.1
H12: A1/209 | I12: 340.98 | J12: 0.1
H13: A1/202 | I13: 235.37 | J13: 0.1

Sheet _____CARNICAS OPC
B2: 46204
H4: TOTAL | I4: =SUM(F6:F300) -> 240.66
B5: PRODUCTO | C5: UNIDADES | D5: PRECIO | E5: DTO | F5: TOTAL | H5: ALBARANES | I5: =SUM(I9:I300) -> 240.66
B6: MEDIA CAJA HUEVO | C6: 1 | D6: 45 | E6: 0 | F6: =(C6*D6)-((C6*D6)*E6) -> 45 | H6: DIFERENCIA | I6: =I5-I4 -> 0
B7: PANCETA ADOBADA | C7: =4.2+4+3 -> 11.2 | D7: 8.8 | E7: 0 | F7: =(C7*D7)-((C7*D7)*E7) -> 98.56
B8: CAJA HUEVOS CORRAL | C8: 1 | D8: 52.5 | E8: 0 | F8: =(C8*D8)-((C8*D8)*E8) -> 52.5 | H8: Nº ALBARÁN | I8: BASE | J8: % IVA
B9: POLLO TROCEADO | C9: =5.2 -> 5.2 | D9: 3.5 | E9: 0 | F9: =(C9*D9)-((C9*D9)*E9) -> 18.2 | H9: A2607-0221 | I9: 81.96 | J9: 0.1
B10: OREJA DE CERDO | C10: =4.4 -> 4.4 | D10: 6 | E10: 0 | F10: =(C10*D10)-((C10*D10)*E10) -> 26.4 | H10: A2607-0169 | I10: 105.9 | J10: 0.21
H11: A2607-0092 | I11: 52.8 | J11: 0.1

Sheet _____COCA-COLA
B2: 46204 | L2: 46235
H4: TOTAL | I4: =SUM(F6:F300) -> 2124 | R4: TOTAL | S4: =SUM(P6:P300) -> 457.7196
B5: PRODUCTO | C5: UNIDADES | D5: PRECIO | E5: DTO | F5: TOTAL | H5: ALBARANES | I5: =SUM(I9:I300) -> 2124.02 | L5: PRODUCTO | M5: UNIDADES | N5: PRECIO | O5: DTO | P5: TOTAL | R5: ALBARANES | S5: =SUM(S9:S300) -> 457.72
B6: CAJA+BOTELLAS VR237 | C6: 20 | D6: 4.8 | E6: 0 | F6: =(C6*D6)-((C6*D6)*E6) -> 96 | H6: DIFERENCIA | I6: =I5-I4 -> 0.02 | L6: COCACOLA VR237 C24 (neto caja) | M6: 3 | N6: 20.28 | O6: 0 | P6: =(M6*N6)-((M6*N6)*O6) -> 60.84 | R6: DIFERENCIA | S6: =S5-S4 -> 0.0004
B7: COCACOLA PET2L C6 | C7: 36 | D7: 2.504 | E7: 0 | F7: =(C7*D7)-((C7*D7)*E7) -> 90.144 | L7: COCACOLA ZERO VR237 C24 (neto caja) | M7: 6 | N7: 20.2783 | O7: 0 | P7: =(M7*N7)-((M7*N7)*O7) -> 121.6698
B8: COCACOLA VR237 C24 | C8: =48+48+96+96+96+144 -> 528 | D8: 0.845 | E8: 0 | F8: =(C8*D8)-((C8*D8)*E8) -> 446.16 | H8: Nº ALBARÁN | I8: BASE | J8: % IVA | L8: COCACOLA ZERO ZERO VR237 C24 (neto caja) | M8: =2+1 -> 3 | N8: 20.28 | O8: 0 | P8: =(M8*N8)-((M8*N8)*O8) -> 60.84 | R8: Nº ALBARÁN | S8: BASE | T8: % IVA
B9: COCACOLA VR237 C24 | C9: 21 | D9: 4.8 | E9: 0 | F9: =(C9*D9)-((C9*D9)*E9) -> 100.8 | H9: 521604 | I9: 200.66 | J9: 0.21 | L9: COCACOLA PET 2L C6 (neto caja) | M9: 1 | N9: 15.02 | O9: 0 | P9: =(M9*N9)-((M9*N9)*O9) -> 15.02 | R9: 4536210096 | S9: 238.09 | T9: 0.21
B10: COCACOLA ZER VR237 C24 | C10: =144+120+168+216+144+360+288 -> 1440 | D10: 0.845 | E10: 0 | F10: =(C10*D10)-((C10*D10)*E10) -> 1216.8 | H10: 629349 | I10: 141.96 | J10: 0.21 | L10: COCACOLA VR237 C24 (neto caja) | M10: 6 | N10: 20.2783 | O10: 0 | P10: =(M10*N10)-((M10*N10)*O10) -> 121.6698 | R10: 4536386996 | S10: 223.07 | T10: 0.21
B11: COCACOLA ZER ZER VR237 C24 | C11: =48+24+72 -> 144 | D11: 0.845 | E11: 0 | F11: =(C11*D11)-((C11*D11)*E11) -> 121.68 | H11: 658014 | I11: 34.96 | J11: 0.1 | L11: COCACOLA ZERO VR237 C24 (neto caja) | M11: 4 | N11: 20.28 | O11: 0 | P11: =(M11*N11)-((M11*N11)*O11) -> 81.12 | R11: 4536386996 | S11: 34.96 | T11: 0.1
B12: MINUTE MAID TOM VNR20 C24 | C12: =48+24 -> 72 | D12: 0.728 | E12: 0 | F12: =(C12*D12)-((C12*D12)*E12) -> 52.416 | H12: 658014 | I12: 293.69 | J12: 0.21 | L12: MINUTE MAID TOMATE VNR20 C24 (neto caja) | M12: 2 | N12: 17.48 | O12: 0 | P12: =(M12*N12)-((M12*N12)*O12) -> 34.96 | R12: 4536386995 | S12: -38.4 | T12: 0.21
H13: 657975 | I13: 48 | J13: 0.21 | L13: DEVOLUCION CAJA+BOTELLAS VR237 | M13: -8 | N13: 4.8 | O13: 0 | P13: =(M13*N13)-((M13*N13)*O13) -> -38.4
H14: 874907 | I14: 17.48 | J14: 0.1
H15: 874907 | I15: 287.64 | J15: 0.21
H16: 970813 | I16: 232.84 | J16: 0.21
H17: 122492 | I17: 484.55 | J17: 0.21
H18: 366393 | I18: 334.24 | J18: 0.1
H19: 366398 | I19: 48 | J19: 0.21

Sheet _____CONS. SELEC. SANT
B2: 46204 | L2: 46235
H4: TOTAL | I4: =SUM(F6:F300) -> 705.24 | R4: TOTAL | S4: =SUM(P6:P300) -> 382.59
B5: PRODUCTO | C5: UNIDADES | D5: PRECIO | E5: DTO | F5: TOTAL | H5: ALBARANES | I5: =SUM(I9:I300) -> 705.24 | L5: PRODUCTO | M5: UNIDADES | N5: PRECIO | O5: DTO | P5: TOTAL | R5: ALBARANES | S5: =SUM(S9:S300) -> 382.59
B6: DON BOCARTE MEDIO PULPO 360-400 gr | C6: =12.88+13.24 -> 26.12 | D6: 27 | E6: 0 | F6: =(C6*D6)-((C6*D6)*E6) -> 705.24 | H6: DIFERENCIA | I6: =I5-I4 -> 0 | L6: DON BOCARTE MEDIO PULPO 360-400 gr | M6: 14.17 | N6: 27 | O6: 0 | P6: =(M6*N6)-((M6*N6)*O6) -> 382.59 | R6: DIFERENCIA | S6: =S5-S4 -> 0
H8: Nº ALBARÁN | I8: BASE | J8: % IVA | R8: Nº ALBARÁN | S8: BASE | T8: % IVA
H9: 4604 | I9: 347.76 | J9: 0.1 | R9: 5653 | S9: 382.59 | T9: 0.1
H10: 5016 | I10: 357.48 | J10: 0.1

Sheet _____CONS. Y SALAZONES
B2: 46204 | L2: 46235
H4: TOTAL | I4: =SUM(F6:F300) -> 3739.9387 | R4: TOTAL | S4: =SUM(P6:P300) -> 1061.5909
B5: PRODUCTO | C5: UNIDADES | D5: PRECIO | E5: DTO | F5: TOTAL | H5: ALBARANES | I5: =SUM(I9:I300) -> 3739.92 | L5: PRODUCTO | M5: UNIDADES | N5: PRECIO | O5: DTO | P5: TOTAL | R5: ALBARANES | S5: =SUM(S9:S300) -> 1061.59
B6: ANCHOAS CANTABRICO COSTERA | C6: =8+8+8+8+8+8 -> 48 | D6: 16.9 | E6: 0.02 | F6: =(C6*D6)-((C6*D6)*E6) -> 794.976 | H6: DIFERENCIA | I6: =I5-I4 -> -0.01872 | L6: ANCHOAS CANTABRICO COSTERA | M6: =8+8 -> 16 | N6: 16.9 | O6: 0.02 | P6: =(M6*N6)-((M6*N6)*O6) -> 264.992 | R6: DIFERENCIA | S6: =S5-S4 -> -0.00088
B7: ANCHOAS DEL CANTABRICO GRAN RESERVA | C7: =16+16+16+16 -> 64 | D7: 28.66 | E7: 0.02 | F7: =(C7*D7)-((C7*D7)*E7) -> 1797.5552 | L7: VENTRESCA DE BONITO EXTRA | M7: 24 | N7: 5.86 | O7: 0.02 | P7: =(M7*N7)-((M7*N7)*O7) -> 137.8272
B8: VENTRESCA DE BONITO EXTRA | C8: =24+24 -> 48 | D8: 5.86 | E8: 0.02 | F8: =(C8*D8)-((C8*D8)*E8) -> 275.6544 | H8: Nº ALBARÁN | I8: BASE | J8: % IVA | L8: ANCHOAS DEL CANTABRICO GRAN RESERVA | M8: 16 | N8: 28.66 | O8: 0.02 | P8: =(M8*N8)-((M8*N8)*O8) -> 449.3888 | R8: Nº ALBARÁN | S8: BASE | T8: % IVA
B9: MEJILLONES ESCABECHE RIAS GALLEGAS RR-125 | C9: 25 | D9: 5.86 | E9: 0.02 | F9: =(C9*D9)-((C9*D9)*E9) -> 143.57 | H9: 26A00878 | I9: 719.71 | J9: 0.1 | L9: MEJILLONES ESCABECHE RIAS GALLEGAS OL-120 6/8 | M9: 24 | N9: 5.96 | O9: 0.02 | P9: =(M9*N9)-((M9*N9)*O9) -> 140.1792 | R9: 26A01042 | S9: 859.89 | T9: 0.1
B10: BERBERECHOS RIAS GALLEGAS RO-120 30/40 | C10: 24 | D10: 11.4 | E10: 0.02 | F10: =(C10*D10)-((C10*D10)*E10) -> 268.128 | H10: 26A00831 | I10: 993.58 | J10: 0.1 | L10: MOJAMA EXTRA SUPERIOR LA CHANCA | M10: 1.94 | N10: 36.4 | O10: 0.02 | P10: =(M10*N10)-((M10*N10)*O10) -> 69.20368 | R10: 26A01059 | S10: 201.7 | T10: 0.1
B11: ANCHOAS CANTABRICO RO-550 ETIQUETA ROJA | C11: 18 | D11: 20.6 | E11: 0.02 | F11: =(C11*D11)-((C11*D11)*E11) -> 363.384 | H11: 26A00946 | I11: 270.32 | J11: 0.1
B12: MOJAMA EXTRA SUPERIOR LA CHANCA | C12: 2.71 | D12: 36.4 | E12: 0.02 | F12: =(C12*D12)-((C12*D12)*E12) -> 96.67112 | H12: 26A00922 | I12: 132.5 | J12: 0.1
H13: 26A00916 | I13: 812.77 | J13: 0.1
H14: 26A00903 | I14: 229.16 | J14: 0.1
H15: 26A00978 | I15: 581.88 | J15: 0.1

Sheet _____CRNAS SERVAN
B2: 46204 | L2: 46235
H4: TOTAL | I4: =SUM(F6:F300) -> 1086.025 | R4: TOTAL | S4: =SUM(P6:P300) -> 890.28
B5: PRODUCTO | C5: UNIDADES | D5: PRECIO | E5: DTO | F5: TOTAL | H5: ALBARANES | I5: =SUM(I9:I300) -> 1086.03 | L5: PRODUCTO | M5: UNIDADES | N5: PRECIO | O5: DTO | P5: TOTAL | R5: ALBARANES | S5: =SUM(S9:S300) -> 890.28
B6: MEDIA CAJA DE HUERVO | C6: =2+1 -> 3 | D6: 45 | E6: 0 | F6: =(C6*D6)-((C6*D6)*E6) -> 135 | H6: DIFERENCIA | I6: =I5-I4 -> 0.005 | L6: MEDIA CAJA DE HUERVO | M6: =1+1+1+1 -> 4 | N6: 45 | O6: 0 | P6: =(M6*N6)-((M6*N6)*O6) -> 180 | R6: DIFERENCIA | S6: =S5-S4 -> 0
B7: PANCETA ADOBADA | C7: =4.5+8.5+4.3+8.8+3.8+9.8+7.8 -> 47.5 | D7: 8.8 | E7: 0 | F7: =(C7*D7)-((C7*D7)*E7) -> 418 | L7: PANCETA ADOBADA | M7: =3.9+4.1+3.1+3.9+6.8+6.9+7.4 -> 36.1 | N7: 8.8 | O7: 0 | P7: =(M7*N7)-((M7*N7)*O7) -> 317.68
B8: CAJA HUEVOS DE CORRAL | C8: =1+1+1 -> 3 | D8: 52.5 | E8: 0 | F8: =(C8*D8)-((C8*D8)*E8) -> 157.5 | H8: Nº ALBARÁN | I8: BASE | J8: % IVA | L8: HUESO FRESCO | M8: 6 | N8: 2 | O8: 0 | P8: =(M8*N8)-((M8*N8)*O8) -> 12 | R8: Nº ALBARÁN | S8: BASE | T8: % IVA
B9: POLLO TROCEADO | C9: =5.5+5.5+6.5 -> 17.5 | D9: 3.5 | E9: 0 | F9: =(C9*D9)-((C9*D9)*E9) -> 61.25 | H9: A2607-0444 | I9: 84.6 | J9: 0.1 | L9: HUESO DE TUETANO | M9: 6 | N9: 3 | O9: 0 | P9: =(M9*N9)-((M9*N9)*O9) -> 18 | R9: A2608-0010 | S9: 45 | T9: 0.1
B10: PALETILLA IBERICA | C10: 3.8 | D10: 36 | E10: 0 | F10: =(C10*D10)-((C10*D10)*E10) -> 136.8 | H10: A2607-0048 | I10: 172.3 | J10: 0.1 | L10: MORCILLA ASTURIANA | M10: 8.6 | N10: 9 | O10: 0 | P10: =(M10*N10)-((M10*N10)*O10) -> 77.4 | R10: A2608-0213 | S10: 285.02 | T10: 0.1
B11: OREJA DE CERDO | C11: =4.4+5.1 -> 9.5 | D11: 6 | E11: 0 | F11: =(C11*D11)-((C11*D11)*E11) -> 57 | H11: A2607-0010 | I11: 57.09 | J11: 0.1 | L11: MORRO DE TERNERA | M11: 4 | N11: 8.5 | O11: 0 | P11: =(M11*N11)-((M11*N11)*O11) -> 34 | R11: A2608-0233 | S11: 111.68 | T11: 0.1
B12: POLLO ENTERO | C12: 5.9 | D12: 3.5 | E12: 0 | F12: =(C12*D12)-((C12*D12)*E12) -> 20.65 | H12: A2607-0507 | I12: 208.55 | J12: 0.1 | L12: FALDA DE TERNERA | M12: 6.4 | N12: 11.5 | O12: 0 | P12: =(M12*N12)-((M12*N12)*O12) -> 73.6 | R12: A2608-0257 | S12: 27.28 | T12: 0.1
B13: GALLINAS | C13: 4.9 | D13: 3.75 | E13: 0 | F13: =(C13*D13)-((C13*D13)*E13) -> 18.375 | H13: A2607-0519 | I13: 77.44 | J13: 0.1 | L13: PATAS DE TERNERA | M13: 4.2 | N13: 8.5 | O13: 0 | P13: =(M13*N13)-((M13*N13)*O13) -> 35.7 | R13: A2608-0274 | S13: 67.32 | T13: 0.1
B14: MORCILLO DE TERNERA | C14: 3 | D14: 12.5 | E14: 0 | F14: =(C14*D14)-((C14*D14)*E14) -> 37.5 | H14: A2607-0476 | I14: 71.4 | J14: 0.1 | L14: OREJA DE CERDO | M14: =5.1+5.5+4.3 -> 14.9 | N14: 6 | O14: 0 | P14: =(M14*N14)-((M14*N14)*O14) -> 89.4 | R14: A2608-0327 | S14: 45 | T14: 0.1
B15: PATAS DE TERNERA | C15: 2 | D15: 8.5 | E15: 0 | F15: =(C15*D15)-((C15*D15)*E15) -> 17 | H15: A2607-0335 | I15: 64.04 | J15: 0.1 | L15: CAJA HUEVOS DE CORRAL | M15: 1 | N15: 52.5 | O15: 0 | P15: =(M15*N15)-((M15*N15)*O15) -> 52.5 | R15: A2608-0351 | S15: 104.84 | T15: 0.1
B16: MANOS DE CERDO | C16: 2.1 | D16: 4.5 | E16: 0 | F16: =(C16*D16)-((C16*D16)*E16) -> 9.45 | H16: A2607-0309 | I16: 161.49 | J16: 0.1 | R16: A2608-0356 | S16: 60.72 | T16: 0.1
B17: MORRO DE TERNERA | C17: 1 | D17: 8.5 | E17: 0 | F17: =(C17*D17)-((C17*D17)*E17) -> 8.5 | H17: A2607-0239 | I17: 189.12 | J17: 0.1 | R17: A2608-0379 | S17: 143.42 | T17: 0.1
B18: CHORIZO ASTURIANO | C18: 1 | D18: 9 | E18: 0 | F18: =(C18*D18)-((C18*D18)*E18) -> 9

Sheet _____CRUSTAPESCA
B2: 46204 | L2: 46235
H4: TOTAL | I4: =SUM(F6:F300) -> 1970.464 | R4: TOTAL | S4: =SUM(P6:P300) -> 772
B5: PRODUCTO | C5: UNIDADES | D5: PRECIO | E5: DTO | F5: TOTAL | H5: ALBARANES | I5: =SUM(I9:I300) -> 1970.46 | L5: PRODUCTO | M5: UNIDADES | N5: PRECIO | O5: DTO | P5: TOTAL | R5: ALBARANES | S5: =SUM(S9:S300) -> 772
B6: GAMBA FR M | C6: =18+3+3+3+6+3+6+3+4+3 -> 52 | D6: 26 | E6: 0 | F6: =(C6*D6)-((C6*D6)*E6) -> 1352 | H6: DIFERENCIA | I6: =I5-I4 -> -0.004 | L6: COLA GAMBON (abono) | M6: -5 | N6: 22 | O6: 0 | P6: =(M6*N6)-((M6*N6)*O6) -> -110 | R6: DIFERENCIA | S6: =S5-S4 -> 0
B7: VENTRESCA | C7: 4.84 | D7: 59.6 | E7: 0 | F7: =(C7*D7)-((C7*D7)*E7) -> 288.464 | L7: VENTRESCA (abono) | M7: -2 | N7: 59.8 | O7: 0 | P7: =(M7*N7)-((M7*N7)*O7) -> -119.6
B8: COLA G | C8: =4.5+6+6 -> 16.5 | D8: 20 | E8: 0 | F8: =(C8*D8)-((C8*D8)*E8) -> 330 | H8: Nº ALBARÁN | I8: BASE | J8: % IVA | L8: VENTRESCA | M8: 2 | N8: 59.8 | O8: 0 | P8: =(M8*N8)-((M8*N8)*O8) -> 119.6 | R8: Nº ALBARÁN | S8: BASE | T8: % IVA
H9: 10073 | I9: 78 | J9: 0.1 | L9: GAMBA FR M | M9: =3+3+3+3+3+3+3+6 -> 27 | N9: 26 | O9: 0 | P9: =(M9*N9)-((M9*N9)*O9) -> 702 | R9: 20081 (ABONO) | S9: -229.6 | T9: 0.1
H10: 9071 | I10: 156 | J10: 0.1 | L10: COLA G | M10: =4.5+4.5 -> 9 | N10: 20 | O10: 0 | P10: =(M10*N10)-((M10*N10)*O10) -> 180 | R10: 25081 | S10: 119.6 | T10: 0.1
H11: 8074 | I11: 288.46 | J11: 0.1 | R11: 27084 | S11: 78 | T11: 0.1
H12: 2074 | I12: 156 | J12: 0.1 | R12: 5081 | S12: 78 | T12: 0.1
H13: 1074 | I13: 78 | J13: 0.1 | R13: 6083 | S13: 78 | T13: 0.1
H14: 31074 | I14: 90 | J14: 0.1 | R14: 18086 | S14: 78 | T14: 0.1
H15: 30076 | I15: 78 | J15: 0.1 | R15: 19083 | S15: 78 | T15: 0.1
H16: 29074 | I16: 78 | J16: 0.1 | R16: S/N 22-08 | S16: 168 | T16: 0.1
H17: 28071 | I17: 198 | J17: 0.1 | R17: 25085 | S17: 78 | T17: 0.1
H18: 18071 | I18: 156 | J18: 0.1 | R18: 29082 | S18: 246 | T18: 0.1
H19: S/N 16-07 | I19: 78 | J19: 0.1
H20: 150710 | I20: 120 | J20: 0.1
H21: 14071 | I21: 156 | J21: 0.1
H22: 23077 | I22: 78 | J22: 0.1
H23: S/N 21-07 | I23: 104 | J23: 0.1
H24: S/N 24-07 | I24: 78 | J24: 0.1

Sheet _____DELIPAN
B2: 46204 | L2: 46235
H4: TOTAL | I4: =SUM(F6:F300) -> 1032.66 | R4: TOTAL | S4: =SUM(P6:P300) -> 381.21
B5: PRODUCTO | C5: UNIDADES | D5: PRECIO | E5: DTO | F5: TOTAL | H5: ALBARANES | I5: =SUM(I9:I300) -> 1032.66 | L5: PRODUCTO | M5: UNIDADES | N5: PRECIO | O5: DTO | P5: TOTAL | R5: ALBARANES | S5: =SUM(S9:S300) -> 381.21
B6: DELIPAN | C6: 4 | D6: 17.73 | E6: 0 | F6: =(C6*D6)-((C6*D6)*E6) -> 70.92 | H6: DIFERENCIA | I6: =I5-I4 -> 0 | L6: PICOS ARTESANOS 500gr | M6: =2+2+3 -> 7 | N6: 11.48 | O6: 0 | P6: =(M6*N6)-((M6*N6)*O6) -> 80.36 | R6: DIFERENCIA | S6: =S5-S4 -> 0
B7: PICOS ARTESANOS 500gr | C7: =5+2+1+2+2+2 -> 14 | D7: 11.48 | E7: 0 | F7: =(C7*D7)-((C7*D7)*E7) -> 160.72 | L7: DELIFLAUTA 17 PERRITO 90 uds | M7: =1+2+3+3+3 -> 12 | N7: 17.73 | O7: 0 | P7: =(M7*N7)-((M7*N7)*O7) -> 212.76
B8: DELIFLAUTA 17 PERRITO 90 uds | C8: =3+4+3+2+4+4+5+4 -> 29 | D8: 17.73 | E8: 0 | F8: =(C8*D8)-((C8*D8)*E8) -> 514.17 | H8: Nº ALBARÁN | I8: BASE | J8: % IVA | L8: PAN MOLDE BRIOCHE (7 ud) | M8: 1 | N8: 88.09 | O8: 0 | P8: =(M8*N8)-((M8*N8)*O8) -> 88.09 | R8: Nº ALBARÁN | S8: BASE | T8: % IVA
B9: PAN MOLDE BRIOCHE (7 ud) | C9: =1+1+1 -> 3 | D9: 88.09 | E9: 0 | F9: =(C9*D9)-((C9*D9)*E9) -> 264.27 | H9: A2/8520 | I9: 105.36 | J9: 0.04 | R9: A2/9526 | S9: 88.09 | T9: 0.1
B10: PICOS SIN GLUTEN 20gr (25 uds) | C10: =1+1 -> 2 | D10: 11.29 | E10: 0 | F10: =(C10*D10)-((C10*D10)*E10) -> 22.58 | H10: A2/8358 | I10: 88.09 | J10: 0.1 | R10: A2/9526 | S10: 40.69 | T10: 0.04
H11: A2/8358 | I11: 76.15 | J11: 0.04 | R11: A2/9861 | S11: 35.46 | T11: 0.04
H12: A2/8248 | I12: 105.17 | J12: 0.04 | R12: A2/10002 | S12: 76.15 | T12: 0.04
H13: A2/9083 | I13: 88.09 | J13: 0.1 | R13: A2/10106 | S13: 53.19 | T13: 0.04
H14: A2/9083 | I14: 75.96 | J14: 0.04 | R14: A2/10260 | S14: 87.63 | T14: 0.04
H15: A2/8944 | I15: 35.46 | J15: 0.04
H16: A2/8841 | I16: 93.88 | J16: 0.04
H17: A2/8675 | I17: 88.09 | J17: 0.1
H18: A2/8675 | I18: 93.88 | J18: 0.04
H19: A2/9337 | I19: 88.65 | J19: 0.04
H20: A2/9201 | I20: 93.88 | J20: 0.04

Sheet _____DISOLTRIGO
B2: 46204 | L2: 46235
H4: TOTAL | I4: =SUM(F6:F300) -> 1295.5 | R4: TOTAL | S4: =SUM(P6:P300) -> 318
B5: PRODUCTO | C5: UNIDADES | D5: PRECIO | E5: DTO | F5: TOTAL | H5: ALBARANES | I5: =SUM(I9:I300) -> 1295.5 | L5: PRODUCTO | M5: UNIDADES | N5: PRECIO | O5: DTO | P5: TOTAL | R5: ALBARANES | S5: =SUM(S9:S300) -> 318
B6: BOQUERON EN VINAGRE PANDERETA | C6: =8+8+8+8 -> 32 | D6: 19 | E6: 0 | F6: =(C6*D6)-((C6*D6)*E6) -> 608 | H6: DIFERENCIA | I6: =I5-I4 -> 0 | L6: 24 PERLE NOIRE N.2 | M6: =2+2 -> 4 | N6: 41.5 | O6: 0 | P6: =(M6*N6)-((M6*N6)*O6) -> 166 | R6: DIFERENCIA | S6: =S5-S4 -> 0
B7: 24 PERLE NOIRE N.2 | C7: =2+4+1+3+3 -> 13 | D7: 41.5 | E7: 0 | F7: =(C7*D7)-((C7*D7)*E7) -> 539.5 | L7: BOQUERON EN VINAGRE PANDERETA | M7: 8 | N7: 19 | O7: 0 | P7: =(M7*N7)-((M7*N7)*O7) -> 152
B8: BOQUERON CASERO EN ACEITE 700g | C8: 8 | D8: 18.5 | E8: 0 | F8: =(C8*D8)-((C8*D8)*E8) -> 148 | H8: Nº ALBARÁN | I8: BASE | J8: % IVA | R8: Nº ALBARÁN | S8: BASE | T8: % IVA
H9: 134806 | I9: 152 | J9: 0.1 | R9: 135823 | S9: 83 | T9: 0.1
H10: 134789 | I10: 83 | J10: 0.1 | R10: 136005 | S10: 235 | T10: 0.1
H11: 134442 | I11: 314 | J11: 0.1
H12: 135177 | I12: 193.5 | J12: 0.1
H13: 135027 | I13: 276.5 | J13: 0.1
H14: 135362 | I14: 276.5 | J14: 0.1

Sheet _____DIST. TENA
B2: 46204 | L2: 46235
H4: TOTAL | I4: =SUM(F6:F300) -> 3131.64 | R4: TOTAL | S4: =SUM(P6:P300) -> 1320.36
B5: PRODUCTO | C5: UNIDADES | D5: PRECIO | E5: DTO | F5: TOTAL | H5: ALBARANES | I5: =SUM(I9:I300) -> 3131.64 | L5: PRODUCTO | M5: UNIDADES | N5: PRECIO | O5: DTO | P5: TOTAL | R5: ALBARANES | S5: =SUM(S9:S300) -> 1320.36
B6: ALBARIÑO MAR DE FRADES | C6: =(23)*6 -> 138 | D6: 11.42 | E6: 0 | F6: =(C6*D6)-((C6*D6)*E6) -> 1575.96 | H6: DIFERENCIA | I6: =I5-I4 -> 0 | L6: ALBARIÑO MAR DE FRADES | M6: =(8+2)*6 -> 60 | N6: 11.42 | O6: 0 | P6: =(M6*N6)-((M6*N6)*O6) -> 685.2 | R6: DIFERENCIA | S6: =S5-S4 -> 0
B7: CAVA BRUT NATURE GRAN CLAUSTRO | C7: =(2)*6 -> 12 | D7: 15.12 | E7: 0 | F7: =(C7*D7)-((C7*D7)*E7) -> 181.44 | L7: CHARDONAY LIAS ECOLOGICO F.ELEZ | M7: =(3)*6 -> 18 | N7: 9.02 | O7: 0 | P7: =(M7*N7)-((M7*N7)*O7) -> 162.36
B8: CHARDONAY LIAS ECOLOGICO F.ELEZ | C8: =(6)*6 -> 36 | D8: 9.02 | E8: 0 | F8: =(C8*D8)-((C8*D8)*E8) -> 324.72 | H8: Nº ALBARÁN | I8: BASE | J8: % IVA | L8: SEÑORIO DE FITERO ROBLE | M8: =(5+3)*6 -> 48 | N8: 2.82 | O8: 0 | P8: =(M8*N8)-((M8*N8)*O8) -> 135.36 | R8: Nº ALBARÁN | S8: BASE | T8: % IVA
B9: GINEBRA MARTIN MILLER 3/4 | C9: =(3)*6 -> 18 | D9: 16.1 | E9: 0 | F9: =(C9*D9)-((C9*D9)*E9) -> 289.8 | H9: FD 2221 | I9: 137.04 | J9: 0.21 | L9: GODELLO VIÑAREDO | M9: =(2+2)*12 -> 48 | N9: 7.03 | O9: 0 | P9: =(M9*N9)-((M9*N9)*O9) -> 337.44 | R9: FD 2485 | S9: 795.12 | T9: 0.21
B10: GODELLO VIÑAREDO | C10: =(7)*12 -> 84 | D10: 7.03 | E10: 0 | F10: =(C10*D10)-((C10*D10)*E10) -> 590.52 | H10: FD 2267 | I10: 488.88 | J10: 0.21 | R10: FD 2606 | S10: 356.52 | T10: 0.21
B11: SEÑORIO DE FITERO ROBLE | C11: =(10)*6 -> 60 | D11: 2.82 | E11: 0 | F11: =(C11*D11)-((C11*D11)*E11) -> 169.2 | H11: FD 2309 | I11: 799.08 | J11: 0.21 | R11: FD 2650 | S11: 168.72 | T11: 0.21
H12: FD 2334 | I12: 411.12 | J12: 0.21
H13: FD 2369 | I13: 765.48 | J13: 0.21
H14: FD 2419 | I14: 530.04 | J14: 0.21

Sheet _____EIF DISTRIBUCIONES
B2: 46204 | L2: 46235
H4: TOTAL | I4: =SUM(F6:F300) -> 646.5718 | R4: TOTAL | S4: =SUM(P6:P300) -> 604.0463
B5: PRODUCTO | C5: UNIDADES | D5: PRECIO | E5: DTO | F5: TOTAL | H5: ALBARANES | I5: =SUM(I9:I300) -> 646.58 | L5: PRODUCTO | M5: UNIDADES | N5: PRECIO | O5: DTO | P5: TOTAL | R5: ALBARANES | S5: =SUM(S9:S300) -> 604.05
B6: IZAGUIRRE BOX 20L | C6: 2 | D6: 120.15 | E6: 0.03 | F6: =(C6*D6)-((C6*D6)*E6) -> 233.091 | H6: DIFERENCIA | I6: =I5-I4 -> 0.0082 | L6: IZAGUIRRE BOX 20L | M6: 1 | N6: 120.15 | O6: 0.03 | P6: =(M6*N6)-((M6*N6)*O6) -> 116.5455 | R6: DIFERENCIA | S6: =S5-S4 -> 0.0037
B7: RED BULL | C7: 3 | D7: 20.88 | E7: 0 | F7: =(C7*D7)-((C7*D7)*E7) -> 62.64 | L7: ALBARAN | M7: =1+1 -> 2 | N7: 1 | O7: 0 | P7: =(M7*N7)-((M7*N7)*O7) -> 2
B8: ALBARAN | C8: 4 | D8: 1 | E8: 0 | F8: =(C8*D8)-((C8*D8)*E8) -> 4 | H8: Nº ALBARÁN | I8: BASE | J8: % IVA | L8: SCHWEPPES TONICA RET 28 UDS | M8: 5 | N8: 24.84 | O8: 0 | P8: =(M8*N8)-((M8*N8)*O8) -> 124.2 | R8: Nº ALBARÁN | S8: BASE | T8: % IVA
B9: SOLAN DE CABRAS CON GAS | C9: 5 | D9: 26.8 | E9: 0 | F9: =(C9*D9)-((C9*D9)*E9) -> 134 | H9: 2026/1/18961 | I9: 138.43 | J9: 0.21 | L9: COCA COLA ZERO NAC RET | M9: 4 | N9: 21.78 | O9: 0 | P9: =(M9*N9)-((M9*N9)*O9) -> 87.12 | R9: 2026/1/23727 | S9: 117.55 | T9: 0.21
B10: BARCELO AÑEJO | C10: 12 | D10: 12.72 | E10: 0.03 | F10: =(C10*D10)-((C10*D10)*E10) -> 148.0608 | H10: 2026/1/19030 | I10: 134 | J10: 0.1 | L10: MAHOU 0,0 TOSTADA | M10: 3 | N10: 23.85 | O10: 0 | P10: =(M10*N10)-((M10*N10)*O10) -> 71.55 | R10: 2026/1/24261 | S10: 283.84 | T10: 0.21
B11: RED BULL SIN AZUCAR | C11: 1 | D11: 20.88 | E11: 0 | F11: =(C11*D11)-((C11*D11)*E11) -> 20.88 | H11: 2026/1/19510 | I11: 149.06 | J11: 0.21 | L11: ALBARAN | M11: 1 | N11: 1 | O11: 0.03 | P11: =(M11*N11)-((M11*N11)*O11) -> 0.97 | R11: 2026/1/24376 | S11: 53.6 | T11: 0.1
B12: MAHOU SIN GLUTEN | C12: 2 | D12: 21.95 | E12: 0 | F12: =(C12*D12)-((C12*D12)*E12) -> 43.9 | H12: 2026/1/20194 | I12: 180.19 | J12: 0.21 | L12: SOLAN DE CABRAS CON GAS | M12: 2 | N12: 26.8 | O12: 0 | P12: =(M12*N12)-((M12*N12)*O12) -> 53.6 | R12: 2026/1/24376 | S12: 1 | T12: 0.21
H13: 2026/1/20864 | I13: 44.9 | J13: 0.21 | L13: BARCELO AÑEJO | M13: 12 | N13: 12.72 | O13: 0.03 | P13: =(M13*N13)-((M13*N13)*O13) -> 148.0608 | R13: 2026/1/24385 | S13: 148.06 | T13: 0.21

Sheet _____ENRIQUE CAMPS
B2: 46204 | L2: 46235
H4: TOTAL | I4: =SUM(F6:F300) -> 1189 | R4: TOTAL | S4: =SUM(P6:P300) -> 432
B5: PRODUCTO | C5: UNIDADES | D5: PRECIO | E5: DTO | F5: TOTAL | H5: ALBARANES | I5: =SUM(I9:I300) -> 1189 | L5: PRODUCTO | M5: UNIDADES | N5: PRECIO | O5: DTO | P5: TOTAL | R5: ALBARANES | S5: =SUM(S9:S300) -> 432
B6: TARTA CHOCOLATE | C6: =2+4+2+1+3+3+2 -> 17 | D6: 37 | E6: 0 | F6: =(C6*D6)-((C6*D6)*E6) -> 629 | H6: DIFERENCIA | I6: =I5-I4 -> 0 | L6: TARTA QUESO | M6: =3+3 -> 6 | N6: 35 | O6: 0 | P6: =(M6*N6)-((M6*N6)*O6) -> 210 | R6: DIFERENCIA | S6: =S5-S4 -> 0
B7: TARTA QUESO | C7: =1+4+2+1+3+3+2 -> 16 | D7: 35 | E7: 0 | F7: =(C7*D7)-((C7*D7)*E7) -> 560 | L7: TARTA CHOCOLATE | M7: =3+3 -> 6 | N7: 37 | O7: 0 | P7: =(M7*N7)-((M7*N7)*O7) -> 222
H8: Nº ALBARÁN | I8: BASE | J8: % IVA | R8: Nº ALBARÁN | S8: BASE | T8: % IVA
H9: A26/1816 | I9: 109 | J9: 0.1 | R9: A26/2164 | S9: 216 | T9: 0.1
H10: A26/1739 | I10: 288 | J10: 0.1 | R10: A26/2116 | S10: 216 | T10: 0.1
H11: A26/1957 | I11: 144 | J11: 0.1
H12: A26/2026 | I12: 72 | J12: 0.1
H13: A26/1984 | I13: 216 | J13: 0.1
H14: A26/1892 | I14: 216 | J14: 0.1
H15: A26/1840 | I15: 144 | J15: 0.1

Sheet _____ESCRIBANO SANZ
B2: 46204 | L2: 46235
H4: TOTAL | I4: =SUM(F6:F300) -> 193.69 | R4: TOTAL | S4: =SUM(P6:P300) -> 84.48
B5: PRODUCTO | C5: UNIDADES | D5: PRECIO | E5: DTO | F5: TOTAL | H5: ALBARANES | I5: =SUM(I9:I300) -> 193.7 | L5: PRODUCTO | M5: UNIDADES | N5: PRECIO | O5: DTO | P5: TOTAL | R5: ALBARANES | S5: =SUM(S9:S300) -> 84.48
B6: LOMO BELLOTA 100% | C6: =1.15 -> 1.15 | D6: 48.6 | E6: 0 | F6: =(C6*D6)-((C6*D6)*E6) -> 55.89 | H6: DIFERENCIA | I6: =I5-I4 -> 0.01 | L6: LOMO BELLOTA 100% | M6: 1.1 | N6: 51 | O6: 0 | P6: =(M6*N6)-((M6*N6)*O6) -> 56.1 | R6: DIFERENCIA | S6: =S5-S4 -> 0
B7: PAPADA IBERICA | C7: =10+15 -> 25 | D7: 2.3 | E7: 0 | F7: =(C7*D7)-((C7*D7)*E7) -> 57.5 | L7: SALCHICHON IBERICO | M7: 1.29 | N7: 22 | O7: 0 | P7: =(M7*N7)-((M7*N7)*O7) -> 28.38
B8: SALCHICHON IBERICO | C8: 1.1 | D8: 22 | E8: 0 | F8: =(C8*D8)-((C8*D8)*E8) -> 24.2 | H8: Nº ALBARÁN | I8: BASE | J8: % IVA | R8: Nº ALBARÁN | S8: BASE | T8: % IVA
B9: LOMO BELLOTA 100% | C9: 1.1 | D9: 51 | E9: 0 | F9: =(C9*D9)-((C9*D9)*E9) -> 56.1 | H9: 371 | I9: 78.9 | J9: 0.1 | R9: 0613 | S9: 84.48 | T9: 0.1
H10: 0465 | I10: 80.3 | J10: 0.1
H11: 0524 | I11: 34.5 | J11: 0.1

Sheet _____FCO JAVIER LABRADOR
B2: 46204 | L2: 46235
H4: TOTAL | I4: =SUM(F6:F300) -> 183.2 | R4: TOTAL | S4: =SUM(P6:P300) -> 91.6
B5: PRODUCTO | C5: UNIDADES | D5: PRECIO | E5: DTO | F5: TOTAL | H5: ALBARANES | I5: =SUM(I9:I300) -> 183.2 | L5: PRODUCTO | M5: UNIDADES | N5: PRECIO | O5: DTO | P5: TOTAL | R5: ALBARANES | S5: =SUM(S9:S300) -> 91.6
B6: FLOR DE ALCACHOFA CONFITADA A. ORUJO (20 uds) | C6: =4+4 -> 8 | D6: 22.9 | E6: 0 | F6: =(C6*D6)-((C6*D6)*E6) -> 183.2 | H6: DIFERENCIA | I6: =I5-I4 -> 0 | L6: FLOR DE ALCACHOFA CONFITADA A. ORUJO (20 uds) | M6: 4 | N6: 22.9 | O6: 0 | P6: =(M6*N6)-((M6*N6)*O6) -> 91.6 | R6: DIFERENCIA | S6: =S5-S4 -> 0
H8: Nº ALBARÁN | I8: BASE | J8: % IVA | R8: Nº ALBARÁN | S8: BASE | T8: % IVA
H9: 01-07/26 | I9: 91.6 | J9: 0.1 | R9: 01-08/26 | S9: 91.6 | T9: 0.1
H10: 02-07/26 | I10: 91.6 | J10: 0.1

Sheet _____FRUTERIA DALISTE
B2: 46204
H4: TOTAL | I4: =SUM(F6:F300) -> 158.9995
B5: PRODUCTO | C5: UNIDADES | D5: PRECIO | E5: DTO | F5: TOTAL | H5: ALBARANES | I5: =SUM(I9:I300) -> 158.99
B6: LIMON | C6: =9.18 -> 9.18 | D6: 3.6 | E6: 0 | F6: =(C6*D6)-((C6*D6)*E6) -> 33.048 | H6: DIFERENCIA | I6: =I5-I4 -> -0.0095
B7: PIMIENTO ROJO | C7: =3.115 -> 3.115 | D7: 4.3 | E7: 0 | F7: =(C7*D7)-((C7*D7)*E7) -> 13.3945
B8: CEBOLLETA CHINA | C8: 2 | D8: 2.2 | E8: 0 | F8: =(C8*D8)-((C8*D8)*E8) -> 4.4 | H8: Nº ALBARÁN | I8: BASE | J8: % IVA
B9: PEREJIL | C9: 1 | D9: 1.6 | E9: 0 | F9: =(C9*D9)-((C9*D9)*E9) -> 1.6 | H9: 08/07/2026 | I9: 91.2 | J9: 0.04
B10: TOMATE IBERICO | C10: =5.96+5.205 -> 11.165 | D10: 5.8 | E10: 0 | F10: =(C10*D10)-((C10*D10)*E10) -> 64.757 | H10: 03/07/2026 | I10: 67.79 | J10: 0.04
B11: LECHUGA BATAVIA | C11: 2 | D11: 2.1 | E11: 0 | F11: =(C11*D11)-((C11*D11)*E11) -> 4.2
B12: CEBOLLETAS | C12: 6 | D12: 2.1 | E12: 0 | F12: =(C12*D12)-((C12*D12)*E12) -> 12.6
B13: PATATAS CREMA (saco 25 kg) | C13: 1 | D13: 25 | E13: 0 | F13: =(C13*D13)-((C13*D13)*E13) -> 25

Sheet _____JC MACKINTOSH
B2: 46235
H4: TOTAL | I4: =SUM(F6:F300) -> 516
